{
  "version": 8,
  "blockIdVersion": 11,
  "anchorX": 8,
  "anchorY": 3,
  "anchorZ": 7,
  "blocks": [
    {
      "x": 7,
      "y": 6,
      "z": 6,
      "name": "TFJ_Titanwood_Log"
    },
    {
      "x": 7,
      "y": 7,
      "z": 6,
      "name": "TFJ_Titanwood_Log"
    },
    {
      "x": 7,
      "y": 5,
      "z": 7,
      "name": "TFJ_Titanwood_Log"
    },
    {
      "x": 8,
      "y": 8,
      "z": 3,
      "name": "TFJ_Canopy_Leaves"
    },
    {
      "x": 8,
      "y": 8,
      "z": 4,
      "name": "TFJ_Canopy_Leaves"
    },
    {
      "x": 8,
      "y": 7,
      "z": 5,
      "name": "TFJ_Titanwood_Log"
    },
    {
      "x": 8,
      "y": 8,
      "z": 5,
      "name": "TFJ_Titanwood_Log"
    },
    {
      "x": 8,
      "y": 3,
      "z": 7,
      "name": "TFJ_Titanwood_Log"
    },
    {
      "x": 8,
      "y": 4,
      "z": 7,
      "name": "TFJ_Titanwood_Log"
    },
    {
      "x": 8,
      "y": 5,
      "z": 7,
      "name": "TFJ_Titanwood_Log"
    },
    {
      "x": 8,
      "y": 6,
      "z": 7,
      "name": "TFJ_Titanwood_Log"
    },
    {
      "x": 9,
      "y": 8,
      "z": 2,
      "name": "TFJ_Canopy_Leaves"
    },
    {
      "x": 9,
      "y": 9,
      "z": 2,
      "name": "TFJ_Canopy_Leaves"
    },
    {
      "x": 9,
      "y": 9,
      "z": 3,
      "name": "TFJ_Canopy_Leaves"
    },
    {
      "x": 9,
      "y": 8,
      "z": 4,
      "name": "TFJ_Titanwood_Log"
    },
    {
      "x": 9,
      "y": 9,
      "z": 4,
      "name": "TFJ_Canopy_Leaves"
    },
    {
      "x": 9,
      "y": 8,
      "z": 5,
      "name": "TFJ_Titanwood_Log"
    },
    {
      "x": 9,
      "y": 6,
      "z": 7,
      "name": "TFJ_Titanwood_Log"
    },
    {
      "x": 9,
      "y": 7,
      "z": 7,
      "name": "TFJ_Titanwood_Log"
    },
    {
      "x": 9,
      "y": 7,
      "z": 8,
      "name": "TFJ_Canopy_Leaves"
    },
    {
      "x": 9,
      "y": 8,
      "z": 8,
      "name": "TFJ_Canopy_Leaves"
    },
    {
      "x": 10,
      "y": 8,
      "z": 1,
      "name": "TFJ_Canopy_Leaves"
    },
    {
      "x": 10,
      "y": 8,
      "z": 2,
      "name": "TFJ_Canopy_Leaves"
    },
    {
      "x": 10,
      "y": 8,
      "z": 3,
      "name": "TFJ_Canopy_Leaves"
    },
    {
      "x": 10,
      "y": 9,
      "z": 3,
      "name": "TFJ_Canopy_Leaves"
    },
    {
      "x": 10,
      "y": 8,
      "z": 4,
      "name": "TFJ_Titanwood_Log"
    },
    {
      "x": 10,
      "y": 9,
      "z": 4,
      "name": "TFJ_Canopy_Leaves"
    },
    {
      "x": 10,
      "y": 8,
      "z": 5,
      "name": "TFJ_Canopy_Leaves"
    },
    {
      "x": 10,
      "y": 7,
      "z": 7,
      "name": "TFJ_Titanwood_Log"
    },
    {
      "x": 10,
      "y": 7,
      "z": 8,
      "name": "TFJ_Titanwood_Log"
    },
    {
      "x": 10,
      "y": 8,
      "z": 8,
      "name": "TFJ_Canopy_Leaves"
    },
    {
      "x": 10,
      "y": 7,
      "z": 9,
      "name": "TFJ_Canopy_Leaves"
    },
    {
      "x": 10,
      "y": 8,
      "z": 9,
      "name": "TFJ_Canopy_Leaves"
    },
    {
      "x": 10,
      "y": 8,
      "z": 10,
      "name": "TFJ_Canopy_Leaves"
    },
    {
      "x": 11,
      "y": 8,
      "z": 1,
      "name": "TFJ_Canopy_Leaves"
    },
    {
      "x": 11,
      "y": 7,
      "z": 2,
      "name": "TFJ_Canopy_Leaves"
    },
    {
      "x": 11,
      "y": 8,
      "z": 2,
      "name": "TFJ_Canopy_Leaves"
    },
    {
      "x": 11,
      "y": 8,
      "z": 3,
      "name": "TFJ_Canopy_Leaves"
    },
    {
      "x": 11,
      "y": 9,
      "z": 3,
      "name": "TFJ_Canopy_Leaves"
    },
    {
      "x": 11,
      "y": 8,
      "z": 4,
      "name": "TFJ_Titanwood_Log"
    },
    {
      "x": 11,
      "y": 9,
      "z": 4,
      "name": "TFJ_Canopy_Leaves"
    },
    {
      "x": 11,
      "y": 8,
      "z": 5,
      "name": "TFJ_Canopy_Leaves"
    },
    {
      "x": 11,
      "y": 7,
      "z": 7,
      "name": "TFJ_Canopy_Leaves"
    },
    {
      "x": 11,
      "y": 8,
      "z": 7,
      "name": "TFJ_Canopy_Leaves"
    },
    {
      "x": 11,
      "y": 7,
      "z": 8,
      "name": "TFJ_Titanwood_Log"
    },
    {
      "x": 11,
      "y": 8,
      "z": 8,
      "name": "TFJ_Canopy_Leaves"
    },
    {
      "x": 11,
      "y": 7,
      "z": 9,
      "name": "TFJ_Canopy_Leaves"
    },
    {
      "x": 11,
      "y": 8,
      "z": 9,
      "name": "TFJ_Canopy_Leaves"
    },
    {
      "x": 11,
      "y": 7,
      "z": 10,
      "name": "TFJ_Canopy_Leaves"
    },
    {
      "x": 12,
      "y": 7,
      "z": 1,
      "name": "TFJ_Canopy_Leaves"
    },
    {
      "x": 12,
      "y": 7,
      "z": 2,
      "name": "TFJ_Canopy_Leaves"
    },
    {
      "x": 12,
      "y": 8,
      "z": 2,
      "name": "TFJ_Canopy_Leaves"
    },
    {
      "x": 12,
      "y": 8,
      "z": 3,
      "name": "TFJ_Canopy_Leaves"
    },
    {
      "x": 12,
      "y": 9,
      "z": 3,
      "name": "TFJ_Canopy_Leaves"
    },
    {
      "x": 12,
      "y": 8,
      "z": 4,
      "name": "TFJ_Canopy_Leaves"
    },
    {
      "x": 12,
      "y": 9,
      "z": 4,
      "name": "TFJ_Canopy_Leaves"
    },
    {
      "x": 12,
      "y": 8,
      "z": 5,
      "name": "TFJ_Canopy_Leaves"
    },
    {
      "x": 12,
      "y": 8,
      "z": 6,
      "name": "TFJ_Canopy_Leaves"
    },
    {
      "x": 12,
      "y": 7,
      "z": 7,
      "name": "TFJ_Canopy_Leaves"
    },
    {
      "x": 12,
      "y": 8,
      "z": 7,
      "name": "TFJ_Canopy_Leaves"
    },
    {
      "x": 12,
      "y": 9,
      "z": 7,
      "name": "TFJ_Canopy_Leaves"
    },
    {
      "x": 12,
      "y": 7,
      "z": 8,
      "name": "TFJ_Canopy_Leaves"
    },
    {
      "x": 12,
      "y": 8,
      "z": 8,
      "name": "TFJ_Canopy_Leaves"
    },
    {
      "x": 12,
      "y": 9,
      "z": 8,
      "name": "TFJ_Canopy_Leaves"
    },
    {
      "x": 12,
      "y": 7,
      "z": 9,
      "name": "TFJ_Canopy_Leaves"
    },
    {
      "x": 12,
      "y": 8,
      "z": 9,
      "name": "TFJ_Canopy_Leaves"
    },
    {
      "x": 12,
      "y": 7,
      "z": 10,
      "name": "TFJ_Canopy_Leaves"
    },
    {
      "x": 12,
      "y": 8,
      "z": 10,
      "name": "TFJ_Canopy_Leaves"
    },
    {
      "x": 12,
      "y": 7,
      "z": 11,
      "name": "TFJ_Canopy_Leaves"
    },
    {
      "x": 13,
      "y": 6,
      "z": 1,
      "name": "TFJ_Canopy_Leaves"
    },
    {
      "x": 13,
      "y": 7,
      "z": 1,
      "name": "TFJ_Canopy_Leaves"
    },
    {
      "x": 13,
      "y": 6,
      "z": 2,
      "name": "TFJ_Canopy_Leaves"
    },
    {
      "x": 13,
      "y": 7,
      "z": 2,
      "name": "TFJ_Canopy_Leaves"
    },
    {
      "x": 13,
      "y": 8,
      "z": 2,
      "name": "TFJ_Canopy_Leaves"
    },
    {
      "x": 13,
      "y": 7,
      "z": 3,
      "name": "TFJ_Canopy_Leaves"
    },
    {
      "x": 13,
      "y": 8,
      "z": 3,
      "name": "TFJ_Canopy_Leaves"
    },
    {
      "x": 13,
      "y": 7,
      "z": 4,
      "name": "TFJ_Canopy_Leaves"
    },
    {
      "x": 13,
      "y": 8,
      "z": 4,
      "name": "TFJ_Canopy_Leaves"
    },
    {
      "x": 13,
      "y": 8,
      "z": 8,
      "name": "TFJ_Canopy_Leaves"
    },
    {
      "x": 13,
      "y": 9,
      "z": 8,
      "name": "TFJ_Canopy_Leaves"
    },
    {
      "x": 13,
      "y": 8,
      "z": 9,
      "name": "TFJ_Canopy_Leaves"
    },
    {
      "x": 13,
      "y": 7,
      "z": 10,
      "name": "TFJ_Canopy_Leaves"
    },
    {
      "x": 13,
      "y": 7,
      "z": 11,
      "name": "TFJ_Canopy_Leaves"
    },
    {
      "x": 14,
      "y": 8,
      "z": 8,
      "name": "TFJ_Canopy_Leaves"
    },
    {
      "x": 14,
      "y": 8,
      "z": 9,
      "name": "TFJ_Canopy_Leaves"
    }
  ],
  "fluids": [],
  "entities": []
}
