{
  "version": 8,
  "blockIdVersion": 11,
  "anchorX": 8,
  "anchorY": 3,
  "anchorZ": 7,
  "blocks": [
    {
      "x": 1,
      "y": 8,
      "z": 0,
      "name": "TFJ_Canopy_Leaves"
    },
    {
      "x": 1,
      "y": 8,
      "z": 1,
      "name": "TFJ_Canopy_Leaves"
    },
    {
      "x": 1,
      "y": 9,
      "z": 1,
      "name": "TFJ_Canopy_Leaves"
    },
    {
      "x": 1,
      "y": 9,
      "z": 3,
      "name": "TFJ_Canopy_Leaves"
    },
    {
      "x": 1,
      "y": 9,
      "z": 4,
      "name": "TFJ_Canopy_Leaves"
    },
    {
      "x": 2,
      "y": 8,
      "z": 0,
      "name": "TFJ_Canopy_Leaves"
    },
    {
      "x": 2,
      "y": 8,
      "z": 1,
      "name": "TFJ_Canopy_Leaves"
    },
    {
      "x": 2,
      "y": 9,
      "z": 1,
      "name": "TFJ_Canopy_Leaves"
    },
    {
      "x": 2,
      "y": 9,
      "z": 2,
      "name": "TFJ_Canopy_Leaves"
    },
    {
      "x": 2,
      "y": 9,
      "z": 3,
      "name": "TFJ_Canopy_Leaves"
    },
    {
      "x": 2,
      "y": 9,
      "z": 4,
      "name": "TFJ_Canopy_Leaves"
    },
    {
      "x": 3,
      "y": 8,
      "z": 0,
      "name": "TFJ_Canopy_Leaves"
    },
    {
      "x": 3,
      "y": 8,
      "z": 1,
      "name": "TFJ_Canopy_Leaves"
    },
    {
      "x": 3,
      "y": 9,
      "z": 2,
      "name": "TFJ_Canopy_Leaves"
    },
    {
      "x": 3,
      "y": 9,
      "z": 3,
      "name": "TFJ_Canopy_Leaves"
    },
    {
      "x": 3,
      "y": 10,
      "z": 3,
      "name": "TFJ_Canopy_Leaves"
    },
    {
      "x": 3,
      "y": 9,
      "z": 4,
      "name": "TFJ_Canopy_Leaves"
    },
    {
      "x": 3,
      "y": 9,
      "z": 5,
      "name": "TFJ_Canopy_Leaves"
    },
    {
      "x": 3,
      "y": 9,
      "z": 6,
      "name": "TFJ_Canopy_Leaves"
    },
    {
      "x": 3,
      "y": 9,
      "z": 7,
      "name": "TFJ_Canopy_Leaves"
    },
    {
      "x": 4,
      "y": 8,
      "z": 0,
      "name": "TFJ_Canopy_Leaves"
    },
    {
      "x": 4,
      "y": 9,
      "z": 2,
      "name": "TFJ_Canopy_Leaves"
    },
    {
      "x": 4,
      "y": 9,
      "z": 3,
      "name": "TFJ_Canopy_Leaves"
    },
    {
      "x": 4,
      "y": 10,
      "z": 3,
      "name": "TFJ_Canopy_Leaves"
    },
    {
      "x": 4,
      "y": 9,
      "z": 4,
      "name": "TFJ_Canopy_Leaves"
    },
    {
      "x": 4,
      "y": 10,
      "z": 4,
      "name": "TFJ_Canopy_Leaves"
    },
    {
      "x": 4,
      "y": 9,
      "z": 5,
      "name": "TFJ_Canopy_Leaves"
    },
    {
      "x": 4,
      "y": 9,
      "z": 7,
      "name": "TFJ_Canopy_Leaves"
    },
    {
      "x": 4,
      "y": 8,
      "z": 8,
      "name": "TFJ_Canopy_Leaves"
    },
    {
      "x": 5,
      "y": 9,
      "z": 1,
      "name": "TFJ_Canopy_Leaves"
    },
    {
      "x": 5,
      "y": 9,
      "z": 2,
      "name": "TFJ_Canopy_Leaves"
    },
    {
      "x": 5,
      "y": 10,
      "z": 2,
      "name": "TFJ_Canopy_Leaves"
    },
    {
      "x": 5,
      "y": 9,
      "z": 3,
      "name": "TFJ_Titanwood_Log"
    },
    {
      "x": 5,
      "y": 10,
      "z": 3,
      "name": "TFJ_Canopy_Leaves"
    },
    {
      "x": 5,
      "y": 9,
      "z": 4,
      "name": "TFJ_Titanwood_Log"
    },
    {
      "x": 5,
      "y": 10,
      "z": 4,
      "name": "TFJ_Canopy_Leaves"
    },
    {
      "x": 5,
      "y": 10,
      "z": 5,
      "name": "TFJ_Canopy_Leaves"
    },
    {
      "x": 5,
      "y": 8,
      "z": 7,
      "name": "TFJ_Canopy_Leaves"
    },
    {
      "x": 5,
      "y": 9,
      "z": 7,
      "name": "TFJ_Canopy_Leaves"
    },
    {
      "x": 5,
      "y": 8,
      "z": 8,
      "name": "TFJ_Canopy_Leaves"
    },
    {
      "x": 6,
      "y": 9,
      "z": 2,
      "name": "TFJ_Canopy_Leaves"
    },
    {
      "x": 6,
      "y": 9,
      "z": 3,
      "name": "TFJ_Canopy_Leaves"
    },
    {
      "x": 6,
      "y": 9,
      "z": 4,
      "name": "TFJ_Titanwood_Log"
    },
    {
      "x": 6,
      "y": 10,
      "z": 4,
      "name": "TFJ_Canopy_Leaves"
    },
    {
      "x": 6,
      "y": 8,
      "z": 5,
      "name": "TFJ_Titanwood_Log"
    },
    {
      "x": 6,
      "y": 9,
      "z": 5,
      "name": "TFJ_Titanwood_Log"
    },
    {
      "x": 6,
      "y": 10,
      "z": 5,
      "name": "TFJ_Canopy_Leaves"
    },
    {
      "x": 6,
      "y": 8,
      "z": 6,
      "name": "TFJ_Titanwood_Log"
    },
    {
      "x": 6,
      "y": 9,
      "z": 6,
      "name": "TFJ_Canopy_Leaves"
    },
    {
      "x": 6,
      "y": 10,
      "z": 6,
      "name": "TFJ_Canopy_Leaves"
    },
    {
      "x": 6,
      "y": 7,
      "z": 7,
      "name": "TFJ_Canopy_Leaves"
    },
    {
      "x": 6,
      "y": 8,
      "z": 7,
      "name": "TFJ_Canopy_Leaves"
    },
    {
      "x": 6,
      "y": 7,
      "z": 8,
      "name": "TFJ_Canopy_Leaves"
    },
    {
      "x": 6,
      "y": 7,
      "z": 9,
      "name": "TFJ_Canopy_Leaves"
    },
    {
      "x": 7,
      "y": 8,
      "z": 3,
      "name": "TFJ_Canopy_Leaves"
    },
    {
      "x": 7,
      "y": 9,
      "z": 3,
      "name": "TFJ_Canopy_Leaves"
    },
    {
      "x": 7,
      "y": 8,
      "z": 4,
      "name": "TFJ_Canopy_Leaves"
    },
    {
      "x": 7,
      "y": 9,
      "z": 4,
      "name": "TFJ_Canopy_Leaves"
    },
    {
      "x": 7,
      "y": 8,
      "z": 5,
      "name": "TFJ_Canopy_Leaves"
    },
    {
      "x": 7,
      "y": 9,
      "z": 5,
      "name": "TFJ_Canopy_Leaves"
    },
    {
      "x": 7,
      "y": 10,
      "z": 5,
      "name": "TFJ_Canopy_Leaves"
    },
    {
      "x": 7,
      "y": 6,
      "z": 6,
      "name": "TFJ_Titanwood_Log"
    },
    {
      "x": 7,
      "y": 7,
      "z": 6,
      "name": "TFJ_Titanwood_Log"
    },
    {
      "x": 7,
      "y": 8,
      "z": 6,
      "name": "TFJ_Titanwood_Log"
    },
    {
      "x": 7,
      "y": 9,
      "z": 6,
      "name": "TFJ_Canopy_Leaves"
    },
    {
      "x": 7,
      "y": 6,
      "z": 7,
      "name": "TFJ_Titanwood_Log"
    },
    {
      "x": 7,
      "y": 7,
      "z": 7,
      "name": "TFJ_Canopy_Leaves"
    },
    {
      "x": 7,
      "y": 8,
      "z": 7,
      "name": "TFJ_Canopy_Leaves"
    },
    {
      "x": 7,
      "y": 9,
      "z": 7,
      "name": "TFJ_Canopy_Leaves"
    },
    {
      "x": 7,
      "y": 6,
      "z": 8,
      "name": "TFJ_Canopy_Leaves"
    },
    {
      "x": 7,
      "y": 7,
      "z": 8,
      "name": "TFJ_Canopy_Leaves"
    },
    {
      "x": 7,
      "y": 7,
      "z": 9,
      "name": "TFJ_Canopy_Leaves"
    },
    {
      "x": 8,
      "y": 8,
      "z": 2,
      "name": "TFJ_Canopy_Leaves"
    },
    {
      "x": 8,
      "y": 8,
      "z": 3,
      "name": "TFJ_Canopy_Leaves"
    },
    {
      "x": 8,
      "y": 9,
      "z": 4,
      "name": "TFJ_Canopy_Leaves"
    },
    {
      "x": 8,
      "y": 7,
      "z": 5,
      "name": "TFJ_Canopy_Leaves"
    },
    {
      "x": 8,
      "y": 8,
      "z": 5,
      "name": "TFJ_Canopy_Leaves"
    },
    {
      "x": 8,
      "y": 7,
      "z": 6,
      "name": "TFJ_Canopy_Leaves"
    },
    {
      "x": 8,
      "y": 8,
      "z": 6,
      "name": "TFJ_Canopy_Leaves"
    },
    {
      "x": 8,
      "y": 9,
      "z": 6,
      "name": "TFJ_Canopy_Leaves"
    },
    {
      "x": 8,
      "y": 3,
      "z": 7,
      "name": "TFJ_Titanwood_Log"
    },
    {
      "x": 8,
      "y": 4,
      "z": 7,
      "name": "TFJ_Titanwood_Log"
    },
    {
      "x": 8,
      "y": 5,
      "z": 7,
      "name": "TFJ_Titanwood_Log"
    },
    {
      "x": 8,
      "y": 6,
      "z": 7,
      "name": "TFJ_Titanwood_Log"
    },
    {
      "x": 8,
      "y": 7,
      "z": 7,
      "name": "TFJ_Canopy_Leaves"
    },
    {
      "x": 8,
      "y": 6,
      "z": 8,
      "name": "TFJ_Canopy_Leaves"
    },
    {
      "x": 9,
      "y": 7,
      "z": 4,
      "name": "TFJ_Canopy_Leaves"
    },
    {
      "x": 9,
      "y": 7,
      "z": 5,
      "name": "TFJ_Canopy_Leaves"
    },
    {
      "x": 9,
      "y": 7,
      "z": 6,
      "name": "TFJ_Canopy_Leaves"
    },
    {
      "x": 9,
      "y": 6,
      "z": 7,
      "name": "TFJ_Canopy_Leaves"
    },
    {
      "x": 10,
      "y": 7,
      "z": 3,
      "name": "TFJ_Canopy_Leaves"
    },
    {
      "x": 10,
      "y": 7,
      "z": 4,
      "name": "TFJ_Canopy_Leaves"
    }
  ],
  "fluids": [],
  "entities": []
}
