{
  "version": 8,
  "blockIdVersion": 11,
  "anchorX": 0,
  "anchorY": 0,
  "anchorZ": 0,
  "blocks": [
    {
      "x": -4,
      "y": 0,
      "z": -5,
      "name": "Soil_Grass_Full"
    },
    {
      "x": -4,
      "y": 1,
      "z": -5,
      "name": "Plant_Grass_Sharp"
    },
    {
      "x": -4,
      "y": 0,
      "z": -4,
      "name": "Soil_Grass_Full"
    },
    {
      "x": -4,
      "y": 1,
      "z": -4,
      "name": "Plant_Grass_Sharp"
    },
    {
      "x": -4,
      "y": 0,
      "z": -3,
      "name": "Soil_Grass_Full"
    },
    {
      "x": -4,
      "y": 0,
      "z": -2,
      "name": "Soil_Pathway"
    },
    {
      "x": -4,
      "y": 0,
      "z": -1,
      "name": "Soil_Pathway"
    },
    {
      "x": -4,
      "y": 0,
      "z": 0,
      "name": "Soil_Pathway"
    },
    {
      "x": -4,
      "y": 0,
      "z": 1,
      "name": "Soil_Grass_Full"
    },
    {
      "x": -4,
      "y": 1,
      "z": 1,
      "name": "Plant_Grass_Sharp_Tall"
    },
    {
      "x": -4,
      "y": 0,
      "z": 2,
      "name": "Soil_Grass_Full"
    },
    {
      "x": -4,
      "y": 1,
      "z": 2,
      "name": "Plant_Grass_Sharp_Tall"
    },
    {
      "x": -4,
      "y": 0,
      "z": 3,
      "name": "Soil_Grass_Sunny"
    },
    {
      "x": -4,
      "y": 0,
      "z": 4,
      "name": "Soil_Grass_Full"
    },
    {
      "x": -4,
      "y": 1,
      "z": 4,
      "name": "Plant_Grass_Sharp"
    },
    {
      "x": -4,
      "y": 0,
      "z": 5,
      "name": "Soil_Grass_Full"
    },
    {
      "x": -4,
      "y": 1,
      "z": 5,
      "name": "Plant_Grass_Sharp"
    },
    {
      "x": -4,
      "y": 0,
      "z": 6,
      "name": "Soil_Grass_Full"
    },
    {
      "x": -4,
      "y": 1,
      "z": 6,
      "name": "Plant_Grass_Sharp_Tall"
    },
    {
      "x": -3,
      "y": 0,
      "z": -5,
      "name": "Soil_Grass_Full"
    },
    {
      "x": -3,
      "y": 0,
      "z": -4,
      "name": "Soil_Pathway"
    },
    {
      "x": -3,
      "y": 0,
      "z": -3,
      "name": "Soil_Pathway"
    },
    {
      "x": -3,
      "y": 0,
      "z": -2,
      "name": "Soil_Pathway"
    },
    {
      "x": -3,
      "y": 3,
      "z": -2,
      "name": "Wood_Tropicalwood_Planks"
    },
    {
      "x": -3,
      "y": 4,
      "z": -2,
      "name": "Wood_Tropicalwood_Fence",
      "rotation": 1
    },
    {
      "x": -3,
      "y": 0,
      "z": -1,
      "name": "Soil_Pathway"
    },
    {
      "x": -3,
      "y": 3,
      "z": -1,
      "name": "Wood_Tropicalwood_Planks"
    },
    {
      "x": -3,
      "y": 4,
      "z": -1,
      "name": "Wood_Tropicalwood_Fence",
      "rotation": 1
    },
    {
      "x": -3,
      "y": 0,
      "z": 0,
      "name": "Soil_Grass_Full"
    },
    {
      "x": -3,
      "y": 1,
      "z": 0,
      "name": "Wood_Tropicalwood_Beam"
    },
    {
      "x": -3,
      "y": 2,
      "z": 0,
      "name": "Wood_Tropicalwood_Beam"
    },
    {
      "x": -3,
      "y": 3,
      "z": 0,
      "name": "Wood_Tropicalwood_Planks"
    },
    {
      "x": -3,
      "y": 4,
      "z": 0,
      "name": "Wood_Tropicalwood_Fence",
      "rotation": 3
    },
    {
      "x": -3,
      "y": 10,
      "z": 0,
      "name": "*Wood_Tropicalwood_Roof_Steep_State_Definitions_Corner_Left",
      "rotation": 2
    },
    {
      "x": -3,
      "y": 11,
      "z": 0,
      "name": "*Wood_Tropicalwood_Roof_Steep_State_Definitions_Corner_Left",
      "filler": 1024,
      "rotation": 2
    },
    {
      "x": -3,
      "y": 0,
      "z": 1,
      "name": "Soil_Grass_Full"
    },
    {
      "x": -3,
      "y": 1,
      "z": 1,
      "name": "Plant_Grass_Lush_Short"
    },
    {
      "x": -3,
      "y": 3,
      "z": 1,
      "name": "Wood_Tropicalwood_Planks"
    },
    {
      "x": -3,
      "y": 4,
      "z": 1,
      "name": "Wood_Tropicalwood_Fence",
      "rotation": 3
    },
    {
      "x": -3,
      "y": 10,
      "z": 1,
      "name": "Wood_Tropicalwood_Roof_Steep",
      "rotation": 3
    },
    {
      "x": -3,
      "y": 11,
      "z": 1,
      "name": "Wood_Tropicalwood_Roof_Steep",
      "filler": 1024,
      "rotation": 3
    },
    {
      "x": -3,
      "y": 0,
      "z": 2,
      "name": "Soil_Grass_Full"
    },
    {
      "x": -3,
      "y": 1,
      "z": 2,
      "name": "Plant_Grass_Sharp"
    },
    {
      "x": -3,
      "y": 3,
      "z": 2,
      "name": "Wood_Tropicalwood_Planks"
    },
    {
      "x": -3,
      "y": 4,
      "z": 2,
      "name": "Wood_Tropicalwood_Fence",
      "rotation": 3
    },
    {
      "x": -3,
      "y": 10,
      "z": 2,
      "name": "Wood_Tropicalwood_Roof_Steep",
      "rotation": 3
    },
    {
      "x": -3,
      "y": 11,
      "z": 2,
      "name": "Wood_Tropicalwood_Roof_Steep",
      "filler": 1024,
      "rotation": 3
    },
    {
      "x": -3,
      "y": 0,
      "z": 3,
      "name": "Soil_Grass_Sunny"
    },
    {
      "x": -3,
      "y": 1,
      "z": 3,
      "name": "Wood_Tropicalwood_Beam"
    },
    {
      "x": -3,
      "y": 2,
      "z": 3,
      "name": "Wood_Tropicalwood_Beam"
    },
    {
      "x": -3,
      "y": 3,
      "z": 3,
      "name": "Wood_Tropicalwood_Planks"
    },
    {
      "x": -3,
      "y": 4,
      "z": 3,
      "name": "Wood_Tropicalwood_Fence",
      "rotation": 3
    },
    {
      "x": -3,
      "y": 10,
      "z": 3,
      "name": "Wood_Tropicalwood_Roof_Steep",
      "rotation": 3
    },
    {
      "x": -3,
      "y": 11,
      "z": 3,
      "name": "Wood_Tropicalwood_Roof_Steep",
      "filler": 1024,
      "rotation": 3
    },
    {
      "x": -3,
      "y": 0,
      "z": 4,
      "name": "Soil_Grass_Full"
    },
    {
      "x": -3,
      "y": 3,
      "z": 4,
      "name": "Wood_Tropicalwood_Planks"
    },
    {
      "x": -3,
      "y": 4,
      "z": 4,
      "name": "Wood_Tropicalwood_Fence",
      "rotation": 3
    },
    {
      "x": -3,
      "y": 10,
      "z": 4,
      "name": "Wood_Tropicalwood_Roof_Steep",
      "rotation": 3
    },
    {
      "x": -3,
      "y": 11,
      "z": 4,
      "name": "Wood_Tropicalwood_Roof_Steep",
      "filler": 1024,
      "rotation": 3
    },
    {
      "x": -3,
      "y": 0,
      "z": 5,
      "name": "Soil_Grass_Full"
    },
    {
      "x": -3,
      "y": 1,
      "z": 5,
      "name": "Plant_Grass_Sharp"
    },
    {
      "x": -3,
      "y": 3,
      "z": 5,
      "name": "Wood_Tropicalwood_Planks"
    },
    {
      "x": -3,
      "y": 4,
      "z": 5,
      "name": "Wood_Tropicalwood_Fence",
      "rotation": 3
    },
    {
      "x": -3,
      "y": 10,
      "z": 5,
      "name": "Wood_Tropicalwood_Roof_Steep",
      "rotation": 3
    },
    {
      "x": -3,
      "y": 11,
      "z": 5,
      "name": "Wood_Tropicalwood_Roof_Steep",
      "filler": 1024,
      "rotation": 3
    },
    {
      "x": -3,
      "y": 0,
      "z": 6,
      "name": "Soil_Grass_Full"
    },
    {
      "x": -3,
      "y": 1,
      "z": 6,
      "name": "Wood_Tropicalwood_Beam"
    },
    {
      "x": -3,
      "y": 2,
      "z": 6,
      "name": "Wood_Tropicalwood_Beam"
    },
    {
      "x": -3,
      "y": 3,
      "z": 6,
      "name": "Wood_Tropicalwood_Planks"
    },
    {
      "x": -3,
      "y": 4,
      "z": 6,
      "name": "*Wood_Tropicalwood_Fence_State_Definitions_Corner",
      "rotation": 2
    },
    {
      "x": -3,
      "y": 10,
      "z": 6,
      "name": "*Wood_Tropicalwood_Roof_Steep_State_Definitions_Corner_Left",
      "rotation": 3
    },
    {
      "x": -3,
      "y": 11,
      "z": 6,
      "name": "*Wood_Tropicalwood_Roof_Steep_State_Definitions_Corner_Left",
      "filler": 1024,
      "rotation": 3
    },
    {
      "x": -2,
      "y": 0,
      "z": -5,
      "name": "Soil_Pathway"
    },
    {
      "x": -2,
      "y": 0,
      "z": -4,
      "name": "Soil_Pathway"
    },
    {
      "x": -2,
      "y": 0,
      "z": -3,
      "name": "Soil_Pathway"
    },
    {
      "x": -2,
      "y": 0,
      "z": -2,
      "name": "Soil_Grass_Sunny"
    },
    {
      "x": -2,
      "y": 3,
      "z": -2,
      "name": "Wood_Tropicalwood_Planks"
    },
    {
      "x": -2,
      "y": 0,
      "z": -1,
      "name": "Soil_Grass_Full"
    },
    {
      "x": -2,
      "y": 1,
      "z": -1,
      "name": "Plant_Grass_Sharp"
    },
    {
      "x": -2,
      "y": 3,
      "z": -1,
      "name": "Wood_Tropicalwood_Planks"
    },
    {
      "x": -2,
      "y": 0,
      "z": 0,
      "name": "Soil_Grass_Full"
    },
    {
      "x": -2,
      "y": 1,
      "z": 0,
      "name": "Plant_Grass_Sharp"
    },
    {
      "x": -2,
      "y": 3,
      "z": 0,
      "name": "Wood_Tropicalwood_Planks"
    },
    {
      "x": -2,
      "y": 10,
      "z": 0,
      "name": "Wood_Tropicalwood_Roof_Steep",
      "rotation": 2
    },
    {
      "x": -2,
      "y": 11,
      "z": 0,
      "name": "Wood_Tropicalwood_Roof_Steep",
      "filler": 1024,
      "rotation": 2
    },
    {
      "x": -2,
      "y": 0,
      "z": 1,
      "name": "Soil_Grass_Full"
    },
    {
      "x": -2,
      "y": 1,
      "z": 1,
      "name": "Plant_Grass_Sharp"
    },
    {
      "x": -2,
      "y": 3,
      "z": 1,
      "name": "Wood_Tropicalwood_Planks"
    },
    {
      "x": -2,
      "y": 4,
      "z": 1,
      "name": "Wood_Tropicalwood_Beam"
    },
    {
      "x": -2,
      "y": 5,
      "z": 1,
      "name": "Wood_Tropicalwood_Beam"
    },
    {
      "x": -2,
      "y": 6,
      "z": 1,
      "name": "Wood_Tropicalwood_Beam"
    },
    {
      "x": -2,
      "y": 7,
      "z": 1,
      "name": "Wood_Palm_Trunk",
      "support": 15
    },
    {
      "x": -2,
      "y": 8,
      "z": 1,
      "name": "*Wood_Tropicalwood_Fence_State_Definitions_Corner",
      "rotation": 1
    },
    {
      "x": -2,
      "y": 9,
      "z": 1,
      "name": "Wood_Tropicalwood_Beam"
    },
    {
      "x": -2,
      "y": 10,
      "z": 1,
      "name": "Wood_Tropicalwood_Beam"
    },
    {
      "x": -2,
      "y": 11,
      "z": 1,
      "name": "Wood_Tropicalwood_Beam"
    },
    {
      "x": -2,
      "y": 12,
      "z": 1,
      "name": "Wood_Tropicalwood_Roof_Flat",
      "rotation": 1
    },
    {
      "x": -2,
      "y": 0,
      "z": 2,
      "name": "Soil_Grass_Full"
    },
    {
      "x": -2,
      "y": 1,
      "z": 2,
      "name": "Plant_Grass_Lush_Short"
    },
    {
      "x": -2,
      "y": 3,
      "z": 2,
      "name": "Wood_Tropicalwood_Planks"
    },
    {
      "x": -2,
      "y": 7,
      "z": 2,
      "name": "Wood_Palm_Trunk",
      "support": 15
    },
    {
      "x": -2,
      "y": 8,
      "z": 2,
      "name": "Wood_Tropicalwood_Fence",
      "rotation": 1
    },
    {
      "x": -2,
      "y": 12,
      "z": 2,
      "name": "Wood_Tropicalwood_Roof_Flat",
      "rotation": 1
    },
    {
      "x": -2,
      "y": 0,
      "z": 3,
      "name": "Soil_Grass_Full"
    },
    {
      "x": -2,
      "y": 3,
      "z": 3,
      "name": "Wood_Tropicalwood_Planks"
    },
    {
      "x": -2,
      "y": 4,
      "z": 3,
      "name": "Wood_Palm_Trunk",
      "support": 15
    },
    {
      "x": -2,
      "y": 5,
      "z": 3,
      "name": "Wood_Palm_Trunk",
      "support": 15
    },
    {
      "x": -2,
      "y": 6,
      "z": 3,
      "name": "Wood_Palm_Trunk",
      "support": 15
    },
    {
      "x": -2,
      "y": 7,
      "z": 3,
      "name": "Wood_Palm_Trunk",
      "support": 15
    },
    {
      "x": -2,
      "y": 8,
      "z": 3,
      "name": "Wood_Tropicalwood_Fence",
      "rotation": 1
    },
    {
      "x": -2,
      "y": 12,
      "z": 3,
      "name": "Wood_Tropicalwood_Roof_Flat",
      "rotation": 1
    },
    {
      "x": -2,
      "y": 0,
      "z": 4,
      "name": "Soil_Grass_Full"
    },
    {
      "x": -2,
      "y": 3,
      "z": 4,
      "name": "Wood_Tropicalwood_Planks"
    },
    {
      "x": -2,
      "y": 4,
      "z": 4,
      "name": "Wood_Palm_Trunk",
      "support": 15
    },
    {
      "x": -2,
      "y": 5,
      "z": 4,
      "name": "Wood_Palm_Trunk",
      "support": 15
    },
    {
      "x": -2,
      "y": 6,
      "z": 4,
      "name": "Wood_Palm_Trunk",
      "support": 15
    },
    {
      "x": -2,
      "y": 7,
      "z": 4,
      "name": "Wood_Palm_Trunk",
      "support": 15
    },
    {
      "x": -2,
      "y": 8,
      "z": 4,
      "name": "Wood_Tropicalwood_Fence",
      "rotation": 1
    },
    {
      "x": -2,
      "y": 12,
      "z": 4,
      "name": "Wood_Tropicalwood_Roof_Flat",
      "rotation": 1
    },
    {
      "x": -2,
      "y": 0,
      "z": 5,
      "name": "Soil_Grass_Full"
    },
    {
      "x": -2,
      "y": 1,
      "z": 5,
      "name": "Plant_Grass_Sharp"
    },
    {
      "x": -2,
      "y": 3,
      "z": 5,
      "name": "Wood_Tropicalwood_Planks"
    },
    {
      "x": -2,
      "y": 4,
      "z": 5,
      "name": "Wood_Palm_Trunk",
      "support": 15
    },
    {
      "x": -2,
      "y": 5,
      "z": 5,
      "name": "Wood_Palm_Trunk",
      "support": 15
    },
    {
      "x": -2,
      "y": 6,
      "z": 5,
      "name": "Wood_Palm_Trunk",
      "support": 15
    },
    {
      "x": -2,
      "y": 7,
      "z": 5,
      "name": "Wood_Palm_Trunk",
      "support": 15
    },
    {
      "x": -2,
      "y": 8,
      "z": 5,
      "name": "*Wood_Tropicalwood_Fence_State_Definitions_Corner",
      "rotation": 2
    },
    {
      "x": -2,
      "y": 9,
      "z": 5,
      "name": "Wood_Tropicalwood_Beam"
    },
    {
      "x": -2,
      "y": 10,
      "z": 5,
      "name": "Wood_Tropicalwood_Beam"
    },
    {
      "x": -2,
      "y": 11,
      "z": 5,
      "name": "Wood_Tropicalwood_Beam"
    },
    {
      "x": -2,
      "y": 12,
      "z": 5,
      "name": "Wood_Tropicalwood_Roof_Flat",
      "rotation": 1
    },
    {
      "x": -2,
      "y": 0,
      "z": 6,
      "name": "Soil_Grass_Full"
    },
    {
      "x": -2,
      "y": 3,
      "z": 6,
      "name": "Wood_Tropicalwood_Planks"
    },
    {
      "x": -2,
      "y": 4,
      "z": 6,
      "name": "Wood_Tropicalwood_Fence"
    },
    {
      "x": -2,
      "y": 10,
      "z": 6,
      "name": "Wood_Tropicalwood_Roof_Steep"
    },
    {
      "x": -2,
      "y": 11,
      "z": 6,
      "name": "Wood_Tropicalwood_Roof_Steep",
      "filler": 1024
    },
    {
      "x": -1,
      "y": 0,
      "z": -5,
      "name": "Soil_Pathway"
    },
    {
      "x": -1,
      "y": 0,
      "z": -4,
      "name": "Soil_Grass_Sunny"
    },
    {
      "x": -1,
      "y": 0,
      "z": -3,
      "name": "Soil_Grass_Sunny"
    },
    {
      "x": -1,
      "y": 1,
      "z": -3,
      "name": "Plant_Fern_Giant",
      "support": 15
    },
    {
      "x": -1,
      "y": 0,
      "z": -2,
      "name": "Soil_Grass_Sunny"
    },
    {
      "x": -1,
      "y": 3,
      "z": -2,
      "name": "Wood_Tropicalwood_Planks"
    },
    {
      "x": -1,
      "y": 0,
      "z": -1,
      "name": "Soil_Grass_Full"
    },
    {
      "x": -1,
      "y": 1,
      "z": -1,
      "name": "Plant_Grass_Sharp"
    },
    {
      "x": -1,
      "y": 3,
      "z": -1,
      "name": "Wood_Tropicalwood_Planks"
    },
    {
      "x": -1,
      "y": 0,
      "z": 0,
      "name": "Soil_Grass_Full"
    },
    {
      "x": -1,
      "y": 3,
      "z": 0,
      "name": "Wood_Tropicalwood_Planks"
    },
    {
      "x": -1,
      "y": 10,
      "z": 0,
      "name": "Wood_Tropicalwood_Roof_Steep",
      "rotation": 2
    },
    {
      "x": -1,
      "y": 11,
      "z": 0,
      "name": "Wood_Tropicalwood_Roof_Steep",
      "filler": 1024,
      "rotation": 2
    },
    {
      "x": -1,
      "y": 0,
      "z": 1,
      "name": "Soil_Grass_Full"
    },
    {
      "x": -1,
      "y": 3,
      "z": 1,
      "name": "Wood_Tropicalwood_Planks"
    },
    {
      "x": -1,
      "y": 7,
      "z": 1,
      "name": "Wood_Palm_Trunk",
      "support": 15
    },
    {
      "x": -1,
      "y": 8,
      "z": 1,
      "name": "Wood_Tropicalwood_Fence"
    },
    {
      "x": -1,
      "y": 12,
      "z": 1,
      "name": "Wood_Tropicalwood_Roof_Flat",
      "rotation": 1
    },
    {
      "x": -1,
      "y": 0,
      "z": 2,
      "name": "Soil_Grass_Full"
    },
    {
      "x": -1,
      "y": 1,
      "z": 2,
      "name": "Plant_Grass_Sharp"
    },
    {
      "x": -1,
      "y": 3,
      "z": 2,
      "name": "Wood_Tropicalwood_Planks"
    },
    {
      "x": -1,
      "y": 7,
      "z": 2,
      "name": "Wood_Tropicalwood_Decorative"
    },
    {
      "x": -1,
      "y": 12,
      "z": 2,
      "name": "Wood_Tropicalwood_Roof_Flat",
      "rotation": 1
    },
    {
      "x": -1,
      "y": 0,
      "z": 3,
      "name": "Soil_Grass_Full"
    },
    {
      "x": -1,
      "y": 3,
      "z": 3,
      "name": "Wood_Tropicalwood_Planks"
    },
    {
      "x": -1,
      "y": 7,
      "z": 3,
      "name": "Wood_Tropicalwood_Decorative"
    },
    {
      "x": -1,
      "y": 12,
      "z": 3,
      "name": "Wood_Tropicalwood_Roof_Flat",
      "rotation": 1
    },
    {
      "x": -1,
      "y": 0,
      "z": 4,
      "name": "Soil_Grass_Full"
    },
    {
      "x": -1,
      "y": 1,
      "z": 4,
      "name": "Plant_Grass_Sharp"
    },
    {
      "x": -1,
      "y": 3,
      "z": 4,
      "name": "Wood_Tropicalwood_Planks"
    },
    {
      "x": -1,
      "y": 4,
      "z": 4,
      "name": "Furniture_Feran_Planter"
    },
    {
      "x": -1,
      "y": 5,
      "z": 4,
      "name": "Plant_Flower_Tall_Purple"
    },
    {
      "x": -1,
      "y": 7,
      "z": 4,
      "name": "Wood_Tropicalwood_Decorative"
    },
    {
      "x": -1,
      "y": 12,
      "z": 4,
      "name": "Wood_Tropicalwood_Roof_Flat",
      "rotation": 1
    },
    {
      "x": -1,
      "y": 0,
      "z": 5,
      "name": "Soil_Grass_Full"
    },
    {
      "x": -1,
      "y": 1,
      "z": 5,
      "name": "Plant_Grass_Sharp"
    },
    {
      "x": -1,
      "y": 3,
      "z": 5,
      "name": "Wood_Tropicalwood_Planks"
    },
    {
      "x": -1,
      "y": 4,
      "z": 5,
      "name": "Wood_Palm_Trunk",
      "support": 15
    },
    {
      "x": -1,
      "y": 5,
      "z": 5,
      "name": "Wood_Palm_Trunk",
      "support": 15
    },
    {
      "x": -1,
      "y": 6,
      "z": 5,
      "name": "Wood_Palm_Trunk",
      "support": 15
    },
    {
      "x": -1,
      "y": 7,
      "z": 5,
      "name": "Wood_Palm_Trunk",
      "support": 15
    },
    {
      "x": -1,
      "y": 8,
      "z": 5,
      "name": "Wood_Tropicalwood_Fence",
      "rotation": 2
    },
    {
      "x": -1,
      "y": 12,
      "z": 5,
      "name": "Wood_Tropicalwood_Roof_Flat",
      "rotation": 1
    },
    {
      "x": -1,
      "y": 0,
      "z": 6,
      "name": "Soil_Grass_Full"
    },
    {
      "x": -1,
      "y": 1,
      "z": 6,
      "name": "Plant_Grass_Sharp"
    },
    {
      "x": -1,
      "y": 3,
      "z": 6,
      "name": "Wood_Tropicalwood_Planks"
    },
    {
      "x": -1,
      "y": 4,
      "z": 6,
      "name": "Wood_Tropicalwood_Fence"
    },
    {
      "x": -1,
      "y": 10,
      "z": 6,
      "name": "Wood_Tropicalwood_Roof_Steep"
    },
    {
      "x": -1,
      "y": 11,
      "z": 6,
      "name": "Wood_Tropicalwood_Roof_Steep",
      "filler": 1024
    },
    {
      "x": 0,
      "y": 0,
      "z": -5,
      "name": "Soil_Pathway"
    },
    {
      "x": 0,
      "y": 0,
      "z": -4,
      "name": "Soil_Pathway"
    },
    {
      "x": 0,
      "y": 0,
      "z": -3,
      "name": "Soil_Grass_Sunny"
    },
    {
      "x": 0,
      "y": 0,
      "z": -2,
      "name": "Soil_Grass_Sunny"
    },
    {
      "x": 0,
      "y": 2,
      "z": -2,
      "name": "Wood_Tropicalwood_Stairs",
      "rotation": 9
    },
    {
      "x": 0,
      "y": 3,
      "z": -2,
      "name": "Wood_Tropicalwood_Stairs",
      "rotation": 1
    },
    {
      "x": 0,
      "y": 0,
      "z": -1,
      "name": "Soil_Grass_Full"
    },
    {
      "x": 0,
      "y": 2,
      "z": -1,
      "name": "Wood_Tropicalwood_Stairs",
      "rotation": 9
    },
    {
      "x": 0,
      "y": 3,
      "z": -1,
      "name": "Wood_Tropicalwood_Stairs",
      "rotation": 1
    },
    {
      "x": 0,
      "y": 0,
      "z": 0,
      "name": "Soil_Grass_Full"
    },
    {
      "x": 0,
      "y": 1,
      "z": 0,
      "name": "Wood_Tropicalwood_Beam"
    },
    {
      "x": 0,
      "y": 2,
      "z": 0,
      "name": "Wood_Tropicalwood_Beam"
    },
    {
      "x": 0,
      "y": 3,
      "z": 0,
      "name": "Wood_Tropicalwood_Planks"
    },
    {
      "x": 0,
      "y": 4,
      "z": 0,
      "name": "Wood_Tropicalwood_Fence",
      "rotation": 2
    },
    {
      "x": 0,
      "y": 10,
      "z": 0,
      "name": "Wood_Tropicalwood_Roof_Steep",
      "rotation": 2
    },
    {
      "x": 0,
      "y": 11,
      "z": 0,
      "name": "Wood_Tropicalwood_Roof_Steep",
      "filler": 1024,
      "rotation": 2
    },
    {
      "x": 0,
      "y": 0,
      "z": 1,
      "name": "Soil_Grass_Full"
    },
    {
      "x": 0,
      "y": 3,
      "z": 1,
      "name": "Wood_Tropicalwood_Planks"
    },
    {
      "x": 0,
      "y": 4,
      "z": 1,
      "name": "Wood_Palm_Trunk",
      "support": 15
    },
    {
      "x": 0,
      "y": 5,
      "z": 1,
      "name": "Wood_Palm_Trunk",
      "support": 15
    },
    {
      "x": 0,
      "y": 6,
      "z": 1,
      "name": "Wood_Palm_Trunk",
      "support": 15
    },
    {
      "x": 0,
      "y": 7,
      "z": 1,
      "name": "Wood_Palm_Trunk",
      "support": 15
    },
    {
      "x": 0,
      "y": 8,
      "z": 1,
      "name": "Wood_Tropicalwood_Fence"
    },
    {
      "x": 0,
      "y": 12,
      "z": 1,
      "name": "Wood_Tropicalwood_Roof_Flat",
      "rotation": 1
    },
    {
      "x": 0,
      "y": 0,
      "z": 2,
      "name": "Soil_Grass_Full"
    },
    {
      "x": 0,
      "y": 3,
      "z": 2,
      "name": "Wood_Tropicalwood_Planks"
    },
    {
      "x": 0,
      "y": 7,
      "z": 2,
      "name": "Wood_Tropicalwood_Decorative"
    },
    {
      "x": 0,
      "y": 12,
      "z": 2,
      "name": "Wood_Tropicalwood_Roof_Flat",
      "rotation": 1
    },
    {
      "x": 0,
      "y": 0,
      "z": 3,
      "name": "Soil_Grass_Full"
    },
    {
      "x": 0,
      "y": 3,
      "z": 3,
      "name": "Wood_Tropicalwood_Planks"
    },
    {
      "x": 0,
      "y": 7,
      "z": 3,
      "name": "Wood_Tropicalwood_Decorative"
    },
    {
      "x": 0,
      "y": 11,
      "z": 3,
      "name": "Deco_Lantern_Ceiling"
    },
    {
      "x": 0,
      "y": 12,
      "z": 3,
      "name": "Wood_Tropicalwood_Roof_Flat",
      "rotation": 1
    },
    {
      "x": 0,
      "y": 0,
      "z": 4,
      "name": "Soil_Grass_Full"
    },
    {
      "x": 0,
      "y": 1,
      "z": 4,
      "name": "Plant_Grass_Sharp"
    },
    {
      "x": 0,
      "y": 3,
      "z": 4,
      "name": "Wood_Tropicalwood_Planks"
    },
    {
      "x": 0,
      "y": 4,
      "z": 4,
      "name": "Plant_Vine_Liana",
      "support": 15,
      "rotation": 2
    },
    {
      "x": 0,
      "y": 5,
      "z": 4,
      "name": "Plant_Vine_Liana",
      "support": 15,
      "rotation": 2
    },
    {
      "x": 0,
      "y": 6,
      "z": 4,
      "name": "Plant_Vine_Liana",
      "support": 15,
      "rotation": 2
    },
    {
      "x": 0,
      "y": 7,
      "z": 4,
      "name": "Plant_Vine_Liana",
      "support": 15,
      "rotation": 2
    },
    {
      "x": 0,
      "y": 12,
      "z": 4,
      "name": "Wood_Tropicalwood_Roof_Flat",
      "rotation": 1
    },
    {
      "x": 0,
      "y": 0,
      "z": 5,
      "name": "Soil_Grass_Full"
    },
    {
      "x": 0,
      "y": 3,
      "z": 5,
      "name": "Wood_Tropicalwood_Planks"
    },
    {
      "x": 0,
      "y": 4,
      "z": 5,
      "name": "Wood_Palm_Trunk",
      "support": 15
    },
    {
      "x": 0,
      "y": 5,
      "z": 5,
      "name": "Wood_Palm_Trunk",
      "support": 15
    },
    {
      "x": 0,
      "y": 6,
      "z": 5,
      "name": "Wood_Palm_Trunk",
      "support": 15
    },
    {
      "x": 0,
      "y": 7,
      "z": 5,
      "name": "Wood_Palm_Trunk",
      "support": 15
    },
    {
      "x": 0,
      "y": 8,
      "z": 5,
      "name": "Wood_Tropicalwood_Fence",
      "rotation": 2
    },
    {
      "x": 0,
      "y": 12,
      "z": 5,
      "name": "Wood_Tropicalwood_Roof_Flat",
      "rotation": 1
    },
    {
      "x": 0,
      "y": 0,
      "z": 6,
      "name": "Soil_Grass_Full"
    },
    {
      "x": 0,
      "y": 1,
      "z": 6,
      "name": "Wood_Tropicalwood_Beam"
    },
    {
      "x": 0,
      "y": 2,
      "z": 6,
      "name": "Wood_Tropicalwood_Beam"
    },
    {
      "x": 0,
      "y": 3,
      "z": 6,
      "name": "Wood_Tropicalwood_Planks"
    },
    {
      "x": 0,
      "y": 4,
      "z": 6,
      "name": "Wood_Tropicalwood_Fence"
    },
    {
      "x": 0,
      "y": 10,
      "z": 6,
      "name": "Wood_Tropicalwood_Roof_Steep"
    },
    {
      "x": 0,
      "y": 11,
      "z": 6,
      "name": "Wood_Tropicalwood_Roof_Steep",
      "filler": 1024
    },
    {
      "x": 1,
      "y": 0,
      "z": -5,
      "name": "Soil_Pathway"
    },
    {
      "x": 1,
      "y": 0,
      "z": -4,
      "name": "Soil_Pathway"
    },
    {
      "x": 1,
      "y": 0,
      "z": -3,
      "name": "Soil_Pathway"
    },
    {
      "x": 1,
      "y": 0,
      "z": -2,
      "name": "Soil_Grass_Full"
    },
    {
      "x": 1,
      "y": 1,
      "z": -2,
      "name": "Wood_Tropicalwood_Stairs",
      "rotation": 9
    },
    {
      "x": 1,
      "y": 2,
      "z": -2,
      "name": "Wood_Tropicalwood_Stairs",
      "rotation": 1
    },
    {
      "x": 1,
      "y": 0,
      "z": -1,
      "name": "Soil_Grass_Full"
    },
    {
      "x": 1,
      "y": 1,
      "z": -1,
      "name": "Wood_Tropicalwood_Stairs",
      "rotation": 9
    },
    {
      "x": 1,
      "y": 2,
      "z": -1,
      "name": "Wood_Tropicalwood_Stairs",
      "rotation": 1
    },
    {
      "x": 1,
      "y": 0,
      "z": 0,
      "name": "Soil_Grass_Full"
    },
    {
      "x": 1,
      "y": 1,
      "z": 0,
      "name": "Plant_Grass_Lush_Short"
    },
    {
      "x": 1,
      "y": 3,
      "z": 0,
      "name": "Wood_Tropicalwood_Planks"
    },
    {
      "x": 1,
      "y": 4,
      "z": 0,
      "name": "Wood_Tropicalwood_Fence",
      "rotation": 2
    },
    {
      "x": 1,
      "y": 10,
      "z": 0,
      "name": "Wood_Tropicalwood_Roof_Steep",
      "rotation": 2
    },
    {
      "x": 1,
      "y": 11,
      "z": 0,
      "name": "Wood_Tropicalwood_Roof_Steep",
      "filler": 1024,
      "rotation": 2
    },
    {
      "x": 1,
      "y": 0,
      "z": 1,
      "name": "Soil_Grass_Full"
    },
    {
      "x": 1,
      "y": 3,
      "z": 1,
      "name": "Wood_Tropicalwood_Planks"
    },
    {
      "x": 1,
      "y": 4,
      "z": 1,
      "name": "Wood_Palm_Trunk",
      "support": 15
    },
    {
      "x": 1,
      "y": 5,
      "z": 1,
      "name": "Wood_Palm_Trunk",
      "support": 15
    },
    {
      "x": 1,
      "y": 6,
      "z": 1,
      "name": "Wood_Palm_Trunk",
      "support": 15
    },
    {
      "x": 1,
      "y": 7,
      "z": 1,
      "name": "Wood_Palm_Trunk",
      "support": 15
    },
    {
      "x": 1,
      "y": 8,
      "z": 1,
      "name": "Wood_Tropicalwood_Fence"
    },
    {
      "x": 1,
      "y": 12,
      "z": 1,
      "name": "Wood_Tropicalwood_Roof_Flat",
      "rotation": 1
    },
    {
      "x": 1,
      "y": 0,
      "z": 2,
      "name": "Soil_Grass_Full"
    },
    {
      "x": 1,
      "y": 3,
      "z": 2,
      "name": "Wood_Tropicalwood_Planks"
    },
    {
      "x": 1,
      "y": 4,
      "z": 2,
      "name": "Furniture_Kweebec_Platform"
    },
    {
      "x": 1,
      "y": 5,
      "z": 2,
      "name": "Deco_Lantern"
    },
    {
      "x": 1,
      "y": 7,
      "z": 2,
      "name": "Wood_Tropicalwood_Decorative"
    },
    {
      "x": 1,
      "y": 12,
      "z": 2,
      "name": "Wood_Tropicalwood_Roof_Flat",
      "rotation": 1
    },
    {
      "x": 1,
      "y": 0,
      "z": 3,
      "name": "Soil_Grass_Full"
    },
    {
      "x": 1,
      "y": 1,
      "z": 3,
      "name": "Plant_Grass_Sharp"
    },
    {
      "x": 1,
      "y": 3,
      "z": 3,
      "name": "Wood_Tropicalwood_Planks"
    },
    {
      "x": 1,
      "y": 4,
      "z": 3,
      "name": "Furniture_Kweebec_Platform"
    },
    {
      "x": 1,
      "y": 7,
      "z": 3,
      "name": "Wood_Tropicalwood_Decorative"
    },
    {
      "x": 1,
      "y": 12,
      "z": 3,
      "name": "Wood_Tropicalwood_Roof_Flat",
      "rotation": 1
    },
    {
      "x": 1,
      "y": 0,
      "z": 4,
      "name": "Soil_Grass_Full"
    },
    {
      "x": 1,
      "y": 1,
      "z": 4,
      "name": "Plant_Grass_Sharp_Tall"
    },
    {
      "x": 1,
      "y": 3,
      "z": 4,
      "name": "Wood_Tropicalwood_Planks"
    },
    {
      "x": 1,
      "y": 7,
      "z": 4,
      "name": "Wood_Tropicalwood_Decorative"
    },
    {
      "x": 1,
      "y": 12,
      "z": 4,
      "name": "Wood_Tropicalwood_Roof_Flat",
      "rotation": 1
    },
    {
      "x": 1,
      "y": 0,
      "z": 5,
      "name": "Soil_Grass_Full"
    },
    {
      "x": 1,
      "y": 1,
      "z": 5,
      "name": "Plant_Grass_Sharp_Tall"
    },
    {
      "x": 1,
      "y": 3,
      "z": 5,
      "name": "Wood_Tropicalwood_Planks"
    },
    {
      "x": 1,
      "y": 4,
      "z": 5,
      "name": "Wood_Palm_Trunk",
      "support": 15
    },
    {
      "x": 1,
      "y": 5,
      "z": 5,
      "name": "Wood_Palm_Trunk",
      "support": 15
    },
    {
      "x": 1,
      "y": 6,
      "z": 5,
      "name": "Wood_Palm_Trunk",
      "support": 15
    },
    {
      "x": 1,
      "y": 7,
      "z": 5,
      "name": "Wood_Palm_Trunk",
      "support": 15
    },
    {
      "x": 1,
      "y": 8,
      "z": 5,
      "name": "Wood_Tropicalwood_Fence",
      "rotation": 2
    },
    {
      "x": 1,
      "y": 12,
      "z": 5,
      "name": "Wood_Tropicalwood_Roof_Flat",
      "rotation": 1
    },
    {
      "x": 1,
      "y": 0,
      "z": 6,
      "name": "Soil_Grass_Full"
    },
    {
      "x": 1,
      "y": 3,
      "z": 6,
      "name": "Wood_Tropicalwood_Planks"
    },
    {
      "x": 1,
      "y": 4,
      "z": 6,
      "name": "Wood_Tropicalwood_Fence"
    },
    {
      "x": 1,
      "y": 10,
      "z": 6,
      "name": "Wood_Tropicalwood_Roof_Steep"
    },
    {
      "x": 1,
      "y": 11,
      "z": 6,
      "name": "Wood_Tropicalwood_Roof_Steep",
      "filler": 1024
    },
    {
      "x": 2,
      "y": 0,
      "z": -5,
      "name": "Soil_Pathway"
    },
    {
      "x": 2,
      "y": 0,
      "z": -4,
      "name": "Soil_Pathway"
    },
    {
      "x": 2,
      "y": 0,
      "z": -3,
      "name": "Soil_Grass_Full"
    },
    {
      "x": 2,
      "y": 1,
      "z": -3,
      "name": "Wood_Tropicalwood_Stairs",
      "rotation": 2
    },
    {
      "x": 2,
      "y": 0,
      "z": -2,
      "name": "Soil_Dirt"
    },
    {
      "x": 2,
      "y": 1,
      "z": -2,
      "name": "Wood_Tropicalwood_Planks"
    },
    {
      "x": 2,
      "y": 0,
      "z": -1,
      "name": "Soil_Dirt"
    },
    {
      "x": 2,
      "y": 1,
      "z": -1,
      "name": "Wood_Tropicalwood_Planks"
    },
    {
      "x": 2,
      "y": 0,
      "z": 0,
      "name": "Soil_Grass_Full"
    },
    {
      "x": 2,
      "y": 3,
      "z": 0,
      "name": "Wood_Tropicalwood_Planks"
    },
    {
      "x": 2,
      "y": 4,
      "z": 0,
      "name": "Wood_Tropicalwood_Fence",
      "rotation": 2
    },
    {
      "x": 2,
      "y": 10,
      "z": 0,
      "name": "Wood_Tropicalwood_Roof_Steep",
      "rotation": 2
    },
    {
      "x": 2,
      "y": 11,
      "z": 0,
      "name": "Wood_Tropicalwood_Roof_Steep",
      "filler": 1024,
      "rotation": 2
    },
    {
      "x": 2,
      "y": 0,
      "z": 1,
      "name": "Soil_Grass_Full"
    },
    {
      "x": 2,
      "y": 3,
      "z": 1,
      "name": "Wood_Tropicalwood_Planks"
    },
    {
      "x": 2,
      "y": 4,
      "z": 1,
      "name": "Wood_Palm_Trunk",
      "support": 15
    },
    {
      "x": 2,
      "y": 5,
      "z": 1,
      "name": "Wood_Palm_Trunk",
      "support": 15
    },
    {
      "x": 2,
      "y": 6,
      "z": 1,
      "name": "Wood_Palm_Trunk",
      "support": 15
    },
    {
      "x": 2,
      "y": 7,
      "z": 1,
      "name": "Wood_Palm_Trunk",
      "support": 15
    },
    {
      "x": 2,
      "y": 8,
      "z": 1,
      "name": "*Wood_Tropicalwood_Fence_State_Definitions_Corner"
    },
    {
      "x": 2,
      "y": 9,
      "z": 1,
      "name": "Wood_Tropicalwood_Beam"
    },
    {
      "x": 2,
      "y": 10,
      "z": 1,
      "name": "Wood_Tropicalwood_Beam"
    },
    {
      "x": 2,
      "y": 11,
      "z": 1,
      "name": "Wood_Tropicalwood_Beam"
    },
    {
      "x": 2,
      "y": 12,
      "z": 1,
      "name": "Wood_Tropicalwood_Roof_Flat",
      "rotation": 1
    },
    {
      "x": 2,
      "y": 0,
      "z": 2,
      "name": "Soil_Grass_Full"
    },
    {
      "x": 2,
      "y": 1,
      "z": 2,
      "name": "Plant_Grass_Sharp"
    },
    {
      "x": 2,
      "y": 3,
      "z": 2,
      "name": "Wood_Tropicalwood_Planks"
    },
    {
      "x": 2,
      "y": 4,
      "z": 2,
      "name": "Wood_Palm_Trunk",
      "support": 15
    },
    {
      "x": 2,
      "y": 5,
      "z": 2,
      "name": "Wood_Palm_Trunk",
      "support": 15
    },
    {
      "x": 2,
      "y": 6,
      "z": 2,
      "name": "Wood_Palm_Trunk",
      "support": 15
    },
    {
      "x": 2,
      "y": 7,
      "z": 2,
      "name": "Wood_Palm_Trunk",
      "support": 15
    },
    {
      "x": 2,
      "y": 8,
      "z": 2,
      "name": "Wood_Tropicalwood_Fence",
      "rotation": 3
    },
    {
      "x": 2,
      "y": 12,
      "z": 2,
      "name": "Wood_Tropicalwood_Roof_Flat",
      "rotation": 1
    },
    {
      "x": 2,
      "y": 0,
      "z": 3,
      "name": "Soil_Grass_Full"
    },
    {
      "x": 2,
      "y": 3,
      "z": 3,
      "name": "Wood_Tropicalwood_Planks"
    },
    {
      "x": 2,
      "y": 4,
      "z": 3,
      "name": "Wood_Palm_Trunk",
      "support": 15
    },
    {
      "x": 2,
      "y": 5,
      "z": 3,
      "name": "Wood_Palm_Trunk",
      "support": 15
    },
    {
      "x": 2,
      "y": 6,
      "z": 3,
      "name": "Wood_Palm_Trunk",
      "support": 15
    },
    {
      "x": 2,
      "y": 7,
      "z": 3,
      "name": "Wood_Palm_Trunk",
      "support": 15
    },
    {
      "x": 2,
      "y": 8,
      "z": 3,
      "name": "Wood_Tropicalwood_Fence",
      "rotation": 3
    },
    {
      "x": 2,
      "y": 12,
      "z": 3,
      "name": "Wood_Tropicalwood_Roof_Flat",
      "rotation": 1
    },
    {
      "x": 2,
      "y": 0,
      "z": 4,
      "name": "Soil_Grass_Full"
    },
    {
      "x": 2,
      "y": 1,
      "z": 4,
      "name": "Plant_Grass_Sharp"
    },
    {
      "x": 2,
      "y": 3,
      "z": 4,
      "name": "Wood_Tropicalwood_Planks"
    },
    {
      "x": 2,
      "y": 4,
      "z": 4,
      "name": "Wood_Palm_Trunk",
      "support": 15
    },
    {
      "x": 2,
      "y": 5,
      "z": 4,
      "name": "Wood_Palm_Trunk",
      "support": 15
    },
    {
      "x": 2,
      "y": 6,
      "z": 4,
      "name": "Wood_Palm_Trunk",
      "support": 15
    },
    {
      "x": 2,
      "y": 7,
      "z": 4,
      "name": "Wood_Palm_Trunk",
      "support": 15
    },
    {
      "x": 2,
      "y": 8,
      "z": 4,
      "name": "Wood_Tropicalwood_Fence",
      "rotation": 3
    },
    {
      "x": 2,
      "y": 12,
      "z": 4,
      "name": "Wood_Tropicalwood_Roof_Flat",
      "rotation": 1
    },
    {
      "x": 2,
      "y": 0,
      "z": 5,
      "name": "Soil_Grass_Full"
    },
    {
      "x": 2,
      "y": 1,
      "z": 5,
      "name": "Plant_Grass_Sharp_Tall"
    },
    {
      "x": 2,
      "y": 3,
      "z": 5,
      "name": "Wood_Tropicalwood_Planks"
    },
    {
      "x": 2,
      "y": 4,
      "z": 5,
      "name": "Wood_Palm_Trunk",
      "support": 15
    },
    {
      "x": 2,
      "y": 5,
      "z": 5,
      "name": "Wood_Palm_Trunk",
      "support": 15
    },
    {
      "x": 2,
      "y": 6,
      "z": 5,
      "name": "Wood_Palm_Trunk",
      "support": 15
    },
    {
      "x": 2,
      "y": 7,
      "z": 5,
      "name": "Wood_Palm_Trunk",
      "support": 15
    },
    {
      "x": 2,
      "y": 8,
      "z": 5,
      "name": "*Wood_Tropicalwood_Fence_State_Definitions_Corner",
      "rotation": 3
    },
    {
      "x": 2,
      "y": 9,
      "z": 5,
      "name": "Wood_Tropicalwood_Beam"
    },
    {
      "x": 2,
      "y": 10,
      "z": 5,
      "name": "Wood_Tropicalwood_Beam"
    },
    {
      "x": 2,
      "y": 11,
      "z": 5,
      "name": "Wood_Tropicalwood_Beam"
    },
    {
      "x": 2,
      "y": 12,
      "z": 5,
      "name": "Wood_Tropicalwood_Roof_Flat",
      "rotation": 1
    },
    {
      "x": 2,
      "y": 0,
      "z": 6,
      "name": "Soil_Grass_Full"
    },
    {
      "x": 2,
      "y": 3,
      "z": 6,
      "name": "Wood_Tropicalwood_Planks"
    },
    {
      "x": 2,
      "y": 4,
      "z": 6,
      "name": "Wood_Tropicalwood_Fence"
    },
    {
      "x": 2,
      "y": 10,
      "z": 6,
      "name": "Wood_Tropicalwood_Roof_Steep"
    },
    {
      "x": 2,
      "y": 11,
      "z": 6,
      "name": "Wood_Tropicalwood_Roof_Steep",
      "filler": 1024
    },
    {
      "x": 3,
      "y": 0,
      "z": -5,
      "name": "Soil_Grass_Full"
    },
    {
      "x": 3,
      "y": 0,
      "z": -4,
      "name": "Soil_Pathway"
    },
    {
      "x": 3,
      "y": 0,
      "z": -3,
      "name": "Soil_Grass_Full"
    },
    {
      "x": 3,
      "y": 1,
      "z": -3,
      "name": "Wood_Tropicalwood_Stairs",
      "rotation": 2
    },
    {
      "x": 3,
      "y": 0,
      "z": -2,
      "name": "Soil_Dirt"
    },
    {
      "x": 3,
      "y": 1,
      "z": -2,
      "name": "Wood_Tropicalwood_Planks"
    },
    {
      "x": 3,
      "y": 0,
      "z": -1,
      "name": "Soil_Dirt"
    },
    {
      "x": 3,
      "y": 1,
      "z": -1,
      "name": "Wood_Tropicalwood_Planks"
    },
    {
      "x": 3,
      "y": 0,
      "z": 0,
      "name": "Soil_Grass_Full"
    },
    {
      "x": 3,
      "y": 1,
      "z": 0,
      "name": "Wood_Tropicalwood_Beam"
    },
    {
      "x": 3,
      "y": 2,
      "z": 0,
      "name": "Wood_Tropicalwood_Beam"
    },
    {
      "x": 3,
      "y": 3,
      "z": 0,
      "name": "Wood_Tropicalwood_Planks"
    },
    {
      "x": 3,
      "y": 4,
      "z": 0,
      "name": "*Wood_Tropicalwood_Fence_State_Definitions_Corner"
    },
    {
      "x": 3,
      "y": 10,
      "z": 0,
      "name": "*Wood_Tropicalwood_Roof_Steep_State_Definitions_Corner_Right",
      "rotation": 2
    },
    {
      "x": 3,
      "y": 11,
      "z": 0,
      "name": "*Wood_Tropicalwood_Roof_Steep_State_Definitions_Corner_Right",
      "filler": 1024,
      "rotation": 2
    },
    {
      "x": 3,
      "y": 0,
      "z": 1,
      "name": "Soil_Grass_Full"
    },
    {
      "x": 3,
      "y": 1,
      "z": 1,
      "name": "Plant_Grass_Lush_Short"
    },
    {
      "x": 3,
      "y": 3,
      "z": 1,
      "name": "Wood_Tropicalwood_Planks"
    },
    {
      "x": 3,
      "y": 4,
      "z": 1,
      "name": "Wood_Tropicalwood_Fence",
      "rotation": 1
    },
    {
      "x": 3,
      "y": 10,
      "z": 1,
      "name": "Wood_Tropicalwood_Roof_Steep",
      "rotation": 1
    },
    {
      "x": 3,
      "y": 11,
      "z": 1,
      "name": "Wood_Tropicalwood_Roof_Steep",
      "filler": 1024,
      "rotation": 1
    },
    {
      "x": 3,
      "y": 0,
      "z": 2,
      "name": "Soil_Grass_Full"
    },
    {
      "x": 3,
      "y": 3,
      "z": 2,
      "name": "Wood_Tropicalwood_Planks"
    },
    {
      "x": 3,
      "y": 4,
      "z": 2,
      "name": "Wood_Tropicalwood_Fence",
      "rotation": 1
    },
    {
      "x": 3,
      "y": 10,
      "z": 2,
      "name": "Wood_Tropicalwood_Roof_Steep",
      "rotation": 1
    },
    {
      "x": 3,
      "y": 11,
      "z": 2,
      "name": "Wood_Tropicalwood_Roof_Steep",
      "filler": 1024,
      "rotation": 1
    },
    {
      "x": 3,
      "y": 0,
      "z": 3,
      "name": "Soil_Grass_Full"
    },
    {
      "x": 3,
      "y": 1,
      "z": 3,
      "name": "Wood_Tropicalwood_Beam"
    },
    {
      "x": 3,
      "y": 2,
      "z": 3,
      "name": "Wood_Tropicalwood_Beam"
    },
    {
      "x": 3,
      "y": 3,
      "z": 3,
      "name": "Wood_Tropicalwood_Planks"
    },
    {
      "x": 3,
      "y": 4,
      "z": 3,
      "name": "Wood_Tropicalwood_Fence",
      "rotation": 1
    },
    {
      "x": 3,
      "y": 10,
      "z": 3,
      "name": "Wood_Tropicalwood_Roof_Steep",
      "rotation": 1
    },
    {
      "x": 3,
      "y": 11,
      "z": 3,
      "name": "Wood_Tropicalwood_Roof_Steep",
      "filler": 1024,
      "rotation": 1
    },
    {
      "x": 3,
      "y": 0,
      "z": 4,
      "name": "Soil_Grass_Full"
    },
    {
      "x": 3,
      "y": 3,
      "z": 4,
      "name": "Wood_Tropicalwood_Planks"
    },
    {
      "x": 3,
      "y": 4,
      "z": 4,
      "name": "Wood_Tropicalwood_Fence",
      "rotation": 1
    },
    {
      "x": 3,
      "y": 10,
      "z": 4,
      "name": "Wood_Tropicalwood_Roof_Steep",
      "rotation": 1
    },
    {
      "x": 3,
      "y": 11,
      "z": 4,
      "name": "Wood_Tropicalwood_Roof_Steep",
      "filler": 1024,
      "rotation": 1
    },
    {
      "x": 3,
      "y": 0,
      "z": 5,
      "name": "Soil_Grass_Full"
    },
    {
      "x": 3,
      "y": 1,
      "z": 5,
      "name": "Plant_Grass_Lush_Short"
    },
    {
      "x": 3,
      "y": 3,
      "z": 5,
      "name": "Wood_Tropicalwood_Planks"
    },
    {
      "x": 3,
      "y": 4,
      "z": 5,
      "name": "Wood_Tropicalwood_Fence",
      "rotation": 1
    },
    {
      "x": 3,
      "y": 10,
      "z": 5,
      "name": "Wood_Tropicalwood_Roof_Steep",
      "rotation": 1
    },
    {
      "x": 3,
      "y": 11,
      "z": 5,
      "name": "Wood_Tropicalwood_Roof_Steep",
      "filler": 1024,
      "rotation": 1
    },
    {
      "x": 3,
      "y": 0,
      "z": 6,
      "name": "Soil_Grass_Full"
    },
    {
      "x": 3,
      "y": 1,
      "z": 6,
      "name": "Wood_Tropicalwood_Beam"
    },
    {
      "x": 3,
      "y": 2,
      "z": 6,
      "name": "Wood_Tropicalwood_Beam"
    },
    {
      "x": 3,
      "y": 3,
      "z": 6,
      "name": "Wood_Tropicalwood_Planks"
    },
    {
      "x": 3,
      "y": 4,
      "z": 6,
      "name": "*Wood_Tropicalwood_Fence_State_Definitions_Corner",
      "rotation": 3
    },
    {
      "x": 3,
      "y": 10,
      "z": 6,
      "name": "*Wood_Tropicalwood_Roof_Steep_State_Definitions_Corner_Left"
    },
    {
      "x": 3,
      "y": 11,
      "z": 6,
      "name": "*Wood_Tropicalwood_Roof_Steep_State_Definitions_Corner_Left",
      "filler": 1024
    },
    {
      "x": 4,
      "y": 0,
      "z": -5,
      "name": "Soil_Grass_Full"
    },
    {
      "x": 4,
      "y": 0,
      "z": -4,
      "name": "Soil_Pathway"
    },
    {
      "x": 4,
      "y": 0,
      "z": -3,
      "name": "Soil_Pathway"
    },
    {
      "x": 4,
      "y": 0,
      "z": -2,
      "name": "Soil_Pathway"
    },
    {
      "x": 4,
      "y": 0,
      "z": -1,
      "name": "Soil_Grass_Full"
    },
    {
      "x": 4,
      "y": 0,
      "z": 0,
      "name": "Soil_Grass_Full"
    },
    {
      "x": 4,
      "y": 0,
      "z": 1,
      "name": "Soil_Grass_Full"
    },
    {
      "x": 4,
      "y": 0,
      "z": 2,
      "name": "Soil_Grass_Full"
    },
    {
      "x": 4,
      "y": 0,
      "z": 3,
      "name": "Soil_Grass_Full"
    },
    {
      "x": 4,
      "y": 0,
      "z": 4,
      "name": "Soil_Grass_Full"
    },
    {
      "x": 4,
      "y": 0,
      "z": 5,
      "name": "Soil_Grass_Full"
    },
    {
      "x": 4,
      "y": 1,
      "z": 5,
      "name": "Plant_Grass_Lush_Short"
    },
    {
      "x": 4,
      "y": 0,
      "z": 6,
      "name": "Soil_Grass_Full"
    },
    {
      "x": 4,
      "y": 1,
      "z": 6,
      "name": "Plant_Grass_Sharp_Tall"
    },
    {
      "x": 5,
      "y": 0,
      "z": -5,
      "name": "Soil_Grass_Full"
    },
    {
      "x": 5,
      "y": 0,
      "z": -4,
      "name": "Soil_Grass_Full"
    },
    {
      "x": 5,
      "y": 0,
      "z": -3,
      "name": "Soil_Grass_Full"
    },
    {
      "x": 5,
      "y": 0,
      "z": -2,
      "name": "Soil_Grass_Full"
    },
    {
      "x": 5,
      "y": 0,
      "z": -1,
      "name": "Soil_Grass_Full"
    },
    {
      "x": 5,
      "y": 0,
      "z": 0,
      "name": "Soil_Grass_Full"
    },
    {
      "x": 5,
      "y": 0,
      "z": 1,
      "name": "Soil_Grass_Full"
    },
    {
      "x": 5,
      "y": 0,
      "z": 2,
      "name": "Soil_Grass_Full"
    },
    {
      "x": 5,
      "y": 1,
      "z": 2,
      "name": "Plant_Grass_Sharp_Tall"
    },
    {
      "x": 5,
      "y": 0,
      "z": 3,
      "name": "Soil_Grass_Full"
    },
    {
      "x": 5,
      "y": 0,
      "z": 4,
      "name": "Soil_Grass_Full"
    },
    {
      "x": 5,
      "y": 1,
      "z": 4,
      "name": "Plant_Fern_Giant",
      "support": 15
    },
    {
      "x": 5,
      "y": 0,
      "z": 5,
      "name": "Soil_Grass_Full"
    },
    {
      "x": 5,
      "y": 1,
      "z": 5,
      "name": "Plant_Grass_Sharp"
    },
    {
      "x": 5,
      "y": 0,
      "z": 6,
      "name": "Soil_Grass_Full"
    }
  ],
  "fluids": [
    {
      "x": -4,
      "y": 0,
      "z": -5,
      "name": "Empty",
      "level": 0
    },
    {
      "x": -4,
      "y": 1,
      "z": -5,
      "name": "Empty",
      "level": 0
    },
    {
      "x": -4,
      "y": 0,
      "z": -4,
      "name": "Empty",
      "level": 0
    },
    {
      "x": -4,
      "y": 1,
      "z": -4,
      "name": "Empty",
      "level": 0
    },
    {
      "x": -4,
      "y": 0,
      "z": -3,
      "name": "Empty",
      "level": 0
    },
    {
      "x": -4,
      "y": 0,
      "z": -2,
      "name": "Empty",
      "level": 0
    },
    {
      "x": -4,
      "y": 0,
      "z": -1,
      "name": "Empty",
      "level": 0
    },
    {
      "x": -4,
      "y": 0,
      "z": 0,
      "name": "Empty",
      "level": 0
    },
    {
      "x": -4,
      "y": 0,
      "z": 1,
      "name": "Empty",
      "level": 0
    },
    {
      "x": -4,
      "y": 1,
      "z": 1,
      "name": "Empty",
      "level": 0
    },
    {
      "x": -4,
      "y": 0,
      "z": 2,
      "name": "Empty",
      "level": 0
    },
    {
      "x": -4,
      "y": 1,
      "z": 2,
      "name": "Empty",
      "level": 0
    },
    {
      "x": -4,
      "y": 0,
      "z": 3,
      "name": "Empty",
      "level": 0
    },
    {
      "x": -4,
      "y": 0,
      "z": 4,
      "name": "Empty",
      "level": 0
    },
    {
      "x": -4,
      "y": 1,
      "z": 4,
      "name": "Empty",
      "level": 0
    },
    {
      "x": -4,
      "y": 0,
      "z": 5,
      "name": "Empty",
      "level": 0
    },
    {
      "x": -4,
      "y": 1,
      "z": 5,
      "name": "Empty",
      "level": 0
    },
    {
      "x": -4,
      "y": 0,
      "z": 6,
      "name": "Empty",
      "level": 0
    },
    {
      "x": -4,
      "y": 1,
      "z": 6,
      "name": "Empty",
      "level": 0
    },
    {
      "x": -3,
      "y": 0,
      "z": -5,
      "name": "Empty",
      "level": 0
    },
    {
      "x": -3,
      "y": 0,
      "z": -4,
      "name": "Empty",
      "level": 0
    },
    {
      "x": -3,
      "y": 0,
      "z": -3,
      "name": "Empty",
      "level": 0
    },
    {
      "x": -3,
      "y": 0,
      "z": -2,
      "name": "Empty",
      "level": 0
    },
    {
      "x": -3,
      "y": 3,
      "z": -2,
      "name": "Empty",
      "level": 0
    },
    {
      "x": -3,
      "y": 4,
      "z": -2,
      "name": "Empty",
      "level": 0
    },
    {
      "x": -3,
      "y": 0,
      "z": -1,
      "name": "Empty",
      "level": 0
    },
    {
      "x": -3,
      "y": 3,
      "z": -1,
      "name": "Empty",
      "level": 0
    },
    {
      "x": -3,
      "y": 4,
      "z": -1,
      "name": "Empty",
      "level": 0
    },
    {
      "x": -3,
      "y": 0,
      "z": 0,
      "name": "Empty",
      "level": 0
    },
    {
      "x": -3,
      "y": 1,
      "z": 0,
      "name": "Empty",
      "level": 0
    },
    {
      "x": -3,
      "y": 2,
      "z": 0,
      "name": "Empty",
      "level": 0
    },
    {
      "x": -3,
      "y": 3,
      "z": 0,
      "name": "Empty",
      "level": 0
    },
    {
      "x": -3,
      "y": 4,
      "z": 0,
      "name": "Empty",
      "level": 0
    },
    {
      "x": -3,
      "y": 10,
      "z": 0,
      "name": "Empty",
      "level": 0
    },
    {
      "x": -3,
      "y": 11,
      "z": 0,
      "name": "Empty",
      "level": 0
    },
    {
      "x": -3,
      "y": 0,
      "z": 1,
      "name": "Empty",
      "level": 0
    },
    {
      "x": -3,
      "y": 1,
      "z": 1,
      "name": "Empty",
      "level": 0
    },
    {
      "x": -3,
      "y": 3,
      "z": 1,
      "name": "Empty",
      "level": 0
    },
    {
      "x": -3,
      "y": 4,
      "z": 1,
      "name": "Empty",
      "level": 0
    },
    {
      "x": -3,
      "y": 10,
      "z": 1,
      "name": "Empty",
      "level": 0
    },
    {
      "x": -3,
      "y": 11,
      "z": 1,
      "name": "Empty",
      "level": 0
    },
    {
      "x": -3,
      "y": 0,
      "z": 2,
      "name": "Empty",
      "level": 0
    },
    {
      "x": -3,
      "y": 1,
      "z": 2,
      "name": "Empty",
      "level": 0
    },
    {
      "x": -3,
      "y": 3,
      "z": 2,
      "name": "Empty",
      "level": 0
    },
    {
      "x": -3,
      "y": 4,
      "z": 2,
      "name": "Empty",
      "level": 0
    },
    {
      "x": -3,
      "y": 10,
      "z": 2,
      "name": "Empty",
      "level": 0
    },
    {
      "x": -3,
      "y": 11,
      "z": 2,
      "name": "Empty",
      "level": 0
    },
    {
      "x": -3,
      "y": 0,
      "z": 3,
      "name": "Empty",
      "level": 0
    },
    {
      "x": -3,
      "y": 1,
      "z": 3,
      "name": "Empty",
      "level": 0
    },
    {
      "x": -3,
      "y": 2,
      "z": 3,
      "name": "Empty",
      "level": 0
    },
    {
      "x": -3,
      "y": 3,
      "z": 3,
      "name": "Empty",
      "level": 0
    },
    {
      "x": -3,
      "y": 4,
      "z": 3,
      "name": "Empty",
      "level": 0
    },
    {
      "x": -3,
      "y": 10,
      "z": 3,
      "name": "Empty",
      "level": 0
    },
    {
      "x": -3,
      "y": 11,
      "z": 3,
      "name": "Empty",
      "level": 0
    },
    {
      "x": -3,
      "y": 0,
      "z": 4,
      "name": "Empty",
      "level": 0
    },
    {
      "x": -3,
      "y": 3,
      "z": 4,
      "name": "Empty",
      "level": 0
    },
    {
      "x": -3,
      "y": 4,
      "z": 4,
      "name": "Empty",
      "level": 0
    },
    {
      "x": -3,
      "y": 10,
      "z": 4,
      "name": "Empty",
      "level": 0
    },
    {
      "x": -3,
      "y": 11,
      "z": 4,
      "name": "Empty",
      "level": 0
    },
    {
      "x": -3,
      "y": 0,
      "z": 5,
      "name": "Empty",
      "level": 0
    },
    {
      "x": -3,
      "y": 1,
      "z": 5,
      "name": "Empty",
      "level": 0
    },
    {
      "x": -3,
      "y": 3,
      "z": 5,
      "name": "Empty",
      "level": 0
    },
    {
      "x": -3,
      "y": 4,
      "z": 5,
      "name": "Empty",
      "level": 0
    },
    {
      "x": -3,
      "y": 10,
      "z": 5,
      "name": "Empty",
      "level": 0
    },
    {
      "x": -3,
      "y": 11,
      "z": 5,
      "name": "Empty",
      "level": 0
    },
    {
      "x": -3,
      "y": 0,
      "z": 6,
      "name": "Empty",
      "level": 0
    },
    {
      "x": -3,
      "y": 1,
      "z": 6,
      "name": "Empty",
      "level": 0
    },
    {
      "x": -3,
      "y": 2,
      "z": 6,
      "name": "Empty",
      "level": 0
    },
    {
      "x": -3,
      "y": 3,
      "z": 6,
      "name": "Empty",
      "level": 0
    },
    {
      "x": -3,
      "y": 4,
      "z": 6,
      "name": "Empty",
      "level": 0
    },
    {
      "x": -3,
      "y": 10,
      "z": 6,
      "name": "Empty",
      "level": 0
    },
    {
      "x": -3,
      "y": 11,
      "z": 6,
      "name": "Empty",
      "level": 0
    },
    {
      "x": -2,
      "y": 0,
      "z": -5,
      "name": "Empty",
      "level": 0
    },
    {
      "x": -2,
      "y": 0,
      "z": -4,
      "name": "Empty",
      "level": 0
    },
    {
      "x": -2,
      "y": 0,
      "z": -3,
      "name": "Empty",
      "level": 0
    },
    {
      "x": -2,
      "y": 0,
      "z": -2,
      "name": "Empty",
      "level": 0
    },
    {
      "x": -2,
      "y": 3,
      "z": -2,
      "name": "Empty",
      "level": 0
    },
    {
      "x": -2,
      "y": 0,
      "z": -1,
      "name": "Empty",
      "level": 0
    },
    {
      "x": -2,
      "y": 1,
      "z": -1,
      "name": "Empty",
      "level": 0
    },
    {
      "x": -2,
      "y": 3,
      "z": -1,
      "name": "Empty",
      "level": 0
    },
    {
      "x": -2,
      "y": 0,
      "z": 0,
      "name": "Empty",
      "level": 0
    },
    {
      "x": -2,
      "y": 1,
      "z": 0,
      "name": "Empty",
      "level": 0
    },
    {
      "x": -2,
      "y": 3,
      "z": 0,
      "name": "Empty",
      "level": 0
    },
    {
      "x": -2,
      "y": 10,
      "z": 0,
      "name": "Empty",
      "level": 0
    },
    {
      "x": -2,
      "y": 11,
      "z": 0,
      "name": "Empty",
      "level": 0
    },
    {
      "x": -2,
      "y": 0,
      "z": 1,
      "name": "Empty",
      "level": 0
    },
    {
      "x": -2,
      "y": 1,
      "z": 1,
      "name": "Empty",
      "level": 0
    },
    {
      "x": -2,
      "y": 3,
      "z": 1,
      "name": "Empty",
      "level": 0
    },
    {
      "x": -2,
      "y": 4,
      "z": 1,
      "name": "Empty",
      "level": 0
    },
    {
      "x": -2,
      "y": 5,
      "z": 1,
      "name": "Empty",
      "level": 0
    },
    {
      "x": -2,
      "y": 6,
      "z": 1,
      "name": "Empty",
      "level": 0
    },
    {
      "x": -2,
      "y": 7,
      "z": 1,
      "name": "Empty",
      "level": 0
    },
    {
      "x": -2,
      "y": 8,
      "z": 1,
      "name": "Empty",
      "level": 0
    },
    {
      "x": -2,
      "y": 9,
      "z": 1,
      "name": "Empty",
      "level": 0
    },
    {
      "x": -2,
      "y": 10,
      "z": 1,
      "name": "Empty",
      "level": 0
    },
    {
      "x": -2,
      "y": 11,
      "z": 1,
      "name": "Empty",
      "level": 0
    },
    {
      "x": -2,
      "y": 12,
      "z": 1,
      "name": "Empty",
      "level": 0
    },
    {
      "x": -2,
      "y": 0,
      "z": 2,
      "name": "Empty",
      "level": 0
    },
    {
      "x": -2,
      "y": 1,
      "z": 2,
      "name": "Empty",
      "level": 0
    },
    {
      "x": -2,
      "y": 3,
      "z": 2,
      "name": "Empty",
      "level": 0
    },
    {
      "x": -2,
      "y": 7,
      "z": 2,
      "name": "Empty",
      "level": 0
    },
    {
      "x": -2,
      "y": 8,
      "z": 2,
      "name": "Empty",
      "level": 0
    },
    {
      "x": -2,
      "y": 12,
      "z": 2,
      "name": "Empty",
      "level": 0
    },
    {
      "x": -2,
      "y": 0,
      "z": 3,
      "name": "Empty",
      "level": 0
    },
    {
      "x": -2,
      "y": 3,
      "z": 3,
      "name": "Empty",
      "level": 0
    },
    {
      "x": -2,
      "y": 4,
      "z": 3,
      "name": "Empty",
      "level": 0
    },
    {
      "x": -2,
      "y": 5,
      "z": 3,
      "name": "Empty",
      "level": 0
    },
    {
      "x": -2,
      "y": 6,
      "z": 3,
      "name": "Empty",
      "level": 0
    },
    {
      "x": -2,
      "y": 7,
      "z": 3,
      "name": "Empty",
      "level": 0
    },
    {
      "x": -2,
      "y": 8,
      "z": 3,
      "name": "Empty",
      "level": 0
    },
    {
      "x": -2,
      "y": 12,
      "z": 3,
      "name": "Empty",
      "level": 0
    },
    {
      "x": -2,
      "y": 0,
      "z": 4,
      "name": "Empty",
      "level": 0
    },
    {
      "x": -2,
      "y": 3,
      "z": 4,
      "name": "Empty",
      "level": 0
    },
    {
      "x": -2,
      "y": 4,
      "z": 4,
      "name": "Empty",
      "level": 0
    },
    {
      "x": -2,
      "y": 5,
      "z": 4,
      "name": "Empty",
      "level": 0
    },
    {
      "x": -2,
      "y": 6,
      "z": 4,
      "name": "Empty",
      "level": 0
    },
    {
      "x": -2,
      "y": 7,
      "z": 4,
      "name": "Empty",
      "level": 0
    },
    {
      "x": -2,
      "y": 8,
      "z": 4,
      "name": "Empty",
      "level": 0
    },
    {
      "x": -2,
      "y": 12,
      "z": 4,
      "name": "Empty",
      "level": 0
    },
    {
      "x": -2,
      "y": 0,
      "z": 5,
      "name": "Empty",
      "level": 0
    },
    {
      "x": -2,
      "y": 1,
      "z": 5,
      "name": "Empty",
      "level": 0
    },
    {
      "x": -2,
      "y": 3,
      "z": 5,
      "name": "Empty",
      "level": 0
    },
    {
      "x": -2,
      "y": 4,
      "z": 5,
      "name": "Empty",
      "level": 0
    },
    {
      "x": -2,
      "y": 5,
      "z": 5,
      "name": "Empty",
      "level": 0
    },
    {
      "x": -2,
      "y": 6,
      "z": 5,
      "name": "Empty",
      "level": 0
    },
    {
      "x": -2,
      "y": 7,
      "z": 5,
      "name": "Empty",
      "level": 0
    },
    {
      "x": -2,
      "y": 8,
      "z": 5,
      "name": "Empty",
      "level": 0
    },
    {
      "x": -2,
      "y": 9,
      "z": 5,
      "name": "Empty",
      "level": 0
    },
    {
      "x": -2,
      "y": 10,
      "z": 5,
      "name": "Empty",
      "level": 0
    },
    {
      "x": -2,
      "y": 11,
      "z": 5,
      "name": "Empty",
      "level": 0
    },
    {
      "x": -2,
      "y": 12,
      "z": 5,
      "name": "Empty",
      "level": 0
    },
    {
      "x": -2,
      "y": 0,
      "z": 6,
      "name": "Empty",
      "level": 0
    },
    {
      "x": -2,
      "y": 3,
      "z": 6,
      "name": "Empty",
      "level": 0
    },
    {
      "x": -2,
      "y": 4,
      "z": 6,
      "name": "Empty",
      "level": 0
    },
    {
      "x": -2,
      "y": 10,
      "z": 6,
      "name": "Empty",
      "level": 0
    },
    {
      "x": -2,
      "y": 11,
      "z": 6,
      "name": "Empty",
      "level": 0
    },
    {
      "x": -1,
      "y": 0,
      "z": -5,
      "name": "Empty",
      "level": 0
    },
    {
      "x": -1,
      "y": 0,
      "z": -4,
      "name": "Empty",
      "level": 0
    },
    {
      "x": -1,
      "y": 0,
      "z": -3,
      "name": "Empty",
      "level": 0
    },
    {
      "x": -1,
      "y": 1,
      "z": -3,
      "name": "Empty",
      "level": 0
    },
    {
      "x": -1,
      "y": 0,
      "z": -2,
      "name": "Empty",
      "level": 0
    },
    {
      "x": -1,
      "y": 3,
      "z": -2,
      "name": "Empty",
      "level": 0
    },
    {
      "x": -1,
      "y": 0,
      "z": -1,
      "name": "Empty",
      "level": 0
    },
    {
      "x": -1,
      "y": 1,
      "z": -1,
      "name": "Empty",
      "level": 0
    },
    {
      "x": -1,
      "y": 3,
      "z": -1,
      "name": "Empty",
      "level": 0
    },
    {
      "x": -1,
      "y": 0,
      "z": 0,
      "name": "Empty",
      "level": 0
    },
    {
      "x": -1,
      "y": 3,
      "z": 0,
      "name": "Empty",
      "level": 0
    },
    {
      "x": -1,
      "y": 10,
      "z": 0,
      "name": "Empty",
      "level": 0
    },
    {
      "x": -1,
      "y": 11,
      "z": 0,
      "name": "Empty",
      "level": 0
    },
    {
      "x": -1,
      "y": 0,
      "z": 1,
      "name": "Empty",
      "level": 0
    },
    {
      "x": -1,
      "y": 3,
      "z": 1,
      "name": "Empty",
      "level": 0
    },
    {
      "x": -1,
      "y": 7,
      "z": 1,
      "name": "Empty",
      "level": 0
    },
    {
      "x": -1,
      "y": 8,
      "z": 1,
      "name": "Empty",
      "level": 0
    },
    {
      "x": -1,
      "y": 12,
      "z": 1,
      "name": "Empty",
      "level": 0
    },
    {
      "x": -1,
      "y": 0,
      "z": 2,
      "name": "Empty",
      "level": 0
    },
    {
      "x": -1,
      "y": 1,
      "z": 2,
      "name": "Empty",
      "level": 0
    },
    {
      "x": -1,
      "y": 3,
      "z": 2,
      "name": "Empty",
      "level": 0
    },
    {
      "x": -1,
      "y": 7,
      "z": 2,
      "name": "Empty",
      "level": 0
    },
    {
      "x": -1,
      "y": 12,
      "z": 2,
      "name": "Empty",
      "level": 0
    },
    {
      "x": -1,
      "y": 0,
      "z": 3,
      "name": "Empty",
      "level": 0
    },
    {
      "x": -1,
      "y": 3,
      "z": 3,
      "name": "Empty",
      "level": 0
    },
    {
      "x": -1,
      "y": 7,
      "z": 3,
      "name": "Empty",
      "level": 0
    },
    {
      "x": -1,
      "y": 12,
      "z": 3,
      "name": "Empty",
      "level": 0
    },
    {
      "x": -1,
      "y": 0,
      "z": 4,
      "name": "Empty",
      "level": 0
    },
    {
      "x": -1,
      "y": 1,
      "z": 4,
      "name": "Empty",
      "level": 0
    },
    {
      "x": -1,
      "y": 3,
      "z": 4,
      "name": "Empty",
      "level": 0
    },
    {
      "x": -1,
      "y": 4,
      "z": 4,
      "name": "Empty",
      "level": 0
    },
    {
      "x": -1,
      "y": 5,
      "z": 4,
      "name": "Empty",
      "level": 0
    },
    {
      "x": -1,
      "y": 7,
      "z": 4,
      "name": "Empty",
      "level": 0
    },
    {
      "x": -1,
      "y": 12,
      "z": 4,
      "name": "Empty",
      "level": 0
    },
    {
      "x": -1,
      "y": 0,
      "z": 5,
      "name": "Empty",
      "level": 0
    },
    {
      "x": -1,
      "y": 1,
      "z": 5,
      "name": "Empty",
      "level": 0
    },
    {
      "x": -1,
      "y": 3,
      "z": 5,
      "name": "Empty",
      "level": 0
    },
    {
      "x": -1,
      "y": 4,
      "z": 5,
      "name": "Empty",
      "level": 0
    },
    {
      "x": -1,
      "y": 5,
      "z": 5,
      "name": "Empty",
      "level": 0
    },
    {
      "x": -1,
      "y": 6,
      "z": 5,
      "name": "Empty",
      "level": 0
    },
    {
      "x": -1,
      "y": 7,
      "z": 5,
      "name": "Empty",
      "level": 0
    },
    {
      "x": -1,
      "y": 8,
      "z": 5,
      "name": "Empty",
      "level": 0
    },
    {
      "x": -1,
      "y": 12,
      "z": 5,
      "name": "Empty",
      "level": 0
    },
    {
      "x": -1,
      "y": 0,
      "z": 6,
      "name": "Empty",
      "level": 0
    },
    {
      "x": -1,
      "y": 1,
      "z": 6,
      "name": "Empty",
      "level": 0
    },
    {
      "x": -1,
      "y": 3,
      "z": 6,
      "name": "Empty",
      "level": 0
    },
    {
      "x": -1,
      "y": 4,
      "z": 6,
      "name": "Empty",
      "level": 0
    },
    {
      "x": -1,
      "y": 10,
      "z": 6,
      "name": "Empty",
      "level": 0
    },
    {
      "x": -1,
      "y": 11,
      "z": 6,
      "name": "Empty",
      "level": 0
    },
    {
      "x": 0,
      "y": 0,
      "z": -5,
      "name": "Empty",
      "level": 0
    },
    {
      "x": 0,
      "y": 0,
      "z": -4,
      "name": "Empty",
      "level": 0
    },
    {
      "x": 0,
      "y": 0,
      "z": -3,
      "name": "Empty",
      "level": 0
    },
    {
      "x": 0,
      "y": 0,
      "z": -2,
      "name": "Empty",
      "level": 0
    },
    {
      "x": 0,
      "y": 2,
      "z": -2,
      "name": "Empty",
      "level": 0
    },
    {
      "x": 0,
      "y": 3,
      "z": -2,
      "name": "Empty",
      "level": 0
    },
    {
      "x": 0,
      "y": 0,
      "z": -1,
      "name": "Empty",
      "level": 0
    },
    {
      "x": 0,
      "y": 2,
      "z": -1,
      "name": "Empty",
      "level": 0
    },
    {
      "x": 0,
      "y": 3,
      "z": -1,
      "name": "Empty",
      "level": 0
    },
    {
      "x": 0,
      "y": 0,
      "z": 0,
      "name": "Empty",
      "level": 0
    },
    {
      "x": 0,
      "y": 1,
      "z": 0,
      "name": "Empty",
      "level": 0
    },
    {
      "x": 0,
      "y": 2,
      "z": 0,
      "name": "Empty",
      "level": 0
    },
    {
      "x": 0,
      "y": 3,
      "z": 0,
      "name": "Empty",
      "level": 0
    },
    {
      "x": 0,
      "y": 4,
      "z": 0,
      "name": "Empty",
      "level": 0
    },
    {
      "x": 0,
      "y": 10,
      "z": 0,
      "name": "Empty",
      "level": 0
    },
    {
      "x": 0,
      "y": 11,
      "z": 0,
      "name": "Empty",
      "level": 0
    },
    {
      "x": 0,
      "y": 0,
      "z": 1,
      "name": "Empty",
      "level": 0
    },
    {
      "x": 0,
      "y": 3,
      "z": 1,
      "name": "Empty",
      "level": 0
    },
    {
      "x": 0,
      "y": 4,
      "z": 1,
      "name": "Empty",
      "level": 0
    },
    {
      "x": 0,
      "y": 5,
      "z": 1,
      "name": "Empty",
      "level": 0
    },
    {
      "x": 0,
      "y": 6,
      "z": 1,
      "name": "Empty",
      "level": 0
    },
    {
      "x": 0,
      "y": 7,
      "z": 1,
      "name": "Empty",
      "level": 0
    },
    {
      "x": 0,
      "y": 8,
      "z": 1,
      "name": "Empty",
      "level": 0
    },
    {
      "x": 0,
      "y": 12,
      "z": 1,
      "name": "Empty",
      "level": 0
    },
    {
      "x": 0,
      "y": 0,
      "z": 2,
      "name": "Empty",
      "level": 0
    },
    {
      "x": 0,
      "y": 3,
      "z": 2,
      "name": "Empty",
      "level": 0
    },
    {
      "x": 0,
      "y": 7,
      "z": 2,
      "name": "Empty",
      "level": 0
    },
    {
      "x": 0,
      "y": 12,
      "z": 2,
      "name": "Empty",
      "level": 0
    },
    {
      "x": 0,
      "y": 0,
      "z": 3,
      "name": "Empty",
      "level": 0
    },
    {
      "x": 0,
      "y": 3,
      "z": 3,
      "name": "Empty",
      "level": 0
    },
    {
      "x": 0,
      "y": 7,
      "z": 3,
      "name": "Empty",
      "level": 0
    },
    {
      "x": 0,
      "y": 11,
      "z": 3,
      "name": "Empty",
      "level": 0
    },
    {
      "x": 0,
      "y": 12,
      "z": 3,
      "name": "Empty",
      "level": 0
    },
    {
      "x": 0,
      "y": 0,
      "z": 4,
      "name": "Empty",
      "level": 0
    },
    {
      "x": 0,
      "y": 1,
      "z": 4,
      "name": "Empty",
      "level": 0
    },
    {
      "x": 0,
      "y": 3,
      "z": 4,
      "name": "Empty",
      "level": 0
    },
    {
      "x": 0,
      "y": 4,
      "z": 4,
      "name": "Empty",
      "level": 0
    },
    {
      "x": 0,
      "y": 5,
      "z": 4,
      "name": "Empty",
      "level": 0
    },
    {
      "x": 0,
      "y": 6,
      "z": 4,
      "name": "Empty",
      "level": 0
    },
    {
      "x": 0,
      "y": 7,
      "z": 4,
      "name": "Empty",
      "level": 0
    },
    {
      "x": 0,
      "y": 12,
      "z": 4,
      "name": "Empty",
      "level": 0
    },
    {
      "x": 0,
      "y": 0,
      "z": 5,
      "name": "Empty",
      "level": 0
    },
    {
      "x": 0,
      "y": 3,
      "z": 5,
      "name": "Empty",
      "level": 0
    },
    {
      "x": 0,
      "y": 4,
      "z": 5,
      "name": "Empty",
      "level": 0
    },
    {
      "x": 0,
      "y": 5,
      "z": 5,
      "name": "Empty",
      "level": 0
    },
    {
      "x": 0,
      "y": 6,
      "z": 5,
      "name": "Empty",
      "level": 0
    },
    {
      "x": 0,
      "y": 7,
      "z": 5,
      "name": "Empty",
      "level": 0
    },
    {
      "x": 0,
      "y": 8,
      "z": 5,
      "name": "Empty",
      "level": 0
    },
    {
      "x": 0,
      "y": 12,
      "z": 5,
      "name": "Empty",
      "level": 0
    },
    {
      "x": 0,
      "y": 0,
      "z": 6,
      "name": "Empty",
      "level": 0
    },
    {
      "x": 0,
      "y": 1,
      "z": 6,
      "name": "Empty",
      "level": 0
    },
    {
      "x": 0,
      "y": 2,
      "z": 6,
      "name": "Empty",
      "level": 0
    },
    {
      "x": 0,
      "y": 3,
      "z": 6,
      "name": "Empty",
      "level": 0
    },
    {
      "x": 0,
      "y": 4,
      "z": 6,
      "name": "Empty",
      "level": 0
    },
    {
      "x": 0,
      "y": 10,
      "z": 6,
      "name": "Empty",
      "level": 0
    },
    {
      "x": 0,
      "y": 11,
      "z": 6,
      "name": "Empty",
      "level": 0
    },
    {
      "x": 1,
      "y": 0,
      "z": -5,
      "name": "Empty",
      "level": 0
    },
    {
      "x": 1,
      "y": 0,
      "z": -4,
      "name": "Empty",
      "level": 0
    },
    {
      "x": 1,
      "y": 0,
      "z": -3,
      "name": "Empty",
      "level": 0
    },
    {
      "x": 1,
      "y": 0,
      "z": -2,
      "name": "Empty",
      "level": 0
    },
    {
      "x": 1,
      "y": 1,
      "z": -2,
      "name": "Empty",
      "level": 0
    },
    {
      "x": 1,
      "y": 2,
      "z": -2,
      "name": "Empty",
      "level": 0
    },
    {
      "x": 1,
      "y": 0,
      "z": -1,
      "name": "Empty",
      "level": 0
    },
    {
      "x": 1,
      "y": 1,
      "z": -1,
      "name": "Empty",
      "level": 0
    },
    {
      "x": 1,
      "y": 2,
      "z": -1,
      "name": "Empty",
      "level": 0
    },
    {
      "x": 1,
      "y": 0,
      "z": 0,
      "name": "Empty",
      "level": 0
    },
    {
      "x": 1,
      "y": 1,
      "z": 0,
      "name": "Empty",
      "level": 0
    },
    {
      "x": 1,
      "y": 3,
      "z": 0,
      "name": "Empty",
      "level": 0
    },
    {
      "x": 1,
      "y": 4,
      "z": 0,
      "name": "Empty",
      "level": 0
    },
    {
      "x": 1,
      "y": 10,
      "z": 0,
      "name": "Empty",
      "level": 0
    },
    {
      "x": 1,
      "y": 11,
      "z": 0,
      "name": "Empty",
      "level": 0
    },
    {
      "x": 1,
      "y": 0,
      "z": 1,
      "name": "Empty",
      "level": 0
    },
    {
      "x": 1,
      "y": 3,
      "z": 1,
      "name": "Empty",
      "level": 0
    },
    {
      "x": 1,
      "y": 4,
      "z": 1,
      "name": "Empty",
      "level": 0
    },
    {
      "x": 1,
      "y": 5,
      "z": 1,
      "name": "Empty",
      "level": 0
    },
    {
      "x": 1,
      "y": 6,
      "z": 1,
      "name": "Empty",
      "level": 0
    },
    {
      "x": 1,
      "y": 7,
      "z": 1,
      "name": "Empty",
      "level": 0
    },
    {
      "x": 1,
      "y": 8,
      "z": 1,
      "name": "Empty",
      "level": 0
    },
    {
      "x": 1,
      "y": 12,
      "z": 1,
      "name": "Empty",
      "level": 0
    },
    {
      "x": 1,
      "y": 0,
      "z": 2,
      "name": "Empty",
      "level": 0
    },
    {
      "x": 1,
      "y": 3,
      "z": 2,
      "name": "Empty",
      "level": 0
    },
    {
      "x": 1,
      "y": 4,
      "z": 2,
      "name": "Empty",
      "level": 0
    },
    {
      "x": 1,
      "y": 5,
      "z": 2,
      "name": "Empty",
      "level": 0
    },
    {
      "x": 1,
      "y": 7,
      "z": 2,
      "name": "Empty",
      "level": 0
    },
    {
      "x": 1,
      "y": 12,
      "z": 2,
      "name": "Empty",
      "level": 0
    },
    {
      "x": 1,
      "y": 0,
      "z": 3,
      "name": "Empty",
      "level": 0
    },
    {
      "x": 1,
      "y": 1,
      "z": 3,
      "name": "Empty",
      "level": 0
    },
    {
      "x": 1,
      "y": 3,
      "z": 3,
      "name": "Empty",
      "level": 0
    },
    {
      "x": 1,
      "y": 4,
      "z": 3,
      "name": "Empty",
      "level": 0
    },
    {
      "x": 1,
      "y": 7,
      "z": 3,
      "name": "Empty",
      "level": 0
    },
    {
      "x": 1,
      "y": 12,
      "z": 3,
      "name": "Empty",
      "level": 0
    },
    {
      "x": 1,
      "y": 0,
      "z": 4,
      "name": "Empty",
      "level": 0
    },
    {
      "x": 1,
      "y": 1,
      "z": 4,
      "name": "Empty",
      "level": 0
    },
    {
      "x": 1,
      "y": 3,
      "z": 4,
      "name": "Empty",
      "level": 0
    },
    {
      "x": 1,
      "y": 7,
      "z": 4,
      "name": "Empty",
      "level": 0
    },
    {
      "x": 1,
      "y": 12,
      "z": 4,
      "name": "Empty",
      "level": 0
    },
    {
      "x": 1,
      "y": 0,
      "z": 5,
      "name": "Empty",
      "level": 0
    },
    {
      "x": 1,
      "y": 1,
      "z": 5,
      "name": "Empty",
      "level": 0
    },
    {
      "x": 1,
      "y": 3,
      "z": 5,
      "name": "Empty",
      "level": 0
    },
    {
      "x": 1,
      "y": 4,
      "z": 5,
      "name": "Empty",
      "level": 0
    },
    {
      "x": 1,
      "y": 5,
      "z": 5,
      "name": "Empty",
      "level": 0
    },
    {
      "x": 1,
      "y": 6,
      "z": 5,
      "name": "Empty",
      "level": 0
    },
    {
      "x": 1,
      "y": 7,
      "z": 5,
      "name": "Empty",
      "level": 0
    },
    {
      "x": 1,
      "y": 8,
      "z": 5,
      "name": "Empty",
      "level": 0
    },
    {
      "x": 1,
      "y": 12,
      "z": 5,
      "name": "Empty",
      "level": 0
    },
    {
      "x": 1,
      "y": 0,
      "z": 6,
      "name": "Empty",
      "level": 0
    },
    {
      "x": 1,
      "y": 3,
      "z": 6,
      "name": "Empty",
      "level": 0
    },
    {
      "x": 1,
      "y": 4,
      "z": 6,
      "name": "Empty",
      "level": 0
    },
    {
      "x": 1,
      "y": 10,
      "z": 6,
      "name": "Empty",
      "level": 0
    },
    {
      "x": 1,
      "y": 11,
      "z": 6,
      "name": "Empty",
      "level": 0
    },
    {
      "x": 2,
      "y": 0,
      "z": -5,
      "name": "Empty",
      "level": 0
    },
    {
      "x": 2,
      "y": 0,
      "z": -4,
      "name": "Empty",
      "level": 0
    },
    {
      "x": 2,
      "y": 0,
      "z": -3,
      "name": "Empty",
      "level": 0
    },
    {
      "x": 2,
      "y": 1,
      "z": -3,
      "name": "Empty",
      "level": 0
    },
    {
      "x": 2,
      "y": 0,
      "z": -2,
      "name": "Empty",
      "level": 0
    },
    {
      "x": 2,
      "y": 1,
      "z": -2,
      "name": "Empty",
      "level": 0
    },
    {
      "x": 2,
      "y": 0,
      "z": -1,
      "name": "Empty",
      "level": 0
    },
    {
      "x": 2,
      "y": 1,
      "z": -1,
      "name": "Empty",
      "level": 0
    },
    {
      "x": 2,
      "y": 0,
      "z": 0,
      "name": "Empty",
      "level": 0
    },
    {
      "x": 2,
      "y": 3,
      "z": 0,
      "name": "Empty",
      "level": 0
    },
    {
      "x": 2,
      "y": 4,
      "z": 0,
      "name": "Empty",
      "level": 0
    },
    {
      "x": 2,
      "y": 10,
      "z": 0,
      "name": "Empty",
      "level": 0
    },
    {
      "x": 2,
      "y": 11,
      "z": 0,
      "name": "Empty",
      "level": 0
    },
    {
      "x": 2,
      "y": 0,
      "z": 1,
      "name": "Empty",
      "level": 0
    },
    {
      "x": 2,
      "y": 3,
      "z": 1,
      "name": "Empty",
      "level": 0
    },
    {
      "x": 2,
      "y": 4,
      "z": 1,
      "name": "Empty",
      "level": 0
    },
    {
      "x": 2,
      "y": 5,
      "z": 1,
      "name": "Empty",
      "level": 0
    },
    {
      "x": 2,
      "y": 6,
      "z": 1,
      "name": "Empty",
      "level": 0
    },
    {
      "x": 2,
      "y": 7,
      "z": 1,
      "name": "Empty",
      "level": 0
    },
    {
      "x": 2,
      "y": 8,
      "z": 1,
      "name": "Empty",
      "level": 0
    },
    {
      "x": 2,
      "y": 9,
      "z": 1,
      "name": "Empty",
      "level": 0
    },
    {
      "x": 2,
      "y": 10,
      "z": 1,
      "name": "Empty",
      "level": 0
    },
    {
      "x": 2,
      "y": 11,
      "z": 1,
      "name": "Empty",
      "level": 0
    },
    {
      "x": 2,
      "y": 12,
      "z": 1,
      "name": "Empty",
      "level": 0
    },
    {
      "x": 2,
      "y": 0,
      "z": 2,
      "name": "Empty",
      "level": 0
    },
    {
      "x": 2,
      "y": 1,
      "z": 2,
      "name": "Empty",
      "level": 0
    },
    {
      "x": 2,
      "y": 3,
      "z": 2,
      "name": "Empty",
      "level": 0
    },
    {
      "x": 2,
      "y": 4,
      "z": 2,
      "name": "Empty",
      "level": 0
    },
    {
      "x": 2,
      "y": 5,
      "z": 2,
      "name": "Empty",
      "level": 0
    },
    {
      "x": 2,
      "y": 6,
      "z": 2,
      "name": "Empty",
      "level": 0
    },
    {
      "x": 2,
      "y": 7,
      "z": 2,
      "name": "Empty",
      "level": 0
    },
    {
      "x": 2,
      "y": 8,
      "z": 2,
      "name": "Empty",
      "level": 0
    },
    {
      "x": 2,
      "y": 12,
      "z": 2,
      "name": "Empty",
      "level": 0
    },
    {
      "x": 2,
      "y": 0,
      "z": 3,
      "name": "Empty",
      "level": 0
    },
    {
      "x": 2,
      "y": 3,
      "z": 3,
      "name": "Empty",
      "level": 0
    },
    {
      "x": 2,
      "y": 4,
      "z": 3,
      "name": "Empty",
      "level": 0
    },
    {
      "x": 2,
      "y": 5,
      "z": 3,
      "name": "Empty",
      "level": 0
    },
    {
      "x": 2,
      "y": 6,
      "z": 3,
      "name": "Empty",
      "level": 0
    },
    {
      "x": 2,
      "y": 7,
      "z": 3,
      "name": "Empty",
      "level": 0
    },
    {
      "x": 2,
      "y": 8,
      "z": 3,
      "name": "Empty",
      "level": 0
    },
    {
      "x": 2,
      "y": 12,
      "z": 3,
      "name": "Empty",
      "level": 0
    },
    {
      "x": 2,
      "y": 0,
      "z": 4,
      "name": "Empty",
      "level": 0
    },
    {
      "x": 2,
      "y": 1,
      "z": 4,
      "name": "Empty",
      "level": 0
    },
    {
      "x": 2,
      "y": 3,
      "z": 4,
      "name": "Empty",
      "level": 0
    },
    {
      "x": 2,
      "y": 4,
      "z": 4,
      "name": "Empty",
      "level": 0
    },
    {
      "x": 2,
      "y": 5,
      "z": 4,
      "name": "Empty",
      "level": 0
    },
    {
      "x": 2,
      "y": 6,
      "z": 4,
      "name": "Empty",
      "level": 0
    },
    {
      "x": 2,
      "y": 7,
      "z": 4,
      "name": "Empty",
      "level": 0
    },
    {
      "x": 2,
      "y": 8,
      "z": 4,
      "name": "Empty",
      "level": 0
    },
    {
      "x": 2,
      "y": 12,
      "z": 4,
      "name": "Empty",
      "level": 0
    },
    {
      "x": 2,
      "y": 0,
      "z": 5,
      "name": "Empty",
      "level": 0
    },
    {
      "x": 2,
      "y": 1,
      "z": 5,
      "name": "Empty",
      "level": 0
    },
    {
      "x": 2,
      "y": 3,
      "z": 5,
      "name": "Empty",
      "level": 0
    },
    {
      "x": 2,
      "y": 4,
      "z": 5,
      "name": "Empty",
      "level": 0
    },
    {
      "x": 2,
      "y": 5,
      "z": 5,
      "name": "Empty",
      "level": 0
    },
    {
      "x": 2,
      "y": 6,
      "z": 5,
      "name": "Empty",
      "level": 0
    },
    {
      "x": 2,
      "y": 7,
      "z": 5,
      "name": "Empty",
      "level": 0
    },
    {
      "x": 2,
      "y": 8,
      "z": 5,
      "name": "Empty",
      "level": 0
    },
    {
      "x": 2,
      "y": 9,
      "z": 5,
      "name": "Empty",
      "level": 0
    },
    {
      "x": 2,
      "y": 10,
      "z": 5,
      "name": "Empty",
      "level": 0
    },
    {
      "x": 2,
      "y": 11,
      "z": 5,
      "name": "Empty",
      "level": 0
    },
    {
      "x": 2,
      "y": 12,
      "z": 5,
      "name": "Empty",
      "level": 0
    },
    {
      "x": 2,
      "y": 0,
      "z": 6,
      "name": "Empty",
      "level": 0
    },
    {
      "x": 2,
      "y": 3,
      "z": 6,
      "name": "Empty",
      "level": 0
    },
    {
      "x": 2,
      "y": 4,
      "z": 6,
      "name": "Empty",
      "level": 0
    },
    {
      "x": 2,
      "y": 10,
      "z": 6,
      "name": "Empty",
      "level": 0
    },
    {
      "x": 2,
      "y": 11,
      "z": 6,
      "name": "Empty",
      "level": 0
    },
    {
      "x": 3,
      "y": 0,
      "z": -5,
      "name": "Empty",
      "level": 0
    },
    {
      "x": 3,
      "y": 0,
      "z": -4,
      "name": "Empty",
      "level": 0
    },
    {
      "x": 3,
      "y": 0,
      "z": -3,
      "name": "Empty",
      "level": 0
    },
    {
      "x": 3,
      "y": 1,
      "z": -3,
      "name": "Empty",
      "level": 0
    },
    {
      "x": 3,
      "y": 0,
      "z": -2,
      "name": "Empty",
      "level": 0
    },
    {
      "x": 3,
      "y": 1,
      "z": -2,
      "name": "Empty",
      "level": 0
    },
    {
      "x": 3,
      "y": 0,
      "z": -1,
      "name": "Empty",
      "level": 0
    },
    {
      "x": 3,
      "y": 1,
      "z": -1,
      "name": "Empty",
      "level": 0
    },
    {
      "x": 3,
      "y": 0,
      "z": 0,
      "name": "Empty",
      "level": 0
    },
    {
      "x": 3,
      "y": 1,
      "z": 0,
      "name": "Empty",
      "level": 0
    },
    {
      "x": 3,
      "y": 2,
      "z": 0,
      "name": "Empty",
      "level": 0
    },
    {
      "x": 3,
      "y": 3,
      "z": 0,
      "name": "Empty",
      "level": 0
    },
    {
      "x": 3,
      "y": 4,
      "z": 0,
      "name": "Empty",
      "level": 0
    },
    {
      "x": 3,
      "y": 10,
      "z": 0,
      "name": "Empty",
      "level": 0
    },
    {
      "x": 3,
      "y": 11,
      "z": 0,
      "name": "Empty",
      "level": 0
    },
    {
      "x": 3,
      "y": 0,
      "z": 1,
      "name": "Empty",
      "level": 0
    },
    {
      "x": 3,
      "y": 1,
      "z": 1,
      "name": "Empty",
      "level": 0
    },
    {
      "x": 3,
      "y": 3,
      "z": 1,
      "name": "Empty",
      "level": 0
    },
    {
      "x": 3,
      "y": 4,
      "z": 1,
      "name": "Empty",
      "level": 0
    },
    {
      "x": 3,
      "y": 10,
      "z": 1,
      "name": "Empty",
      "level": 0
    },
    {
      "x": 3,
      "y": 11,
      "z": 1,
      "name": "Empty",
      "level": 0
    },
    {
      "x": 3,
      "y": 0,
      "z": 2,
      "name": "Empty",
      "level": 0
    },
    {
      "x": 3,
      "y": 3,
      "z": 2,
      "name": "Empty",
      "level": 0
    },
    {
      "x": 3,
      "y": 4,
      "z": 2,
      "name": "Empty",
      "level": 0
    },
    {
      "x": 3,
      "y": 10,
      "z": 2,
      "name": "Empty",
      "level": 0
    },
    {
      "x": 3,
      "y": 11,
      "z": 2,
      "name": "Empty",
      "level": 0
    },
    {
      "x": 3,
      "y": 0,
      "z": 3,
      "name": "Empty",
      "level": 0
    },
    {
      "x": 3,
      "y": 1,
      "z": 3,
      "name": "Empty",
      "level": 0
    },
    {
      "x": 3,
      "y": 2,
      "z": 3,
      "name": "Empty",
      "level": 0
    },
    {
      "x": 3,
      "y": 3,
      "z": 3,
      "name": "Empty",
      "level": 0
    },
    {
      "x": 3,
      "y": 4,
      "z": 3,
      "name": "Empty",
      "level": 0
    },
    {
      "x": 3,
      "y": 10,
      "z": 3,
      "name": "Empty",
      "level": 0
    },
    {
      "x": 3,
      "y": 11,
      "z": 3,
      "name": "Empty",
      "level": 0
    },
    {
      "x": 3,
      "y": 0,
      "z": 4,
      "name": "Empty",
      "level": 0
    },
    {
      "x": 3,
      "y": 3,
      "z": 4,
      "name": "Empty",
      "level": 0
    },
    {
      "x": 3,
      "y": 4,
      "z": 4,
      "name": "Empty",
      "level": 0
    },
    {
      "x": 3,
      "y": 10,
      "z": 4,
      "name": "Empty",
      "level": 0
    },
    {
      "x": 3,
      "y": 11,
      "z": 4,
      "name": "Empty",
      "level": 0
    },
    {
      "x": 3,
      "y": 0,
      "z": 5,
      "name": "Empty",
      "level": 0
    },
    {
      "x": 3,
      "y": 1,
      "z": 5,
      "name": "Empty",
      "level": 0
    },
    {
      "x": 3,
      "y": 3,
      "z": 5,
      "name": "Empty",
      "level": 0
    },
    {
      "x": 3,
      "y": 4,
      "z": 5,
      "name": "Empty",
      "level": 0
    },
    {
      "x": 3,
      "y": 10,
      "z": 5,
      "name": "Empty",
      "level": 0
    },
    {
      "x": 3,
      "y": 11,
      "z": 5,
      "name": "Empty",
      "level": 0
    },
    {
      "x": 3,
      "y": 0,
      "z": 6,
      "name": "Empty",
      "level": 0
    },
    {
      "x": 3,
      "y": 1,
      "z": 6,
      "name": "Empty",
      "level": 0
    },
    {
      "x": 3,
      "y": 2,
      "z": 6,
      "name": "Empty",
      "level": 0
    },
    {
      "x": 3,
      "y": 3,
      "z": 6,
      "name": "Empty",
      "level": 0
    },
    {
      "x": 3,
      "y": 4,
      "z": 6,
      "name": "Empty",
      "level": 0
    },
    {
      "x": 3,
      "y": 10,
      "z": 6,
      "name": "Empty",
      "level": 0
    },
    {
      "x": 3,
      "y": 11,
      "z": 6,
      "name": "Empty",
      "level": 0
    },
    {
      "x": 4,
      "y": 0,
      "z": -5,
      "name": "Empty",
      "level": 0
    },
    {
      "x": 4,
      "y": 0,
      "z": -4,
      "name": "Empty",
      "level": 0
    },
    {
      "x": 4,
      "y": 0,
      "z": -3,
      "name": "Empty",
      "level": 0
    },
    {
      "x": 4,
      "y": 0,
      "z": -2,
      "name": "Empty",
      "level": 0
    },
    {
      "x": 4,
      "y": 0,
      "z": -1,
      "name": "Empty",
      "level": 0
    },
    {
      "x": 4,
      "y": 0,
      "z": 0,
      "name": "Empty",
      "level": 0
    },
    {
      "x": 4,
      "y": 0,
      "z": 1,
      "name": "Empty",
      "level": 0
    },
    {
      "x": 4,
      "y": 0,
      "z": 2,
      "name": "Empty",
      "level": 0
    },
    {
      "x": 4,
      "y": 0,
      "z": 3,
      "name": "Empty",
      "level": 0
    },
    {
      "x": 4,
      "y": 0,
      "z": 4,
      "name": "Empty",
      "level": 0
    },
    {
      "x": 4,
      "y": 0,
      "z": 5,
      "name": "Empty",
      "level": 0
    },
    {
      "x": 4,
      "y": 1,
      "z": 5,
      "name": "Empty",
      "level": 0
    },
    {
      "x": 4,
      "y": 0,
      "z": 6,
      "name": "Empty",
      "level": 0
    },
    {
      "x": 4,
      "y": 1,
      "z": 6,
      "name": "Empty",
      "level": 0
    },
    {
      "x": 5,
      "y": 0,
      "z": -5,
      "name": "Empty",
      "level": 0
    },
    {
      "x": 5,
      "y": 0,
      "z": -4,
      "name": "Empty",
      "level": 0
    },
    {
      "x": 5,
      "y": 0,
      "z": -3,
      "name": "Empty",
      "level": 0
    },
    {
      "x": 5,
      "y": 0,
      "z": -2,
      "name": "Empty",
      "level": 0
    },
    {
      "x": 5,
      "y": 0,
      "z": -1,
      "name": "Empty",
      "level": 0
    },
    {
      "x": 5,
      "y": 0,
      "z": 0,
      "name": "Empty",
      "level": 0
    },
    {
      "x": 5,
      "y": 0,
      "z": 1,
      "name": "Empty",
      "level": 0
    },
    {
      "x": 5,
      "y": 0,
      "z": 2,
      "name": "Empty",
      "level": 0
    },
    {
      "x": 5,
      "y": 1,
      "z": 2,
      "name": "Empty",
      "level": 0
    },
    {
      "x": 5,
      "y": 0,
      "z": 3,
      "name": "Empty",
      "level": 0
    },
    {
      "x": 5,
      "y": 0,
      "z": 4,
      "name": "Empty",
      "level": 0
    },
    {
      "x": 5,
      "y": 1,
      "z": 4,
      "name": "Empty",
      "level": 0
    },
    {
      "x": 5,
      "y": 0,
      "z": 5,
      "name": "Empty",
      "level": 0
    },
    {
      "x": 5,
      "y": 1,
      "z": 5,
      "name": "Empty",
      "level": 0
    },
    {
      "x": 5,
      "y": 0,
      "z": 6,
      "name": "Empty",
      "level": 0
    }
  ]
}
