{
    "version":  8,
    "blockIdVersion":  11,
    "anchorX":  0,
    "anchorY":  0,
    "anchorZ":  0,
    "blocks":  [
                   {
                       "x":  -5,
                       "y":  0,
                       "z":  -7,
                       "name":  "Soil_Grass_Full"
                   },
                   {
                       "x":  -5,
                       "y":  0,
                       "z":  -6,
                       "name":  "Soil_Grass_Full"
                   },
                   {
                       "x":  -5,
                       "y":  0,
                       "z":  -5,
                       "name":  "Soil_Grass_Full"
                   },
                   {
                       "x":  -5,
                       "y":  0,
                       "z":  -4,
                       "name":  "Soil_Grass_Full"
                   },
                   {
                       "x":  -5,
                       "y":  0,
                       "z":  -3,
                       "name":  "Soil_Grass_Full"
                   },
                   {
                       "x":  -5,
                       "y":  0,
                       "z":  -2,
                       "name":  "Soil_Grass_Full"
                   },
                   {
                       "x":  -5,
                       "y":  0,
                       "z":  -1,
                       "name":  "Soil_Grass_Full"
                   },
                   {
                       "x":  -5,
                       "y":  0,
                       "z":  0,
                       "name":  "Soil_Grass_Full"
                   },
                   {
                       "x":  -5,
                       "y":  0,
                       "z":  1,
                       "name":  "Soil_Grass_Full"
                   },
                   {
                       "x":  -5,
                       "y":  0,
                       "z":  2,
                       "name":  "Soil_Grass_Full"
                   },
                   {
                       "x":  -5,
                       "y":  0,
                       "z":  3,
                       "name":  "Soil_Grass_Full"
                   },
                   {
                       "x":  -5,
                       "y":  0,
                       "z":  4,
                       "name":  "Soil_Grass_Full"
                   },
                   {
                       "x":  -5,
                       "y":  0,
                       "z":  5,
                       "name":  "Soil_Grass_Full"
                   },
                   {
                       "x":  -5,
                       "y":  0,
                       "z":  6,
                       "name":  "Soil_Grass_Full"
                   },
                   {
                       "x":  -5,
                       "y":  0,
                       "z":  7,
                       "name":  "Soil_Grass_Full"
                   },
                   {
                       "x":  -5,
                       "y":  1,
                       "z":  7,
                       "name":  "Plant_Grass_Sharp_Tall"
                   },
                   {
                       "x":  -5,
                       "y":  0,
                       "z":  8,
                       "name":  "Soil_Grass_Full"
                   },
                   {
                       "x":  -5,
                       "y":  1,
                       "z":  8,
                       "name":  "Plant_Grass_Sharp"
                   },
                   {
                       "x":  -4,
                       "y":  0,
                       "z":  -7,
                       "name":  "Soil_Grass_Full"
                   },
                   {
                       "x":  -4,
                       "y":  0,
                       "z":  -6,
                       "name":  "Soil_Grass_Full"
                   },
                   {
                       "x":  -4,
                       "y":  0,
                       "z":  -5,
                       "name":  "Soil_Grass_Full"
                   },
                   {
                       "x":  -4,
                       "y":  0,
                       "z":  -4,
                       "name":  "Soil_Grass_Full"
                   },
                   {
                       "x":  -4,
                       "y":  0,
                       "z":  -3,
                       "name":  "Soil_Grass_Full"
                   },
                   {
                       "x":  -4,
                       "y":  24,
                       "z":  -3,
                       "name":  "Plant_Leaves_Beech",
                       "support":  15
                   },
                   {
                       "x":  -4,
                       "y":  0,
                       "z":  -2,
                       "name":  "Soil_Grass_Full"
                   },
                   {
                       "x":  -4,
                       "y":  1,
                       "z":  -2,
                       "name":  "Deco_Bone_Pile"
                   },
                   {
                       "x":  -4,
                       "y":  24,
                       "z":  -2,
                       "name":  "Plant_Leaves_Beech",
                       "support":  15
                   },
                   {
                       "x":  -4,
                       "y":  0,
                       "z":  -1,
                       "name":  "Soil_Grass_Full"
                   },
                   {
                       "x":  -4,
                       "y":  1,
                       "z":  -1,
                       "name":  "Wood_Jungle_Trunk_Stairs",
                       "rotation":  3
                   },
                   {
                       "x":  -4,
                       "y":  23,
                       "z":  -1,
                       "name":  "Plant_Leaves_Jungle",
                       "support":  15
                   },
                   {
                       "x":  -4,
                       "y":  24,
                       "z":  -1,
                       "name":  "Plant_Leaves_Beech",
                       "support":  15
                   },
                   {
                       "x":  -4,
                       "y":  0,
                       "z":  0,
                       "name":  "Soil_Grass_Full"
                   },
                   {
                       "x":  -4,
                       "y":  2,
                       "z":  0,
                       "name":  "Plant_Vine_Jungle",
                       "support":  15,
                       "rotation":  3
                   },
                   {
                       "x":  -4,
                       "y":  3,
                       "z":  0,
                       "name":  "Plant_Vine_Jungle",
                       "support":  15,
                       "rotation":  3
                   },
                   {
                       "x":  -4,
                       "y":  19,
                       "z":  0,
                       "name":  "Plant_Leaves_Jungle",
                       "support":  15
                   },
                   {
                       "x":  -4,
                       "y":  20,
                       "z":  0,
                       "name":  "Plant_Leaves_Beech",
                       "support":  15
                   },
                   {
                       "x":  -4,
                       "y":  24,
                       "z":  0,
                       "name":  "Plant_Leaves_Beech",
                       "support":  15
                   },
                   {
                       "x":  -4,
                       "y":  0,
                       "z":  1,
                       "name":  "Soil_Grass_Full"
                   },
                   {
                       "x":  -4,
                       "y":  3,
                       "z":  1,
                       "name":  "Plant_Vine_Jungle",
                       "support":  15,
                       "rotation":  3
                   },
                   {
                       "x":  -4,
                       "y":  20,
                       "z":  1,
                       "name":  "Plant_Leaves_Beech",
                       "support":  15
                   },
                   {
                       "x":  -4,
                       "y":  24,
                       "z":  1,
                       "name":  "Plant_Leaves_Beech",
                       "support":  15
                   },
                   {
                       "x":  -4,
                       "y":  0,
                       "z":  2,
                       "name":  "Soil_Grass_Full"
                   },
                   {
                       "x":  -4,
                       "y":  21,
                       "z":  2,
                       "name":  "Plant_Leaves_Jungle",
                       "support":  15
                   },
                   {
                       "x":  -4,
                       "y":  24,
                       "z":  2,
                       "name":  "Plant_Leaves_Beech",
                       "support":  15
                   },
                   {
                       "x":  -4,
                       "y":  0,
                       "z":  3,
                       "name":  "Soil_Grass_Full"
                   },
                   {
                       "x":  -4,
                       "y":  1,
                       "z":  3,
                       "name":  "Wood_Jungle_Trunk_Stairs",
                       "rotation":  3
                   },
                   {
                       "x":  -4,
                       "y":  24,
                       "z":  3,
                       "name":  "Plant_Leaves_Beech",
                       "support":  15
                   },
                   {
                       "x":  -4,
                       "y":  0,
                       "z":  4,
                       "name":  "Soil_Grass_Full"
                   },
                   {
                       "x":  -4,
                       "y":  24,
                       "z":  4,
                       "name":  "Plant_Leaves_Beech",
                       "support":  15
                   },
                   {
                       "x":  -4,
                       "y":  0,
                       "z":  5,
                       "name":  "Soil_Grass_Full"
                   },
                   {
                       "x":  -4,
                       "y":  24,
                       "z":  5,
                       "name":  "Plant_Leaves_Beech",
                       "support":  15
                   },
                   {
                       "x":  -4,
                       "y":  0,
                       "z":  6,
                       "name":  "Soil_Grass_Full"
                   },
                   {
                       "x":  -4,
                       "y":  24,
                       "z":  6,
                       "name":  "Plant_Leaves_Beech",
                       "support":  15
                   },
                   {
                       "x":  -4,
                       "y":  0,
                       "z":  7,
                       "name":  "Soil_Grass_Full"
                   },
                   {
                       "x":  -4,
                       "y":  0,
                       "z":  8,
                       "name":  "Soil_Grass_Full"
                   },
                   {
                       "x":  -3,
                       "y":  0,
                       "z":  -7,
                       "name":  "Soil_Grass_Full"
                   },
                   {
                       "x":  -3,
                       "y":  0,
                       "z":  -6,
                       "name":  "Soil_Grass_Full"
                   },
                   {
                       "x":  -3,
                       "y":  0,
                       "z":  -5,
                       "name":  "Soil_Grass_Full"
                   },
                   {
                       "x":  -3,
                       "y":  24,
                       "z":  -5,
                       "name":  "Plant_Leaves_Beech",
                       "support":  15
                   },
                   {
                       "x":  -3,
                       "y":  0,
                       "z":  -4,
                       "name":  "Soil_Grass_Full"
                   },
                   {
                       "x":  -3,
                       "y":  1,
                       "z":  -4,
                       "name":  "Deco_Bone_Spike"
                   },
                   {
                       "x":  -3,
                       "y":  0,
                       "z":  -3,
                       "name":  "Soil_Dirt"
                   },
                   {
                       "x":  -3,
                       "y":  1,
                       "z":  -3,
                       "name":  "Wood_Jungle_Trunk_Full",
                       "support":  15
                   },
                   {
                       "x":  -3,
                       "y":  2,
                       "z":  -3,
                       "name":  "Plant_Leaves_Jungle",
                       "support":  15
                   },
                   {
                       "x":  -3,
                       "y":  24,
                       "z":  -3,
                       "name":  "Plant_Leaves_Beech",
                       "support":  15
                   },
                   {
                       "x":  -3,
                       "y":  0,
                       "z":  -2,
                       "name":  "Soil_Dirt"
                   },
                   {
                       "x":  -3,
                       "y":  1,
                       "z":  -2,
                       "name":  "Wood_Jungle_Trunk",
                       "support":  15
                   },
                   {
                       "x":  -3,
                       "y":  2,
                       "z":  -2,
                       "name":  "Wood_Jungle_Trunk_Full",
                       "support":  15
                   },
                   {
                       "x":  -3,
                       "y":  3,
                       "z":  -2,
                       "name":  "Plant_Leaves_Jungle",
                       "support":  15
                   },
                   {
                       "x":  -3,
                       "y":  24,
                       "z":  -2,
                       "name":  "Plant_Leaves_Beech",
                       "support":  15
                   },
                   {
                       "x":  -3,
                       "y":  25,
                       "z":  -2,
                       "name":  "Plant_Leaves_Beech",
                       "support":  15
                   },
                   {
                       "x":  -3,
                       "y":  0,
                       "z":  -1,
                       "name":  "Soil_Dirt"
                   },
                   {
                       "x":  -3,
                       "y":  1,
                       "z":  -1,
                       "name":  "Wood_Jungle_Trunk_Full",
                       "support":  15
                   },
                   {
                       "x":  -3,
                       "y":  2,
                       "z":  -1,
                       "name":  "Wood_Jungle_Trunk_Full",
                       "support":  15
                   },
                   {
                       "x":  -3,
                       "y":  3,
                       "z":  -1,
                       "name":  "Wood_Jungle_Trunk_Full",
                       "support":  15
                   },
                   {
                       "x":  -3,
                       "y":  20,
                       "z":  -1,
                       "name":  "Plant_Leaves_Beech",
                       "support":  15
                   },
                   {
                       "x":  -3,
                       "y":  24,
                       "z":  -1,
                       "name":  "Plant_Leaves_Beech",
                       "support":  15
                   },
                   {
                       "x":  -3,
                       "y":  25,
                       "z":  -1,
                       "name":  "Plant_Leaves_Beech",
                       "support":  15
                   },
                   {
                       "x":  -3,
                       "y":  0,
                       "z":  0,
                       "name":  "Soil_Grass_Full"
                   },
                   {
                       "x":  -3,
                       "y":  3,
                       "z":  0,
                       "name":  "Wood_Jungle_Trunk_Full",
                       "support":  15,
                       "rotation":  4
                   },
                   {
                       "x":  -3,
                       "y":  4,
                       "z":  0,
                       "name":  "Wood_Jungle_Trunk_Stairs",
                       "rotation":  3
                   },
                   {
                       "x":  -3,
                       "y":  19,
                       "z":  0,
                       "name":  "Plant_Leaves_Beech",
                       "support":  15
                   },
                   {
                       "x":  -3,
                       "y":  20,
                       "z":  0,
                       "name":  "Plant_Leaves_Beech",
                       "support":  15
                   },
                   {
                       "x":  -3,
                       "y":  24,
                       "z":  0,
                       "name":  "Plant_Leaves_Beech",
                       "support":  15
                   },
                   {
                       "x":  -3,
                       "y":  25,
                       "z":  0,
                       "name":  "Plant_Leaves_Beech",
                       "support":  15
                   },
                   {
                       "x":  -3,
                       "y":  0,
                       "z":  1,
                       "name":  "Soil_Grass_Full"
                   },
                   {
                       "x":  -3,
                       "y":  3,
                       "z":  1,
                       "name":  "Wood_Jungle_Trunk_Full",
                       "support":  15,
                       "rotation":  4
                   },
                   {
                       "x":  -3,
                       "y":  4,
                       "z":  1,
                       "name":  "Wood_Jungle_Trunk_Stairs",
                       "rotation":  3
                   },
                   {
                       "x":  -3,
                       "y":  17,
                       "z":  1,
                       "name":  "Wood_Jungle_Branch_Corner",
                       "support":  15,
                       "rotation":  3
                   },
                   {
                       "x":  -3,
                       "y":  18,
                       "z":  1,
                       "name":  "Wood_Jungle_Branch_Long",
                       "support":  15
                   },
                   {
                       "x":  -3,
                       "y":  19,
                       "z":  1,
                       "name":  "Plant_Leaves_Beech",
                       "support":  15
                   },
                   {
                       "x":  -3,
                       "y":  20,
                       "z":  1,
                       "name":  "Plant_Leaves_Beech",
                       "support":  15
                   },
                   {
                       "x":  -3,
                       "y":  24,
                       "z":  1,
                       "name":  "Plant_Leaves_Beech",
                       "support":  15
                   },
                   {
                       "x":  -3,
                       "y":  25,
                       "z":  1,
                       "name":  "Plant_Leaves_Beech",
                       "support":  15
                   },
                   {
                       "x":  -3,
                       "y":  0,
                       "z":  2,
                       "name":  "Soil_Dirt"
                   },
                   {
                       "x":  -3,
                       "y":  1,
                       "z":  2,
                       "name":  "Wood_Jungle_Trunk",
                       "support":  15
                   },
                   {
                       "x":  -3,
                       "y":  2,
                       "z":  2,
                       "name":  "Wood_Jungle_Trunk",
                       "support":  15
                   },
                   {
                       "x":  -3,
                       "y":  3,
                       "z":  2,
                       "name":  "Wood_Jungle_Trunk_Full",
                       "support":  15
                   },
                   {
                       "x":  -3,
                       "y":  20,
                       "z":  2,
                       "name":  "Plant_Leaves_Beech",
                       "support":  15
                   },
                   {
                       "x":  -3,
                       "y":  21,
                       "z":  2,
                       "name":  "Plant_Leaves_Beech",
                       "support":  15
                   },
                   {
                       "x":  -3,
                       "y":  24,
                       "z":  2,
                       "name":  "Plant_Leaves_Beech",
                       "support":  15
                   },
                   {
                       "x":  -3,
                       "y":  25,
                       "z":  2,
                       "name":  "Plant_Leaves_Beech",
                       "support":  15
                   },
                   {
                       "x":  -3,
                       "y":  0,
                       "z":  3,
                       "name":  "Soil_Dirt"
                   },
                   {
                       "x":  -3,
                       "y":  1,
                       "z":  3,
                       "name":  "Wood_Jungle_Trunk",
                       "support":  15
                   },
                   {
                       "x":  -3,
                       "y":  2,
                       "z":  3,
                       "name":  "Wood_Jungle_Trunk_Full",
                       "support":  15
                   },
                   {
                       "x":  -3,
                       "y":  3,
                       "z":  3,
                       "name":  "Wood_Jungle_Trunk_Stairs"
                   },
                   {
                       "x":  -3,
                       "y":  19,
                       "z":  3,
                       "name":  "Plant_Leaves_Jungle",
                       "support":  15
                   },
                   {
                       "x":  -3,
                       "y":  20,
                       "z":  3,
                       "name":  "Plant_Leaves_Beech",
                       "support":  15
                   },
                   {
                       "x":  -3,
                       "y":  21,
                       "z":  3,
                       "name":  "Plant_Leaves_Beech",
                       "support":  15
                   },
                   {
                       "x":  -3,
                       "y":  23,
                       "z":  3,
                       "name":  "Plant_Leaves_Jungle",
                       "support":  15
                   },
                   {
                       "x":  -3,
                       "y":  24,
                       "z":  3,
                       "name":  "Plant_Leaves_Beech",
                       "support":  15
                   },
                   {
                       "x":  -3,
                       "y":  25,
                       "z":  3,
                       "name":  "Plant_Leaves_Beech",
                       "support":  15
                   },
                   {
                       "x":  -3,
                       "y":  0,
                       "z":  4,
                       "name":  "Soil_Dirt"
                   },
                   {
                       "x":  -3,
                       "y":  1,
                       "z":  4,
                       "name":  "Wood_Jungle_Trunk_Full",
                       "support":  15
                   },
                   {
                       "x":  -3,
                       "y":  20,
                       "z":  4,
                       "name":  "Plant_Leaves_Beech",
                       "support":  15
                   },
                   {
                       "x":  -3,
                       "y":  24,
                       "z":  4,
                       "name":  "Plant_Leaves_Beech",
                       "support":  15
                   },
                   {
                       "x":  -3,
                       "y":  25,
                       "z":  4,
                       "name":  "Plant_Leaves_Beech",
                       "support":  15
                   },
                   {
                       "x":  -3,
                       "y":  0,
                       "z":  5,
                       "name":  "Soil_Grass_Full"
                   },
                   {
                       "x":  -3,
                       "y":  1,
                       "z":  5,
                       "name":  "Plant_Leaves_Jungle",
                       "support":  15
                   },
                   {
                       "x":  -3,
                       "y":  20,
                       "z":  5,
                       "name":  "Plant_Leaves_Beech",
                       "support":  15
                   },
                   {
                       "x":  -3,
                       "y":  24,
                       "z":  5,
                       "name":  "Plant_Leaves_Beech",
                       "support":  15
                   },
                   {
                       "x":  -3,
                       "y":  25,
                       "z":  5,
                       "name":  "Plant_Leaves_Beech",
                       "support":  15
                   },
                   {
                       "x":  -3,
                       "y":  0,
                       "z":  6,
                       "name":  "Soil_Grass_Full"
                   },
                   {
                       "x":  -3,
                       "y":  20,
                       "z":  6,
                       "name":  "Plant_Leaves_Jungle",
                       "support":  15
                   },
                   {
                       "x":  -3,
                       "y":  24,
                       "z":  6,
                       "name":  "Plant_Leaves_Beech",
                       "support":  15
                   },
                   {
                       "x":  -3,
                       "y":  0,
                       "z":  7,
                       "name":  "Soil_Grass_Full"
                   },
                   {
                       "x":  -3,
                       "y":  24,
                       "z":  7,
                       "name":  "Plant_Leaves_Beech",
                       "support":  15
                   },
                   {
                       "x":  -3,
                       "y":  0,
                       "z":  8,
                       "name":  "Soil_Grass_Full"
                   },
                   {
                       "x":  -3,
                       "y":  1,
                       "z":  8,
                       "name":  "Plant_Grass_Sharp"
                   },
                   {
                       "x":  -2,
                       "y":  0,
                       "z":  -7,
                       "name":  "Soil_Grass_Full"
                   },
                   {
                       "x":  -2,
                       "y":  0,
                       "z":  -6,
                       "name":  "Soil_Grass_Full"
                   },
                   {
                       "x":  -2,
                       "y":  0,
                       "z":  -5,
                       "name":  "Soil_Grass_Full"
                   },
                   {
                       "x":  -2,
                       "y":  24,
                       "z":  -5,
                       "name":  "Plant_Leaves_Beech",
                       "support":  15
                   },
                   {
                       "x":  -2,
                       "y":  0,
                       "z":  -4,
                       "name":  "Soil_Grass_Full"
                   },
                   {
                       "x":  -2,
                       "y":  24,
                       "z":  -4,
                       "name":  "Plant_Leaves_Beech",
                       "support":  15
                   },
                   {
                       "x":  -2,
                       "y":  0,
                       "z":  -3,
                       "name":  "Wood_Jungle_Trunk",
                       "support":  15
                   },
                   {
                       "x":  -2,
                       "y":  1,
                       "z":  -3,
                       "name":  "Wood_Jungle_Trunk",
                       "support":  15
                   },
                   {
                       "x":  -2,
                       "y":  2,
                       "z":  -3,
                       "name":  "Wood_Jungle_Trunk_Full",
                       "support":  15
                   },
                   {
                       "x":  -2,
                       "y":  20,
                       "z":  -3,
                       "name":  "Plant_Leaves_Beech",
                       "support":  15
                   },
                   {
                       "x":  -2,
                       "y":  23,
                       "z":  -3,
                       "name":  "Plant_Leaves_Jungle",
                       "support":  15
                   },
                   {
                       "x":  -2,
                       "y":  24,
                       "z":  -3,
                       "name":  "Plant_Leaves_Beech",
                       "support":  15
                   },
                   {
                       "x":  -2,
                       "y":  0,
                       "z":  -2,
                       "name":  "Soil_Dirt"
                   },
                   {
                       "x":  -2,
                       "y":  1,
                       "z":  -2,
                       "name":  "Wood_Jungle_Trunk",
                       "support":  15
                   },
                   {
                       "x":  -2,
                       "y":  2,
                       "z":  -2,
                       "name":  "Wood_Jungle_Trunk",
                       "support":  15
                   },
                   {
                       "x":  -2,
                       "y":  3,
                       "z":  -2,
                       "name":  "Wood_Jungle_Trunk_Full",
                       "support":  15
                   },
                   {
                       "x":  -2,
                       "y":  20,
                       "z":  -2,
                       "name":  "Plant_Leaves_Beech",
                       "support":  15
                   },
                   {
                       "x":  -2,
                       "y":  24,
                       "z":  -2,
                       "name":  "Plant_Leaves_Beech",
                       "support":  15
                   },
                   {
                       "x":  -2,
                       "y":  25,
                       "z":  -2,
                       "name":  "Plant_Leaves_Beech",
                       "support":  15
                   },
                   {
                       "x":  -2,
                       "y":  0,
                       "z":  -1,
                       "name":  "Soil_Grass_Full"
                   },
                   {
                       "x":  -2,
                       "y":  1,
                       "z":  -1,
                       "name":  "Plant_Fern_Giant",
                       "support":  15
                   },
                   {
                       "x":  -2,
                       "y":  3,
                       "z":  -1,
                       "name":  "Wood_Jungle_Trunk_Full",
                       "support":  15
                   },
                   {
                       "x":  -2,
                       "y":  4,
                       "z":  -1,
                       "name":  "Wood_Jungle_Trunk_Stairs",
                       "rotation":  3
                   },
                   {
                       "x":  -2,
                       "y":  19,
                       "z":  -1,
                       "name":  "Plant_Leaves_Jungle",
                       "support":  15
                   },
                   {
                       "x":  -2,
                       "y":  20,
                       "z":  -1,
                       "name":  "Plant_Leaves_Beech",
                       "support":  15
                   },
                   {
                       "x":  -2,
                       "y":  21,
                       "z":  -1,
                       "name":  "Plant_Leaves_Beech",
                       "support":  15
                   },
                   {
                       "x":  -2,
                       "y":  24,
                       "z":  -1,
                       "name":  "Plant_Leaves_Beech",
                       "support":  15
                   },
                   {
                       "x":  -2,
                       "y":  25,
                       "z":  -1,
                       "name":  "Plant_Leaves_Beech",
                       "support":  15
                   },
                   {
                       "x":  -2,
                       "y":  0,
                       "z":  0,
                       "name":  "Soil_Pathway"
                   },
                   {
                       "x":  -2,
                       "y":  4,
                       "z":  0,
                       "name":  "Wood_Jungle_Trunk_Full",
                       "support":  15
                   },
                   {
                       "x":  -2,
                       "y":  5,
                       "z":  0,
                       "name":  "Plant_Vine_Jungle",
                       "support":  15,
                       "rotation":  3
                   },
                   {
                       "x":  -2,
                       "y":  6,
                       "z":  0,
                       "name":  "Plant_Vine_Jungle",
                       "support":  15,
                       "rotation":  3
                   },
                   {
                       "x":  -2,
                       "y":  7,
                       "z":  0,
                       "name":  "Plant_Vine_Jungle",
                       "support":  15,
                       "rotation":  3
                   },
                   {
                       "x":  -2,
                       "y":  16,
                       "z":  0,
                       "name":  "Plant_Vine_Jungle",
                       "support":  15,
                       "rotation":  3
                   },
                   {
                       "x":  -2,
                       "y":  19,
                       "z":  0,
                       "name":  "Plant_Leaves_Beech",
                       "support":  15
                   },
                   {
                       "x":  -2,
                       "y":  20,
                       "z":  0,
                       "name":  "Plant_Leaves_Beech",
                       "support":  15
                   },
                   {
                       "x":  -2,
                       "y":  21,
                       "z":  0,
                       "name":  "Plant_Leaves_Beech",
                       "support":  15
                   },
                   {
                       "x":  -2,
                       "y":  24,
                       "z":  0,
                       "name":  "Plant_Leaves_Beech",
                       "support":  15
                   },
                   {
                       "x":  -2,
                       "y":  25,
                       "z":  0,
                       "name":  "Plant_Leaves_Beech",
                       "support":  15
                   },
                   {
                       "x":  -2,
                       "y":  0,
                       "z":  1,
                       "name":  "Soil_Pathway"
                   },
                   {
                       "x":  -2,
                       "y":  4,
                       "z":  1,
                       "name":  "Wood_Jungle_Trunk_Full",
                       "support":  15
                   },
                   {
                       "x":  -2,
                       "y":  17,
                       "z":  1,
                       "name":  "Wood_Jungle_Branch_Long",
                       "support":  15,
                       "rotation":  5
                   },
                   {
                       "x":  -2,
                       "y":  19,
                       "z":  1,
                       "name":  "Plant_Leaves_Beech",
                       "support":  15
                   },
                   {
                       "x":  -2,
                       "y":  20,
                       "z":  1,
                       "name":  "Plant_Leaves_Beech",
                       "support":  15
                   },
                   {
                       "x":  -2,
                       "y":  21,
                       "z":  1,
                       "name":  "Wood_Jungle_Branch_Long",
                       "support":  15
                   },
                   {
                       "x":  -2,
                       "y":  22,
                       "z":  1,
                       "name":  "Wood_Jungle_Branch_Corner",
                       "support":  15,
                       "rotation":  8
                   },
                   {
                       "x":  -2,
                       "y":  24,
                       "z":  1,
                       "name":  "Plant_Leaves_Beech",
                       "support":  15
                   },
                   {
                       "x":  -2,
                       "y":  25,
                       "z":  1,
                       "name":  "Plant_Leaves_Beech",
                       "support":  15
                   },
                   {
                       "x":  -2,
                       "y":  0,
                       "z":  2,
                       "name":  "Soil_Grass_Full"
                   },
                   {
                       "x":  -2,
                       "y":  3,
                       "z":  2,
                       "name":  "Wood_Jungle_Trunk_Full",
                       "support":  15
                   },
                   {
                       "x":  -2,
                       "y":  4,
                       "z":  2,
                       "name":  "Plant_Leaves_Jungle",
                       "support":  15
                   },
                   {
                       "x":  -2,
                       "y":  19,
                       "z":  2,
                       "name":  "Plant_Leaves_Beech",
                       "support":  15
                   },
                   {
                       "x":  -2,
                       "y":  20,
                       "z":  2,
                       "name":  "Plant_Leaves_Beech",
                       "support":  15
                   },
                   {
                       "x":  -2,
                       "y":  21,
                       "z":  2,
                       "name":  "Plant_Leaves_Beech",
                       "support":  15
                   },
                   {
                       "x":  -2,
                       "y":  22,
                       "z":  2,
                       "name":  "Wood_Jungle_Branch_Corner",
                       "support":  15
                   },
                   {
                       "x":  -2,
                       "y":  23,
                       "z":  2,
                       "name":  "Wood_Jungle_Branch_Long",
                       "support":  15
                   },
                   {
                       "x":  -2,
                       "y":  24,
                       "z":  2,
                       "name":  "Plant_Leaves_Beech",
                       "support":  15
                   },
                   {
                       "x":  -2,
                       "y":  25,
                       "z":  2,
                       "name":  "Plant_Leaves_Beech",
                       "support":  15
                   },
                   {
                       "x":  -2,
                       "y":  0,
                       "z":  3,
                       "name":  "Soil_Grass_Sunny"
                   },
                   {
                       "x":  -2,
                       "y":  1,
                       "z":  3,
                       "name":  "Plant_Fern_Giant",
                       "support":  15
                   },
                   {
                       "x":  -2,
                       "y":  2,
                       "z":  3,
                       "name":  "Wood_Jungle_Trunk_Full",
                       "support":  15
                   },
                   {
                       "x":  -2,
                       "y":  20,
                       "z":  3,
                       "name":  "Plant_Leaves_Beech",
                       "support":  15
                   },
                   {
                       "x":  -2,
                       "y":  21,
                       "z":  3,
                       "name":  "Plant_Leaves_Beech",
                       "support":  15
                   },
                   {
                       "x":  -2,
                       "y":  24,
                       "z":  3,
                       "name":  "Plant_Leaves_Beech",
                       "support":  15
                   },
                   {
                       "x":  -2,
                       "y":  25,
                       "z":  3,
                       "name":  "Plant_Leaves_Beech",
                       "support":  15
                   },
                   {
                       "x":  -2,
                       "y":  0,
                       "z":  4,
                       "name":  "Soil_Dirt"
                   },
                   {
                       "x":  -2,
                       "y":  1,
                       "z":  4,
                       "name":  "Wood_Jungle_Trunk_Full",
                       "support":  15
                   },
                   {
                       "x":  -2,
                       "y":  2,
                       "z":  4,
                       "name":  "Plant_Leaves_Jungle",
                       "support":  15
                   },
                   {
                       "x":  -2,
                       "y":  20,
                       "z":  4,
                       "name":  "Plant_Leaves_Beech",
                       "support":  15
                   },
                   {
                       "x":  -2,
                       "y":  21,
                       "z":  4,
                       "name":  "Plant_Leaves_Beech",
                       "support":  15
                   },
                   {
                       "x":  -2,
                       "y":  24,
                       "z":  4,
                       "name":  "Plant_Leaves_Beech",
                       "support":  15
                   },
                   {
                       "x":  -2,
                       "y":  25,
                       "z":  4,
                       "name":  "Plant_Leaves_Beech",
                       "support":  15
                   },
                   {
                       "x":  -2,
                       "y":  0,
                       "z":  5,
                       "name":  "Soil_Grass_Full"
                   },
                   {
                       "x":  -2,
                       "y":  20,
                       "z":  5,
                       "name":  "Plant_Leaves_Beech",
                       "support":  15
                   },
                   {
                       "x":  -2,
                       "y":  24,
                       "z":  5,
                       "name":  "Plant_Leaves_Beech",
                       "support":  15
                   },
                   {
                       "x":  -2,
                       "y":  25,
                       "z":  5,
                       "name":  "Plant_Leaves_Beech",
                       "support":  15
                   },
                   {
                       "x":  -2,
                       "y":  0,
                       "z":  6,
                       "name":  "Soil_Grass_Full"
                   },
                   {
                       "x":  -2,
                       "y":  20,
                       "z":  6,
                       "name":  "Plant_Leaves_Beech",
                       "support":  15
                   },
                   {
                       "x":  -2,
                       "y":  24,
                       "z":  6,
                       "name":  "Plant_Leaves_Beech",
                       "support":  15
                   },
                   {
                       "x":  -2,
                       "y":  25,
                       "z":  6,
                       "name":  "Plant_Leaves_Beech",
                       "support":  15
                   },
                   {
                       "x":  -2,
                       "y":  0,
                       "z":  7,
                       "name":  "Soil_Grass_Full"
                   },
                   {
                       "x":  -2,
                       "y":  24,
                       "z":  7,
                       "name":  "Plant_Leaves_Beech",
                       "support":  15
                   },
                   {
                       "x":  -2,
                       "y":  0,
                       "z":  8,
                       "name":  "Soil_Grass_Full"
                   },
                   {
                       "x":  -1,
                       "y":  0,
                       "z":  -7,
                       "name":  "Soil_Grass_Full"
                   },
                   {
                       "x":  -1,
                       "y":  0,
                       "z":  -6,
                       "name":  "Soil_Grass_Full"
                   },
                   {
                       "x":  -1,
                       "y":  24,
                       "z":  -6,
                       "name":  "Plant_Leaves_Beech",
                       "support":  15
                   },
                   {
                       "x":  -1,
                       "y":  0,
                       "z":  -5,
                       "name":  "Soil_Grass_Full"
                   },
                   {
                       "x":  -1,
                       "y":  24,
                       "z":  -5,
                       "name":  "Plant_Leaves_Beech",
                       "support":  15
                   },
                   {
                       "x":  -1,
                       "y":  0,
                       "z":  -4,
                       "name":  "Soil_Grass_Full"
                   },
                   {
                       "x":  -1,
                       "y":  1,
                       "z":  -4,
                       "name":  "Plant_Leaves_Jungle",
                       "support":  15
                   },
                   {
                       "x":  -1,
                       "y":  24,
                       "z":  -4,
                       "name":  "Plant_Leaves_Beech",
                       "support":  15
                   },
                   {
                       "x":  -1,
                       "y":  25,
                       "z":  -4,
                       "name":  "Plant_Leaves_Beech",
                       "support":  15
                   },
                   {
                       "x":  -1,
                       "y":  0,
                       "z":  -3,
                       "name":  "Soil_Dirt"
                   },
                   {
                       "x":  -1,
                       "y":  1,
                       "z":  -3,
                       "name":  "Wood_Jungle_Trunk",
                       "support":  15
                   },
                   {
                       "x":  -1,
                       "y":  2,
                       "z":  -3,
                       "name":  "Wood_Jungle_Trunk",
                       "support":  15
                   },
                   {
                       "x":  -1,
                       "y":  3,
                       "z":  -3,
                       "name":  "Wood_Jungle_Trunk_Full",
                       "support":  15
                   },
                   {
                       "x":  -1,
                       "y":  20,
                       "z":  -3,
                       "name":  "Plant_Leaves_Beech",
                       "support":  15
                   },
                   {
                       "x":  -1,
                       "y":  21,
                       "z":  -3,
                       "name":  "Plant_Leaves_Beech",
                       "support":  15
                   },
                   {
                       "x":  -1,
                       "y":  22,
                       "z":  -3,
                       "name":  "Wood_Jungle_Branch_Corner",
                       "support":  15,
                       "rotation":  2
                   },
                   {
                       "x":  -1,
                       "y":  23,
                       "z":  -3,
                       "name":  "Wood_Jungle_Branch_Long",
                       "support":  15
                   },
                   {
                       "x":  -1,
                       "y":  24,
                       "z":  -3,
                       "name":  "Plant_Leaves_Beech",
                       "support":  15
                   },
                   {
                       "x":  -1,
                       "y":  25,
                       "z":  -3,
                       "name":  "Plant_Leaves_Beech",
                       "support":  15
                   },
                   {
                       "x":  -1,
                       "y":  0,
                       "z":  -2,
                       "name":  "Soil_Pathway"
                   },
                   {
                       "x":  -1,
                       "y":  1,
                       "z":  -2,
                       "name":  "Food_Wildmeat_Raw"
                   },
                   {
                       "x":  -1,
                       "y":  3,
                       "z":  -2,
                       "name":  "Wood_Jungle_Trunk_Full",
                       "support":  15
                   },
                   {
                       "x":  -1,
                       "y":  4,
                       "z":  -2,
                       "name":  "Plant_Leaves_Jungle",
                       "support":  15
                   },
                   {
                       "x":  -1,
                       "y":  19,
                       "z":  -2,
                       "name":  "Plant_Leaves_Jungle",
                       "support":  15
                   },
                   {
                       "x":  -1,
                       "y":  20,
                       "z":  -2,
                       "name":  "Plant_Leaves_Beech",
                       "support":  15
                   },
                   {
                       "x":  -1,
                       "y":  21,
                       "z":  -2,
                       "name":  "Plant_Leaves_Beech",
                       "support":  15
                   },
                   {
                       "x":  -1,
                       "y":  22,
                       "z":  -2,
                       "name":  "Wood_Jungle_Branch_Long",
                       "support":  15,
                       "rotation":  4
                   },
                   {
                       "x":  -1,
                       "y":  24,
                       "z":  -2,
                       "name":  "Plant_Leaves_Beech",
                       "support":  15
                   },
                   {
                       "x":  -1,
                       "y":  25,
                       "z":  -2,
                       "name":  "Plant_Leaves_Beech",
                       "support":  15
                   },
                   {
                       "x":  -1,
                       "y":  0,
                       "z":  -1,
                       "name":  "Soil_Pathway"
                   },
                   {
                       "x":  -1,
                       "y":  3,
                       "z":  -1,
                       "name":  "Wood_Jungle_Trunk_Full",
                       "support":  15
                   },
                   {
                       "x":  -1,
                       "y":  4,
                       "z":  -1,
                       "name":  "Wood_Jungle_Trunk_Full",
                       "support":  15
                   },
                   {
                       "x":  -1,
                       "y":  14,
                       "z":  -1,
                       "name":  "Plant_Vine_Jungle",
                       "support":  15,
                       "rotation":  2
                   },
                   {
                       "x":  -1,
                       "y":  15,
                       "z":  -1,
                       "name":  "Plant_Vine_Jungle",
                       "support":  15,
                       "rotation":  2
                   },
                   {
                       "x":  -1,
                       "y":  19,
                       "z":  -1,
                       "name":  "Plant_Leaves_Beech",
                       "support":  15
                   },
                   {
                       "x":  -1,
                       "y":  20,
                       "z":  -1,
                       "name":  "Plant_Leaves_Beech",
                       "support":  15
                   },
                   {
                       "x":  -1,
                       "y":  21,
                       "z":  -1,
                       "name":  "Wood_Jungle_Branch_Long",
                       "support":  15
                   },
                   {
                       "x":  -1,
                       "y":  22,
                       "z":  -1,
                       "name":  "Wood_Jungle_Branch_Corner",
                       "support":  15,
                       "rotation":  10
                   },
                   {
                       "x":  -1,
                       "y":  24,
                       "z":  -1,
                       "name":  "Plant_Leaves_Beech",
                       "support":  15
                   },
                   {
                       "x":  -1,
                       "y":  25,
                       "z":  -1,
                       "name":  "Plant_Leaves_Beech",
                       "support":  15
                   },
                   {
                       "x":  -1,
                       "y":  0,
                       "z":  0,
                       "name":  "Soil_Pathway"
                   },
                   {
                       "x":  -1,
                       "y":  4,
                       "z":  0,
                       "name":  "Wood_Jungle_Trunk_Full",
                       "support":  15
                   },
                   {
                       "x":  -1,
                       "y":  5,
                       "z":  0,
                       "name":  "Wood_Jungle_Trunk",
                       "support":  15
                   },
                   {
                       "x":  -1,
                       "y":  6,
                       "z":  0,
                       "name":  "Wood_Jungle_Trunk",
                       "support":  15
                   },
                   {
                       "x":  -1,
                       "y":  7,
                       "z":  0,
                       "name":  "Wood_Jungle_Trunk",
                       "support":  15
                   },
                   {
                       "x":  -1,
                       "y":  8,
                       "z":  0,
                       "name":  "Wood_Jungle_Trunk",
                       "support":  15
                   },
                   {
                       "x":  -1,
                       "y":  9,
                       "z":  0,
                       "name":  "Wood_Jungle_Trunk",
                       "support":  15
                   },
                   {
                       "x":  -1,
                       "y":  10,
                       "z":  0,
                       "name":  "Wood_Jungle_Trunk",
                       "support":  15
                   },
                   {
                       "x":  -1,
                       "y":  11,
                       "z":  0,
                       "name":  "Wood_Jungle_Trunk",
                       "support":  15
                   },
                   {
                       "x":  -1,
                       "y":  12,
                       "z":  0,
                       "name":  "Wood_Jungle_Trunk_Full",
                       "support":  15
                   },
                   {
                       "x":  -1,
                       "y":  13,
                       "z":  0,
                       "name":  "Wood_Jungle_Branch_Long",
                       "support":  15
                   },
                   {
                       "x":  -1,
                       "y":  14,
                       "z":  0,
                       "name":  "Wood_Jungle_Branch_Long",
                       "support":  15
                   },
                   {
                       "x":  -1,
                       "y":  15,
                       "z":  0,
                       "name":  "Wood_Jungle_Trunk_Full",
                       "support":  15
                   },
                   {
                       "x":  -1,
                       "y":  16,
                       "z":  0,
                       "name":  "Wood_Jungle_Trunk",
                       "support":  15
                   },
                   {
                       "x":  -1,
                       "y":  17,
                       "z":  0,
                       "name":  "Wood_Jungle_Trunk",
                       "support":  15
                   },
                   {
                       "x":  -1,
                       "y":  18,
                       "z":  0,
                       "name":  "Wood_Jungle_Trunk",
                       "support":  15
                   },
                   {
                       "x":  -1,
                       "y":  19,
                       "z":  0,
                       "name":  "Wood_Jungle_Trunk",
                       "support":  15
                   },
                   {
                       "x":  -1,
                       "y":  20,
                       "z":  0,
                       "name":  "Wood_Jungle_Trunk_Full",
                       "support":  15
                   },
                   {
                       "x":  -1,
                       "y":  21,
                       "z":  0,
                       "name":  "Plant_Leaves_Beech",
                       "support":  15
                   },
                   {
                       "x":  -1,
                       "y":  24,
                       "z":  0,
                       "name":  "Plant_Leaves_Beech",
                       "support":  15
                   },
                   {
                       "x":  -1,
                       "y":  25,
                       "z":  0,
                       "name":  "Plant_Leaves_Beech",
                       "support":  15
                   },
                   {
                       "x":  -1,
                       "y":  0,
                       "z":  1,
                       "name":  "Soil_Pathway"
                   },
                   {
                       "x":  -1,
                       "y":  4,
                       "z":  1,
                       "name":  "Wood_Jungle_Trunk_Full",
                       "support":  15
                   },
                   {
                       "x":  -1,
                       "y":  5,
                       "z":  1,
                       "name":  "Wood_Jungle_Trunk",
                       "support":  15
                   },
                   {
                       "x":  -1,
                       "y":  6,
                       "z":  1,
                       "name":  "Wood_Jungle_Trunk",
                       "support":  15
                   },
                   {
                       "x":  -1,
                       "y":  7,
                       "z":  1,
                       "name":  "Wood_Jungle_Trunk_Full",
                       "support":  15
                   },
                   {
                       "x":  -1,
                       "y":  8,
                       "z":  1,
                       "name":  "Wood_Jungle_Branch_Long",
                       "support":  15
                   },
                   {
                       "x":  -1,
                       "y":  9,
                       "z":  1,
                       "name":  "Wood_Jungle_Branch_Long",
                       "support":  15
                   },
                   {
                       "x":  -1,
                       "y":  10,
                       "z":  1,
                       "name":  "Wood_Jungle_Branch_Long",
                       "support":  15
                   },
                   {
                       "x":  -1,
                       "y":  11,
                       "z":  1,
                       "name":  "Wood_Jungle_Trunk_Full",
                       "support":  15
                   },
                   {
                       "x":  -1,
                       "y":  12,
                       "z":  1,
                       "name":  "Wood_Jungle_Trunk",
                       "support":  15
                   },
                   {
                       "x":  -1,
                       "y":  13,
                       "z":  1,
                       "name":  "Wood_Jungle_Trunk",
                       "support":  15
                   },
                   {
                       "x":  -1,
                       "y":  14,
                       "z":  1,
                       "name":  "Wood_Jungle_Trunk",
                       "support":  15
                   },
                   {
                       "x":  -1,
                       "y":  15,
                       "z":  1,
                       "name":  "Wood_Jungle_Trunk",
                       "support":  15
                   },
                   {
                       "x":  -1,
                       "y":  16,
                       "z":  1,
                       "name":  "Wood_Jungle_Trunk",
                       "support":  15
                   },
                   {
                       "x":  -1,
                       "y":  17,
                       "z":  1,
                       "name":  "Wood_Jungle_Trunk",
                       "support":  15
                   },
                   {
                       "x":  -1,
                       "y":  18,
                       "z":  1,
                       "name":  "Wood_Jungle_Trunk",
                       "support":  15
                   },
                   {
                       "x":  -1,
                       "y":  19,
                       "z":  1,
                       "name":  "Wood_Jungle_Trunk",
                       "support":  15
                   },
                   {
                       "x":  -1,
                       "y":  20,
                       "z":  1,
                       "name":  "Wood_Jungle_Trunk_Full",
                       "support":  15
                   },
                   {
                       "x":  -1,
                       "y":  21,
                       "z":  1,
                       "name":  "Plant_Leaves_Beech",
                       "support":  15
                   },
                   {
                       "x":  -1,
                       "y":  24,
                       "z":  1,
                       "name":  "Plant_Leaves_Beech",
                       "support":  15
                   },
                   {
                       "x":  -1,
                       "y":  25,
                       "z":  1,
                       "name":  "Plant_Leaves_Beech",
                       "support":  15
                   },
                   {
                       "x":  -1,
                       "y":  0,
                       "z":  2,
                       "name":  "Soil_Grass_Sunny"
                   },
                   {
                       "x":  -1,
                       "y":  3,
                       "z":  2,
                       "name":  "Wood_Jungle_Trunk_Full",
                       "support":  15
                   },
                   {
                       "x":  -1,
                       "y":  4,
                       "z":  2,
                       "name":  "Wood_Jungle_Trunk_Stairs"
                   },
                   {
                       "x":  -1,
                       "y":  10,
                       "z":  2,
                       "name":  "Plant_Vine_Jungle",
                       "support":  15
                   },
                   {
                       "x":  -1,
                       "y":  11,
                       "z":  2,
                       "name":  "Plant_Vine_Jungle",
                       "support":  15
                   },
                   {
                       "x":  -1,
                       "y":  12,
                       "z":  2,
                       "name":  "Plant_Vine_Jungle",
                       "support":  15
                   },
                   {
                       "x":  -1,
                       "y":  13,
                       "z":  2,
                       "name":  "Plant_Vine_Jungle",
                       "support":  15
                   },
                   {
                       "x":  -1,
                       "y":  14,
                       "z":  2,
                       "name":  "Plant_Vine_Jungle",
                       "support":  15
                   },
                   {
                       "x":  -1,
                       "y":  16,
                       "z":  2,
                       "name":  "Wood_Jungle_Branch_Long",
                       "support":  15,
                       "rotation":  4
                   },
                   {
                       "x":  -1,
                       "y":  19,
                       "z":  2,
                       "name":  "Plant_Leaves_Beech",
                       "support":  15
                   },
                   {
                       "x":  -1,
                       "y":  20,
                       "z":  2,
                       "name":  "Plant_Leaves_Beech",
                       "support":  15
                   },
                   {
                       "x":  -1,
                       "y":  21,
                       "z":  2,
                       "name":  "Plant_Leaves_Beech",
                       "support":  15
                   },
                   {
                       "x":  -1,
                       "y":  24,
                       "z":  2,
                       "name":  "Plant_Leaves_Beech",
                       "support":  15
                   },
                   {
                       "x":  -1,
                       "y":  25,
                       "z":  2,
                       "name":  "Plant_Leaves_Beech",
                       "support":  15
                   },
                   {
                       "x":  -1,
                       "y":  0,
                       "z":  3,
                       "name":  "Soil_Grass_Sunny"
                   },
                   {
                       "x":  -1,
                       "y":  2,
                       "z":  3,
                       "name":  "Wood_Jungle_Trunk_Full",
                       "support":  15
                   },
                   {
                       "x":  -1,
                       "y":  16,
                       "z":  3,
                       "name":  "Wood_Jungle_Branch_Corner",
                       "support":  15
                   },
                   {
                       "x":  -1,
                       "y":  17,
                       "z":  3,
                       "name":  "Wood_Jungle_Branch_Corner",
                       "support":  15,
                       "rotation":  8
                   },
                   {
                       "x":  -1,
                       "y":  20,
                       "z":  3,
                       "name":  "Plant_Leaves_Beech",
                       "support":  15
                   },
                   {
                       "x":  -1,
                       "y":  21,
                       "z":  3,
                       "name":  "Plant_Leaves_Beech",
                       "support":  15
                   },
                   {
                       "x":  -1,
                       "y":  24,
                       "z":  3,
                       "name":  "Plant_Leaves_Beech",
                       "support":  15
                   },
                   {
                       "x":  -1,
                       "y":  25,
                       "z":  3,
                       "name":  "Plant_Leaves_Beech",
                       "support":  15
                   },
                   {
                       "x":  -1,
                       "y":  0,
                       "z":  4,
                       "name":  "Soil_Dirt"
                   },
                   {
                       "x":  -1,
                       "y":  1,
                       "z":  4,
                       "name":  "Wood_Jungle_Trunk_Full",
                       "support":  15
                   },
                   {
                       "x":  -1,
                       "y":  2,
                       "z":  4,
                       "name":  "Wood_Jungle_Trunk_Stairs"
                   },
                   {
                       "x":  -1,
                       "y":  3,
                       "z":  4,
                       "name":  "Plant_Leaves_Jungle",
                       "support":  15
                   },
                   {
                       "x":  -1,
                       "y":  17,
                       "z":  4,
                       "name":  "Wood_Jungle_Branch_Long",
                       "support":  15,
                       "rotation":  4
                   },
                   {
                       "x":  -1,
                       "y":  20,
                       "z":  4,
                       "name":  "Plant_Leaves_Beech",
                       "support":  15
                   },
                   {
                       "x":  -1,
                       "y":  21,
                       "z":  4,
                       "name":  "Plant_Leaves_Beech",
                       "support":  15
                   },
                   {
                       "x":  -1,
                       "y":  24,
                       "z":  4,
                       "name":  "Plant_Leaves_Beech",
                       "support":  15
                   },
                   {
                       "x":  -1,
                       "y":  25,
                       "z":  4,
                       "name":  "Plant_Leaves_Beech",
                       "support":  15
                   },
                   {
                       "x":  -1,
                       "y":  0,
                       "z":  5,
                       "name":  "Soil_Grass_Full"
                   },
                   {
                       "x":  -1,
                       "y":  17,
                       "z":  5,
                       "name":  "Wood_Jungle_Branch_Corner",
                       "support":  15
                   },
                   {
                       "x":  -1,
                       "y":  18,
                       "z":  5,
                       "name":  "Wood_Jungle_Branch_Long",
                       "support":  15
                   },
                   {
                       "x":  -1,
                       "y":  19,
                       "z":  5,
                       "name":  "Wood_Jungle_Branch_Long",
                       "support":  15
                   },
                   {
                       "x":  -1,
                       "y":  20,
                       "z":  5,
                       "name":  "Plant_Leaves_Beech",
                       "support":  15
                   },
                   {
                       "x":  -1,
                       "y":  24,
                       "z":  5,
                       "name":  "Plant_Leaves_Beech",
                       "support":  15
                   },
                   {
                       "x":  -1,
                       "y":  25,
                       "z":  5,
                       "name":  "Plant_Leaves_Beech",
                       "support":  15
                   },
                   {
                       "x":  -1,
                       "y":  0,
                       "z":  6,
                       "name":  "Soil_Grass_Full"
                   },
                   {
                       "x":  -1,
                       "y":  20,
                       "z":  6,
                       "name":  "Plant_Leaves_Beech",
                       "support":  15
                   },
                   {
                       "x":  -1,
                       "y":  24,
                       "z":  6,
                       "name":  "Plant_Leaves_Beech",
                       "support":  15
                   },
                   {
                       "x":  -1,
                       "y":  25,
                       "z":  6,
                       "name":  "Plant_Leaves_Beech",
                       "support":  15
                   },
                   {
                       "x":  -1,
                       "y":  0,
                       "z":  7,
                       "name":  "Soil_Grass_Full"
                   },
                   {
                       "x":  -1,
                       "y":  24,
                       "z":  7,
                       "name":  "Plant_Leaves_Beech",
                       "support":  15
                   },
                   {
                       "x":  -1,
                       "y":  0,
                       "z":  8,
                       "name":  "Soil_Grass_Full"
                   },
                   {
                       "x":  0,
                       "y":  0,
                       "z":  -7,
                       "name":  "Soil_Grass_Sunny"
                   },
                   {
                       "x":  0,
                       "y":  0,
                       "z":  -6,
                       "name":  "Soil_Grass_Full"
                   },
                   {
                       "x":  0,
                       "y":  24,
                       "z":  -6,
                       "name":  "Plant_Leaves_Beech",
                       "support":  15
                   },
                   {
                       "x":  0,
                       "y":  0,
                       "z":  -5,
                       "name":  "Soil_Grass_Full"
                   },
                   {
                       "x":  0,
                       "y":  24,
                       "z":  -5,
                       "name":  "Plant_Leaves_Beech",
                       "support":  15
                   },
                   {
                       "x":  0,
                       "y":  25,
                       "z":  -5,
                       "name":  "Plant_Leaves_Beech",
                       "support":  15
                   },
                   {
                       "x":  0,
                       "y":  0,
                       "z":  -4,
                       "name":  "Soil_Grass_Full"
                   },
                   {
                       "x":  0,
                       "y":  24,
                       "z":  -4,
                       "name":  "Plant_Leaves_Beech",
                       "support":  15
                   },
                   {
                       "x":  0,
                       "y":  25,
                       "z":  -4,
                       "name":  "Plant_Leaves_Beech",
                       "support":  15
                   },
                   {
                       "x":  0,
                       "y":  0,
                       "z":  -3,
                       "name":  "Soil_Dirt"
                   },
                   {
                       "x":  0,
                       "y":  1,
                       "z":  -3,
                       "name":  "Wood_Jungle_Trunk_Full",
                       "support":  15
                   },
                   {
                       "x":  0,
                       "y":  2,
                       "z":  -3,
                       "name":  "Wood_Jungle_Trunk_Full",
                       "support":  15
                   },
                   {
                       "x":  0,
                       "y":  21,
                       "z":  -3,
                       "name":  "Plant_Leaves_Beech",
                       "support":  15
                   },
                   {
                       "x":  0,
                       "y":  24,
                       "z":  -3,
                       "name":  "Plant_Leaves_Beech",
                       "support":  15
                   },
                   {
                       "x":  0,
                       "y":  25,
                       "z":  -3,
                       "name":  "Plant_Leaves_Beech",
                       "support":  15
                   },
                   {
                       "x":  0,
                       "y":  0,
                       "z":  -2,
                       "name":  "Soil_Pathway"
                   },
                   {
                       "x":  0,
                       "y":  1,
                       "z":  -2,
                       "name":  "Food_Chicken_Raw"
                   },
                   {
                       "x":  0,
                       "y":  3,
                       "z":  -2,
                       "name":  "Wood_Jungle_Trunk_Full",
                       "support":  15
                   },
                   {
                       "x":  0,
                       "y":  19,
                       "z":  -2,
                       "name":  "Plant_Leaves_Beech",
                       "support":  15
                   },
                   {
                       "x":  0,
                       "y":  20,
                       "z":  -2,
                       "name":  "Plant_Leaves_Beech",
                       "support":  15
                   },
                   {
                       "x":  0,
                       "y":  21,
                       "z":  -2,
                       "name":  "Plant_Leaves_Beech",
                       "support":  15
                   },
                   {
                       "x":  0,
                       "y":  24,
                       "z":  -2,
                       "name":  "Plant_Leaves_Beech",
                       "support":  15
                   },
                   {
                       "x":  0,
                       "y":  25,
                       "z":  -2,
                       "name":  "Plant_Leaves_Beech",
                       "support":  15
                   },
                   {
                       "x":  0,
                       "y":  0,
                       "z":  -1,
                       "name":  "Soil_Pathway"
                   },
                   {
                       "x":  0,
                       "y":  3,
                       "z":  -1,
                       "name":  "Wood_Jungle_Trunk_Full",
                       "support":  15
                   },
                   {
                       "x":  0,
                       "y":  4,
                       "z":  -1,
                       "name":  "Wood_Jungle_Trunk_Full",
                       "support":  15
                   },
                   {
                       "x":  0,
                       "y":  15,
                       "z":  -1,
                       "name":  "Plant_Vine_Jungle",
                       "support":  15,
                       "rotation":  2
                   },
                   {
                       "x":  0,
                       "y":  17,
                       "z":  -1,
                       "name":  "Wood_Jungle_Branch_Corner",
                       "support":  15,
                       "rotation":  2
                   },
                   {
                       "x":  0,
                       "y":  18,
                       "z":  -1,
                       "name":  "Wood_Jungle_Branch_Long",
                       "support":  15
                   },
                   {
                       "x":  0,
                       "y":  19,
                       "z":  -1,
                       "name":  "Plant_Leaves_Beech",
                       "support":  15
                   },
                   {
                       "x":  0,
                       "y":  20,
                       "z":  -1,
                       "name":  "Plant_Leaves_Beech",
                       "support":  15
                   },
                   {
                       "x":  0,
                       "y":  21,
                       "z":  -1,
                       "name":  "Plant_Leaves_Beech",
                       "support":  15
                   },
                   {
                       "x":  0,
                       "y":  24,
                       "z":  -1,
                       "name":  "Plant_Leaves_Beech",
                       "support":  15
                   },
                   {
                       "x":  0,
                       "y":  25,
                       "z":  -1,
                       "name":  "Plant_Leaves_Beech",
                       "support":  15
                   },
                   {
                       "x":  0,
                       "y":  0,
                       "z":  0,
                       "name":  "Soil_Pathway"
                   },
                   {
                       "x":  0,
                       "y":  4,
                       "z":  0,
                       "name":  "Wood_Jungle_Trunk_Full",
                       "support":  15
                   },
                   {
                       "x":  0,
                       "y":  5,
                       "z":  0,
                       "name":  "Wood_Jungle_Branch_Long",
                       "support":  15
                   },
                   {
                       "x":  0,
                       "y":  6,
                       "z":  0,
                       "name":  "Wood_Jungle_Branch_Long",
                       "support":  15
                   },
                   {
                       "x":  0,
                       "y":  7,
                       "z":  0,
                       "name":  "Wood_Jungle_Branch_Long",
                       "support":  15
                   },
                   {
                       "x":  0,
                       "y":  8,
                       "z":  0,
                       "name":  "Wood_Jungle_Trunk_Full",
                       "support":  15
                   },
                   {
                       "x":  0,
                       "y":  9,
                       "z":  0,
                       "name":  "Wood_Jungle_Trunk_Full",
                       "support":  15
                   },
                   {
                       "x":  0,
                       "y":  10,
                       "z":  0,
                       "name":  "Wood_Jungle_Branch_Long",
                       "support":  15
                   },
                   {
                       "x":  0,
                       "y":  11,
                       "z":  0,
                       "name":  "Wood_Jungle_Trunk_Full",
                       "support":  15
                   },
                   {
                       "x":  0,
                       "y":  12,
                       "z":  0,
                       "name":  "Wood_Jungle_Trunk",
                       "support":  15
                   },
                   {
                       "x":  0,
                       "y":  13,
                       "z":  0,
                       "name":  "Wood_Jungle_Trunk",
                       "support":  15
                   },
                   {
                       "x":  0,
                       "y":  14,
                       "z":  0,
                       "name":  "Wood_Jungle_Trunk",
                       "support":  15
                   },
                   {
                       "x":  0,
                       "y":  15,
                       "z":  0,
                       "name":  "Wood_Jungle_Trunk_Full",
                       "support":  15
                   },
                   {
                       "x":  0,
                       "y":  16,
                       "z":  0,
                       "name":  "Wood_Jungle_Branch_Long",
                       "support":  15
                   },
                   {
                       "x":  0,
                       "y":  17,
                       "z":  0,
                       "name":  "Wood_Jungle_Trunk_Full",
                       "support":  15
                   },
                   {
                       "x":  0,
                       "y":  18,
                       "z":  0,
                       "name":  "Wood_Jungle_Trunk",
                       "support":  15
                   },
                   {
                       "x":  0,
                       "y":  19,
                       "z":  0,
                       "name":  "Wood_Jungle_Trunk",
                       "support":  15
                   },
                   {
                       "x":  0,
                       "y":  20,
                       "z":  0,
                       "name":  "Wood_Jungle_Trunk_Full",
                       "support":  15
                   },
                   {
                       "x":  0,
                       "y":  21,
                       "z":  0,
                       "name":  "Plant_Leaves_Beech",
                       "support":  15
                   },
                   {
                       "x":  0,
                       "y":  24,
                       "z":  0,
                       "name":  "Plant_Leaves_Beech",
                       "support":  15
                   },
                   {
                       "x":  0,
                       "y":  25,
                       "z":  0,
                       "name":  "Plant_Leaves_Beech",
                       "support":  15
                   },
                   {
                       "x":  0,
                       "y":  0,
                       "z":  1,
                       "name":  "Soil_Pathway"
                   },
                   {
                       "x":  0,
                       "y":  4,
                       "z":  1,
                       "name":  "Wood_Jungle_Trunk_Full",
                       "support":  15
                   },
                   {
                       "x":  0,
                       "y":  5,
                       "z":  1,
                       "name":  "Wood_Jungle_Trunk",
                       "support":  15
                   },
                   {
                       "x":  0,
                       "y":  6,
                       "z":  1,
                       "name":  "Wood_Jungle_Trunk",
                       "support":  15
                   },
                   {
                       "x":  0,
                       "y":  7,
                       "z":  1,
                       "name":  "Wood_Jungle_Trunk",
                       "support":  15
                   },
                   {
                       "x":  0,
                       "y":  8,
                       "z":  1,
                       "name":  "Wood_Jungle_Trunk",
                       "support":  15
                   },
                   {
                       "x":  0,
                       "y":  9,
                       "z":  1,
                       "name":  "Wood_Jungle_Trunk",
                       "support":  15
                   },
                   {
                       "x":  0,
                       "y":  10,
                       "z":  1,
                       "name":  "Wood_Jungle_Trunk",
                       "support":  15
                   },
                   {
                       "x":  0,
                       "y":  11,
                       "z":  1,
                       "name":  "Wood_Jungle_Trunk",
                       "support":  15
                   },
                   {
                       "x":  0,
                       "y":  12,
                       "z":  1,
                       "name":  "Wood_Jungle_Trunk_Full",
                       "support":  15
                   },
                   {
                       "x":  0,
                       "y":  13,
                       "z":  1,
                       "name":  "Wood_Jungle_Branch_Long",
                       "support":  15
                   },
                   {
                       "x":  0,
                       "y":  14,
                       "z":  1,
                       "name":  "Wood_Jungle_Trunk_Full",
                       "support":  15
                   },
                   {
                       "x":  0,
                       "y":  15,
                       "z":  1,
                       "name":  "Wood_Jungle_Trunk",
                       "support":  15
                   },
                   {
                       "x":  0,
                       "y":  16,
                       "z":  1,
                       "name":  "Wood_Jungle_Trunk",
                       "support":  15
                   },
                   {
                       "x":  0,
                       "y":  17,
                       "z":  1,
                       "name":  "Wood_Jungle_Trunk",
                       "support":  15
                   },
                   {
                       "x":  0,
                       "y":  18,
                       "z":  1,
                       "name":  "Wood_Jungle_Trunk",
                       "support":  15
                   },
                   {
                       "x":  0,
                       "y":  19,
                       "z":  1,
                       "name":  "Wood_Jungle_Trunk",
                       "support":  15
                   },
                   {
                       "x":  0,
                       "y":  20,
                       "z":  1,
                       "name":  "Wood_Jungle_Trunk_Full",
                       "support":  15
                   },
                   {
                       "x":  0,
                       "y":  21,
                       "z":  1,
                       "name":  "Plant_Leaves_Beech",
                       "support":  15
                   },
                   {
                       "x":  0,
                       "y":  24,
                       "z":  1,
                       "name":  "Plant_Leaves_Beech",
                       "support":  15
                   },
                   {
                       "x":  0,
                       "y":  25,
                       "z":  1,
                       "name":  "Plant_Leaves_Beech",
                       "support":  15
                   },
                   {
                       "x":  0,
                       "y":  0,
                       "z":  2,
                       "name":  "Soil_Grass_Sunny"
                   },
                   {
                       "x":  0,
                       "y":  1,
                       "z":  2,
                       "name":  "Plant_Fern_Giant",
                       "support":  15
                   },
                   {
                       "x":  0,
                       "y":  3,
                       "z":  2,
                       "name":  "Wood_Jungle_Trunk_Full",
                       "support":  15
                   },
                   {
                       "x":  0,
                       "y":  4,
                       "z":  2,
                       "name":  "Wood_Jungle_Trunk_Stairs"
                   },
                   {
                       "x":  0,
                       "y":  19,
                       "z":  2,
                       "name":  "Plant_Leaves_Beech",
                       "support":  15
                   },
                   {
                       "x":  0,
                       "y":  20,
                       "z":  2,
                       "name":  "Plant_Leaves_Beech",
                       "support":  15
                   },
                   {
                       "x":  0,
                       "y":  21,
                       "z":  2,
                       "name":  "Plant_Leaves_Beech",
                       "support":  15
                   },
                   {
                       "x":  0,
                       "y":  24,
                       "z":  2,
                       "name":  "Plant_Leaves_Beech",
                       "support":  15
                   },
                   {
                       "x":  0,
                       "y":  25,
                       "z":  2,
                       "name":  "Plant_Leaves_Beech",
                       "support":  15
                   },
                   {
                       "x":  0,
                       "y":  0,
                       "z":  3,
                       "name":  "Soil_Grass_Sunny"
                   },
                   {
                       "x":  0,
                       "y":  2,
                       "z":  3,
                       "name":  "Wood_Jungle_Trunk_Full",
                       "support":  15
                   },
                   {
                       "x":  0,
                       "y":  3,
                       "z":  3,
                       "name":  "Plant_Leaves_Jungle",
                       "support":  15
                   },
                   {
                       "x":  0,
                       "y":  19,
                       "z":  3,
                       "name":  "Plant_Leaves_Beech",
                       "support":  15
                   },
                   {
                       "x":  0,
                       "y":  20,
                       "z":  3,
                       "name":  "Plant_Leaves_Beech",
                       "support":  15
                   },
                   {
                       "x":  0,
                       "y":  24,
                       "z":  3,
                       "name":  "Plant_Leaves_Beech",
                       "support":  15
                   },
                   {
                       "x":  0,
                       "y":  25,
                       "z":  3,
                       "name":  "Plant_Leaves_Beech",
                       "support":  15
                   },
                   {
                       "x":  0,
                       "y":  0,
                       "z":  4,
                       "name":  "Soil_Dirt"
                   },
                   {
                       "x":  0,
                       "y":  1,
                       "z":  4,
                       "name":  "Wood_Jungle_Trunk_Full",
                       "support":  15
                   },
                   {
                       "x":  0,
                       "y":  20,
                       "z":  4,
                       "name":  "Plant_Leaves_Beech",
                       "support":  15
                   },
                   {
                       "x":  0,
                       "y":  24,
                       "z":  4,
                       "name":  "Plant_Leaves_Beech",
                       "support":  15
                   },
                   {
                       "x":  0,
                       "y":  25,
                       "z":  4,
                       "name":  "Plant_Leaves_Beech",
                       "support":  15
                   },
                   {
                       "x":  0,
                       "y":  0,
                       "z":  5,
                       "name":  "Soil_Grass_Full"
                   },
                   {
                       "x":  0,
                       "y":  20,
                       "z":  5,
                       "name":  "Plant_Leaves_Beech",
                       "support":  15
                   },
                   {
                       "x":  0,
                       "y":  24,
                       "z":  5,
                       "name":  "Plant_Leaves_Beech",
                       "support":  15
                   },
                   {
                       "x":  0,
                       "y":  25,
                       "z":  5,
                       "name":  "Plant_Leaves_Beech",
                       "support":  15
                   },
                   {
                       "x":  0,
                       "y":  0,
                       "z":  6,
                       "name":  "Soil_Grass_Full"
                   },
                   {
                       "x":  0,
                       "y":  20,
                       "z":  6,
                       "name":  "Plant_Leaves_Jungle",
                       "support":  15
                   },
                   {
                       "x":  0,
                       "y":  24,
                       "z":  6,
                       "name":  "Plant_Leaves_Beech",
                       "support":  15
                   },
