{
  "version": 8,
  "blockIdVersion": 11,
  "anchorX": 0,
  "anchorY": 0,
  "anchorZ": 0,
  "blocks": [
    {
      "x": 0,
      "y": 0,
      "z": 0,
      "name": "TFJ_Titanwood_Log"
    },
    {
      "x": 1,
      "y": 0,
      "z": 0,
      "name": "TFJ_Roots"
    },
    {
      "x": -1,
      "y": 0,
      "z": 0,
      "name": "TFJ_Roots"
    },
    {
      "x": 0,
      "y": 0,
      "z": -1,
      "name": "TFJ_Roots"
    },
    {
      "x": 0,
      "y": 1,
      "z": 0,
      "name": "TFJ_Titanwood_Log"
    },
    {
      "x": 0,
      "y": 2,
      "z": 0,
      "name": "TFJ_Titanwood_Log"
    },
    {
      "x": 0,
      "y": 3,
      "z": 0,
      "name": "TFJ_Titanwood_Log"
    },
    {
      "x": 1,
      "y": 3,
      "z": 0,
      "name": "TFJ_Titanwood_Log"
    },
    {
      "x": -1,
      "y": 3,
      "z": 0,
      "name": "TFJ_Titanwood_Log"
    },
    {
      "x": 0,
      "y": 3,
      "z": 1,
      "name": "TFJ_Titanwood_Log"
    },
    {
      "x": 0,
      "y": 3,
      "z": -1,
      "name": "TFJ_Titanwood_Log"
    },
    {
      "x": 0,
      "y": 4,
      "z": 0,
      "name": "TFJ_Titanwood_Log"
    },
    {
      "x": 0,
      "y": 5,
      "z": 0,
      "name": "TFJ_Titanwood_Log"
    },
    {
      "x": 0,
      "y": 6,
      "z": 0,
      "name": "TFJ_Titanwood_Log"
    },
    {
      "x": 1,
      "y": 6,
      "z": 0,
      "name": "TFJ_Titanwood_Log"
    },
    {
      "x": 0,
      "y": 6,
      "z": 1,
      "name": "TFJ_Titanwood_Log"
    },
    {
      "x": 0,
      "y": 6,
      "z": -1,
      "name": "TFJ_Titanwood_Log"
    },
    {
      "x": 0,
      "y": 7,
      "z": 0,
      "name": "TFJ_Titanwood_Log"
    },
    {
      "x": 0,
      "y": 8,
      "z": 0,
      "name": "TFJ_Titanwood_Log"
    },
    {
      "x": 0,
      "y": 9,
      "z": 0,
      "name": "TFJ_Titanwood_Log"
    },
    {
      "x": 1,
      "y": 9,
      "z": 0,
      "name": "TFJ_Titanwood_Log"
    },
    {
      "x": 0,
      "y": 9,
      "z": 1,
      "name": "TFJ_Titanwood_Log"
    },
    {
      "x": 0,
      "y": 9,
      "z": -1,
      "name": "TFJ_Titanwood_Log"
    },
    {
      "x": 0,
      "y": 10,
      "z": 0,
      "name": "TFJ_Titanwood_Log"
    },
    {
      "x": 0,
      "y": 11,
      "z": 0,
      "name": "TFJ_Titanwood_Log"
    },
    {
      "x": 0,
      "y": 12,
      "z": 0,
      "name": "TFJ_Titanwood_Log"
    },
    {
      "x": 0,
      "y": 12,
      "z": 1,
      "name": "TFJ_Titanwood_Log"
    },
    {
      "x": 0,
      "y": 12,
      "z": -1,
      "name": "TFJ_Titanwood_Log"
    },
    {
      "x": 0,
      "y": 13,
      "z": 0,
      "name": "TFJ_Titanwood_Log"
    },
    {
      "x": 0,
      "y": 14,
      "z": 0,
      "name": "TFJ_Titanwood_Log"
    },
    {
      "x": -3,
      "y": 11,
      "z": -1,
      "name": "TFJ_Canopy_Leaves"
    },
    {
      "x": -3,
      "y": 10,
      "z": -1,
      "name": "TFJ_Hanging_Vines"
    },
    {
      "x": -3,
      "y": 11,
      "z": 1,
      "name": "TFJ_Canopy_Leaves"
    },
    {
      "x": -2,
      "y": 11,
      "z": -1,
      "name": "TFJ_Canopy_Leaves"
    },
    {
      "x": -2,
      "y": 11,
      "z": 0,
      "name": "TFJ_Canopy_Leaves"
    },
    {
      "x": -2,
      "y": 11,
      "z": 1,
      "name": "TFJ_Canopy_Leaves"
    },
    {
      "x": -2,
      "y": 11,
      "z": 2,
      "name": "TFJ_Canopy_Leaves"
    },
    {
      "x": -1,
      "y": 11,
      "z": -3,
      "name": "TFJ_Canopy_Leaves"
    },
    {
      "x": -1,
      "y": 11,
      "z": -2,
      "name": "TFJ_Canopy_Leaves"
    },
    {
      "x": -1,
      "y": 11,
      "z": -1,
      "name": "TFJ_Canopy_Leaves"
    },
    {
      "x": -1,
      "y": 11,
      "z": 0,
      "name": "TFJ_Canopy_Leaves"
    },
    {
      "x": -1,
      "y": 11,
      "z": 2,
      "name": "TFJ_Canopy_Leaves"
    },
    {
      "x": -1,
      "y": 11,
      "z": 3,
      "name": "TFJ_Canopy_Leaves"
    },
    {
      "x": 0,
      "y": 11,
      "z": -3,
      "name": "TFJ_Canopy_Leaves"
    },
    {
      "x": 0,
      "y": 11,
      "z": -1,
      "name": "TFJ_Canopy_Leaves"
    },
    {
      "x": 0,
      "y": 11,
      "z": 0,
      "name": "TFJ_Canopy_Leaves"
    },
    {
      "x": 0,
      "y": 11,
      "z": 1,
      "name": "TFJ_Canopy_Leaves"
    },
    {
      "x": 0,
      "y": 10,
      "z": 1,
      "name": "TFJ_Hanging_Vines"
    },
    {
      "x": 0,
      "y": 9,
      "z": 1,
      "name": "TFJ_Hanging_Vines"
    },
    {
      "x": 0,
      "y": 11,
      "z": 2,
      "name": "TFJ_Canopy_Leaves"
    },
    {
      "x": 1,
      "y": 11,
      "z": -3,
      "name": "TFJ_Canopy_Leaves"
    },
    {
      "x": 1,
      "y": 11,
      "z": -2,
      "name": "TFJ_Canopy_Leaves"
    },
    {
      "x": 1,
      "y": 10,
      "z": -2,
      "name": "TFJ_Hanging_Vines"
    },
    {
      "x": 1,
      "y": 9,
      "z": -2,
      "name": "TFJ_Hanging_Vines"
    },
    {
      "x": 1,
      "y": 11,
      "z": -1,
      "name": "TFJ_Canopy_Leaves"
    },
    {
      "x": 1,
      "y": 10,
      "z": -1,
      "name": "TFJ_Hanging_Vines"
    },
    {
      "x": 1,
      "y": 9,
      "z": -1,
      "name": "TFJ_Hanging_Vines"
    },
    {
      "x": 1,
      "y": 8,
      "z": -1,
      "name": "TFJ_Hanging_Vines"
    },
    {
      "x": 1,
      "y": 7,
      "z": -1,
      "name": "TFJ_Hanging_Vines"
    },
    {
      "x": 1,
      "y": 11,
      "z": 0,
      "name": "TFJ_Canopy_Leaves"
    },
    {
      "x": 1,
      "y": 11,
      "z": 1,
      "name": "TFJ_Canopy_Leaves"
    },
    {
      "x": 1,
      "y": 11,
      "z": 2,
      "name": "TFJ_Canopy_Leaves"
    },
    {
      "x": 1,
      "y": 11,
      "z": 3,
      "name": "TFJ_Canopy_Leaves"
    },
    {
      "x": 2,
      "y": 11,
      "z": -1,
      "name": "TFJ_Canopy_Leaves"
    },
    {
      "x": 2,
      "y": 11,
      "z": 0,
      "name": "TFJ_Canopy_Leaves"
    },
    {
      "x": 2,
      "y": 11,
      "z": 1,
      "name": "TFJ_Canopy_Leaves"
    },
    {
      "x": 2,
      "y": 11,
      "z": 2,
      "name": "TFJ_Canopy_Leaves"
    },
    {
      "x": 3,
      "y": 11,
      "z": -1,
      "name": "TFJ_Canopy_Leaves"
    },
    {
      "x": 3,
      "y": 11,
      "z": 0,
      "name": "TFJ_Canopy_Leaves"
    },
    {
      "x": 3,
      "y": 10,
      "z": 0,
      "name": "TFJ_Hanging_Vines"
    },
    {
      "x": 3,
      "y": 9,
      "z": 0,
      "name": "TFJ_Hanging_Vines"
    },
    {
      "x": 3,
      "y": 11,
      "z": 1,
      "name": "TFJ_Canopy_Leaves"
    },
    {
      "x": -3,
      "y": 12,
      "z": -1,
      "name": "TFJ_Canopy_Leaves"
    },
    {
      "x": -3,
      "y": 12,
      "z": 0,
      "name": "TFJ_Canopy_Leaves"
    },
    {
      "x": -3,
      "y": 12,
      "z": 1,
      "name": "TFJ_Canopy_Leaves"
    },
    {
      "x": -2,
      "y": 12,
      "z": 0,
      "name": "TFJ_Canopy_Leaves"
    },
    {
      "x": -2,
      "y": 12,
      "z": 1,
      "name": "TFJ_Canopy_Leaves"
    },
    {
      "x": -2,
      "y": 12,
      "z": 2,
      "name": "TFJ_Canopy_Leaves"
    },
    {
      "x": -1,
      "y": 12,
      "z": -3,
      "name": "TFJ_Canopy_Leaves"
    },
    {
      "x": -1,
      "y": 12,
      "z": -2,
      "name": "TFJ_Canopy_Leaves"
    },
    {
      "x": -1,
      "y": 12,
      "z": -1,
      "name": "TFJ_Canopy_Leaves"
    },
    {
      "x": -1,
      "y": 12,
      "z": 0,
      "name": "TFJ_Canopy_Leaves"
    },
    {
      "x": -1,
      "y": 12,
      "z": 1,
      "name": "TFJ_Canopy_Leaves"
    },
    {
      "x": -1,
      "y": 12,
      "z": 2,
      "name": "TFJ_Canopy_Leaves"
    },
    {
      "x": -1,
      "y": 12,
      "z": 3,
      "name": "TFJ_Canopy_Leaves"
    },
    {
      "x": 0,
      "y": 12,
      "z": -3,
      "name": "TFJ_Canopy_Leaves"
    },
    {
      "x": 0,
      "y": 12,
      "z": -2,
      "name": "TFJ_Canopy_Leaves"
    },
    {
      "x": 0,
      "y": 12,
      "z": -1,
      "name": "TFJ_Canopy_Leaves"
    },
    {
      "x": 0,
      "y": 12,
      "z": 0,
      "name": "TFJ_Canopy_Leaves"
    },
    {
      "x": 0,
      "y": 12,
      "z": 1,
      "name": "TFJ_Canopy_Leaves"
    },
    {
      "x": 0,
      "y": 12,
      "z": 2,
      "name": "TFJ_Canopy_Leaves"
    },
    {
      "x": 0,
      "y": 12,
      "z": 3,
      "name": "TFJ_Canopy_Leaves"
    },
    {
      "x": 1,
      "y": 12,
      "z": -3,
      "name": "TFJ_Canopy_Leaves"
    },
    {
      "x": 1,
      "y": 12,
      "z": -2,
      "name": "TFJ_Canopy_Leaves"
    },
    {
      "x": 1,
      "y": 12,
      "z": -1,
      "name": "TFJ_Canopy_Leaves"
    },
    {
      "x": 1,
      "y": 12,
      "z": 0,
      "name": "TFJ_Canopy_Leaves"
    },
    {
      "x": 1,
      "y": 12,
      "z": 1,
      "name": "TFJ_Canopy_Leaves"
    },
    {
      "x": 2,
      "y": 12,
      "z": -2,
      "name": "TFJ_Canopy_Leaves"
    },
    {
      "x": 2,
      "y": 12,
      "z": -1,
      "name": "TFJ_Canopy_Leaves"
    },
    {
      "x": 2,
      "y": 12,
      "z": 0,
      "name": "TFJ_Canopy_Leaves"
    },
    {
      "x": 2,
      "y": 12,
      "z": 1,
      "name": "TFJ_Canopy_Leaves"
    },
    {
      "x": 2,
      "y": 12,
      "z": 2,
      "name": "TFJ_Canopy_Leaves"
    },
    {
      "x": 3,
      "y": 12,
      "z": -1,
      "name": "TFJ_Canopy_Leaves"
    },
    {
      "x": 3,
      "y": 12,
      "z": 0,
      "name": "TFJ_Canopy_Leaves"
    },
    {
      "x": 3,
      "y": 12,
      "z": 1,
      "name": "TFJ_Canopy_Leaves"
    },
    {
      "x": -4,
      "y": 13,
      "z": -1,
      "name": "TFJ_Canopy_Leaves"
    },
    {
      "x": -4,
      "y": 13,
      "z": 1,
      "name": "TFJ_Canopy_Leaves"
    },
    {
      "x": -3,
      "y": 13,
      "z": -2,
      "name": "TFJ_Canopy_Leaves"
    },
    {
      "x": -3,
      "y": 13,
      "z": -1,
      "name": "TFJ_Canopy_Leaves"
    },
    {
      "x": -3,
      "y": 13,
      "z": 0,
      "name": "TFJ_Canopy_Leaves"
    },
    {
      "x": -3,
      "y": 13,
      "z": 1,
      "name": "TFJ_Canopy_Leaves"
    },
    {
      "x": -3,
      "y": 13,
      "z": 2,
      "name": "TFJ_Canopy_Leaves"
    },
    {
      "x": -2,
      "y": 13,
      "z": -3,
      "name": "TFJ_Canopy_Leaves"
    },
    {
      "x": -2,
      "y": 13,
      "z": -1,
      "name": "TFJ_Canopy_Leaves"
    },
    {
      "x": -2,
      "y": 13,
      "z": 0,
      "name": "TFJ_Canopy_Leaves"
    },
    {
      "x": -2,
      "y": 13,
      "z": 2,
      "name": "TFJ_Canopy_Leaves"
    },
    {
      "x": -2,
      "y": 13,
      "z": 3,
      "name": "TFJ_Canopy_Leaves"
    },
    {
      "x": -1,
      "y": 13,
      "z": -4,
      "name": "TFJ_Canopy_Leaves"
    },
    {
      "x": -1,
      "y": 13,
      "z": -3,
      "name": "TFJ_Canopy_Leaves"
    },
    {
      "x": -1,
      "y": 13,
      "z": -2,
      "name": "TFJ_Canopy_Leaves"
    },
    {
      "x": -1,
      "y": 13,
      "z": -1,
      "name": "TFJ_Canopy_Leaves"
    },
    {
      "x": -1,
      "y": 13,
      "z": 0,
      "name": "TFJ_Canopy_Leaves"
    },
    {
      "x": -1,
      "y": 13,
      "z": 1,
      "name": "TFJ_Canopy_Leaves"
    },
    {
      "x": -1,
      "y": 13,
      "z": 2,
      "name": "TFJ_Canopy_Leaves"
    },
    {
      "x": -1,
      "y": 13,
      "z": 3,
      "name": "TFJ_Canopy_Leaves"
    },
    {
      "x": -1,
      "y": 13,
      "z": 4,
      "name": "TFJ_Canopy_Leaves"
    },
    {
      "x": 0,
      "y": 13,
      "z": -2,
      "name": "TFJ_Canopy_Leaves"
    },
    {
      "x": 0,
      "y": 13,
      "z": -1,
      "name": "TFJ_Canopy_Leaves"
    },
    {
      "x": 0,
      "y": 13,
      "z": 0,
      "name": "TFJ_Canopy_Leaves"
    },
    {
      "x": 0,
      "y": 13,
      "z": 2,
      "name": "TFJ_Canopy_Leaves"
    },
    {
      "x": 0,
      "y": 13,
      "z": 3,
      "name": "TFJ_Canopy_Leaves"
    },
    {
      "x": 0,
      "y": 13,
      "z": 4,
      "name": "TFJ_Canopy_Leaves"
    },
    {
      "x": 1,
      "y": 13,
      "z": -4,
      "name": "TFJ_Canopy_Leaves"
    },
    {
      "x": 1,
      "y": 13,
      "z": -3,
      "name": "TFJ_Canopy_Leaves"
    },
    {
      "x": 1,
      "y": 13,
      "z": -1,
      "name": "TFJ_Canopy_Leaves"
    },
    {
      "x": 1,
      "y": 13,
      "z": 0,
      "name": "TFJ_Canopy_Leaves"
    },
    {
      "x": 1,
      "y": 13,
      "z": 1,
      "name": "TFJ_Canopy_Leaves"
    },
    {
      "x": 1,
      "y": 13,
      "z": 2,
      "name": "TFJ_Canopy_Leaves"
    },
    {
      "x": 1,
      "y": 13,
      "z": 3,
      "name": "TFJ_Canopy_Leaves"
    },
    {
      "x": 1,
      "y": 13,
      "z": 4,
      "name": "TFJ_Canopy_Leaves"
    },
    {
      "x": 2,
      "y": 13,
      "z": -3,
      "name": "TFJ_Canopy_Leaves"
    },
    {
      "x": 2,
      "y": 13,
      "z": -2,
      "name": "TFJ_Canopy_Leaves"
    },
    {
      "x": 2,
      "y": 13,
      "z": -1,
      "name": "TFJ_Canopy_Leaves"
    },
    {
      "x": 2,
      "y": 13,
      "z": 0,
      "name": "TFJ_Canopy_Leaves"
    },
    {
      "x": 2,
      "y": 13,
      "z": 1,
      "name": "TFJ_Canopy_Leaves"
    },
    {
      "x": 2,
      "y": 13,
      "z": 2,
      "name": "TFJ_Canopy_Leaves"
    },
    {
      "x": 2,
      "y": 13,
      "z": 3,
      "name": "TFJ_Canopy_Leaves"
    },
    {
      "x": 3,
      "y": 13,
      "z": -2,
      "name": "TFJ_Canopy_Leaves"
    },
    {
      "x": 3,
      "y": 13,
      "z": -1,
      "name": "TFJ_Canopy_Leaves"
    },
    {
      "x": 3,
      "y": 13,
      "z": 0,
      "name": "TFJ_Canopy_Leaves"
    },
    {
      "x": 3,
      "y": 13,
      "z": 1,
      "name": "TFJ_Canopy_Leaves"
    },
    {
      "x": 3,
      "y": 13,
      "z": 2,
      "name": "TFJ_Canopy_Leaves"
    },
    {
      "x": 4,
      "y": 13,
      "z": -1,
      "name": "TFJ_Canopy_Leaves"
    },
    {
      "x": 4,
      "y": 13,
      "z": 1,
      "name": "TFJ_Canopy_Leaves"
    },
    {
      "x": -4,
      "y": 14,
      "z": -1,
      "name": "TFJ_Canopy_Leaves"
    },
    {
      "x": -4,
      "y": 14,
      "z": 0,
      "name": "TFJ_Canopy_Leaves"
    },
    {
      "x": -4,
      "y": 14,
      "z": 1,
      "name": "TFJ_Canopy_Leaves"
    },
    {
      "x": -3,
      "y": 14,
      "z": -2,
      "name": "TFJ_Canopy_Leaves"
    },
    {
      "x": -3,
      "y": 14,
      "z": -1,
      "name": "TFJ_Canopy_Leaves"
    },
    {
      "x": -3,
      "y": 14,
      "z": 0,
      "name": "TFJ_Canopy_Leaves"
    },
    {
      "x": -3,
      "y": 14,
      "z": 1,
      "name": "TFJ_Canopy_Leaves"
    },
    {
      "x": -3,
      "y": 14,
      "z": 2,
      "name": "TFJ_Canopy_Leaves"
    },
    {
      "x": -2,
      "y": 14,
      "z": -2,
      "name": "TFJ_Canopy_Leaves"
    },
    {
      "x": -2,
      "y": 14,
      "z": 0,
      "name": "TFJ_Canopy_Leaves"
    },
    {
      "x": -2,
      "y": 14,
      "z": 1,
      "name": "TFJ_Canopy_Leaves"
    },
    {
      "x": -2,
      "y": 14,
      "z": 2,
      "name": "TFJ_Canopy_Leaves"
    },
    {
      "x": -2,
      "y": 14,
      "z": 3,
      "name": "TFJ_Canopy_Leaves"
    },
    {
      "x": -1,
      "y": 14,
      "z": -4,
      "name": "TFJ_Canopy_Leaves"
    },
    {
      "x": -1,
      "y": 14,
      "z": -3,
      "name": "TFJ_Canopy_Leaves"
    },
    {
      "x": -1,
      "y": 14,
      "z": -2,
      "name": "TFJ_Canopy_Leaves"
    },
    {
      "x": -1,
      "y": 14,
      "z": -1,
      "name": "TFJ_Canopy_Leaves"
    },
    {
      "x": -1,
      "y": 14,
      "z": 1,
      "name": "TFJ_Canopy_Leaves"
    },
    {
      "x": -1,
      "y": 14,
      "z": 2,
      "name": "TFJ_Canopy_Leaves"
    },
    {
      "x": -1,
      "y": 14,
      "z": 3,
      "name": "TFJ_Canopy_Leaves"
    },
    {
      "x": -1,
      "y": 14,
      "z": 4,
      "name": "TFJ_Canopy_Leaves"
    },
    {
      "x": 0,
      "y": 14,
      "z": -4,
      "name": "TFJ_Canopy_Leaves"
    },
    {
      "x": 0,
      "y": 14,
      "z": -3,
      "name": "TFJ_Canopy_Leaves"
    },
    {
      "x": 0,
      "y": 14,
      "z": -2,
      "name": "TFJ_Canopy_Leaves"
    },
    {
      "x": 0,
      "y": 14,
      "z": -1,
      "name": "TFJ_Canopy_Leaves"
    },
    {
      "x": 0,
      "y": 14,
      "z": 0,
      "name": "TFJ_Canopy_Leaves"
    },
    {
      "x": 0,
      "y": 14,
      "z": 1,
      "name": "TFJ_Canopy_Leaves"
    },
    {
      "x": 0,
      "y": 14,
      "z": 2,
      "name": "TFJ_Canopy_Leaves"
    },
    {
      "x": 0,
      "y": 14,
      "z": 3,
      "name": "TFJ_Canopy_Leaves"
    },
    {
      "x": 0,
      "y": 14,
      "z": 4,
      "name": "TFJ_Canopy_Leaves"
    },
    {
      "x": 1,
      "y": 14,
      "z": -4,
      "name": "TFJ_Canopy_Leaves"
    },
    {
      "x": 1,
      "y": 14,
      "z": -3,
      "name": "TFJ_Canopy_Leaves"
    },
    {
      "x": 1,
      "y": 14,
      "z": -2,
      "name": "TFJ_Canopy_Leaves"
    },
    {
      "x": 1,
      "y": 14,
      "z": -1,
      "name": "TFJ_Canopy_Leaves"
    },
    {
      "x": 1,
      "y": 14,
      "z": 0,
      "name": "TFJ_Canopy_Leaves"
    },
    {
      "x": 1,
      "y": 14,
      "z": 1,
      "name": "TFJ_Canopy_Leaves"
    },
    {
      "x": 1,
      "y": 14,
      "z": 2,
      "name": "TFJ_Canopy_Leaves"
    },
    {
      "x": 1,
      "y": 14,
      "z": 3,
      "name": "TFJ_Canopy_Leaves"
    },
    {
      "x": 1,
      "y": 14,
      "z": 4,
      "name": "TFJ_Canopy_Leaves"
    },
    {
      "x": 2,
      "y": 14,
      "z": -3,
      "name": "TFJ_Canopy_Leaves"
    },
    {
      "x": 2,
      "y": 14,
      "z": -2,
      "name": "TFJ_Canopy_Leaves"
    },
    {
      "x": 2,
      "y": 14,
      "z": -1,
      "name": "TFJ_Canopy_Leaves"
    },
    {
      "x": 2,
      "y": 14,
      "z": 0,
      "name": "TFJ_Canopy_Leaves"
    },
    {
      "x": 2,
      "y": 14,
      "z": 1,
      "name": "TFJ_Canopy_Leaves"
    },
    {
      "x": 2,
      "y": 14,
      "z": 2,
      "name": "TFJ_Canopy_Leaves"
    },
    {
      "x": 2,
      "y": 14,
      "z": 3,
      "name": "TFJ_Canopy_Leaves"
    },
    {
      "x": 3,
      "y": 14,
      "z": -2,
      "name": "TFJ_Canopy_Leaves"
    },
    {
      "x": 3,
      "y": 14,
      "z": -1,
      "name": "TFJ_Canopy_Leaves"
    },
    {
      "x": 3,
      "y": 14,
      "z": 0,
      "name": "TFJ_Canopy_Leaves"
    },
    {
      "x": 3,
      "y": 14,
      "z": 1,
      "name": "TFJ_Canopy_Leaves"
    },
    {
      "x": 3,
      "y": 14,
      "z": 2,
      "name": "TFJ_Canopy_Leaves"
    },
    {
      "x": 4,
      "y": 14,
      "z": -1,
      "name": "TFJ_Canopy_Leaves"
    },
    {
      "x": 4,
      "y": 14,
      "z": 0,
      "name": "TFJ_Canopy_Leaves"
    },
    {
      "x": -5,
      "y": 15,
      "z": 0,
      "name": "TFJ_Canopy_Leaves"
    },
    {
      "x": -4,
      "y": 15,
      "z": -2,
      "name": "TFJ_Canopy_Leaves"
    },
    {
      "x": -4,
      "y": 15,
      "z": -1,
      "name": "TFJ_Canopy_Leaves"
    },
    {
      "x": -4,
      "y": 15,
      "z": 0,
      "name": "TFJ_Canopy_Leaves"
    },
    {
      "x": -4,
      "y": 15,
      "z": 1,
      "name": "TFJ_Canopy_Leaves"
    },
    {
      "x": -3,
      "y": 15,
      "z": -3,
      "name": "TFJ_Canopy_Leaves"
    },
    {
      "x": -3,
      "y": 15,
      "z": -2,
      "name": "TFJ_Canopy_Leaves"
    },
    {
      "x": -3,
      "y": 15,
      "z": 0,
      "name": "TFJ_Canopy_Leaves"
    },
    {
      "x": -3,
      "y": 15,
      "z": 1,
      "name": "TFJ_Canopy_Leaves"
    },
    {
      "x": -3,
      "y": 15,
      "z": 2,
      "name": "TFJ_Canopy_Leaves"
    },
    {
      "x": -2,
      "y": 15,
      "z": -4,
      "name": "TFJ_Canopy_Leaves"
    },
    {
      "x": -2,
      "y": 15,
      "z": -3,
      "name": "TFJ_Canopy_Leaves"
    },
    {
      "x": -2,
      "y": 15,
      "z": -2,
      "name": "TFJ_Canopy_Leaves"
    },
    {
      "x": -2,
      "y": 15,
      "z": -1,
      "name": "TFJ_Canopy_Leaves"
    },
    {
      "x": -2,
      "y": 15,
      "z": 0,
      "name": "TFJ_Canopy_Leaves"
    },
    {
      "x": -2,
      "y": 15,
      "z": 1,
      "name": "TFJ_Canopy_Leaves"
    },
    {
      "x": -2,
      "y": 15,
      "z": 2,
      "name": "TFJ_Canopy_Leaves"
    },
    {
      "x": -2,
      "y": 15,
      "z": 3,
      "name": "TFJ_Canopy_Leaves"
    },
    {
      "x": -2,
      "y": 15,
      "z": 4,
      "name": "TFJ_Canopy_Leaves"
    },
    {
      "x": -1,
      "y": 15,
      "z": -5,
      "name": "TFJ_Canopy_Leaves"
    },
    {
      "x": -1,
      "y": 15,
      "z": -3,
      "name": "TFJ_Canopy_Leaves"
    },
    {
      "x": -1,
      "y": 15,
      "z": -2,
      "name": "TFJ_Canopy_Leaves"
    },
    {
      "x": -1,
      "y": 15,
      "z": -1,
      "name": "TFJ_Canopy_Leaves"
    },
    {
      "x": -1,
      "y": 15,
      "z": 0,
      "name": "TFJ_Canopy_Leaves"
    },
    {
      "x": -1,
      "y": 15,
      "z": 1,
      "name": "TFJ_Canopy_Leaves"
    },
    {
      "x": -1,
      "y": 15,
      "z": 2,
      "name": "TFJ_Canopy_Leaves"
    },
    {
      "x": -1,
      "y": 15,
      "z": 3,
      "name": "TFJ_Canopy_Leaves"
    },
    {
      "x": -1,
      "y": 15,
      "z": 4,
      "name": "TFJ_Canopy_Leaves"
    },
    {
      "x": -1,
      "y": 15,
      "z": 5,
      "name": "TFJ_Canopy_Leaves"
    },
    {
      "x": 0,
      "y": 15,
      "z": -5,
      "name": "TFJ_Canopy_Leaves"
    },
    {
      "x": 0,
      "y": 15,
      "z": -4,
      "name": "TFJ_Canopy_Leaves"
    },
    {
      "x": 0,
      "y": 15,
      "z": -3,
      "name": "TFJ_Canopy_Leaves"
    },
    {
      "x": 0,
      "y": 15,
      "z": -1,
      "name": "TFJ_Canopy_Leaves"
    },
    {
      "x": 0,
      "y": 15,
      "z": 0,
      "name": "TFJ_Canopy_Leaves"
    },
    {
      "x": 0,
      "y": 15,
      "z": 1,
      "name": "TFJ_Canopy_Leaves"
    },
    {
      "x": 0,
      "y": 15,
      "z": 2,
      "name": "TFJ_Canopy_Leaves"
    },
    {
      "x": 0,
      "y": 15,
      "z": 3,
      "name": "TFJ_Canopy_Leaves"
    },
    {
      "x": 0,
      "y": 15,
      "z": 4,
      "name": "TFJ_Canopy_Leaves"
    },
    {
      "x": 0,
      "y": 15,
      "z": 5,
      "name": "TFJ_Canopy_Leaves"
    },
    {
      "x": 1,
      "y": 15,
      "z": -5,
      "name": "TFJ_Canopy_Leaves"
    },
    {
      "x": 1,
      "y": 15,
      "z": -4,
      "name": "TFJ_Canopy_Leaves"
    },
    {
      "x": 1,
      "y": 15,
      "z": -3,
      "name": "TFJ_Canopy_Leaves"
    },
    {
      "x": 1,
      "y": 15,
      "z": -2,
      "name": "TFJ_Canopy_Leaves"
    },
    {
      "x": 1,
      "y": 15,
      "z": -1,
      "name": "TFJ_Canopy_Leaves"
    },
    {
      "x": 1,
      "y": 15,
      "z": 0,
      "name": "TFJ_Canopy_Leaves"
    },
    {
      "x": 1,
      "y": 15,
      "z": 1,
      "name": "TFJ_Canopy_Leaves"
    },
    {
      "x": 1,
      "y": 15,
      "z": 2,
      "name": "TFJ_Canopy_Leaves"
    },
    {
      "x": 1,
      "y": 15,
      "z": 3,
      "name": "TFJ_Canopy_Leaves"
    },
    {
      "x": 1,
      "y": 15,
      "z": 4,
      "name": "TFJ_Canopy_Leaves"
    },
    {
      "x": 1,
      "y": 15,
      "z": 5,
      "name": "TFJ_Canopy_Leaves"
    },
    {
      "x": 2,
      "y": 15,
      "z": -4,
      "name": "TFJ_Canopy_Leaves"
    },
    {
      "x": 2,
      "y": 15,
      "z": -3,
      "name": "TFJ_Canopy_Leaves"
    },
    {
      "x": 2,
      "y": 15,
      "z": -2,
      "name": "TFJ_Canopy_Leaves"
    },
    {
      "x": 2,
      "y": 15,
      "z": -1,
      "name": "TFJ_Canopy_Leaves"
    },
    {
      "x": 2,
      "y": 15,
      "z": 0,
      "name": "TFJ_Canopy_Leaves"
    },
    {
      "x": 2,
      "y": 15,
      "z": 1,
      "name": "TFJ_Canopy_Leaves"
    },
    {
      "x": 2,
      "y": 15,
      "z": 2,
      "name": "TFJ_Canopy_Leaves"
    },
    {
      "x": 2,
      "y": 15,
      "z": 3,
      "name": "TFJ_Canopy_Leaves"
    },
    {
      "x": 2,
      "y": 15,
      "z": 4,
      "name": "TFJ_Canopy_Leaves"
    },
    {
      "x": 3,
      "y": 15,
      "z": -3,
      "name": "TFJ_Canopy_Leaves"
    },
    {
      "x": 3,
      "y": 15,
      "z": -1,
      "name": "TFJ_Canopy_Leaves"
    },
    {
      "x": 3,
      "y": 15,
      "z": 0,
      "name": "TFJ_Canopy_Leaves"
    },
    {
      "x": 3,
      "y": 15,
      "z": 1,
      "name": "TFJ_Canopy_Leaves"
    },
    {
      "x": 3,
      "y": 15,
      "z": 2,
      "name": "TFJ_Canopy_Leaves"
    },
    {
      "x": 4,
      "y": 15,
      "z": -2,
      "name": "TFJ_Canopy_Leaves"
    },
    {
      "x": 4,
      "y": 15,
      "z": 0,
      "name": "TFJ_Canopy_Leaves"
    },
    {
      "x": 4,
      "y": 15,
      "z": 1,
      "name": "TFJ_Canopy_Leaves"
    },
    {
      "x": 4,
      "y": 15,
      "z": 2,
      "name": "TFJ_Canopy_Leaves"
    },
    {
      "x": 5,
      "y": 15,
      "z": -1,
      "name": "TFJ_Canopy_Leaves"
    },
    {
      "x": 5,
      "y": 15,
      "z": 0,
      "name": "TFJ_Canopy_Leaves"
    },
    {
      "x": 5,
      "y": 15,
      "z": 1,
      "name": "TFJ_Canopy_Leaves"
    },
    {
      "x": -5,
      "y": 16,
      "z": -1,
      "name": "TFJ_Canopy_Leaves"
    },
    {
      "x": -5,
      "y": 16,
      "z": 0,
      "name": "TFJ_Canopy_Leaves"
    },
    {
      "x": -5,
      "y": 16,
      "z": 1,
      "name": "TFJ_Canopy_Leaves"
    },
    {
      "x": -4,
      "y": 16,
      "z": -2,
      "name": "TFJ_Canopy_Leaves"
    },
    {
      "x": -4,
      "y": 16,
      "z": -1,
      "name": "TFJ_Canopy_Leaves"
    },
    {
      "x": -4,
      "y": 16,
      "z": 0,
      "name": "TFJ_Canopy_Leaves"
    },
    {
      "x": -4,
      "y": 16,
      "z": 1,
      "name": "TFJ_Canopy_Leaves"
    },
    {
      "x": -3,
      "y": 16,
      "z": -3,
      "name": "TFJ_Canopy_Leaves"
    },
    {
      "x": -3,
      "y": 16,
      "z": -2,
      "name": "TFJ_Canopy_Leaves"
    },
    {
      "x": -3,
      "y": 16,
      "z": -1,
      "name": "TFJ_Canopy_Leaves"
    },
    {
      "x": -3,
      "y": 16,
      "z": 0,
      "name": "TFJ_Canopy_Leaves"
    },
    {
      "x": -3,
      "y": 16,
      "z": 1,
      "name": "TFJ_Canopy_Leaves"
    },
    {
      "x": -3,
      "y": 16,
      "z": 2,
      "name": "TFJ_Canopy_Leaves"
    },
    {
      "x": -3,
      "y": 16,
      "z": 3,
      "name": "TFJ_Canopy_Leaves"
    },
    {
      "x": -2,
      "y": 16,
      "z": -4,
      "name": "TFJ_Canopy_Leaves"
    },
    {
      "x": -2,
      "y": 16,
      "z": -3,
      "name": "TFJ_Canopy_Leaves"
    },
    {
      "x": -2,
      "y": 16,
      "z": -2,
      "name": "TFJ_Canopy_Leaves"
    },
    {
      "x": -2,
      "y": 16,
      "z": -1,
      "name": "TFJ_Canopy_Leaves"
    },
    {
      "x": -2,
      "y": 16,
      "z": 0,
      "name": "TFJ_Canopy_Leaves"
    },
    {
      "x": -2,
      "y": 16,
      "z": 1,
      "name": "TFJ_Canopy_Leaves"
    },
    {
      "x": -2,
      "y": 16,
      "z": 2,
      "name": "TFJ_Canopy_Leaves"
    },
    {
      "x": -2,
      "y": 16,
      "z": 3,
      "name": "TFJ_Canopy_Leaves"
    },
    {
      "x": -2,
      "y": 16,
      "z": 4,
      "name": "TFJ_Canopy_Leaves"
    },
    {
      "x": -1,
      "y": 16,
      "z": -5,
      "name": "TFJ_Canopy_Leaves"
    },
    {
      "x": -1,
      "y": 16,
      "z": -4,
      "name": "TFJ_Canopy_Leaves"
    },
    {
      "x": -1,
      "y": 16,
      "z": -3,
      "name": "TFJ_Canopy_Leaves"
    },
    {
      "x": -1,
      "y": 16,
      "z": -2,
      "name": "TFJ_Canopy_Leaves"
    },
    {
      "x": -1,
      "y": 16,
      "z": -1,
      "name": "TFJ_Canopy_Leaves"
    },
    {
      "x": -1,
      "y": 16,
      "z": 1,
      "name": "TFJ_Canopy_Leaves"
    },
    {
      "x": -1,
      "y": 16,
      "z": 2,
      "name": "TFJ_Canopy_Leaves"
    },
    {
      "x": -1,
      "y": 16,
      "z": 3,
      "name": "TFJ_Canopy_Leaves"
    },
    {
      "x": -1,
      "y": 16,
      "z": 4,
      "name": "TFJ_Canopy_Leaves"
    },
    {
      "x": -1,
      "y": 16,
      "z": 5,
      "name": "TFJ_Canopy_Leaves"
    },
    {
      "x": 0,
      "y": 16,
      "z": -5,
      "name": "TFJ_Canopy_Leaves"
    },
    {
      "x": 0,
      "y": 16,
      "z": -4,
      "name": "TFJ_Canopy_Leaves"
    },
    {
      "x": 0,
      "y": 16,
      "z": -2,
      "name": "TFJ_Canopy_Leaves"
    },
    {
      "x": 0,
      "y": 16,
      "z": -1,
      "name": "TFJ_Canopy_Leaves"
    },
    {
      "x": 0,
      "y": 16,
      "z": 0,
      "name": "TFJ_Canopy_Leaves"
    },
    {
      "x": 0,
      "y": 16,
      "z": 1,
      "name": "TFJ_Canopy_Leaves"
    },
    {
      "x": 0,
      "y": 16,
      "z": 2,
      "name": "TFJ_Canopy_Leaves"
    },
    {
      "x": 0,
      "y": 16,
      "z": 3,
      "name": "TFJ_Canopy_Leaves"
    },
    {
      "x": 0,
      "y": 16,
      "z": 4,
      "name": "TFJ_Canopy_Leaves"
    },
    {
      "x": 0,
      "y": 16,
      "z": 5,
      "name": "TFJ_Canopy_Leaves"
    },
    {
      "x": 1,
      "y": 16,
      "z": -5,
      "name": "TFJ_Canopy_Leaves"
    },
    {
      "x": 1,
      "y": 16,
      "z": -4,
      "name": "TFJ_Canopy_Leaves"
    },
    {
      "x": 1,
      "y": 16,
      "z": -3,
      "name": "TFJ_Canopy_Leaves"
    },
    {
      "x": 1,
      "y": 16,
      "z": -2,
      "name": "TFJ_Canopy_Leaves"
    },
    {
      "x": 1,
      "y": 16,
      "z": -1,
      "name": "TFJ_Canopy_Leaves"
    },
    {
      "x": 1,
      "y": 16,
      "z": 0,
      "name": "TFJ_Canopy_Leaves"
    },
    {
      "x": 1,
      "y": 16,
      "z": 1,
      "name": "TFJ_Canopy_Leaves"
    },
    {
      "x": 1,
      "y": 16,
      "z": 2,
      "name": "TFJ_Canopy_Leaves"
    },
    {
      "x": 1,
      "y": 16,
      "z": 3,
      "name": "TFJ_Canopy_Leaves"
    },
    {
      "x": 1,
      "y": 16,
      "z": 5,
      "name": "TFJ_Canopy_Leaves"
    },
    {
      "x": 2,
      "y": 16,
      "z": -4,
      "name": "TFJ_Canopy_Leaves"
    },
    {
      "x": 2,
      "y": 16,
      "z": -3,
      "name": "TFJ_Canopy_Leaves"
    },
    {
      "x": 2,
      "y": 16,
      "z": -2,
      "name": "TFJ_Canopy_Leaves"
    },
    {
      "x": 2,
      "y": 16,
      "z": -1,
      "name": "TFJ_Canopy_Leaves"
    },
    {
      "x": 2,
      "y": 16,
      "z": 0,
      "name": "TFJ_Canopy_Leaves"
    },
    {
      "x": 2,
      "y": 16,
      "z": 2,
      "name": "TFJ_Canopy_Leaves"
    },
    {
      "x": 2,
      "y": 16,
      "z": 3,
      "name": "TFJ_Canopy_Leaves"
    },
    {
      "x": 2,
      "y": 16,
      "z": 4,
      "name": "TFJ_Canopy_Leaves"
    },
    {
      "x": 3,
      "y": 16,
      "z": -3,
      "name": "TFJ_Canopy_Leaves"
    },
    {
      "x": 3,
      "y": 16,
      "z": -2,
      "name": "TFJ_Canopy_Leaves"
    },
    {
      "x": 3,
      "y": 16,
      "z": -1,
      "name": "TFJ_Canopy_Leaves"
    },
    {
      "x": 3,
      "y": 16,
      "z": 0,
      "name": "TFJ_Canopy_Leaves"
    },
    {
      "x": 3,
      "y": 16,
      "z": 1,
      "name": "TFJ_Canopy_Leaves"
    },
    {
      "x": 3,
      "y": 16,
      "z": 2,
      "name": "TFJ_Canopy_Leaves"
    },
    {
      "x": 3,
      "y": 16,
      "z": 3,
      "name": "TFJ_Canopy_Leaves"
    },
    {
      "x": 4,
      "y": 16,
      "z": -2,
      "name": "TFJ_Canopy_Leaves"
    },
    {
      "x": 4,
      "y": 16,
      "z": -1,
      "name": "TFJ_Canopy_Leaves"
    },
    {
      "x": 4,
      "y": 16,
      "z": 0,
      "name": "TFJ_Canopy_Leaves"
    },
    {
      "x": 4,
      "y": 16,
      "z": 1,
      "name": "TFJ_Canopy_Leaves"
    },
    {
      "x": 4,
      "y": 16,
      "z": 2,
      "name": "TFJ_Canopy_Leaves"
    },
    {
      "x": 5,
      "y": 16,
      "z": -1,
      "name": "TFJ_Canopy_Leaves"
    },
    {
      "x": 5,
      "y": 16,
      "z": 0,
      "name": "TFJ_Canopy_Leaves"
    },
    {
      "x": 5,
      "y": 16,
      "z": 1,
      "name": "TFJ_Canopy_Leaves"
    },
    {
      "x": -5,
      "y": 17,
      "z": -1,
      "name": "TFJ_Canopy_Leaves"
    },
    {
      "x": -5,
      "y": 17,
      "z": 0,
      "name": "TFJ_Canopy_Leaves"
    },
    {
      "x": -5,
      "y": 17,
      "z": 1,
      "name": "TFJ_Canopy_Leaves"
    },
    {
      "x": -4,
      "y": 17,
      "z": -2,
      "name": "TFJ_Canopy_Leaves"
    },
    {
      "x": -4,
      "y": 17,
      "z": -1,
      "name": "TFJ_Canopy_Leaves"
    },
    {
      "x": -4,
      "y": 17,
      "z": 0,
      "name": "TFJ_Canopy_Leaves"
    },
    {
      "x": -4,
      "y": 17,
      "z": 1,
      "name": "TFJ_Canopy_Leaves"
    },
    {
      "x": -4,
      "y": 17,
      "z": 2,
      "name": "TFJ_Canopy_Leaves"
    },
    {
      "x": -3,
      "y": 17,
      "z": -3,
      "name": "TFJ_Canopy_Leaves"
    },
    {
      "x": -3,
      "y": 17,
      "z": -2,
      "name": "TFJ_Canopy_Leaves"
    },
    {
      "x": -3,
      "y": 17,
      "z": -1,
      "name": "TFJ_Canopy_Leaves"
    },
    {
      "x": -3,
      "y": 17,
      "z": 0,
      "name": "TFJ_Canopy_Leaves"
    },
    {
      "x": -3,
      "y": 17,
      "z": 1,
      "name": "TFJ_Canopy_Leaves"
    },
    {
      "x": -3,
      "y": 17,
      "z": 2,
      "name": "TFJ_Canopy_Leaves"
    },
    {
      "x": -2,
      "y": 17,
      "z": -4,
      "name": "TFJ_Canopy_Leaves"
    },
    {
      "x": -2,
      "y": 17,
      "z": -3,
      "name": "TFJ_Canopy_Leaves"
    },
    {
      "x": -2,
      "y": 17,
      "z": -2,
      "name": "TFJ_Canopy_Leaves"
    },
    {
      "x": -2,
      "y": 17,
      "z": -1,
      "name": "TFJ_Canopy_Leaves"
    },
    {
      "x": -2,
      "y": 17,
      "z": 0,
      "name": "TFJ_Canopy_Leaves"
    },
    {
      "x": -2,
      "y": 17,
      "z": 1,
      "name": "TFJ_Canopy_Leaves"
    },
    {
      "x": -2,
      "y": 17,
      "z": 3,
      "name": "TFJ_Canopy_Leaves"
    },
    {
      "x": -2,
      "y": 17,
      "z": 4,
      "name": "TFJ_Canopy_Leaves"
    },
    {
      "x": -1,
      "y": 17,
      "z": -5,
      "name": "TFJ_Canopy_Leaves"
    },
    {
      "x": -1,
      "y": 17,
      "z": -4,
      "name": "TFJ_Canopy_Leaves"
    },
    {
      "x": -1,
      "y": 17,
      "z": -2,
      "name": "TFJ_Canopy_Leaves"
    },
    {
      "x": -1,
      "y": 17,
      "z": -1,
      "name": "TFJ_Canopy_Leaves"
    },
    {
      "x": -1,
      "y": 17,
      "z": 0,
      "name": "TFJ_Canopy_Leaves"
    },
    {
      "x": -1,
      "y": 17,
      "z": 1,
      "name": "TFJ_Canopy_Leaves"
    },
    {
      "x": -1,
      "y": 17,
      "z": 2,
      "name": "TFJ_Canopy_Leaves"
    },
    {
      "x": 0,
      "y": 17,
      "z": -5,
      "name": "TFJ_Canopy_Leaves"
    },
    {
      "x": 0,
      "y": 17,
      "z": -4,
      "name": "TFJ_Canopy_Leaves"
    },
    {
      "x": 0,
      "y": 17,
      "z": -3,
      "name": "TFJ_Canopy_Leaves"
    },
    {
      "x": 0,
      "y": 17,
      "z": -2,
      "name": "TFJ_Canopy_Leaves"
    },
    {
      "x": 0,
      "y": 17,
      "z": -1,
      "name": "TFJ_Canopy_Leaves"
    },
    {
      "x": 0,
      "y": 17,
      "z": 0,
      "name": "TFJ_Canopy_Leaves"
    },
    {
      "x": 0,
      "y": 17,
      "z": 1,
      "name": "TFJ_Canopy_Leaves"
    },
    {
      "x": 0,
      "y": 17,
      "z": 2,
      "name": "TFJ_Canopy_Leaves"
    },
    {
      "x": 0,
      "y": 17,
      "z": 3,
      "name": "TFJ_Canopy_Leaves"
    },
    {
      "x": 1,
      "y": 17,
      "z": -5,
      "name": "TFJ_Canopy_Leaves"
    },
    {
      "x": 1,
      "y": 17,
      "z": -4,
      "name": "TFJ_Canopy_Leaves"
    },
    {
      "x": 1,
      "y": 17,
      "z": -3,
      "name": "TFJ_Canopy_Leaves"
    },
    {
      "x": 1,
      "y": 17,
      "z": -2,
      "name": "TFJ_Canopy_Leaves"
    },
    {
      "x": 1,
      "y": 17,
      "z": -1,
      "name": "TFJ_Canopy_Leaves"
    },
    {
      "x": 1,
      "y": 17,
      "z": 0,
      "name": "TFJ_Canopy_Leaves"
    },
    {
      "x": 1,
      "y": 17,
      "z": 1,
      "name": "TFJ_Canopy_Leaves"
    },
    {
      "x": 1,
      "y": 17,
      "z": 2,
      "name": "TFJ_Canopy_Leaves"
    },
    {
      "x": 1,
      "y": 17,
      "z": 4,
      "name": "TFJ_Canopy_Leaves"
    },
    {
      "x": 1,
      "y": 17,
      "z": 5,
      "name": "TFJ_Canopy_Leaves"
    },
    {
      "x": 2,
      "y": 17,
      "z": -4,
      "name": "TFJ_Canopy_Leaves"
    },
    {
      "x": 2,
      "y": 17,
      "z": -3,
      "name": "TFJ_Canopy_Leaves"
    },
    {
      "x": 2,
      "y": 17,
      "z": -2,
      "name": "TFJ_Canopy_Leaves"
    },
    {
      "x": 2,
      "y": 17,
      "z": -1,
      "name": "TFJ_Canopy_Leaves"
    },
    {
      "x": 2,
      "y": 17,
      "z": 0,
      "name": "TFJ_Canopy_Leaves"
    },
    {
      "x": 2,
      "y": 17,
      "z": 1,
      "name": "TFJ_Canopy_Leaves"
    },
    {
      "x": 2,
      "y": 17,
      "z": 2,
      "name": "TFJ_Canopy_Leaves"
    },
    {
      "x": 2,
      "y": 17,
      "z": 4,
      "name": "TFJ_Canopy_Leaves"
    },
    {
      "x": 3,
      "y": 17,
      "z": -3,
      "name": "TFJ_Canopy_Leaves"
    },
    {
      "x": 3,
      "y": 17,
      "z": -2,
      "name": "TFJ_Canopy_Leaves"
    },
    {
      "x": 3,
      "y": 17,
      "z": -1,
      "name": "TFJ_Canopy_Leaves"
    },
    {
      "x": 3,
      "y": 17,
      "z": 0,
      "name": "TFJ_Canopy_Leaves"
    },
    {
      "x": 3,
      "y": 17,
      "z": 1,
      "name": "TFJ_Canopy_Leaves"
    },
    {
      "x": 3,
      "y": 17,
      "z": 2,
      "name": "TFJ_Canopy_Leaves"
    },
    {
      "x": 3,
      "y": 17,
      "z": 3,
      "name": "TFJ_Canopy_Leaves"
    },
    {
      "x": 4,
      "y": 17,
      "z": -2,
      "name": "TFJ_Canopy_Leaves"
    },
    {
      "x": 4,
      "y": 17,
      "z": -1,
      "name": "TFJ_Canopy_Leaves"
    },
    {
      "x": 4,
      "y": 17,
      "z": 0,
      "name": "TFJ_Canopy_Leaves"
    },
    {
      "x": 4,
      "y": 17,
      "z": 1,
      "name": "TFJ_Canopy_Leaves"
    },
    {
      "x": 4,
      "y": 17,
      "z": 2,
      "name": "TFJ_Canopy_Leaves"
    },
    {
      "x": 5,
      "y": 17,
      "z": -1,
      "name": "TFJ_Canopy_Leaves"
    },
    {
      "x": 5,
      "y": 17,
      "z": 0,
      "name": "TFJ_Canopy_Leaves"
    },
    {
      "x": 5,
      "y": 17,
      "z": 1,
      "name": "TFJ_Canopy_Leaves"
    },
    {
      "x": -4,
      "y": 18,
      "z": -1,
      "name": "TFJ_Canopy_Leaves"
    },
    {
      "x": -4,
      "y": 18,
      "z": 0,
      "name": "TFJ_Canopy_Leaves"
    },
    {
      "x": -4,
      "y": 18,
      "z": 1,
      "name": "TFJ_Canopy_Leaves"
    },
    {
      "x": -3,
      "y": 18,
      "z": -2,
      "name": "TFJ_Canopy_Leaves"
    },
    {
      "x": -3,
      "y": 18,
      "z": -1,
      "name": "TFJ_Canopy_Leaves"
    },
    {
      "x": -3,
      "y": 18,
      "z": 0,
      "name": "TFJ_Canopy_Leaves"
    },
    {
      "x": -3,
      "y": 18,
      "z": 1,
      "name": "TFJ_Canopy_Leaves"
    },
    {
      "x": -2,
      "y": 18,
      "z": -3,
      "name": "TFJ_Canopy_Leaves"
    },
    {
      "x": -2,
      "y": 18,
      "z": -2,
      "name": "TFJ_Canopy_Leaves"
    },
    {
      "x": -2,
      "y": 18,
      "z": 0,
      "name": "TFJ_Canopy_Leaves"
    },
    {
      "x": -2,
      "y": 18,
      "z": 1,
      "name": "TFJ_Canopy_Leaves"
    },
    {
      "x": -2,
      "y": 18,
      "z": 2,
      "name": "TFJ_Canopy_Leaves"
    },
    {
      "x": -2,
      "y": 18,
      "z": 3,
      "name": "TFJ_Canopy_Leaves"
    },
    {
      "x": -1,
      "y": 18,
      "z": -4,
      "name": "TFJ_Canopy_Leaves"
    },
    {
      "x": -1,
      "y": 18,
      "z": -3,
      "name": "TFJ_Canopy_Leaves"
    },
    {
      "x": -1,
      "y": 18,
      "z": -2,
      "name": "TFJ_Canopy_Leaves"
    },
    {
      "x": -1,
      "y": 18,
      "z": -1,
      "name": "TFJ_Canopy_Leaves"
    },
    {
      "x": -1,
      "y": 18,
      "z": 0,
      "name": "TFJ_Canopy_Leaves"
    },
    {
      "x": -1,
      "y": 18,
      "z": 1,
      "name": "TFJ_Canopy_Leaves"
    },
    {
      "x": -1,
      "y": 18,
      "z": 2,
      "name": "TFJ_Canopy_Leaves"
    },
    {
      "x": -1,
      "y": 18,
      "z": 3,
      "name": "TFJ_Canopy_Leaves"
    },
    {
      "x": -1,
      "y": 18,
      "z": 4,
      "name": "TFJ_Canopy_Leaves"
    },
    {
      "x": 0,
      "y": 18,
      "z": -4,
      "name": "TFJ_Canopy_Leaves"
    },
    {
      "x": 0,
      "y": 18,
      "z": -3,
      "name": "TFJ_Canopy_Leaves"
    },
    {
      "x": 0,
      "y": 18,
      "z": -2,
      "name": "TFJ_Canopy_Leaves"
    },
    {
      "x": 0,
      "y": 18,
      "z": 0,
      "name": "TFJ_Canopy_Leaves"
    },
    {
      "x": 0,
      "y": 18,
      "z": 1,
      "name": "TFJ_Canopy_Leaves"
    },
    {
      "x": 0,
      "y": 18,
      "z": 2,
      "name": "TFJ_Canopy_Leaves"
    },
    {
      "x": 0,
      "y": 18,
      "z": 3,
      "name": "TFJ_Canopy_Leaves"
    },
    {
      "x": 1,
      "y": 18,
      "z": -4,
      "name": "TFJ_Canopy_Leaves"
    },
    {
      "x": 1,
      "y": 18,
      "z": -3,
      "name": "TFJ_Canopy_Leaves"
    },
    {
      "x": 1,
      "y": 18,
      "z": -1,
      "name": "TFJ_Canopy_Leaves"
    },
    {
      "x": 1,
      "y": 18,
      "z": 0,
      "name": "TFJ_Canopy_Leaves"
    },
    {
      "x": 1,
      "y": 18,
      "z": 1,
      "name": "TFJ_Canopy_Leaves"
    },
    {
      "x": 1,
      "y": 18,
      "z": 2,
      "name": "TFJ_Canopy_Leaves"
    },
    {
      "x": 1,
      "y": 18,
      "z": 3,
      "name": "TFJ_Canopy_Leaves"
    },
    {
      "x": 1,
      "y": 18,
      "z": 4,
      "name": "TFJ_Canopy_Leaves"
    },
    {
      "x": 2,
      "y": 18,
      "z": -3,
      "name": "TFJ_Canopy_Leaves"
    },
    {
      "x": 2,
      "y": 18,
      "z": -2,
      "name": "TFJ_Canopy_Leaves"
    },
    {
      "x": 2,
      "y": 18,
      "z": -1,
      "name": "TFJ_Canopy_Leaves"
    },
    {
      "x": 2,
      "y": 18,
      "z": 1,
      "name": "TFJ_Canopy_Leaves"
    },
    {
      "x": 2,
      "y": 18,
      "z": 2,
      "name": "TFJ_Canopy_Leaves"
    },
    {
      "x": 3,
      "y": 18,
      "z": -2,
      "name": "TFJ_Canopy_Leaves"
    },
    {
      "x": 3,
      "y": 18,
      "z": -1,
      "name": "TFJ_Canopy_Leaves"
    },
    {
      "x": 3,
      "y": 18,
      "z": 0,
      "name": "TFJ_Canopy_Leaves"
    },
    {
      "x": 3,
      "y": 18,
      "z": 1,
      "name": "TFJ_Canopy_Leaves"
    },
    {
      "x": 3,
      "y": 18,
      "z": 2,
      "name": "TFJ_Canopy_Leaves"
    },
    {
      "x": 4,
      "y": 18,
      "z": -1,
      "name": "TFJ_Canopy_Leaves"
    },
    {
      "x": 4,
      "y": 18,
      "z": 1,
      "name": "TFJ_Canopy_Leaves"
    }
  ],
  "entities": []
}
