{
  "version": 8,
  "blockIdVersion": 11,
  "anchorX": 25,
  "anchorY": 10,
  "anchorZ": 25,
  "blocks": [
    {
      "x": 5,
      "y": 21,
      "z": 44,
      "name": "TFJ_Bone_Block"
    },
    {
      "x": 5,
      "y": 21,
      "z": 45,
      "name": "TFJ_Bone_Block"
    },
    {
      "x": 6,
      "y": 22,
      "z": 36,
      "name": "TFJ_Bone_Block"
    },
    {
      "x": 6,
      "y": 23,
      "z": 36,
      "name": "TFJ_Bone_Block"
    },
    {
      "x": 6,
      "y": 24,
      "z": 36,
      "name": "TFJ_Bone_Block"
    },
    {
      "x": 6,
      "y": 25,
      "z": 36,
      "name": "TFJ_Bone_Block"
    },
    {
      "x": 6,
      "y": 26,
      "z": 36,
      "name": "TFJ_Bone_Block"
    },
    {
      "x": 6,
      "y": 20,
      "z": 37,
      "name": "TFJ_Bone_Block"
    },
    {
      "x": 6,
      "y": 21,
      "z": 37,
      "name": "TFJ_Bone_Block"
    },
    {
      "x": 6,
      "y": 22,
      "z": 37,
      "name": "TFJ_Bone_Block"
    },
    {
      "x": 6,
      "y": 19,
      "z": 38,
      "name": "TFJ_Bone_Block"
    },
    {
      "x": 6,
      "y": 20,
      "z": 38,
      "name": "TFJ_Bone_Block"
    },
    {
      "x": 6,
      "y": 18,
      "z": 39,
      "name": "TFJ_Bone_Block"
    },
    {
      "x": 6,
      "y": 19,
      "z": 39,
      "name": "TFJ_Bone_Block"
    },
    {
      "x": 6,
      "y": 20,
      "z": 43,
      "name": "TFJ_Bone_Block"
    },
    {
      "x": 6,
      "y": 20,
      "z": 44,
      "name": "TFJ_Bone_Block"
    },
    {
      "x": 6,
      "y": 21,
      "z": 44,
      "name": "TFJ_Bone_Block"
    },
    {
      "x": 6,
      "y": 21,
      "z": 45,
      "name": "TFJ_Bone_Block"
    },
    {
      "x": 7,
      "y": 26,
      "z": 37,
      "name": "TFJ_Bone_Block"
    },
    {
      "x": 7,
      "y": 27,
      "z": 37,
      "name": "TFJ_Bone_Block"
    },
    {
      "x": 7,
      "y": 28,
      "z": 37,
      "name": "TFJ_Bone_Block"
    },
    {
      "x": 7,
      "y": 18,
      "z": 38,
      "name": "TFJ_Bone_Block"
    },
    {
      "x": 7,
      "y": 19,
      "z": 38,
      "name": "TFJ_Bone_Block"
    },
    {
      "x": 7,
      "y": 18,
      "z": 39,
      "name": "TFJ_Bone_Block"
    },
    {
      "x": 7,
      "y": 19,
      "z": 39,
      "name": "TFJ_Bone_Block"
    },
    {
      "x": 7,
      "y": 18,
      "z": 40,
      "name": "TFJ_Bone_Block"
    },
    {
      "x": 7,
      "y": 20,
      "z": 42,
      "name": "TFJ_Bone_Block"
    },
    {
      "x": 7,
      "y": 20,
      "z": 43,
      "name": "TFJ_Bone_Block"
    },
    {
      "x": 7,
      "y": 20,
      "z": 44,
      "name": "TFJ_Bone_Block"
    },
    {
      "x": 8,
      "y": 28,
      "z": 38,
      "name": "TFJ_Bone_Block"
    },
    {
      "x": 8,
      "y": 29,
      "z": 38,
      "name": "TFJ_Bone_Block"
    },
    {
      "x": 8,
      "y": 18,
      "z": 39,
      "name": "TFJ_Bone_Block"
    },
    {
      "x": 8,
      "y": 19,
      "z": 39,
      "name": "TFJ_Bone_Block"
    },
    {
      "x": 8,
      "y": 17,
      "z": 40,
      "name": "TFJ_Bone_Block"
    },
    {
      "x": 8,
      "y": 18,
      "z": 40,
      "name": "TFJ_Bone_Block"
    },
    {
      "x": 8,
      "y": 19,
      "z": 40,
      "name": "TFJ_Bone_Block"
    },
    {
      "x": 8,
      "y": 18,
      "z": 41,
      "name": "TFJ_Bone_Block"
    },
    {
      "x": 8,
      "y": 19,
      "z": 41,
      "name": "TFJ_Bone_Block"
    },
    {
      "x": 8,
      "y": 19,
      "z": 42,
      "name": "TFJ_Bone_Block"
    },
    {
      "x": 8,
      "y": 20,
      "z": 43,
      "name": "TFJ_Bone_Block"
    },
    {
      "x": 9,
      "y": 19,
      "z": 31,
      "name": "TFJ_Bone_Block"
    },
    {
      "x": 9,
      "y": 20,
      "z": 31,
      "name": "TFJ_Bone_Block"
    },
    {
      "x": 9,
      "y": 21,
      "z": 31,
      "name": "TFJ_Bone_Block"
    },
    {
      "x": 9,
      "y": 22,
      "z": 31,
      "name": "TFJ_Bone_Block"
    },
    {
      "x": 9,
      "y": 18,
      "z": 38,
      "name": "TFJ_Bone_Block"
    },
    {
      "x": 9,
      "y": 18,
      "z": 39,
      "name": "TFJ_Bone_Block"
    },
    {
      "x": 9,
      "y": 17,
      "z": 40,
      "name": "TFJ_Bone_Block"
    },
    {
      "x": 9,
      "y": 18,
      "z": 40,
      "name": "TFJ_Bone_Block"
    },
    {
      "x": 9,
      "y": 19,
      "z": 40,
      "name": "TFJ_Bone_Block"
    },
    {
      "x": 9,
      "y": 16,
      "z": 41,
      "name": "TFJ_Bone_Block"
    },
    {
      "x": 9,
      "y": 17,
      "z": 41,
      "name": "TFJ_Bone_Block"
    },
    {
      "x": 9,
      "y": 18,
      "z": 41,
      "name": "TFJ_Bone_Block"
    },
    {
      "x": 9,
      "y": 19,
      "z": 41,
      "name": "TFJ_Bone_Block"
    },
    {
      "x": 9,
      "y": 18,
      "z": 42,
      "name": "TFJ_Bone_Block"
    },
    {
      "x": 9,
      "y": 19,
      "z": 42,
      "name": "TFJ_Bone_Block"
    },
    {
      "x": 10,
      "y": 22,
      "z": 30,
      "name": "TFJ_Bone_Block"
    },
    {
      "x": 10,
      "y": 23,
      "z": 30,
      "name": "TFJ_Bone_Block"
    },
    {
      "x": 10,
      "y": 24,
      "z": 30,
      "name": "TFJ_Bone_Block"
    },
    {
      "x": 10,
      "y": 25,
      "z": 30,
      "name": "TFJ_Bone_Block"
    },
    {
      "x": 10,
      "y": 26,
      "z": 30,
      "name": "TFJ_Bone_Block"
    },
    {
      "x": 10,
      "y": 17,
      "z": 32,
      "name": "TFJ_Bone_Block"
    },
    {
      "x": 10,
      "y": 18,
      "z": 32,
      "name": "TFJ_Bone_Block"
    },
    {
      "x": 10,
      "y": 19,
      "z": 32,
      "name": "TFJ_Bone_Block"
    },
    {
      "x": 10,
      "y": 17,
      "z": 33,
      "name": "TFJ_Bone_Block"
    },
    {
      "x": 10,
      "y": 17,
      "z": 39,
      "name": "TFJ_Bone_Block"
    },
    {
      "x": 10,
      "y": 15,
      "z": 40,
      "name": "TFJ_Bone_Block"
    },
    {
      "x": 10,
      "y": 16,
      "z": 40,
      "name": "TFJ_Bone_Block"
    },
    {
      "x": 10,
      "y": 17,
      "z": 40,
      "name": "TFJ_Bone_Block"
    },
    {
      "x": 10,
      "y": 18,
      "z": 40,
      "name": "TFJ_Bone_Block"
    },
    {
      "x": 10,
      "y": 17,
      "z": 41,
      "name": "TFJ_Bone_Block"
    },
    {
      "x": 10,
      "y": 18,
      "z": 41,
      "name": "TFJ_Bone_Block"
    },
    {
      "x": 10,
      "y": 19,
      "z": 41,
      "name": "TFJ_Bone_Block"
    },
    {
      "x": 10,
      "y": 17,
      "z": 42,
      "name": "TFJ_Bone_Block"
    },
    {
      "x": 10,
      "y": 18,
      "z": 42,
      "name": "TFJ_Bone_Block"
    },
    {
      "x": 10,
      "y": 19,
      "z": 42,
      "name": "TFJ_Bone_Block"
    },
    {
      "x": 10,
      "y": 18,
      "z": 43,
      "name": "TFJ_Bone_Block"
    },
    {
      "x": 11,
      "y": 26,
      "z": 30,
      "name": "TFJ_Bone_Block"
    },
    {
      "x": 11,
      "y": 27,
      "z": 30,
      "name": "TFJ_Bone_Block"
    },
    {
      "x": 11,
      "y": 17,
      "z": 32,
      "name": "TFJ_Bone_Block"
    },
    {
      "x": 11,
      "y": 16,
      "z": 33,
      "name": "TFJ_Bone_Block"
    },
    {
      "x": 11,
      "y": 17,
      "z": 33,
      "name": "TFJ_Bone_Block"
    },
    {
      "x": 11,
      "y": 16,
      "z": 34,
      "name": "TFJ_Bone_Block"
    },
    {
      "x": 11,
      "y": 16,
      "z": 38,
      "name": "TFJ_Bone_Block"
    },
    {
      "x": 11,
      "y": 16,
      "z": 39,
      "name": "TFJ_Bone_Block"
    },
    {
      "x": 11,
      "y": 17,
      "z": 40,
      "name": "TFJ_Bone_Block"
    },
    {
      "x": 11,
      "y": 18,
      "z": 41,
      "name": "TFJ_Bone_Block"
    },
    {
      "x": 11,
      "y": 18,
      "z": 42,
      "name": "TFJ_Bone_Block"
    },
    {
      "x": 11,
      "y": 19,
      "z": 42,
      "name": "TFJ_Bone_Block"
    },
    {
      "x": 11,
      "y": 18,
      "z": 43,
      "name": "TFJ_Bone_Block"
    },
    {
      "x": 11,
      "y": 19,
      "z": 43,
      "name": "TFJ_Bone_Block"
    },
    {
      "x": 11,
      "y": 18,
      "z": 44,
      "name": "TFJ_Bone_Block"
    },
    {
      "x": 11,
      "y": 19,
      "z": 44,
      "name": "TFJ_Bone_Block"
    },
    {
      "x": 12,
      "y": 16,
      "z": 33,
      "name": "TFJ_Bone_Block"
    },
    {
      "x": 12,
      "y": 15,
      "z": 34,
      "name": "TFJ_Bone_Block"
    },
    {
      "x": 12,
      "y": 16,
      "z": 34,
      "name": "TFJ_Bone_Block"
    },
    {
      "x": 12,
      "y": 15,
      "z": 35,
      "name": "TFJ_Bone_Block"
    },
    {
      "x": 12,
      "y": 16,
      "z": 35,
      "name": "TFJ_Bone_Block"
    },
    {
      "x": 12,
      "y": 15,
      "z": 37,
      "name": "TFJ_Bone_Block"
    },
    {
      "x": 12,
      "y": 15,
      "z": 38,
      "name": "TFJ_Bone_Block"
    },
    {
      "x": 12,
      "y": 16,
      "z": 39,
      "name": "TFJ_Bone_Block"
    },
    {
      "x": 12,
      "y": 18,
      "z": 41,
      "name": "TFJ_Bone_Block"
    },
    {
      "x": 12,
      "y": 18,
      "z": 43,
      "name": "TFJ_Bone_Block"
    },
    {
      "x": 12,
      "y": 19,
      "z": 43,
      "name": "TFJ_Bone_Block"
    },
    {
      "x": 12,
      "y": 19,
      "z": 44,
      "name": "TFJ_Bone_Block"
    },
    {
      "x": 12,
      "y": 20,
      "z": 44,
      "name": "TFJ_Bone_Block"
    },
    {
      "x": 13,
      "y": 15,
      "z": 34,
      "name": "TFJ_Bone_Block"
    },
    {
      "x": 13,
      "y": 15,
      "z": 35,
      "name": "TFJ_Bone_Block"
    },
    {
      "x": 13,
      "y": 16,
      "z": 35,
      "name": "TFJ_Bone_Block"
    },
    {
      "x": 13,
      "y": 14,
      "z": 36,
      "name": "TFJ_Bone_Block"
    },
    {
      "x": 13,
      "y": 15,
      "z": 36,
      "name": "TFJ_Bone_Block"
    },
    {
      "x": 13,
      "y": 16,
      "z": 36,
      "name": "TFJ_Bone_Block"
    },
    {
      "x": 13,
      "y": 15,
      "z": 37,
      "name": "TFJ_Bone_Block"
    },
    {
      "x": 13,
      "y": 16,
      "z": 37,
      "name": "TFJ_Bone_Block"
    },
    {
      "x": 13,
      "y": 15,
      "z": 38,
      "name": "TFJ_Bone_Block"
    },
    {
      "x": 13,
      "y": 20,
      "z": 44,
      "name": "TFJ_Bone_Block"
    },
    {
      "x": 13,
      "y": 21,
      "z": 44,
      "name": "TFJ_Bone_Block"
    },
    {
      "x": 13,
      "y": 22,
      "z": 44,
      "name": "TFJ_Bone_Block"
    },
    {
      "x": 14,
      "y": 19,
      "z": 25,
      "name": "TFJ_Bone_Block"
    },
    {
      "x": 14,
      "y": 20,
      "z": 25,
      "name": "TFJ_Bone_Block"
    },
    {
      "x": 14,
      "y": 21,
      "z": 25,
      "name": "TFJ_Bone_Block"
    },
    {
      "x": 14,
      "y": 17,
      "z": 26,
      "name": "TFJ_Bone_Block"
    },
    {
      "x": 14,
      "y": 18,
      "z": 26,
      "name": "TFJ_Bone_Block"
    },
    {
      "x": 14,
      "y": 14,
      "z": 33,
      "name": "TFJ_Bone_Block"
    },
    {
      "x": 14,
      "y": 14,
      "z": 34,
      "name": "TFJ_Bone_Block"
    },
    {
      "x": 14,
      "y": 13,
      "z": 35,
      "name": "TFJ_Bone_Block"
    },
    {
      "x": 14,
      "y": 14,
      "z": 35,
      "name": "TFJ_Bone_Block"
    },
    {
      "x": 14,
      "y": 15,
      "z": 35,
      "name": "TFJ_Bone_Block"
    },
    {
      "x": 14,
      "y": 12,
      "z": 36,
      "name": "TFJ_Bone_Block"
    },
    {
      "x": 14,
      "y": 13,
      "z": 36,
      "name": "TFJ_Bone_Block"
    },
    {
      "x": 14,
      "y": 14,
      "z": 36,
      "name": "TFJ_Bone_Block"
    },
    {
      "x": 14,
      "y": 15,
      "z": 36,
      "name": "TFJ_Bone_Block"
    },
    {
      "x": 14,
      "y": 16,
      "z": 36,
      "name": "TFJ_Bone_Block"
    },
    {
      "x": 14,
      "y": 14,
      "z": 37,
      "name": "TFJ_Bone_Block"
    },
    {
      "x": 14,
      "y": 15,
      "z": 37,
      "name": "TFJ_Bone_Block"
    },
    {
      "x": 14,
      "y": 16,
      "z": 37,
      "name": "TFJ_Bone_Block"
    },
    {
      "x": 15,
      "y": 21,
      "z": 24,
      "name": "TFJ_Bone_Block"
    },
    {
      "x": 15,
      "y": 22,
      "z": 24,
      "name": "TFJ_Bone_Block"
    },
    {
      "x": 15,
      "y": 23,
      "z": 24,
      "name": "TFJ_Bone_Block"
    },
    {
      "x": 15,
      "y": 24,
      "z": 24,
      "name": "TFJ_Bone_Block"
    },
    {
      "x": 15,
      "y": 25,
      "z": 24,
      "name": "TFJ_Bone_Block"
    },
    {
      "x": 15,
      "y": 15,
      "z": 27,
      "name": "TFJ_Bone_Block"
    },
    {
      "x": 15,
      "y": 16,
      "z": 27,
      "name": "TFJ_Bone_Block"
    },
    {
      "x": 15,
      "y": 17,
      "z": 27,
      "name": "TFJ_Bone_Block"
    },
    {
      "x": 15,
      "y": 14,
      "z": 28,
      "name": "TFJ_Bone_Block"
    },
    {
      "x": 15,
      "y": 15,
      "z": 28,
      "name": "TFJ_Bone_Block"
    },
    {
      "x": 15,
      "y": 14,
      "z": 29,
      "name": "TFJ_Bone_Block"
    },
    {
      "x": 15,
      "y": 13,
      "z": 34,
      "name": "TFJ_Bone_Block"
    },
    {
      "x": 15,
      "y": 11,
      "z": 35,
      "name": "TFJ_Bone_Block"
    },
    {
      "x": 15,
      "y": 12,
      "z": 35,
      "name": "TFJ_Bone_Block"
    },
    {
      "x": 15,
      "y": 13,
      "z": 35,
      "name": "TFJ_Bone_Block"
    },
    {
      "x": 15,
      "y": 14,
      "z": 35,
      "name": "TFJ_Bone_Block"
    },
    {
      "x": 15,
      "y": 13,
      "z": 36,
      "name": "TFJ_Bone_Block"
    },
    {
      "x": 15,
      "y": 14,
      "z": 36,
      "name": "TFJ_Bone_Block"
    },
    {
      "x": 15,
      "y": 15,
      "z": 36,
      "name": "TFJ_Bone_Block"
    },
    {
      "x": 15,
      "y": 15,
      "z": 37,
      "name": "TFJ_Bone_Block"
    },
    {
      "x": 15,
      "y": 16,
      "z": 37,
      "name": "TFJ_Bone_Block"
    },
    {
      "x": 15,
      "y": 15,
      "z": 38,
      "name": "TFJ_Bone_Block"
    },
    {
      "x": 15,
      "y": 16,
      "z": 38,
      "name": "TFJ_Bone_Block"
    },
    {
      "x": 16,
      "y": 25,
      "z": 25,
      "name": "TFJ_Bone_Block"
    },
    {
      "x": 16,
      "y": 26,
      "z": 25,
      "name": "TFJ_Bone_Block"
    },
    {
      "x": 16,
      "y": 27,
      "z": 25,
      "name": "TFJ_Bone_Block"
    },
    {
      "x": 16,
      "y": 14,
      "z": 28,
      "name": "TFJ_Bone_Block"
    },
    {
      "x": 16,
      "y": 13,
      "z": 29,
      "name": "TFJ_Bone_Block"
    },
    {
      "x": 16,
      "y": 14,
      "z": 29,
      "name": "TFJ_Bone_Block"
    },
    {
      "x": 16,
      "y": 14,
      "z": 30,
      "name": "TFJ_Bone_Block"
    },
    {
      "x": 16,
      "y": 13,
      "z": 33,
      "name": "TFJ_Bone_Block"
    },
    {
      "x": 16,
      "y": 13,
      "z": 34,
      "name": "TFJ_Bone_Block"
    },
    {
      "x": 16,
      "y": 13,
      "z": 35,
      "name": "TFJ_Bone_Block"
    },
    {
      "x": 16,
      "y": 14,
      "z": 36,
      "name": "TFJ_Bone_Block"
    },
    {
      "x": 16,
      "y": 15,
      "z": 37,
      "name": "TFJ_Bone_Block"
    },
    {
      "x": 16,
      "y": 16,
      "z": 37,
      "name": "TFJ_Bone_Block"
    },
    {
      "x": 16,
      "y": 15,
      "z": 38,
      "name": "TFJ_Bone_Block"
    },
    {
      "x": 16,
      "y": 16,
      "z": 38,
      "name": "TFJ_Bone_Block"
    },
    {
      "x": 16,
      "y": 16,
      "z": 39,
      "name": "TFJ_Bone_Block"
    },
    {
      "x": 17,
      "y": 27,
      "z": 26,
      "name": "TFJ_Bone_Block"
    },
    {
      "x": 17,
      "y": 28,
      "z": 26,
      "name": "TFJ_Bone_Block"
    },
    {
      "x": 17,
      "y": 14,
      "z": 29,
      "name": "TFJ_Bone_Block"
    },
    {
      "x": 17,
      "y": 13,
      "z": 30,
      "name": "TFJ_Bone_Block"
    },
    {
      "x": 17,
      "y": 14,
      "z": 30,
      "name": "TFJ_Bone_Block"
    },
    {
      "x": 17,
      "y": 13,
      "z": 31,
      "name": "TFJ_Bone_Block"
    },
    {
      "x": 17,
      "y": 12,
      "z": 32,
      "name": "TFJ_Bone_Block"
    },
    {
      "x": 17,
      "y": 13,
      "z": 32,
      "name": "TFJ_Bone_Block"
    },
    {
      "x": 17,
      "y": 14,
      "z": 32,
      "name": "TFJ_Bone_Block"
    },
    {
      "x": 17,
      "y": 13,
      "z": 33,
      "name": "TFJ_Bone_Block"
    },
    {
      "x": 17,
      "y": 13,
      "z": 34,
      "name": "TFJ_Bone_Block"
    },
    {
      "x": 17,
      "y": 14,
      "z": 36,
      "name": "TFJ_Bone_Block"
    },
    {
      "x": 17,
      "y": 16,
      "z": 38,
      "name": "TFJ_Bone_Block"
    },
    {
      "x": 17,
      "y": 16,
      "z": 39,
      "name": "TFJ_Bone_Block"
    },
    {
      "x": 17,
      "y": 17,
      "z": 39,
      "name": "TFJ_Bone_Block"
    },
    {
      "x": 17,
      "y": 17,
      "z": 40,
      "name": "TFJ_Bone_Block"
    },
    {
      "x": 18,
      "y": 17,
      "z": 22,
      "name": "TFJ_Bone_Block"
    },
    {
      "x": 18,
      "y": 18,
      "z": 22,
      "name": "TFJ_Bone_Block"
    },
    {
      "x": 18,
      "y": 19,
      "z": 22,
      "name": "TFJ_Bone_Block"
    },
    {
      "x": 18,
      "y": 20,
      "z": 22,
      "name": "TFJ_Bone_Block"
    },
    {
      "x": 18,
      "y": 13,
      "z": 29,
      "name": "TFJ_Bone_Block"
    },
    {
      "x": 18,
      "y": 13,
      "z": 30,
      "name": "TFJ_Bone_Block"
    },
    {
      "x": 18,
      "y": 12,
      "z": 31,
      "name": "TFJ_Bone_Block"
    },
    {
      "x": 18,
      "y": 13,
      "z": 31,
      "name": "TFJ_Bone_Block"
    },
    {
      "x": 18,
      "y": 14,
      "z": 31,
      "name": "TFJ_Bone_Block"
    },
    {
      "x": 18,
      "y": 11,
      "z": 32,
      "name": "TFJ_Bone_Block"
    },
    {
      "x": 18,
      "y": 12,
      "z": 32,
      "name": "TFJ_Bone_Block"
    },
    {
      "x": 18,
      "y": 13,
      "z": 32,
      "name": "TFJ_Bone_Block"
    },
    {
      "x": 18,
      "y": 14,
      "z": 32,
      "name": "TFJ_Bone_Block"
    },
    {
      "x": 18,
      "y": 12,
      "z": 33,
      "name": "TFJ_Bone_Block"
    },
    {
      "x": 18,
      "y": 13,
      "z": 33,
      "name": "TFJ_Bone_Block"
    },
    {
      "x": 18,
      "y": 14,
      "z": 33,
      "name": "TFJ_Bone_Block"
    },
    {
      "x": 18,
      "y": 17,
      "z": 39,
      "name": "TFJ_Bone_Block"
    },
    {
      "x": 18,
      "y": 17,
      "z": 40,
      "name": "TFJ_Bone_Block"
    },
    {
      "x": 18,
      "y": 18,
      "z": 40,
      "name": "TFJ_Bone_Block"
    },
    {
      "x": 18,
      "y": 19,
      "z": 40,
      "name": "TFJ_Bone_Block"
    },
    {
      "x": 19,
      "y": 15,
      "z": 23,
      "name": "TFJ_Bone_Block"
    },
    {
      "x": 19,
      "y": 16,
      "z": 23,
      "name": "TFJ_Bone_Block"
    },
    {
      "x": 19,
      "y": 17,
      "z": 23,
      "name": "TFJ_Bone_Block"
    },
    {
      "x": 19,
      "y": 12,
      "z": 30,
      "name": "TFJ_Bone_Block"
    },
    {
      "x": 19,
      "y": 10,
      "z": 31,
      "name": "TFJ_Bone_Block"
    },
    {
      "x": 19,
      "y": 11,
      "z": 31,
      "name": "TFJ_Bone_Block"
    },
    {
      "x": 19,
      "y": 12,
      "z": 31,
      "name": "TFJ_Bone_Block"
    },
    {
      "x": 19,
      "y": 13,
      "z": 31,
      "name": "TFJ_Bone_Block"
    },
    {
      "x": 19,
      "y": 14,
      "z": 31,
      "name": "TFJ_Bone_Block"
    },
    {
      "x": 19,
      "y": 12,
      "z": 32,
      "name": "TFJ_Bone_Block"
    },
    {
      "x": 19,
      "y": 13,
      "z": 32,
      "name": "TFJ_Bone_Block"
    },
    {
      "x": 19,
      "y": 14,
      "z": 32,
      "name": "TFJ_Bone_Block"
    },
    {
      "x": 19,
      "y": 13,
      "z": 33,
      "name": "TFJ_Bone_Block"
    },
    {
      "x": 19,
      "y": 19,
      "z": 41,
      "name": "TFJ_Bone_Block"
    },
    {
      "x": 19,
      "y": 20,
      "z": 41,
      "name": "TFJ_Bone_Block"
    },
    {
      "x": 19,
      "y": 21,
      "z": 41,
      "name": "TFJ_Bone_Block"
    },
    {
      "x": 19,
      "y": 22,
      "z": 41,
      "name": "TFJ_Bone_Block"
    },
    {
      "x": 20,
      "y": 13,
      "z": 24,
      "name": "TFJ_Bone_Block"
    },
    {
      "x": 20,
      "y": 14,
      "z": 24,
      "name": "TFJ_Bone_Block"
    },
    {
      "x": 20,
      "y": 15,
      "z": 24,
      "name": "TFJ_Bone_Block"
    },
    {
      "x": 20,
      "y": 13,
      "z": 25,
      "name": "TFJ_Bone_Block"
    },
    {
      "x": 20,
      "y": 12,
      "z": 29,
      "name": "TFJ_Bone_Block"
    },
    {
      "x": 20,
      "y": 12,
      "z": 30,
      "name": "TFJ_Bone_Block"
    },
    {
      "x": 20,
      "y": 12,
      "z": 31,
      "name": "TFJ_Bone_Block"
    },
    {
      "x": 20,
      "y": 13,
      "z": 32,
      "name": "TFJ_Bone_Block"
    },
    {
      "x": 20,
      "y": 13,
      "z": 33,
      "name": "TFJ_Bone_Block"
    },
    {
      "x": 20,
      "y": 14,
      "z": 33,
      "name": "TFJ_Bone_Block"
    },
    {
      "x": 20,
      "y": 14,
      "z": 34,
      "name": "TFJ_Bone_Block"
    },
    {
      "x": 20,
      "y": 26,
      "z": 39,
      "name": "TFJ_Bone_Block"
    },
    {
      "x": 20,
      "y": 22,
      "z": 40,
      "name": "TFJ_Bone_Block"
    },
    {
      "x": 20,
      "y": 23,
      "z": 40,
      "name": "TFJ_Bone_Block"
    },
    {
      "x": 20,
      "y": 24,
      "z": 40,
      "name": "TFJ_Bone_Block"
    },
    {
      "x": 20,
      "y": 25,
      "z": 40,
      "name": "TFJ_Bone_Block"
    },
    {
      "x": 20,
      "y": 26,
      "z": 40,
      "name": "TFJ_Bone_Block"
    },
    {
      "x": 21,
      "y": 13,
      "z": 24,
      "name": "TFJ_Bone_Block"
    },
    {
      "x": 21,
      "y": 12,
      "z": 25,
      "name": "TFJ_Bone_Block"
    },
    {
      "x": 21,
      "y": 13,
      "z": 25,
      "name": "TFJ_Bone_Block"
    },
    {
      "x": 21,
      "y": 14,
      "z": 25,
      "name": "TFJ_Bone_Block"
    },
    {
      "x": 21,
      "y": 12,
      "z": 26,
      "name": "TFJ_Bone_Block"
    },
    {
      "x": 21,
      "y": 13,
      "z": 26,
      "name": "TFJ_Bone_Block"
    },
    {
      "x": 21,
      "y": 12,
      "z": 27,
      "name": "TFJ_Bone_Block"
    },
    {
      "x": 21,
      "y": 11,
      "z": 28,
      "name": "TFJ_Bone_Block"
    },
    {
      "x": 21,
      "y": 12,
      "z": 28,
      "name": "TFJ_Bone_Block"
    },
    {
      "x": 21,
      "y": 12,
      "z": 29,
      "name": "TFJ_Bone_Block"
    },
    {
      "x": 21,
      "y": 12,
      "z": 30,
      "name": "TFJ_Bone_Block"
    },
    {
      "x": 21,
      "y": 13,
      "z": 32,
      "name": "TFJ_Bone_Block"
    },
    {
      "x": 21,
      "y": 14,
      "z": 33,
      "name": "TFJ_Bone_Block"
    },
    {
      "x": 21,
      "y": 13,
      "z": 34,
      "name": "TFJ_Bone_Block"
    },
    {
      "x": 21,
      "y": 14,
      "z": 34,
      "name": "TFJ_Bone_Block"
    },
    {
      "x": 21,
      "y": 14,
      "z": 35,
      "name": "TFJ_Bone_Block"
    },
    {
      "x": 22,
      "y": 17,
      "z": 20,
      "name": "TFJ_Bone_Block"
    },
    {
      "x": 22,
      "y": 18,
      "z": 20,
      "name": "TFJ_Bone_Block"
    },
    {
      "x": 22,
      "y": 19,
      "z": 20,
      "name": "TFJ_Bone_Block"
    },
    {
      "x": 22,
      "y": 20,
      "z": 20,
      "name": "TFJ_Bone_Block"
    },
    {
      "x": 22,
      "y": 12,
      "z": 25,
      "name": "TFJ_Bone_Block"
    },
    {
      "x": 22,
      "y": 13,
      "z": 25,
      "name": "TFJ_Bone_Block"
    },
    {
      "x": 22,
      "y": 12,
      "z": 26,
      "name": "TFJ_Bone_Block"
    },
    {
      "x": 22,
      "y": 13,
      "z": 26,
      "name": "TFJ_Bone_Block"
    },
    {
      "x": 22,
      "y": 11,
      "z": 27,
      "name": "TFJ_Bone_Block"
    },
    {
      "x": 22,
      "y": 12,
      "z": 27,
      "name": "TFJ_Bone_Block"
    },
    {
      "x": 22,
      "y": 13,
      "z": 27,
      "name": "TFJ_Bone_Block"
    },
    {
      "x": 22,
      "y": 10,
      "z": 28,
      "name": "TFJ_Bone_Block"
    },
    {
      "x": 22,
      "y": 11,
      "z": 28,
      "name": "TFJ_Bone_Block"
    },
    {
      "x": 22,
      "y": 12,
      "z": 28,
      "name": "TFJ_Bone_Block"
    },
    {
      "x": 22,
      "y": 13,
      "z": 28,
      "name": "TFJ_Bone_Block"
    },
    {
      "x": 22,
      "y": 11,
      "z": 29,
      "name": "TFJ_Bone_Block"
    },
    {
      "x": 22,
      "y": 12,
      "z": 29,
      "name": "TFJ_Bone_Block"
    },
    {
      "x": 22,
      "y": 14,
      "z": 34,
      "name": "TFJ_Bone_Block"
    },
    {
      "x": 22,
      "y": 14,
      "z": 35,
      "name": "TFJ_Bone_Block"
    },
    {
      "x": 22,
      "y": 15,
      "z": 35,
      "name": "TFJ_Bone_Block"
    },
    {
      "x": 23,
      "y": 15,
      "z": 20,
      "name": "TFJ_Bone_Block"
    },
    {
      "x": 23,
      "y": 16,
      "z": 20,
      "name": "TFJ_Bone_Block"
    },
    {
      "x": 23,
      "y": 17,
      "z": 20,
      "name": "TFJ_Bone_Block"
    },
    {
      "x": 23,
      "y": 20,
      "z": 21,
      "name": "TFJ_Bone_Block"
    },
    {
      "x": 23,
      "y": 21,
      "z": 21,
      "name": "TFJ_Bone_Block"
    },
    {
      "x": 23,
      "y": 11,
      "z": 26,
      "name": "TFJ_Bone_Block"
    },
    {
      "x": 23,
      "y": 12,
      "z": 26,
      "name": "TFJ_Bone_Block"
    },
    {
      "x": 23,
      "y": 13,
      "z": 26,
      "name": "TFJ_Bone_Block"
    },
    {
      "x": 23,
      "y": 9,
      "z": 27,
      "name": "TFJ_Bone_Block"
    },
    {
      "x": 23,
      "y": 10,
      "z": 27,
      "name": "TFJ_Bone_Block"
    },
    {
      "x": 23,
      "y": 11,
      "z": 27,
      "name": "TFJ_Bone_Block"
    },
    {
      "x": 23,
      "y": 12,
      "z": 27,
      "name": "TFJ_Bone_Block"
    },
    {
      "x": 23,
      "y": 13,
      "z": 27,
      "name": "TFJ_Bone_Block"
    },
    {
      "x": 23,
      "y": 11,
      "z": 28,
      "name": "TFJ_Bone_Block"
    },
    {
      "x": 23,
      "y": 12,
      "z": 28,
      "name": "TFJ_Bone_Block"
    },
    {
      "x": 23,
      "y": 13,
      "z": 28,
      "name": "TFJ_Bone_Block"
    },
    {
      "x": 23,
      "y": 12,
      "z": 29,
      "name": "TFJ_Bone_Block"
    },
    {
      "x": 23,
      "y": 15,
      "z": 35,
      "name": "TFJ_Bone_Block"
    },
    {
      "x": 23,
      "y": 16,
      "z": 35,
      "name": "TFJ_Bone_Block"
    },
    {
      "x": 23,
      "y": 17,
      "z": 35,
      "name": "TFJ_Bone_Block"
    },
    {
      "x": 24,
      "y": 13,
      "z": 20,
      "name": "TFJ_Bone_Block"
    },
    {
      "x": 24,
      "y": 14,
      "z": 20,
      "name": "TFJ_Bone_Block"
    },
    {
      "x": 24,
      "y": 15,
      "z": 20,
      "name": "TFJ_Bone_Block"
    },
    {
      "x": 24,
      "y": 13,
      "z": 21,
      "name": "TFJ_Bone_Block"
    },
    {
      "x": 24,
      "y": 12,
      "z": 25,
      "name": "TFJ_Bone_Block"
    },
    {
      "x": 24,
      "y": 12,
      "z": 26,
      "name": "TFJ_Bone_Block"
    },
    {
      "x": 24,
      "y": 11,
      "z": 27,
      "name": "TFJ_Bone_Block"
    },
    {
      "x": 24,
      "y": 12,
      "z": 27,
      "name": "TFJ_Bone_Block"
    },
    {
      "x": 24,
      "y": 13,
      "z": 27,
      "name": "TFJ_Bone_Block"
    },
    {
      "x": 24,
      "y": 12,
      "z": 28,
      "name": "TFJ_Bone_Block"
    },
    {
      "x": 24,
      "y": 13,
      "z": 28,
      "name": "TFJ_Bone_Block"
    },
    {
      "x": 24,
      "y": 12,
      "z": 29,
      "name": "TFJ_Bone_Block"
    },
    {
      "x": 24,
      "y": 13,
      "z": 29,
      "name": "TFJ_Bone_Block"
    },
    {
      "x": 24,
      "y": 27,
      "z": 33,
      "name": "TFJ_Bone_Block"
    },
    {
      "x": 24,
      "y": 28,
      "z": 33,
      "name": "TFJ_Bone_Block"
    },
    {
      "x": 24,
      "y": 17,
      "z": 36,
      "name": "TFJ_Bone_Block"
    },
    {
      "x": 24,
      "y": 18,
      "z": 36,
      "name": "TFJ_Bone_Block"
    },
    {
      "x": 25,
      "y": 13,
      "z": 20,
      "name": "TFJ_Bone_Block"
    },
    {
      "x": 25,
      "y": 12,
      "z": 21,
      "name": "TFJ_Bone_Block"
    },
    {
      "x": 25,
      "y": 13,
      "z": 21,
      "name": "TFJ_Bone_Block"
    },
    {
      "x": 25,
      "y": 14,
      "z": 21,
      "name": "TFJ_Bone_Block"
    },
    {
      "x": 25,
      "y": 12,
      "z": 22,
      "name": "TFJ_Bone_Block"
    },
    {
      "x": 25,
      "y": 13,
      "z": 22,
      "name": "TFJ_Bone_Block"
    },
    {
      "x": 25,
      "y": 12,
      "z": 23,
      "name": "TFJ_Bone_Block"
    },
    {
      "x": 25,
      "y": 13,
      "z": 23,
      "name": "TFJ_Bone_Block"
    },
    {
      "x": 25,
      "y": 11,
      "z": 24,
      "name": "TFJ_Bone_Block"
    },
    {
      "x": 25,
      "y": 12,
      "z": 24,
      "name": "TFJ_Bone_Block"
    },
    {
      "x": 25,
      "y": 12,
      "z": 25,
      "name": "TFJ_Bone_Block"
    },
    {
      "x": 25,
      "y": 12,
      "z": 26,
      "name": "TFJ_Bone_Block"
    },
    {
      "x": 25,
      "y": 12,
      "z": 28,
      "name": "TFJ_Bone_Block"
    },
    {
      "x": 25,
      "y": 13,
      "z": 28,
      "name": "TFJ_Bone_Block"
    },
    {
      "x": 25,
      "y": 12,
      "z": 29,
      "name": "TFJ_Bone_Block"
    },
    {
      "x": 25,
      "y": 13,
      "z": 29,
      "name": "TFJ_Bone_Block"
    },
    {
      "x": 25,
      "y": 14,
      "z": 29,
      "name": "TFJ_Bone_Block"
    },
    {
      "x": 25,
      "y": 13,
      "z": 30,
      "name": "TFJ_Bone_Block"
    },
    {
      "x": 25,
      "y": 25,
      "z": 34,
      "name": "TFJ_Bone_Block"
    },
    {
      "x": 25,
      "y": 26,
      "z": 34,
      "name": "TFJ_Bone_Block"
    },
    {
      "x": 25,
      "y": 27,
      "z": 34,
      "name": "TFJ_Bone_Block"
    },
    {
      "x": 25,
      "y": 18,
      "z": 36,
      "name": "TFJ_Bone_Block"
    },
    {
      "x": 25,
      "y": 19,
      "z": 36,
      "name": "TFJ_Bone_Block"
    },
    {
      "x": 25,
      "y": 20,
      "z": 36,
      "name": "TFJ_Bone_Block"
    },
    {
      "x": 25,
      "y": 21,
      "z": 36,
      "name": "TFJ_Bone_Block"
    },
    {
      "x": 26,
      "y": 18,
      "z": 16,
      "name": "TFJ_Bone_Block"
    },
    {
      "x": 26,
      "y": 19,
      "z": 16,
      "name": "TFJ_Bone_Block"
    },
    {
      "x": 26,
      "y": 20,
      "z": 16,
      "name": "TFJ_Bone_Block"
    },
    {
      "x": 26,
      "y": 20,
      "z": 17,
      "name": "TFJ_Bone_Block"
    },
    {
      "x": 26,
      "y": 21,
      "z": 17,
      "name": "TFJ_Bone_Block"
    },
    {
      "x": 26,
      "y": 22,
      "z": 17,
      "name": "TFJ_Bone_Block"
    },
    {
      "x": 26,
      "y": 22,
      "z": 18,
      "name": "TFJ_Bone_Block"
    },
    {
      "x": 26,
      "y": 23,
      "z": 18,
      "name": "TFJ_Bone_Block"
    },
    {
      "x": 26,
      "y": 12,
      "z": 21,
      "name": "TFJ_Bone_Block"
    },
    {
      "x": 26,
      "y": 13,
      "z": 21,
      "name": "TFJ_Bone_Block"
    },
    {
      "x": 26,
      "y": 11,
      "z": 22,
      "name": "TFJ_Bone_Block"
    },
    {
      "x": 26,
      "y": 12,
      "z": 22,
      "name": "TFJ_Bone_Block"
    },
    {
      "x": 26,
      "y": 13,
      "z": 22,
      "name": "TFJ_Bone_Block"
    },
    {
      "x": 26,
      "y": 11,
      "z": 23,
      "name": "TFJ_Bone_Block"
    },
    {
      "x": 26,
      "y": 12,
      "z": 23,
      "name": "TFJ_Bone_Block"
    },
    {
      "x": 26,
      "y": 13,
      "z": 23,
      "name": "TFJ_Bone_Block"
    },
    {
      "x": 26,
      "y": 10,
      "z": 24,
      "name": "TFJ_Bone_Block"
    },
    {
      "x": 26,
      "y": 11,
      "z": 24,
      "name": "TFJ_Bone_Block"
    },
    {
      "x": 26,
      "y": 12,
      "z": 24,
      "name": "TFJ_Bone_Block"
    },
    {
      "x": 26,
      "y": 13,
      "z": 24,
      "name": "TFJ_Bone_Block"
    },
    {
      "x": 26,
      "y": 14,
      "z": 24,
      "name": "TFJ_Bone_Block"
    },
    {
      "x": 26,
      "y": 11,
      "z": 25,
      "name": "TFJ_Bone_Block"
    },
    {
      "x": 26,
      "y": 12,
      "z": 25,
      "name": "TFJ_Bone_Block"
    },
    {
      "x": 26,
      "y": 13,
      "z": 29,
      "name": "TFJ_Bone_Block"
    },
    {
      "x": 26,
      "y": 13,
      "z": 30,
      "name": "TFJ_Bone_Block"
    },
    {
      "x": 26,
      "y": 14,
      "z": 30,
      "name": "TFJ_Bone_Block"
    },
    {
      "x": 26,
      "y": 15,
      "z": 30,
      "name": "TFJ_Bone_Block"
    },
    {
      "x": 26,
      "y": 26,
      "z": 30,
      "name": "TFJ_Bone_Block"
    },
    {
      "x": 26,
      "y": 27,
      "z": 30,
      "name": "TFJ_Bone_Block"
    },
    {
      "x": 26,
      "y": 21,
      "z": 35,
      "name": "TFJ_Bone_Block"
    },
    {
      "x": 26,
      "y": 22,
      "z": 35,
      "name": "TFJ_Bone_Block"
    },
    {
      "x": 26,
      "y": 23,
      "z": 35,
      "name": "TFJ_Bone_Block"
    },
    {
      "x": 26,
      "y": 24,
      "z": 35,
      "name": "TFJ_Bone_Block"
    },
    {
      "x": 26,
      "y": 25,
      "z": 35,
      "name": "TFJ_Bone_Block"
    },
    {
      "x": 27,
      "y": 16,
      "z": 16,
      "name": "TFJ_Bone_Block"
    },
    {
      "x": 27,
      "y": 17,
      "z": 16,
      "name": "TFJ_Bone_Block"
    },
    {
      "x": 27,
      "y": 18,
      "z": 16,
      "name": "TFJ_Bone_Block"
    },
    {
      "x": 27,
      "y": 12,
      "z": 22,
      "name": "TFJ_Bone_Block"
    },
    {
      "x": 27,
      "y": 13,
      "z": 22,
      "name": "TFJ_Bone_Block"
    },
    {
      "x": 27,
      "y": 9,
      "z": 23,
      "name": "TFJ_Bone_Block"
    },
    {
      "x": 27,
      "y": 10,
      "z": 23,
      "name": "TFJ_Bone_Block"
    },
    {
      "x": 27,
      "y": 11,
      "z": 23,
      "name": "TFJ_Bone_Block"
    },
    {
      "x": 27,
      "y": 12,
      "z": 23,
      "name": "TFJ_Bone_Block"
    },
    {
      "x": 27,
      "y": 13,
      "z": 23,
      "name": "TFJ_Bone_Block"
    },
    {
      "x": 27,
      "y": 14,
      "z": 23,
      "name": "TFJ_Bone_Block"
    },
    {
      "x": 27,
      "y": 11,
      "z": 24,
      "name": "TFJ_Bone_Block"
    },
    {
      "x": 27,
      "y": 12,
      "z": 24,
      "name": "TFJ_Bone_Block"
    },
    {
      "x": 27,
      "y": 13,
      "z": 24,
      "name": "TFJ_Bone_Block"
    },
    {
      "x": 27,
      "y": 12,
      "z": 25,
      "name": "TFJ_Bone_Block"
    },
    {
      "x": 27,
      "y": 13,
      "z": 25,
      "name": "TFJ_Bone_Block"
    },
    {
      "x": 27,
      "y": 15,
      "z": 31,
      "name": "TFJ_Bone_Block"
    },
    {
      "x": 27,
      "y": 16,
      "z": 31,
      "name": "TFJ_Bone_Block"
    },
    {
      "x": 27,
      "y": 17,
      "z": 31,
      "name": "TFJ_Bone_Block"
    },
    {
      "x": 27,
      "y": 24,
      "z": 31,
      "name": "TFJ_Bone_Block"
    },
    {
      "x": 27,
      "y": 25,
      "z": 31,
      "name": "TFJ_Bone_Block"
    },
    {
      "x": 27,
      "y": 26,
      "z": 31,
      "name": "TFJ_Bone_Block"
    },
    {
      "x": 28,
      "y": 15,
      "z": 16,
      "name": "TFJ_Bone_Block"
    },
    {
      "x": 28,
      "y": 16,
      "z": 16,
      "name": "TFJ_Bone_Block"
    },
    {
      "x": 28,
      "y": 15,
      "z": 17,
      "name": "TFJ_Bone_Block"
    },
    {
      "x": 28,
      "y": 13,
      "z": 21,
      "name": "TFJ_Bone_Block"
    },
    {
      "x": 28,
      "y": 13,
      "z": 22,
      "name": "TFJ_Bone_Block"
    },
    {
      "x": 28,
      "y": 12,
      "z": 23,
      "name": "TFJ_Bone_Block"
    },
    {
      "x": 28,
      "y": 13,
      "z": 23,
      "name": "TFJ_Bone_Block"
    },
    {
      "x": 28,
      "y": 11,
      "z": 24,
      "name": "TFJ_Bone_Block"
    },
    {
      "x": 28,
      "y": 12,
      "z": 24,
      "name": "TFJ_Bone_Block"
    },
    {
      "x": 28,
      "y": 13,
      "z": 24,
      "name": "TFJ_Bone_Block"
    },
    {
      "x": 28,
      "y": 12,
      "z": 25,
      "name": "TFJ_Bone_Block"
    },
    {
      "x": 28,
      "y": 13,
      "z": 25,
      "name": "TFJ_Bone_Block"
    },
    {
      "x": 28,
      "y": 23,
      "z": 26,
      "name": "TFJ_Bone_Block"
    },
    {
      "x": 28,
      "y": 24,
      "z": 26,
      "name": "TFJ_Bone_Block"
    },
    {
      "x": 28,
      "y": 17,
      "z": 32,
      "name": "TFJ_Bone_Block"
    },
    {
      "x": 28,
      "y": 18,
      "z": 32,
      "name": "TFJ_Bone_Block"
    },
    {
      "x": 28,
      "y": 19,
      "z": 32,
      "name": "TFJ_Bone_Block"
    },
    {
      "x": 28,
      "y": 20,
      "z": 32,
      "name": "TFJ_Bone_Block"
    },
    {
      "x": 28,
      "y": 21,
      "z": 32,
      "name": "TFJ_Bone_Block"
    },
    {
      "x": 28,
      "y": 22,
      "z": 32,
      "name": "TFJ_Bone_Block"
    },
    {
      "x": 28,
      "y": 23,
      "z": 32,
      "name": "TFJ_Bone_Block"
    },
    {
      "x": 28,
      "y": 24,
      "z": 32,
      "name": "TFJ_Bone_Block"
    },
    {
      "x": 29,
      "y": 15,
      "z": 16,
      "name": "TFJ_Bone_Block"
    },
    {
      "x": 29,
      "y": 14,
      "z": 17,
      "name": "TFJ_Bone_Block"
    },
    {
      "x": 29,
      "y": 15,
      "z": 17,
      "name": "TFJ_Bone_Block"
    },
    {
      "x": 29,
      "y": 14,
      "z": 18,
      "name": "TFJ_Bone_Block"
    },
    {
      "x": 29,
      "y": 15,
      "z": 18,
      "name": "TFJ_Bone_Block"
    },
    {
      "x": 29,
      "y": 14,
      "z": 19,
      "name": "TFJ_Bone_Block"
    },
    {
      "x": 29,
      "y": 13,
      "z": 20,
      "name": "TFJ_Bone_Block"
    },
    {
      "x": 29,
      "y": 14,
      "z": 20,
      "name": "TFJ_Bone_Block"
    },
    {
      "x": 29,
      "y": 13,
      "z": 21,
      "name": "TFJ_Bone_Block"
    },
    {
      "x": 29,
      "y": 13,
      "z": 22,
      "name": "TFJ_Bone_Block"
    },
    {
      "x": 29,
      "y": 12,
      "z": 24,
      "name": "TFJ_Bone_Block"
    },
    {
      "x": 29,
      "y": 13,
      "z": 24,
      "name": "TFJ_Bone_Block"
    },
    {
      "x": 29,
      "y": 12,
      "z": 25,
      "name": "TFJ_Bone_Block"
    },
    {
      "x": 29,
      "y": 13,
      "z": 25,
      "name": "TFJ_Bone_Block"
    },
    {
      "x": 29,
      "y": 14,
      "z": 25,
      "name": "TFJ_Bone_Block"
    },
    {
      "x": 29,
      "y": 13,
      "z": 26,
      "name": "TFJ_Bone_Block"
    },
    {
      "x": 29,
      "y": 20,
      "z": 27,
      "name": "TFJ_Bone_Block"
    },
    {
      "x": 29,
      "y": 21,
      "z": 27,
      "name": "TFJ_Bone_Block"
    },
    {
      "x": 29,
      "y": 22,
      "z": 27,
      "name": "TFJ_Bone_Block"
    },
    {
      "x": 29,
      "y": 23,
      "z": 27,
      "name": "TFJ_Bone_Block"
    },
    {
      "x": 30,
      "y": 22,
      "z": 13,
      "name": "TFJ_Bone_Block"
    },
    {
      "x": 30,
      "y": 23,
      "z": 13,
      "name": "TFJ_Bone_Block"
    },
    {
      "x": 30,
      "y": 24,
      "z": 13,
      "name": "TFJ_Bone_Block"
    },
    {
      "x": 30,
      "y": 24,
      "z": 14,
      "name": "TFJ_Bone_Block"
    },
    {
      "x": 30,
      "y": 25,
      "z": 14,
      "name": "TFJ_Bone_Block"
    },
    {
      "x": 30,
      "y": 14,
      "z": 17,
      "name": "TFJ_Bone_Block"
    },
    {
      "x": 30,
      "y": 15,
      "z": 17,
      "name": "TFJ_Bone_Block"
    },
    {
      "x": 30,
      "y": 14,
      "z": 18,
      "name": "TFJ_Bone_Block"
    },
    {
      "x": 30,
      "y": 15,
      "z": 18,
      "name": "TFJ_Bone_Block"
    },
    {
      "x": 30,
      "y": 12,
      "z": 19,
      "name": "TFJ_Bone_Block"
    },
    {
      "x": 30,
      "y": 13,
      "z": 19,
      "name": "TFJ_Bone_Block"
    },
    {
      "x": 30,
      "y": 14,
      "z": 19,
      "name": "TFJ_Bone_Block"
    },
    {
      "x": 30,
      "y": 15,
      "z": 19,
      "name": "TFJ_Bone_Block"
    },
    {
      "x": 30,
      "y": 12,
      "z": 20,
      "name": "TFJ_Bone_Block"
    },
    {
      "x": 30,
      "y": 13,
      "z": 20,
      "name": "TFJ_Bone_Block"
    },
    {
      "x": 30,
      "y": 14,
      "z": 20,
      "name": "TFJ_Bone_Block"
    },
    {
      "x": 30,
      "y": 15,
      "z": 20,
      "name": "TFJ_Bone_Block"
    },
    {
      "x": 30,
      "y": 16,
      "z": 20,
      "name": "TFJ_Bone_Block"
    },
    {
      "x": 30,
      "y": 13,
      "z": 21,
      "name": "TFJ_Bone_Block"
    },
    {
      "x": 30,
      "y": 14,
      "z": 21,
      "name": "TFJ_Bone_Block"
    },
    {
      "x": 30,
      "y": 13,
      "z": 25,
      "name": "TFJ_Bone_Block"
    },
    {
      "x": 30,
      "y": 13,
      "z": 26,
      "name": "TFJ_Bone_Block"
    },
    {
      "x": 30,
      "y": 14,
      "z": 26,
      "name": "TFJ_Bone_Block"
    },
    {
      "x": 30,
      "y": 15,
      "z": 26,
      "name": "TFJ_Bone_Block"
    },
    {
      "x": 30,
      "y": 15,
      "z": 27,
      "name": "TFJ_Bone_Block"
    },
    {
      "x": 30,
      "y": 16,
      "z": 27,
      "name": "TFJ_Bone_Block"
    },
    {
      "x": 30,
      "y": 17,
      "z": 27,
      "name": "TFJ_Bone_Block"
    },
    {
      "x": 30,
      "y": 17,
      "z": 28,
      "name": "TFJ_Bone_Block"
    },
    {
      "x": 30,
      "y": 18,
      "z": 28,
      "name": "TFJ_Bone_Block"
    },
    {
      "x": 30,
      "y": 19,
      "z": 28,
      "name": "TFJ_Bone_Block"
    },
    {
      "x": 30,
      "y": 20,
      "z": 28,
      "name": "TFJ_Bone_Block"
    },
    {
      "x": 31,
      "y": 20,
      "z": 12,
      "name": "TFJ_Bone_Block"
    },
    {
      "x": 31,
      "y": 21,
      "z": 12,
      "name": "TFJ_Bone_Block"
    },
    {
      "x": 31,
      "y": 22,
      "z": 12,
      "name": "TFJ_Bone_Block"
    },
    {
      "x": 31,
      "y": 25,
      "z": 15,
      "name": "TFJ_Bone_Block"
    },
    {
      "x": 31,
      "y": 13,
      "z": 18,
      "name": "TFJ_Bone_Block"
    },
    {
      "x": 31,
      "y": 14,
      "z": 18,
      "name": "TFJ_Bone_Block"
    },
    {
      "x": 31,
      "y": 15,
      "z": 18,
      "name": "TFJ_Bone_Block"
    },
    {
      "x": 31,
      "y": 11,
      "z": 19,
      "name": "TFJ_Bone_Block"
    },
    {
      "x": 31,
      "y": 12,
      "z": 19,
      "name": "TFJ_Bone_Block"
    },
    {
      "x": 31,
      "y": 13,
      "z": 19,
      "name": "TFJ_Bone_Block"
    },
    {
      "x": 31,
      "y": 14,
      "z": 19,
      "name": "TFJ_Bone_Block"
    },
    {
      "x": 31,
      "y": 15,
      "z": 19,
      "name": "TFJ_Bone_Block"
    },
    {
      "x": 31,
      "y": 16,
      "z": 19,
      "name": "TFJ_Bone_Block"
    },
    {
      "x": 31,
      "y": 12,
      "z": 20,
      "name": "TFJ_Bone_Block"
    },
    {
      "x": 31,
      "y": 13,
      "z": 20,
      "name": "TFJ_Bone_Block"
    },
    {
      "x": 31,
      "y": 14,
      "z": 20,
      "name": "TFJ_Bone_Block"
    },
    {
      "x": 31,
      "y": 15,
      "z": 20,
      "name": "TFJ_Bone_Block"
    },
    {
      "x": 31,
      "y": 14,
      "z": 21,
      "name": "TFJ_Bone_Block"
    },
    {
      "x": 32,
      "y": 19,
      "z": 12,
      "name": "TFJ_Bone_Block"
    },
    {
      "x": 32,
      "y": 18,
      "z": 13,
      "name": "TFJ_Bone_Block"
    },
    {
      "x": 32,
      "y": 16,
      "z": 17,
      "name": "TFJ_Bone_Block"
    },
    {
      "x": 32,
      "y": 15,
      "z": 18,
      "name": "TFJ_Bone_Block"
    },
    {
      "x": 32,
      "y": 13,
      "z": 19,
      "name": "TFJ_Bone_Block"
    },
    {
      "x": 32,
      "y": 14,
      "z": 19,
      "name": "TFJ_Bone_Block"
    },
    {
      "x": 32,
      "y": 15,
      "z": 19,
      "name": "TFJ_Bone_Block"
    },
    {
      "x": 32,
      "y": 14,
      "z": 20,
      "name": "TFJ_Bone_Block"
    },
    {
      "x": 32,
      "y": 15,
      "z": 20,
      "name": "TFJ_Bone_Block"
    },
    {
      "x": 32,
      "y": 14,
      "z": 21,
      "name": "TFJ_Bone_Block"
    },
    {
      "x": 32,
      "y": 15,
      "z": 21,
      "name": "TFJ_Bone_Block"
    },
    {
      "x": 32,
      "y": 22,
      "z": 24,
      "name": "TFJ_Bone_Block"
    },
    {
      "x": 32,
      "y": 23,
      "z": 24,
      "name": "TFJ_Bone_Block"
    },
    {
      "x": 33,
      "y": 18,
      "z": 12,
      "name": "TFJ_Bone_Block"
    },
    {
      "x": 33,
      "y": 18,
      "z": 13,
      "name": "TFJ_Bone_Block"
    },
    {
      "x": 33,
      "y": 16,
      "z": 14,
      "name": "TFJ_Bone_Block"
    },
    {
      "x": 33,
      "y": 18,
      "z": 14,
      "name": "TFJ_Bone_Block"
    },
    {
      "x": 33,
      "y": 16,
      "z": 15,
      "name": "TFJ_Bone_Block"
    },
    {
      "x": 33,
      "y": 17,
      "z": 15,
      "name": "TFJ_Bone_Block"
    },
    {
      "x": 33,
      "y": 15,
      "z": 16,
      "name": "TFJ_Bone_Block"
    },
    {
      "x": 33,
      "y": 16,
      "z": 16,
      "name": "TFJ_Bone_Block"
    },
    {
      "x": 33,
      "y": 16,
      "z": 17,
      "name": "TFJ_Bone_Block"
    },
    {
      "x": 33,
      "y": 16,
      "z": 18,
      "name": "TFJ_Bone_Block"
    },
    {
      "x": 33,
      "y": 14,
      "z": 20,
      "name": "TFJ_Bone_Block"
    },
    {
      "x": 33,
      "y": 15,
      "z": 20,
      "name": "TFJ_Bone_Block"
    },
    {
      "x": 33,
      "y": 14,
      "z": 21,
      "name": "TFJ_Bone_Block"
    },
    {
      "x": 33,
      "y": 15,
      "z": 21,
      "name": "TFJ_Bone_Block"
    },
    {
      "x": 33,
      "y": 15,
      "z": 22,
      "name": "TFJ_Bone_Block"
    },
    {
      "x": 33,
      "y": 20,
      "z": 24,
      "name": "TFJ_Bone_Block"
    },
    {
      "x": 33,
      "y": 21,
      "z": 24,
      "name": "TFJ_Bone_Block"
    },
    {
      "x": 33,
      "y": 22,
      "z": 24,
      "name": "TFJ_Bone_Block"
    },
    {
      "x": 34,
      "y": 17,
      "z": 13,
      "name": "TFJ_Bone_Block"
    },
    {
      "x": 34,
      "y": 18,
      "z": 13,
      "name": "TFJ_Bone_Block"
    },
    {
      "x": 34,
      "y": 16,
      "z": 14,
      "name": "TFJ_Bone_Block"
    },
    {
      "x": 34,
      "y": 17,
      "z": 14,
      "name": "TFJ_Bone_Block"
    },
    {
      "x": 34,
      "y": 18,
      "z": 14,
      "name": "TFJ_Bone_Block"
    },
    {
      "x": 34,
      "y": 15,
      "z": 15,
      "name": "TFJ_Bone_Block"
    },
    {
      "x": 34,
      "y": 16,
      "z": 15,
      "name": "TFJ_Bone_Block"
    },
    {
      "x": 34,
      "y": 17,
      "z": 15,
      "name": "TFJ_Bone_Block"
    },
    {
      "x": 34,
      "y": 18,
      "z": 15,
      "name": "TFJ_Bone_Block"
    },
    {
      "x": 34,
      "y": 14,
      "z": 16,
      "name": "TFJ_Bone_Block"
    },
    {
      "x": 34,
      "y": 15,
      "z": 16,
      "name": "TFJ_Bone_Block"
    },
    {
      "x": 34,
      "y": 16,
      "z": 16,
      "name": "TFJ_Bone_Block"
    },
    {
      "x": 34,
      "y": 17,
      "z": 16,
      "name": "TFJ_Bone_Block"
    },
    {
      "x": 34,
      "y": 18,
      "z": 16,
      "name": "TFJ_Bone_Block"
    },
    {
      "x": 34,
      "y": 15,
      "z": 17,
      "name": "TFJ_Bone_Block"
    },
    {
      "x": 34,
      "y": 16,
      "z": 17,
      "name": "TFJ_Bone_Block"
    },
    {
      "x": 34,
      "y": 15,
      "z": 21,
      "name": "TFJ_Bone_Block"
    },
    {
      "x": 34,
      "y": 15,
      "z": 22,
      "name": "TFJ_Bone_Block"
    },
    {
      "x": 34,
      "y": 16,
      "z": 22,
      "name": "TFJ_Bone_Block"
    },
    {
      "x": 34,
      "y": 16,
      "z": 23,
      "name": "TFJ_Bone_Block"
    },
    {
      "x": 34,
      "y": 17,
      "z": 23,
      "name": "TFJ_Bone_Block"
    },
    {
      "x": 34,
      "y": 18,
      "z": 23,
      "name": "TFJ_Bone_Block"
    },
    {
      "x": 34,
      "y": 18,
      "z": 24,
      "name": "TFJ_Bone_Block"
    },
    {
      "x": 34,
      "y": 19,
      "z": 24,
      "name": "TFJ_Bone_Block"
    },
    {
      "x": 34,
      "y": 20,
      "z": 24,
      "name": "TFJ_Bone_Block"
    },
    {
      "x": 35,
      "y": 17,
      "z": 14,
      "name": "TFJ_Bone_Block"
    },
    {
      "x": 35,
      "y": 13,
      "z": 15,
      "name": "TFJ_Bone_Block"
    },
    {
      "x": 35,
      "y": 14,
      "z": 15,
      "name": "TFJ_Bone_Block"
    },
    {
      "x": 35,
      "y": 15,
      "z": 15,
      "name": "TFJ_Bone_Block"
    },
    {
      "x": 35,
      "y": 16,
      "z": 15,
      "name": "TFJ_Bone_Block"
    },
    {
      "x": 35,
      "y": 17,
      "z": 15,
      "name": "TFJ_Bone_Block"
    },
    {
      "x": 35,
      "y": 18,
      "z": 15,
      "name": "TFJ_Bone_Block"
    },
    {
      "x": 35,
      "y": 19,
      "z": 15,
      "name": "TFJ_Bone_Block"
    },
    {
      "x": 35,
      "y": 15,
      "z": 16,
      "name": "TFJ_Bone_Block"
    },
    {
      "x": 35,
      "y": 16,
      "z": 16,
      "name": "TFJ_Bone_Block"
    },
    {
      "x": 35,
      "y": 17,
      "z": 16,
      "name": "TFJ_Bone_Block"
    },
    {
      "x": 35,
      "y": 18,
      "z": 16,
      "name": "TFJ_Bone_Block"
    },
    {
      "x": 35,
      "y": 16,
      "z": 17,
      "name": "TFJ_Bone_Block"
    },
    {
      "x": 35,
      "y": 17,
      "z": 17,
      "name": "TFJ_Bone_Block"
    },
    {
      "x": 36,
      "y": 18,
      "z": 13,
      "name": "TFJ_Bone_Block"
    },
    {
      "x": 36,
      "y": 17,
      "z": 14,
      "name": "TFJ_Bone_Block"
    },
    {
      "x": 36,
      "y": 17,
      "z": 15,
      "name": "TFJ_Bone_Block"
    },
    {
      "x": 36,
      "y": 16,
      "z": 16,
      "name": "TFJ_Bone_Block"
    },
    {
      "x": 36,
      "y": 17,
      "z": 16,
      "name": "TFJ_Bone_Block"
    },
    {
      "x": 36,
      "y": 18,
      "z": 16,
      "name": "TFJ_Bone_Block"
    },
    {
      "x": 36,
      "y": 16,
      "z": 17,
      "name": "TFJ_Bone_Block"
    },
    {
      "x": 36,
      "y": 18,
      "z": 17,
      "name": "TFJ_Bone_Block"
    },
    {
      "x": 37,
      "y": 19,
      "z": 8,
      "name": "TFJ_Bone_Block"
    },
    {
      "x": 37,
      "y": 20,
      "z": 8,
      "name": "TFJ_Bone_Block"
    },
    {
      "x": 37,
      "y": 21,
      "z": 8,
      "name": "TFJ_Bone_Block"
    },
    {
      "x": 37,
      "y": 22,
      "z": 8,
      "name": "TFJ_Bone_Block"
    },
    {
      "x": 37,
      "y": 23,
      "z": 8,
      "name": "TFJ_Bone_Block"
    },
    {
      "x": 37,
      "y": 18,
      "z": 12,
      "name": "TFJ_Bone_Block"
    },
    {
      "x": 37,
      "y": 18,
      "z": 13,
      "name": "TFJ_Bone_Block"
    },
    {
      "x": 37,
      "y": 18,
      "z": 14,
      "name": "TFJ_Bone_Block"
    },
    {
      "x": 37,
      "y": 17,
      "z": 16,
      "name": "TFJ_Bone_Block"
    },
    {
      "x": 37,
      "y": 18,
      "z": 16,
      "name": "TFJ_Bone_Block"
    },
    {
      "x": 37,
      "y": 18,
      "z": 17,
      "name": "TFJ_Bone_Block"
    },
    {
      "x": 37,
      "y": 18,
      "z": 18,
      "name": "TFJ_Bone_Block"
    },
    {
      "x": 37,
      "y": 22,
      "z": 20,
      "name": "TFJ_Bone_Block"
    },
    {
      "x": 38,
      "y": 18,
      "z": 9,
      "name": "TFJ_Bone_Block"
    },
    {
      "x": 38,
      "y": 19,
      "z": 9,
      "name": "TFJ_Bone_Block"
    },
    {
      "x": 38,
      "y": 23,
      "z": 9,
      "name": "TFJ_Bone_Block"
    },
    {
      "x": 38,
      "y": 24,
      "z": 9,
      "name": "TFJ_Bone_Block"
    },
    {
      "x": 38,
      "y": 17,
      "z": 10,
      "name": "TFJ_Bone_Block"
    },
    {
      "x": 38,
      "y": 18,
      "z": 10,
      "name": "TFJ_Bone_Block"
    },
    {
      "x": 38,
      "y": 17,
      "z": 11,
      "name": "TFJ_Bone_Block"
    },
    {
      "x": 38,
      "y": 18,
      "z": 12,
      "name": "TFJ_Bone_Block"
    },
    {
      "x": 38,
      "y": 18,
      "z": 13,
      "name": "TFJ_Bone_Block"
    },
    {
      "x": 38,
      "y": 18,
      "z": 17,
      "name": "TFJ_Bone_Block"
    },
    {
      "x": 38,
      "y": 19,
      "z": 18,
      "name": "TFJ_Bone_Block"
    },
    {
      "x": 38,
      "y": 20,
      "z": 19,
      "name": "TFJ_Bone_Block"
    },
    {
      "x": 38,
      "y": 21,
      "z": 19,
      "name": "TFJ_Bone_Block"
    },
    {
      "x": 38,
      "y": 22,
      "z": 19,
      "name": "TFJ_Bone_Block"
    },
    {
      "x": 39,
      "y": 17,
      "z": 9,
      "name": "TFJ_Bone_Block"
    },
    {
      "x": 39,
      "y": 18,
      "z": 9,
      "name": "TFJ_Bone_Block"
    },
    {
      "x": 39,
      "y": 16,
      "z": 10,
      "name": "TFJ_Bone_Block"
    },
    {
      "x": 39,
      "y": 17,
      "z": 10,
      "name": "TFJ_Bone_Block"
    },
    {
      "x": 39,
      "y": 18,
      "z": 10,
      "name": "TFJ_Bone_Block"
    },
    {
      "x": 39,
      "y": 15,
      "z": 11,
      "name": "TFJ_Bone_Block"
    },
    {
      "x": 39,
      "y": 16,
      "z": 11,
      "name": "TFJ_Bone_Block"
    },
    {
      "x": 39,
      "y": 17,
      "z": 11,
      "name": "TFJ_Bone_Block"
    },
    {
      "x": 39,
      "y": 18,
      "z": 11,
      "name": "TFJ_Bone_Block"
    },
    {
      "x": 39,
      "y": 17,
      "z": 12,
      "name": "TFJ_Bone_Block"
    },
    {
      "x": 40,
      "y": 16,
      "z": 9,
      "name": "TFJ_Bone_Block"
    },
    {
      "x": 40,
      "y": 15,
      "z": 10,
      "name": "TFJ_Bone_Block"
    },
    {
      "x": 40,
      "y": 16,
      "z": 10,
      "name": "TFJ_Bone_Block"
    },
    {
      "x": 40,
      "y": 17,
      "z": 10,
      "name": "TFJ_Bone_Block"
    },
    {
      "x": 40,
      "y": 18,
      "z": 10,
      "name": "TFJ_Bone_Block"
    },
    {
      "x": 40,
      "y": 16,
      "z": 11,
      "name": "TFJ_Bone_Block"
    },
    {
      "x": 40,
      "y": 17,
      "z": 11,
      "name": "TFJ_Bone_Block"
    },
    {
      "x": 40,
      "y": 18,
      "z": 11,
      "name": "TFJ_Bone_Block"
    },
    {
      "x": 40,
      "y": 17,
      "z": 12,
      "name": "TFJ_Bone_Block"
    },
    {
      "x": 40,
      "y": 18,
      "z": 12,
      "name": "TFJ_Bone_Block"
    },
    {
      "x": 41,
      "y": 16,
      "z": 8,
      "name": "TFJ_Bone_Block"
    },
    {
      "x": 41,
      "y": 16,
      "z": 9,
      "name": "TFJ_Bone_Block"
    },
    {
      "x": 41,
      "y": 16,
      "z": 10,
      "name": "TFJ_Bone_Block"
    },
    {
      "x": 41,
      "y": 17,
      "z": 11,
      "name": "TFJ_Bone_Block"
    },
    {
      "x": 41,
      "y": 18,
      "z": 11,
      "name": "TFJ_Bone_Block"
    },
    {
      "x": 41,
      "y": 18,
      "z": 12,
      "name": "TFJ_Bone_Block"
    },
    {
      "x": 41,
      "y": 19,
      "z": 12,
      "name": "TFJ_Bone_Block"
    },
    {
      "x": 42,
      "y": 17,
      "z": 4,
      "name": "TFJ_Bone_Block"
    },
    {
      "x": 42,
      "y": 18,
      "z": 4,
      "name": "TFJ_Bone_Block"
    },
    {
      "x": 42,
      "y": 15,
      "z": 6,
      "name": "TFJ_Bone_Block"
    },
    {
      "x": 42,
      "y": 16,
      "z": 6,
      "name": "TFJ_Bone_Block"
    },
    {
      "x": 42,
      "y": 16,
      "z": 7,
      "name": "TFJ_Bone_Block"
    },
    {
      "x": 42,
      "y": 16,
      "z": 8,
      "name": "TFJ_Bone_Block"
    },
    {
      "x": 42,
      "y": 16,
      "z": 9,
      "name": "TFJ_Bone_Block"
    },
    {
      "x": 42,
      "y": 19,
      "z": 13,
      "name": "TFJ_Bone_Block"
    },
    {
      "x": 42,
      "y": 20,
      "z": 13,
      "name": "TFJ_Bone_Block"
    },
    {
      "x": 42,
      "y": 21,
      "z": 13,
      "name": "TFJ_Bone_Block"
    },
    {
      "x": 43,
      "y": 18,
      "z": 4,
      "name": "TFJ_Bone_Block"
    },
    {
      "x": 43,
      "y": 19,
      "z": 4,
      "name": "TFJ_Bone_Block"
    },
    {
      "x": 43,
      "y": 20,
      "z": 4,
      "name": "TFJ_Bone_Block"
    },
    {
      "x": 43,
      "y": 15,
      "z": 5,
      "name": "TFJ_Bone_Block"
    },
    {
      "x": 43,
      "y": 16,
      "z": 5,
      "name": "TFJ_Bone_Block"
    },
    {
      "x": 43,
      "y": 17,
      "z": 5,
      "name": "TFJ_Bone_Block"
    },
    {
      "x": 43,
      "y": 14,
      "z": 6,
      "name": "TFJ_Bone_Block"
    },
    {
      "x": 43,
      "y": 15,
      "z": 6,
      "name": "TFJ_Bone_Block"
    },
    {
      "x": 43,
      "y": 16,
      "z": 6,
      "name": "TFJ_Bone_Block"
    },
    {
      "x": 43,
      "y": 14,
      "z": 7,
      "name": "TFJ_Bone_Block"
    },
    {
      "x": 43,
      "y": 15,
      "z": 7,
      "name": "TFJ_Bone_Block"
    },
    {
      "x": 43,
      "y": 16,
      "z": 7,
      "name": "TFJ_Bone_Block"
    },
    {
      "x": 43,
      "y": 17,
      "z": 7,
      "name": "TFJ_Bone_Block"
    },
    {
      "x": 43,
      "y": 16,
      "z": 8,
      "name": "TFJ_Bone_Block"
    },
    {
      "x": 44,
      "y": 20,
      "z": 4,
      "name": "TFJ_Bone_Block"
    },
    {
      "x": 44,
      "y": 21,
      "z": 4,
      "name": "TFJ_Bone_Block"
    },
    {
      "x": 44,
      "y": 15,
      "z": 5,
      "name": "TFJ_Bone_Block"
    },
    {
      "x": 44,
      "y": 13,
      "z": 6,
      "name": "TFJ_Bone_Block"
    },
    {
      "x": 44,
      "y": 14,
      "z": 6,
      "name": "TFJ_Bone_Block"
    },
    {
      "x": 44,
      "y": 15,
      "z": 6,
      "name": "TFJ_Bone_Block"
    },
    {
      "x": 44,
      "y": 16,
      "z": 6,
      "name": "TFJ_Bone_Block"
    },
    {
      "x": 44,
      "y": 14,
      "z": 7,
      "name": "TFJ_Bone_Block"
    },
    {
      "x": 44,
      "y": 15,
      "z": 7,
      "name": "TFJ_Bone_Block"
    },
    {
      "x": 44,
      "y": 16,
      "z": 7,
      "name": "TFJ_Bone_Block"
    },
    {
      "x": 44,
      "y": 15,
      "z": 8,
      "name": "TFJ_Bone_Block"
    },
    {
      "x": 44,
      "y": 16,
      "z": 8,
      "name": "TFJ_Bone_Block"
    },
    {
      "x": 45,
      "y": 14,
      "z": 4,
      "name": "TFJ_Bone_Block"
    },
    {
      "x": 45,
      "y": 15,
      "z": 5,
      "name": "TFJ_Bone_Block"
    },
    {
      "x": 45,
      "y": 15,
      "z": 6,
      "name": "TFJ_Bone_Block"
    },
    {
      "x": 45,
      "y": 15,
      "z": 7,
      "name": "TFJ_Bone_Block"
    },
    {
      "x": 45,
      "y": 16,
      "z": 7,
      "name": "TFJ_Bone_Block"
    },
    {
      "x": 45,
      "y": 17,
      "z": 7,
      "name": "TFJ_Bone_Block"
    },
    {
      "x": 46,
      "y": 14,
      "z": 3,
      "name": "TFJ_Bone_Block"
    },
    {
      "x": 46,
      "y": 14,
      "z": 4,
      "name": "TFJ_Bone_Block"
    },
    {
      "x": 46,
      "y": 14,
      "z": 5,
      "name": "TFJ_Bone_Block"
    },
    {
      "x": 46,
      "y": 20,
      "z": 6,
      "name": "TFJ_Bone_Block"
    },
    {
      "x": 46,
      "y": 21,
      "z": 6,
      "name": "TFJ_Bone_Block"
    },
    {
      "x": 46,
      "y": 18,
      "z": 7,
      "name": "TFJ_Bone_Block"
    },
    {
      "x": 46,
      "y": 19,
      "z": 7,
      "name": "TFJ_Bone_Block"
    },
    {
      "x": 46,
      "y": 20,
      "z": 7,
      "name": "TFJ_Bone_Block"
    },
    {
      "x": 46,
      "y": 17,
      "z": 8,
      "name": "TFJ_Bone_Block"
    },
    {
      "x": 46,
      "y": 18,
      "z": 8,
      "name": "TFJ_Bone_Block"
    },
    {
      "x": 47,
      "y": 14,
      "z": 2,
      "name": "TFJ_Bone_Block"
    },
    {
      "x": 47,
      "y": 14,
      "z": 3,
      "name": "TFJ_Bone_Block"
    },
    {
      "x": 47,
      "y": 14,
      "z": 4,
      "name": "TFJ_Bone_Block"
    },
    {
      "x": 48,
      "y": 14,
      "z": 2,
      "name": "TFJ_Bone_Block"
    },
    {
      "x": 48,
      "y": 14,
      "z": 3,
      "name": "TFJ_Bone_Block"
    }
  ],
  "fluids": [],
  "entities": [
    {
      "Components": {
        "Nameplate": {
          "Text": "TFJ_Apex_Predator"
        },
        "HiddenFromAdventurePlayer": {},
        "SpawnMarkerComponent": {
          "SpawnMarker": "TFJ_Apex_Predator",
          "RespawnTime": 90,
          "SpawnCount": 1
        },
        "Transform": {
          "Position": {
            "X": 0,
            "Y": 1,
            "Z": 0
          },
          "Rotation": {
            "Pitch": 0,
            "Yaw": 0,
            "Roll": 0
          }
        },
        "Intangible": {},
        "PrefabCopyable": {},
        "Model": {
          "Model": {
            "Id": "NPC_Spawn_Marker",
            "Scale": 1,
            "Static": false
          }
        },
        "UUID": {
          "UUID": {
            "$binary": "XVAIPvctWwGloKllmpszVQ==",
            "$type": "04"
          }
        },
        "HeadRotation": {
          "Rotation": {
            "Pitch": 0,
            "Yaw": 0,
            "Roll": 0
          }
        }
      }
    }
  ]
}
