{
  "version": 8,
  "blockIdVersion": 11,
  "anchorX": 2,
  "anchorY": 3,
  "anchorZ": 2,
  "blocks": [
    {
      "x": 0,
      "y": 6,
      "z": 1,
      "name": "TFJ_Bone_Block"
    },
    {
      "x": 0,
      "y": 7,
      "z": 1,
      "name": "TFJ_Bone_Block"
    },
    {
      "x": 0,
      "y": 8,
      "z": 1,
      "name": "TFJ_Bone_Block"
    },
    {
      "x": 0,
      "y": 9,
      "z": 1,
      "name": "TFJ_Bone_Block"
    },
    {
      "x": 0,
      "y": 10,
      "z": 1,
      "name": "TFJ_Bone_Block"
    },
    {
      "x": 0,
      "y": 4,
      "z": 2,
      "name": "TFJ_Bone_Block"
    },
    {
      "x": 0,
      "y": 5,
      "z": 2,
      "name": "TFJ_Bone_Block"
    },
    {
      "x": 0,
      "y": 6,
      "z": 2,
      "name": "TFJ_Bone_Block"
    },
    {
      "x": 1,
      "y": 2,
      "z": 1,
      "name": "TFJ_Bone_Block"
    },
    {
      "x": 1,
      "y": 3,
      "z": 1,
      "name": "TFJ_Bone_Block"
    },
    {
      "x": 1,
      "y": 4,
      "z": 1,
      "name": "TFJ_Bone_Block"
    },
    {
      "x": 1,
      "y": 5,
      "z": 1,
      "name": "TFJ_Bone_Block"
    },
    {
      "x": 1,
      "y": 6,
      "z": 1,
      "name": "TFJ_Bone_Block"
    },
    {
      "x": 1,
      "y": 10,
      "z": 1,
      "name": "TFJ_Bone_Block"
    },
    {
      "x": 1,
      "y": 11,
      "z": 1,
      "name": "TFJ_Bone_Block"
    },
    {
      "x": 1,
      "y": 12,
      "z": 1,
      "name": "TFJ_Bone_Block"
    },
    {
      "x": 1,
      "y": 13,
      "z": 1,
      "name": "TFJ_Bone_Block"
    },
    {
      "x": 1,
      "y": 2,
      "z": 2,
      "name": "TFJ_Bone_Block"
    },
    {
      "x": 1,
      "y": 3,
      "z": 2,
      "name": "TFJ_Bone_Block"
    },
    {
      "x": 1,
      "y": 4,
      "z": 2,
      "name": "TFJ_Bone_Block"
    },
    {
      "x": 2,
      "y": 2,
      "z": 1,
      "name": "TFJ_Bone_Block"
    },
    {
      "x": 2,
      "y": 3,
      "z": 1,
      "name": "TFJ_Bone_Block"
    },
    {
      "x": 2,
      "y": 13,
      "z": 1,
      "name": "TFJ_Bone_Block"
    },
    {
      "x": 2,
      "y": 14,
      "z": 1,
      "name": "TFJ_Bone_Block"
    },
    {
      "x": 2,
      "y": 1,
      "z": 2,
      "name": "TFJ_Bone_Block"
    },
    {
      "x": 2,
      "y": 2,
      "z": 2,
      "name": "TFJ_Bone_Block"
    },
    {
      "x": 2,
      "y": 3,
      "z": 2,
      "name": "TFJ_Bone_Block"
    },
    {
      "x": 2,
      "y": 2,
      "z": 4,
      "name": "TFJ_Bone_Block"
    },
    {
      "x": 2,
      "y": 3,
      "z": 4,
      "name": "TFJ_Bone_Block"
    },
    {
      "x": 2,
      "y": 4,
      "z": 4,
      "name": "TFJ_Bone_Block"
    },
    {
      "x": 2,
      "y": 5,
      "z": 4,
      "name": "TFJ_Bone_Block"
    },
    {
      "x": 2,
      "y": 6,
      "z": 4,
      "name": "TFJ_Bone_Block"
    },
    {
      "x": 2,
      "y": 7,
      "z": 4,
      "name": "TFJ_Bone_Block"
    },
    {
      "x": 3,
      "y": 0,
      "z": 2,
      "name": "TFJ_Bone_Block"
    },
    {
      "x": 3,
      "y": 1,
      "z": 2,
      "name": "TFJ_Bone_Block"
    },
    {
      "x": 3,
      "y": 1,
      "z": 4,
      "name": "TFJ_Bone_Block"
    },
    {
      "x": 3,
      "y": 2,
      "z": 4,
      "name": "TFJ_Bone_Block"
    },
    {
      "x": 3,
      "y": 7,
      "z": 4,
      "name": "TFJ_Bone_Block"
    },
    {
      "x": 3,
      "y": 8,
      "z": 4,
      "name": "TFJ_Bone_Block"
    },
    {
      "x": 3,
      "y": 9,
      "z": 4,
      "name": "TFJ_Bone_Block"
    },
    {
      "x": 3,
      "y": 10,
      "z": 4,
      "name": "TFJ_Bone_Block"
    },
    {
      "x": 4,
      "y": 10,
      "z": 4,
      "name": "TFJ_Bone_Block"
    },
    {
      "x": 4,
      "y": 11,
      "z": 4,
      "name": "TFJ_Bone_Block"
    }
  ],
  "fluids": [],
  "entities": []
}
