{
  "version": 8,
  "blockIdVersion": 11,
  "anchorX": 0,
  "anchorY": 10,
  "anchorZ": -1,
  "blocks": [
    {
      "x": -13,
      "y": 26,
      "z": -2,
      "name": "TFJ_Canopy_Leaves"
    },
    {
      "x": -13,
      "y": 25,
      "z": -1,
      "name": "TFJ_Canopy_Leaves"
    },
    {
      "x": -13,
      "y": 26,
      "z": -1,
      "name": "TFJ_Canopy_Leaves"
    },
    {
      "x": -13,
      "y": 26,
      "z": 0,
      "name": "TFJ_Canopy_Leaves"
    },
    {
      "x": -13,
      "y": 26,
      "z": 1,
      "name": "TFJ_Canopy_Leaves"
    },
    {
      "x": -12,
      "y": 26,
      "z": -3,
      "name": "TFJ_Canopy_Leaves"
    },
    {
      "x": -12,
      "y": 26,
      "z": -2,
      "name": "TFJ_Canopy_Leaves"
    },
    {
      "x": -12,
      "y": 27,
      "z": -2,
      "name": "TFJ_Canopy_Leaves"
    },
    {
      "x": -12,
      "y": 24,
      "z": -1,
      "name": "TFJ_Canopy_Leaves"
    },
    {
      "x": -12,
      "y": 25,
      "z": -1,
      "name": "TFJ_Canopy_Leaves"
    },
    {
      "x": -12,
      "y": 26,
      "z": -1,
      "name": "TFJ_Canopy_Leaves"
    },
    {
      "x": -12,
      "y": 23,
      "z": 0,
      "name": "TFJ_Canopy_Leaves"
    },
    {
      "x": -12,
      "y": 24,
      "z": 0,
      "name": "TFJ_Canopy_Leaves"
    },
    {
      "x": -12,
      "y": 25,
      "z": 0,
      "name": "TFJ_Canopy_Leaves"
    },
    {
      "x": -12,
      "y": 26,
      "z": 0,
      "name": "TFJ_Canopy_Leaves"
    },
    {
      "x": -12,
      "y": 27,
      "z": 0,
      "name": "TFJ_Canopy_Leaves"
    },
    {
      "x": -12,
      "y": 24,
      "z": 1,
      "name": "TFJ_Canopy_Leaves"
    },
    {
      "x": -12,
      "y": 25,
      "z": 1,
      "name": "TFJ_Canopy_Leaves"
    },
    {
      "x": -12,
      "y": 26,
      "z": 1,
      "name": "TFJ_Canopy_Leaves"
    },
    {
      "x": -12,
      "y": 26,
      "z": 2,
      "name": "TFJ_Canopy_Leaves"
    },
    {
      "x": -12,
      "y": 25,
      "z": 3,
      "name": "TFJ_Canopy_Leaves"
    },
    {
      "x": -12,
      "y": 26,
      "z": 3,
      "name": "TFJ_Canopy_Leaves"
    },
    {
      "x": -11,
      "y": 25,
      "z": -4,
      "name": "TFJ_Canopy_Leaves"
    },
    {
      "x": -11,
      "y": 26,
      "z": -4,
      "name": "TFJ_Canopy_Leaves"
    },
    {
      "x": -11,
      "y": 23,
      "z": -3,
      "name": "TFJ_Canopy_Leaves"
    },
    {
      "x": -11,
      "y": 24,
      "z": -3,
      "name": "TFJ_Canopy_Leaves"
    },
    {
      "x": -11,
      "y": 25,
      "z": -3,
      "name": "TFJ_Canopy_Leaves"
    },
    {
      "x": -11,
      "y": 26,
      "z": -3,
      "name": "TFJ_Canopy_Leaves"
    },
    {
      "x": -11,
      "y": 27,
      "z": -3,
      "name": "TFJ_Canopy_Leaves"
    },
    {
      "x": -11,
      "y": 28,
      "z": -1,
      "name": "TFJ_Canopy_Leaves"
    },
    {
      "x": -11,
      "y": 25,
      "z": 0,
      "name": "TFJ_Titanwood_Log",
      "rotation": 3
    },
    {
      "x": -11,
      "y": 26,
      "z": 0,
      "name": "TFJ_Titanwood_Log"
    },
    {
      "x": -11,
      "y": 27,
      "z": 0,
      "name": "TFJ_Canopy_Leaves"
    },
    {
      "x": -11,
      "y": 28,
      "z": 0,
      "name": "TFJ_Canopy_Leaves"
    },
    {
      "x": -11,
      "y": 28,
      "z": 1,
      "name": "TFJ_Canopy_Leaves"
    },
    {
      "x": -11,
      "y": 25,
      "z": 2,
      "name": "TFJ_Canopy_Leaves"
    },
    {
      "x": -11,
      "y": 26,
      "z": 2,
      "name": "TFJ_Canopy_Leaves"
    },
    {
      "x": -11,
      "y": 27,
      "z": 2,
      "name": "TFJ_Canopy_Leaves"
    },
    {
      "x": -11,
      "y": 24,
      "z": 3,
      "name": "TFJ_Canopy_Leaves"
    },
    {
      "x": -11,
      "y": 25,
      "z": 3,
      "name": "TFJ_Canopy_Leaves"
    },
    {
      "x": -11,
      "y": 26,
      "z": 3,
      "name": "TFJ_Canopy_Leaves"
    },
    {
      "x": -11,
      "y": 25,
      "z": 4,
      "name": "TFJ_Canopy_Leaves"
    },
    {
      "x": -10,
      "y": 24,
      "z": -5,
      "name": "TFJ_Canopy_Leaves"
    },
    {
      "x": -10,
      "y": 25,
      "z": -5,
      "name": "TFJ_Canopy_Leaves"
    },
    {
      "x": -10,
      "y": 26,
      "z": -5,
      "name": "TFJ_Canopy_Leaves"
    },
    {
      "x": -10,
      "y": 24,
      "z": -4,
      "name": "TFJ_Canopy_Leaves"
    },
    {
      "x": -10,
      "y": 25,
      "z": -4,
      "name": "TFJ_Canopy_Leaves"
    },
    {
      "x": -10,
      "y": 25,
      "z": -3,
      "name": "TFJ_Canopy_Leaves"
    },
    {
      "x": -10,
      "y": 28,
      "z": -3,
      "name": "TFJ_Canopy_Leaves"
    },
    {
      "x": -10,
      "y": 25,
      "z": 0,
      "name": "TFJ_Titanwood_Log",
      "rotation": 5
    },
    {
      "x": -10,
      "y": 28,
      "z": 0,
      "name": "TFJ_Canopy_Leaves"
    },
    {
      "x": -10,
      "y": 28,
      "z": 1,
      "name": "TFJ_Canopy_Leaves"
    },
    {
      "x": -10,
      "y": 26,
      "z": 2,
      "name": "TFJ_Canopy_Leaves"
    },
    {
      "x": -10,
      "y": 27,
      "z": 3,
      "name": "TFJ_Canopy_Leaves"
    },
    {
      "x": -10,
      "y": 23,
      "z": 4,
      "name": "TFJ_Canopy_Leaves"
    },
    {
      "x": -10,
      "y": 24,
      "z": 4,
      "name": "TFJ_Canopy_Leaves"
    },
    {
      "x": -10,
      "y": 25,
      "z": 4,
      "name": "TFJ_Canopy_Leaves"
    },
    {
      "x": -10,
      "y": 26,
      "z": 4,
      "name": "TFJ_Canopy_Leaves"
    },
    {
      "x": -9,
      "y": 22,
      "z": -5,
      "name": "TFJ_Canopy_Leaves"
    },
    {
      "x": -9,
      "y": 23,
      "z": -5,
      "name": "TFJ_Canopy_Leaves"
    },
    {
      "x": -9,
      "y": 25,
      "z": -5,
      "name": "TFJ_Canopy_Leaves"
    },
    {
      "x": -9,
      "y": 23,
      "z": -4,
      "name": "TFJ_Canopy_Leaves"
    },
    {
      "x": -9,
      "y": 25,
      "z": -4,
      "name": "TFJ_Canopy_Leaves"
    },
    {
      "x": -9,
      "y": 26,
      "z": -4,
      "name": "TFJ_Canopy_Leaves"
    },
    {
      "x": -9,
      "y": 27,
      "z": -4,
      "name": "TFJ_Canopy_Leaves"
    },
    {
      "x": -9,
      "y": 25,
      "z": -3,
      "name": "TFJ_Titanwood_Log",
      "rotation": 4
    },
    {
      "x": -9,
      "y": 26,
      "z": -3,
      "name": "TFJ_Canopy_Leaves"
    },
    {
      "x": -9,
      "y": 27,
      "z": -3,
      "name": "TFJ_Canopy_Leaves"
    },
    {
      "x": -9,
      "y": 28,
      "z": -3,
      "name": "TFJ_Canopy_Leaves"
    },
    {
      "x": -9,
      "y": 25,
      "z": -2,
      "name": "TFJ_Titanwood_Log",
      "rotation": 4
    },
    {
      "x": -9,
      "y": 28,
      "z": -2,
      "name": "TFJ_Canopy_Leaves"
    },
    {
      "x": -9,
      "y": 25,
      "z": -1,
      "name": "TFJ_Titanwood_Log",
      "rotation": 4
    },
    {
      "x": -9,
      "y": 28,
      "z": -1,
      "name": "TFJ_Canopy_Leaves"
    },
    {
      "x": -9,
      "y": 25,
      "z": 0,
      "name": "TFJ_Titanwood_Log"
    },
    {
      "x": -9,
      "y": 28,
      "z": 0,
      "name": "TFJ_Canopy_Leaves"
    },
    {
      "x": -9,
      "y": 27,
      "z": 2,
      "name": "TFJ_Canopy_Leaves"
    },
    {
      "x": -9,
      "y": 28,
      "z": 2,
      "name": "TFJ_Canopy_Leaves"
    },
    {
      "x": -9,
      "y": 26,
      "z": 3,
      "name": "TFJ_Canopy_Leaves"
    },
    {
      "x": -9,
      "y": 27,
      "z": 3,
      "name": "TFJ_Canopy_Leaves"
    },
    {
      "x": -9,
      "y": 23,
      "z": 4,
      "name": "TFJ_Canopy_Leaves"
    },
    {
      "x": -9,
      "y": 24,
      "z": 4,
      "name": "TFJ_Canopy_Leaves"
    },
    {
      "x": -9,
      "y": 25,
      "z": 4,
      "name": "TFJ_Canopy_Leaves"
    },
    {
      "x": -9,
      "y": 26,
      "z": 4,
      "name": "TFJ_Canopy_Leaves"
    },
    {
      "x": -9,
      "y": 27,
      "z": 4,
      "name": "TFJ_Canopy_Leaves"
    },
    {
      "x": -9,
      "y": 25,
      "z": 5,
      "name": "TFJ_Canopy_Leaves"
    },
    {
      "x": -9,
      "y": 26,
      "z": 5,
      "name": "TFJ_Canopy_Leaves"
    },
    {
      "x": -8,
      "y": 23,
      "z": -5,
      "name": "TFJ_Canopy_Leaves"
    },
    {
      "x": -8,
      "y": 24,
      "z": -5,
      "name": "TFJ_Canopy_Leaves"
    },
    {
      "x": -8,
      "y": 25,
      "z": -5,
      "name": "TFJ_Canopy_Leaves"
    },
    {
      "x": -8,
      "y": 26,
      "z": -5,
      "name": "TFJ_Canopy_Leaves"
    },
    {
      "x": -8,
      "y": 27,
      "z": -5,
      "name": "TFJ_Canopy_Leaves"
    },
    {
      "x": -8,
      "y": 23,
      "z": -4,
      "name": "TFJ_Canopy_Leaves"
    },
    {
      "x": -8,
      "y": 25,
      "z": -4,
      "name": "TFJ_Canopy_Leaves"
    },
    {
      "x": -8,
      "y": 28,
      "z": -3,
      "name": "TFJ_Canopy_Leaves"
    },
    {
      "x": -8,
      "y": 28,
      "z": -2,
      "name": "TFJ_Canopy_Leaves"
    },
    {
      "x": -8,
      "y": 25,
      "z": 0,
      "name": "TFJ_Titanwood_Log"
    },
    {
      "x": -8,
      "y": 26,
      "z": 0,
      "name": "TFJ_Titanwood_Log"
    },
    {
      "x": -8,
      "y": 27,
      "z": 0,
      "name": "TFJ_Titanwood_Log"
    },
    {
      "x": -8,
      "y": 28,
      "z": 0,
      "name": "TFJ_Canopy_Leaves"
    },
    {
      "x": -8,
      "y": 25,
      "z": 1,
      "name": "TFJ_Titanwood_Log",
      "rotation": 4
    },
    {
      "x": -8,
      "y": 25,
      "z": 2,
      "name": "TFJ_Titanwood_Log",
      "rotation": 4
    },
    {
      "x": -8,
      "y": 25,
      "z": 3,
      "name": "TFJ_Titanwood_Log"
    },
    {
      "x": -8,
      "y": 26,
      "z": 3,
      "name": "TFJ_Canopy_Leaves"
    },
    {
      "x": -8,
      "y": 27,
      "z": 3,
      "name": "TFJ_Canopy_Leaves"
    },
    {
      "x": -8,
      "y": 23,
      "z": 4,
      "name": "TFJ_Canopy_Leaves"
    },
    {
      "x": -8,
      "y": 25,
      "z": 4,
      "name": "TFJ_Canopy_Leaves"
    },
    {
      "x": -8,
      "y": 26,
      "z": 4,
      "name": "TFJ_Canopy_Leaves"
    },
    {
      "x": -8,
      "y": 23,
      "z": 5,
      "name": "TFJ_Canopy_Leaves"
    },
    {
      "x": -8,
      "y": 24,
      "z": 5,
      "name": "TFJ_Canopy_Leaves"
    },
    {
      "x": -8,
      "y": 25,
      "z": 5,
      "name": "TFJ_Canopy_Leaves"
    },
    {
      "x": -7,
      "y": 22,
      "z": -10,
      "name": "TFJ_Canopy_Leaves"
    },
    {
      "x": -7,
      "y": 23,
      "z": -10,
      "name": "TFJ_Canopy_Leaves"
    },
    {
      "x": -7,
      "y": 24,
      "z": -10,
      "name": "TFJ_Canopy_Leaves"
    },
    {
      "x": -7,
      "y": 22,
      "z": -9,
      "name": "TFJ_Canopy_Leaves"
    },
    {
      "x": -7,
      "y": 25,
      "z": -9,
      "name": "TFJ_Canopy_Leaves"
    },
    {
      "x": -7,
      "y": 23,
      "z": -8,
      "name": "TFJ_Canopy_Leaves"
    },
    {
      "x": -7,
      "y": 24,
      "z": -8,
      "name": "TFJ_Canopy_Leaves"
    },
    {
      "x": -7,
      "y": 25,
      "z": -8,
      "name": "TFJ_Canopy_Leaves"
    },
    {
      "x": -7,
      "y": 26,
      "z": -8,
      "name": "TFJ_Canopy_Leaves"
    },
    {
      "x": -7,
      "y": 24,
      "z": -7,
      "name": "TFJ_Canopy_Leaves"
    },
    {
      "x": -7,
      "y": 25,
      "z": -7,
      "name": "TFJ_Canopy_Leaves"
    },
    {
      "x": -7,
      "y": 26,
      "z": -7,
      "name": "TFJ_Canopy_Leaves"
    },
    {
      "x": -7,
      "y": 26,
      "z": -6,
      "name": "TFJ_Canopy_Leaves"
    },
    {
      "x": -7,
      "y": 28,
      "z": -3,
      "name": "TFJ_Canopy_Leaves"
    },
    {
      "x": -7,
      "y": 27,
      "z": -1,
      "name": "TFJ_Canopy_Leaves"
    },
    {
      "x": -7,
      "y": 28,
      "z": -1,
      "name": "TFJ_Canopy_Leaves"
    },
    {
      "x": -7,
      "y": 23,
      "z": 0,
      "name": "TFJ_Titanwood_Log"
    },
    {
      "x": -7,
      "y": 24,
      "z": 0,
      "name": "TFJ_Titanwood_Log"
    },
    {
      "x": -7,
      "y": 25,
      "z": 0,
      "name": "TFJ_Titanwood_Log"
    },
    {
      "x": -7,
      "y": 28,
      "z": 0,
      "name": "TFJ_Canopy_Leaves"
    },
    {
      "x": -7,
      "y": 28,
      "z": 1,
      "name": "TFJ_Canopy_Leaves"
    },
    {
      "x": -7,
      "y": 27,
      "z": 2,
      "name": "TFJ_Canopy_Leaves"
    },
    {
      "x": -7,
      "y": 28,
      "z": 2,
      "name": "TFJ_Canopy_Leaves"
    },
    {
      "x": -7,
      "y": 26,
      "z": 3,
      "name": "TFJ_Canopy_Leaves"
    },
    {
      "x": -7,
      "y": 27,
      "z": 3,
      "name": "TFJ_Canopy_Leaves"
    },
    {
      "x": -7,
      "y": 24,
      "z": 4,
      "name": "TFJ_Canopy_Leaves"
    },
    {
      "x": -7,
      "y": 26,
      "z": 4,
      "name": "TFJ_Canopy_Leaves"
    },
    {
      "x": -7,
      "y": 27,
      "z": 4,
      "name": "TFJ_Canopy_Leaves"
    },
    {
      "x": -7,
      "y": 23,
      "z": 6,
      "name": "TFJ_Canopy_Leaves"
    },
    {
      "x": -7,
      "y": 24,
      "z": 6,
      "name": "TFJ_Canopy_Leaves"
    },
    {
      "x": -7,
      "y": 25,
      "z": 6,
      "name": "TFJ_Canopy_Leaves"
    },
    {
      "x": -7,
      "y": 22,
      "z": 7,
      "name": "TFJ_Canopy_Leaves"
    },
    {
      "x": -7,
      "y": 23,
      "z": 7,
      "name": "TFJ_Canopy_Leaves"
    },
    {
      "x": -7,
      "y": 24,
      "z": 7,
      "name": "TFJ_Canopy_Leaves"
    },
    {
      "x": -7,
      "y": 25,
      "z": 7,
      "name": "TFJ_Canopy_Leaves"
    },
    {
      "x": -7,
      "y": 23,
      "z": 8,
      "name": "TFJ_Canopy_Leaves"
    },
    {
      "x": -7,
      "y": 24,
      "z": 8,
      "name": "TFJ_Canopy_Leaves"
    },
    {
      "x": -6,
      "y": 22,
      "z": -11,
      "name": "TFJ_Canopy_Leaves"
    },
    {
      "x": -6,
      "y": 23,
      "z": -11,
      "name": "TFJ_Canopy_Leaves"
    },
    {
      "x": -6,
      "y": 24,
      "z": -11,
      "name": "TFJ_Canopy_Leaves"
    },
    {
      "x": -6,
      "y": 25,
      "z": -11,
      "name": "TFJ_Canopy_Leaves"
    },
    {
      "x": -6,
      "y": 22,
      "z": -10,
      "name": "TFJ_Canopy_Leaves"
    },
    {
      "x": -6,
      "y": 23,
      "z": -10,
      "name": "TFJ_Canopy_Leaves"
    },
    {
      "x": -6,
      "y": 24,
      "z": -10,
      "name": "TFJ_Canopy_Leaves"
    },
    {
      "x": -6,
      "y": 25,
      "z": -10,
      "name": "TFJ_Canopy_Leaves"
    },
    {
      "x": -6,
      "y": 26,
      "z": -10,
      "name": "TFJ_Canopy_Leaves"
    },
    {
      "x": -6,
      "y": 25,
      "z": -9,
      "name": "TFJ_Canopy_Leaves"
    },
    {
      "x": -6,
      "y": 26,
      "z": -9,
      "name": "TFJ_Canopy_Leaves"
    },
    {
      "x": -6,
      "y": 27,
      "z": -9,
      "name": "TFJ_Canopy_Leaves"
    },
    {
      "x": -6,
      "y": 26,
      "z": -8,
      "name": "TFJ_Canopy_Leaves"
    },
    {
      "x": -6,
      "y": 27,
      "z": -8,
      "name": "TFJ_Canopy_Leaves"
    },
    {
      "x": -6,
      "y": 26,
      "z": -7,
      "name": "TFJ_Canopy_Leaves"
    },
    {
      "x": -6,
      "y": 26,
      "z": -6,
      "name": "TFJ_Canopy_Leaves"
    },
    {
      "x": -6,
      "y": 27,
      "z": -6,
      "name": "TFJ_Canopy_Leaves"
    },
    {
      "x": -6,
      "y": 24,
      "z": 0,
      "name": "TFJ_Titanwood_Log"
    },
    {
      "x": -6,
      "y": 28,
      "z": 1,
      "name": "TFJ_Canopy_Leaves"
    },
    {
      "x": -6,
      "y": 27,
      "z": 2,
      "name": "TFJ_Canopy_Leaves"
    },
    {
      "x": -6,
      "y": 29,
      "z": 2,
      "name": "TFJ_Canopy_Leaves"
    },
    {
      "x": -6,
      "y": 30,
      "z": 2,
      "name": "TFJ_Canopy_Leaves"
    },
    {
      "x": -6,
      "y": 31,
      "z": 2,
      "name": "TFJ_Canopy_Leaves"
    },
    {
      "x": -6,
      "y": 31,
      "z": 3,
      "name": "TFJ_Canopy_Leaves"
    },
    {
      "x": -6,
      "y": 31,
      "z": 4,
      "name": "TFJ_Canopy_Leaves"
    },
    {
      "x": -6,
      "y": 24,
      "z": 6,
      "name": "TFJ_Canopy_Leaves"
    },
    {
      "x": -6,
      "y": 26,
      "z": 6,
      "name": "TFJ_Canopy_Leaves"
    },
    {
      "x": -6,
      "y": 22,
      "z": 7,
      "name": "TFJ_Canopy_Leaves"
    },
    {
      "x": -6,
      "y": 23,
      "z": 7,
      "name": "TFJ_Canopy_Leaves"
    },
    {
      "x": -6,
      "y": 24,
      "z": 7,
      "name": "TFJ_Canopy_Leaves"
    },
    {
      "x": -6,
      "y": 21,
      "z": 8,
      "name": "TFJ_Canopy_Leaves"
    },
    {
      "x": -6,
      "y": 22,
      "z": 8,
      "name": "TFJ_Canopy_Leaves"
    },
    {
      "x": -6,
      "y": 23,
      "z": 8,
      "name": "TFJ_Canopy_Leaves"
    },
    {
      "x": -6,
      "y": 26,
      "z": 8,
      "name": "TFJ_Canopy_Leaves"
    },
    {
      "x": -6,
      "y": 21,
      "z": 9,
      "name": "TFJ_Canopy_Leaves"
    },
    {
      "x": -6,
      "y": 22,
      "z": 9,
      "name": "TFJ_Canopy_Leaves"
    },
    {
      "x": -6,
      "y": 23,
      "z": 9,
      "name": "TFJ_Canopy_Leaves"
    },
    {
      "x": -6,
      "y": 22,
      "z": 10,
      "name": "TFJ_Canopy_Leaves"
    },
    {
      "x": -6,
      "y": 23,
      "z": 10,
      "name": "TFJ_Canopy_Leaves"
    },
    {
      "x": -5,
      "y": 23,
      "z": -12,
      "name": "TFJ_Canopy_Leaves"
    },
    {
      "x": -5,
      "y": 23,
      "z": -11,
      "name": "TFJ_Canopy_Leaves"
    },
    {
      "x": -5,
      "y": 24,
      "z": -11,
      "name": "TFJ_Canopy_Leaves"
    },
    {
      "x": -5,
      "y": 25,
      "z": -11,
      "name": "TFJ_Canopy_Leaves"
    },
    {
      "x": -5,
      "y": 26,
      "z": -11,
      "name": "TFJ_Canopy_Leaves"
    },
    {
      "x": -5,
      "y": 26,
      "z": -10,
      "name": "TFJ_Canopy_Leaves"
    },
    {
      "x": -5,
      "y": 27,
      "z": -10,
      "name": "TFJ_Canopy_Leaves"
    },
    {
      "x": -5,
      "y": 27,
      "z": -9,
      "name": "TFJ_Canopy_Leaves"
    },
    {
      "x": -5,
      "y": 24,
      "z": -8,
      "name": "TFJ_Titanwood_Log",
      "rotation": 3
    },
    {
      "x": -5,
      "y": 25,
      "z": -8,
      "name": "TFJ_Titanwood_Log"
    },
    {
      "x": -5,
      "y": 26,
      "z": -8,
      "name": "TFJ_Titanwood_Log"
    },
    {
      "x": -5,
      "y": 27,
      "z": -8,
      "name": "TFJ_Canopy_Leaves"
    },
    {
      "x": -5,
      "y": 28,
      "z": -8,
      "name": "TFJ_Canopy_Leaves"
    },
    {
      "x": -5,
      "y": 23,
      "z": -1,
      "name": "TFJ_Titanwood_Log"
    },
    {
      "x": -5,
      "y": 24,
      "z": -1,
      "name": "TFJ_Titanwood_Log"
    },
    {
      "x": -5,
      "y": 24,
      "z": 0,
      "name": "TFJ_Titanwood_Log"
    },
    {
      "x": -5,
      "y": 31,
      "z": 0,
      "name": "TFJ_Canopy_Leaves"
    },
    {
      "x": -5,
      "y": 28,
      "z": 1,
      "name": "TFJ_Canopy_Leaves"
    },
    {
      "x": -5,
      "y": 31,
      "z": 1,
      "name": "TFJ_Canopy_Leaves"
    },
    {
      "x": -5,
      "y": 32,
      "z": 1,
      "name": "TFJ_Canopy_Leaves"
    },
    {
      "x": -5,
      "y": 28,
      "z": 2,
      "name": "TFJ_Canopy_Leaves"
    },
    {
      "x": -5,
      "y": 30,
      "z": 2,
      "name": "TFJ_Canopy_Leaves"
    },
    {
      "x": -5,
      "y": 31,
      "z": 2,
      "name": "TFJ_Canopy_Leaves"
    },
    {
      "x": -5,
      "y": 32,
      "z": 2,
      "name": "TFJ_Canopy_Leaves"
    },
    {
      "x": -5,
      "y": 33,
      "z": 2,
      "name": "TFJ_Canopy_Leaves"
    },
    {
      "x": -5,
      "y": 32,
      "z": 3,
      "name": "TFJ_Canopy_Leaves"
    },
    {
      "x": -5,
      "y": 32,
      "z": 4,
      "name": "TFJ_Canopy_Leaves"
    },
    {
      "x": -5,
      "y": 33,
      "z": 4,
      "name": "TFJ_Canopy_Leaves"
    },
    {
      "x": -5,
      "y": 26,
      "z": 5,
      "name": "TFJ_Canopy_Leaves"
    },
    {
      "x": -5,
      "y": 30,
      "z": 5,
      "name": "TFJ_Canopy_Leaves"
    },
    {
      "x": -5,
      "y": 26,
      "z": 6,
      "name": "TFJ_Canopy_Leaves"
    },
    {
      "x": -5,
      "y": 22,
      "z": 7,
      "name": "TFJ_Titanwood_Log",
      "rotation": 3
    },
    {
      "x": -5,
      "y": 23,
      "z": 7,
      "name": "TFJ_Titanwood_Log"
    },
    {
      "x": -5,
      "y": 24,
      "z": 7,
      "name": "TFJ_Titanwood_Log"
    },
    {
      "x": -5,
      "y": 25,
      "z": 7,
      "name": "TFJ_Canopy_Leaves"
    },
    {
      "x": -5,
      "y": 23,
      "z": 8,
      "name": "TFJ_Canopy_Leaves"
    },
    {
      "x": -5,
      "y": 25,
      "z": 8,
      "name": "TFJ_Canopy_Leaves"
    },
    {
      "x": -5,
      "y": 26,
      "z": 8,
      "name": "TFJ_Canopy_Leaves"
    },
    {
      "x": -5,
      "y": 23,
      "z": 9,
      "name": "TFJ_Canopy_Leaves"
    },
    {
      "x": -5,
      "y": 24,
      "z": 9,
      "name": "TFJ_Canopy_Leaves"
    },
    {
      "x": -5,
      "y": 25,
      "z": 9,
      "name": "TFJ_Canopy_Leaves"
    },
    {
      "x": -5,
      "y": 22,
      "z": 10,
      "name": "TFJ_Canopy_Leaves"
    },
    {
      "x": -5,
      "y": 23,
      "z": 10,
      "name": "TFJ_Canopy_Leaves"
    },
    {
      "x": -5,
      "y": 24,
      "z": 10,
      "name": "TFJ_Canopy_Leaves"
    },
    {
      "x": -5,
      "y": 25,
      "z": 10,
      "name": "TFJ_Canopy_Leaves"
    },
    {
      "x": -5,
      "y": 21,
      "z": 11,
      "name": "TFJ_Canopy_Leaves"
    },
    {
      "x": -5,
      "y": 22,
      "z": 11,
      "name": "TFJ_Canopy_Leaves"
    },
    {
      "x": -5,
      "y": 23,
      "z": 11,
      "name": "TFJ_Canopy_Leaves"
    },
    {
      "x": -5,
      "y": 21,
      "z": 12,
      "name": "TFJ_Canopy_Leaves"
    },
    {
      "x": -5,
      "y": 22,
      "z": 12,
      "name": "TFJ_Canopy_Leaves"
    },
    {
      "x": -4,
      "y": 23,
      "z": -12,
      "name": "TFJ_Canopy_Leaves"
    },
    {
      "x": -4,
      "y": 24,
      "z": -12,
      "name": "TFJ_Canopy_Leaves"
    },
    {
      "x": -4,
      "y": 25,
      "z": -12,
      "name": "TFJ_Canopy_Leaves"
    },
    {
      "x": -4,
      "y": 25,
      "z": -11,
      "name": "TFJ_Canopy_Leaves"
    },
    {
      "x": -4,
      "y": 26,
      "z": -11,
      "name": "TFJ_Canopy_Leaves"
    },
    {
      "x": -4,
      "y": 24,
      "z": -10,
      "name": "TFJ_Titanwood_Log",
      "rotation": 2
    },
    {
      "x": -4,
      "y": 25,
      "z": -10,
      "name": "TFJ_Titanwood_Log"
    },
    {
      "x": -4,
      "y": 26,
      "z": -10,
      "name": "TFJ_Titanwood_Log"
    },
    {
      "x": -4,
      "y": 27,
      "z": -10,
      "name": "TFJ_Canopy_Leaves"
    },
    {
      "x": -4,
      "y": 24,
      "z": -9,
      "name": "TFJ_Titanwood_Log",
      "rotation": 4
    },
    {
      "x": -4,
      "y": 27,
      "z": -9,
      "name": "TFJ_Canopy_Leaves"
    },
    {
      "x": -4,
      "y": 28,
      "z": -9,
      "name": "TFJ_Canopy_Leaves"
    },
    {
      "x": -4,
      "y": 24,
      "z": -8,
      "name": "TFJ_Titanwood_Log"
    },
    {
      "x": -4,
      "y": 27,
      "z": -8,
      "name": "TFJ_Canopy_Leaves"
    },
    {
      "x": -4,
      "y": 28,
      "z": -8,
      "name": "TFJ_Canopy_Leaves"
    },
    {
      "x": -4,
      "y": 23,
      "z": -7,
      "name": "TFJ_Titanwood_Log"
    },
    {
      "x": -4,
      "y": 24,
      "z": -7,
      "name": "TFJ_Titanwood_Log"
    },
    {
      "x": -4,
      "y": 28,
      "z": -7,
      "name": "TFJ_Canopy_Leaves"
    },
    {
      "x": -4,
      "y": 28,
      "z": -6,
      "name": "TFJ_Canopy_Leaves"
    },
    {
      "x": -4,
      "y": 23,
      "z": -1,
      "name": "TFJ_Titanwood_Log"
    },
    {
      "x": -4,
      "y": 30,
      "z": -1,
      "name": "TFJ_Canopy_Leaves"
    },
    {
      "x": -4,
      "y": 31,
      "z": -1,
      "name": "TFJ_Canopy_Leaves"
    },
    {
      "x": -4,
      "y": 32,
      "z": 0,
      "name": "TFJ_Canopy_Leaves"
    },
    {
      "x": -4,
      "y": 33,
      "z": 0,
      "name": "TFJ_Canopy_Leaves"
    },
    {
      "x": -4,
      "y": 33,
      "z": 1,
      "name": "TFJ_Canopy_Leaves"
    },
    {
      "x": -4,
      "y": 27,
      "z": 2,
      "name": "TFJ_Canopy_Leaves"
    },
    {
      "x": -4,
      "y": 28,
      "z": 2,
      "name": "TFJ_Canopy_Leaves"
    },
    {
      "x": -4,
      "y": 30,
      "z": 2,
      "name": "TFJ_Titanwood_Log",
      "rotation": 5
    },
    {
      "x": -4,
      "y": 32,
      "z": 2,
      "name": "TFJ_Canopy_Leaves"
    },
    {
      "x": -4,
      "y": 33,
      "z": 2,
      "name": "TFJ_Canopy_Leaves"
    },
    {
      "x": -4,
      "y": 34,
      "z": 2,
      "name": "TFJ_Canopy_Leaves"
    },
    {
      "x": -4,
      "y": 33,
      "z": 3,
      "name": "TFJ_Canopy_Leaves"
    },
    {
      "x": -4,
      "y": 33,
      "z": 4,
      "name": "TFJ_Canopy_Leaves"
    },
    {
      "x": -4,
      "y": 30,
      "z": 5,
      "name": "TFJ_Canopy_Leaves"
    },
    {
      "x": -4,
      "y": 31,
      "z": 5,
      "name": "TFJ_Canopy_Leaves"
    },
    {
      "x": -4,
      "y": 32,
      "z": 5,
      "name": "TFJ_Canopy_Leaves"
    },
    {
      "x": -4,
      "y": 26,
      "z": 6,
      "name": "TFJ_Canopy_Leaves"
    },
    {
      "x": -4,
      "y": 30,
      "z": 6,
      "name": "TFJ_Canopy_Leaves"
    },
    {
      "x": -4,
      "y": 31,
      "z": 6,
      "name": "TFJ_Canopy_Leaves"
    },
    {
      "x": -4,
      "y": 22,
      "z": 7,
      "name": "TFJ_Titanwood_Log",
      "rotation": 5
    },
    {
      "x": -4,
      "y": 25,
      "z": 7,
      "name": "TFJ_Canopy_Leaves"
    },
    {
      "x": -4,
      "y": 26,
      "z": 7,
      "name": "TFJ_Canopy_Leaves"
    },
    {
      "x": -4,
      "y": 25,
      "z": 8,
      "name": "TFJ_Canopy_Leaves"
    },
    {
      "x": -4,
      "y": 26,
      "z": 8,
      "name": "TFJ_Canopy_Leaves"
    },
    {
      "x": -4,
      "y": 25,
      "z": 9,
      "name": "TFJ_Canopy_Leaves"
    },
    {
      "x": -4,
      "y": 26,
      "z": 9,
      "name": "TFJ_Canopy_Leaves"
    },
    {
      "x": -4,
      "y": 22,
      "z": 10,
      "name": "TFJ_Canopy_Leaves"
    },
    {
      "x": -4,
      "y": 26,
      "z": 10,
      "name": "TFJ_Canopy_Leaves"
    },
    {
      "x": -4,
      "y": 22,
      "z": 11,
      "name": "TFJ_Canopy_Leaves"
    },
    {
      "x": -4,
      "y": 23,
      "z": 11,
      "name": "TFJ_Canopy_Leaves"
    },
    {
      "x": -4,
      "y": 26,
      "z": 11,
      "name": "TFJ_Canopy_Leaves"
    },
    {
      "x": -4,
      "y": 22,
      "z": 12,
      "name": "TFJ_Canopy_Leaves"
    },
    {
      "x": -4,
      "y": 23,
      "z": 12,
      "name": "TFJ_Canopy_Leaves"
    },
    {
      "x": -3,
      "y": 24,
      "z": -12,
      "name": "TFJ_Canopy_Leaves"
    },
    {
      "x": -3,
      "y": 25,
      "z": -12,
      "name": "TFJ_Canopy_Leaves"
    },
    {
      "x": -3,
      "y": 25,
      "z": -11,
      "name": "TFJ_Canopy_Leaves"
    },
    {
      "x": -3,
      "y": 26,
      "z": -11,
      "name": "TFJ_Canopy_Leaves"
    },
    {
      "x": -3,
      "y": 27,
      "z": -11,
      "name": "TFJ_Canopy_Leaves"
    },
    {
      "x": -3,
      "y": 26,
      "z": -10,
      "name": "TFJ_Canopy_Leaves"
    },
    {
      "x": -3,
      "y": 27,
      "z": -10,
      "name": "TFJ_Canopy_Leaves"
    },
    {
      "x": -3,
      "y": 28,
      "z": -9,
      "name": "TFJ_Canopy_Leaves"
    },
    {
      "x": -3,
      "y": 24,
      "z": -7,
      "name": "TFJ_Titanwood_Log"
    },
    {
      "x": -3,
      "y": 25,
      "z": -7,
      "name": "TFJ_Titanwood_Log"
    },
    {
      "x": -3,
      "y": 26,
      "z": -7,
      "name": "TFJ_Titanwood_Log"
    },
    {
      "x": -3,
      "y": 27,
      "z": -7,
      "name": "TFJ_Titanwood_Log"
    },
    {
      "x": -3,
      "y": 28,
      "z": -7,
      "name": "TFJ_Canopy_Leaves"
    },
    {
      "x": -3,
      "y": 29,
      "z": -7,
      "name": "TFJ_Canopy_Leaves"
    },
    {
      "x": -3,
      "y": 30,
      "z": -7,
      "name": "TFJ_Canopy_Leaves"
    },
    {
      "x": -3,
      "y": 24,
      "z": -6,
      "name": "TFJ_Titanwood_Log"
    },
    {
      "x": -3,
      "y": 27,
      "z": -6,
      "name": "TFJ_Canopy_Leaves"
    },
    {
      "x": -3,
      "y": 28,
      "z": -6,
      "name": "TFJ_Canopy_Leaves"
    },
    {
      "x": -3,
      "y": 29,
      "z": -6,
      "name": "TFJ_Canopy_Leaves"
    },
    {
      "x": -3,
      "y": 30,
      "z": -6,
      "name": "TFJ_Canopy_Leaves"
    },
    {
      "x": -3,
      "y": 28,
      "z": -5,
      "name": "TFJ_Canopy_Leaves"
    },
    {
      "x": -3,
      "y": 29,
      "z": -5,
      "name": "TFJ_Canopy_Leaves"
    },
    {
      "x": -3,
      "y": 30,
      "z": -5,
      "name": "TFJ_Canopy_Leaves"
    },
    {
      "x": -3,
      "y": 31,
      "z": -5,
      "name": "TFJ_Canopy_Leaves"
    },
    {
      "x": -3,
      "y": 28,
      "z": -4,
      "name": "TFJ_Canopy_Leaves"
    },
    {
      "x": -3,
      "y": 30,
      "z": -4,
      "name": "TFJ_Canopy_Leaves"
    },
    {
      "x": -3,
      "y": 29,
      "z": -3,
      "name": "TFJ_Canopy_Leaves"
    },
    {
      "x": -3,
      "y": 22,
      "z": -1,
      "name": "TFJ_Titanwood_Log"
    },
    {
      "x": -3,
      "y": 23,
      "z": -1,
      "name": "TFJ_Titanwood_Log"
    },
    {
      "x": -3,
      "y": 29,
      "z": -1,
      "name": "TFJ_Canopy_Leaves"
    },
    {
      "x": -3,
      "y": 30,
      "z": -1,
      "name": "TFJ_Canopy_Leaves"
    },
    {
      "x": -3,
      "y": 31,
      "z": -1,
      "name": "TFJ_Canopy_Leaves"
    },
    {
      "x": -3,
      "y": 32,
      "z": -1,
      "name": "TFJ_Canopy_Leaves"
    },
    {
      "x": -3,
      "y": 8,
      "z": 0,
      "name": "TFJ_Titanwood_Log"
    },
    {
      "x": -3,
      "y": 9,
      "z": 0,
      "name": "TFJ_Titanwood_Log"
    },
    {
      "x": -3,
      "y": 10,
      "z": 0,
      "name": "TFJ_Titanwood_Log"
    },
    {
      "x": -3,
      "y": 11,
      "z": 0,
      "name": "TFJ_Titanwood_Log"
    },
    {
      "x": -3,
      "y": 12,
      "z": 0,
      "name": "TFJ_Titanwood_Log",
      "rotation": 9
    },
    {
      "x": -3,
      "y": 32,
      "z": 0,
      "name": "TFJ_Canopy_Leaves"
    },
    {
      "x": -3,
      "y": 33,
      "z": 0,
      "name": "TFJ_Canopy_Leaves"
    },
    {
      "x": -3,
      "y": 33,
      "z": 1,
      "name": "TFJ_Canopy_Leaves"
    },
    {
      "x": -3,
      "y": 34,
      "z": 1,
      "name": "TFJ_Canopy_Leaves"
    },
    {
      "x": -3,
      "y": 30,
      "z": 2,
      "name": "TFJ_Titanwood_Log",
      "rotation": 5
    },
    {
      "x": -3,
      "y": 33,
      "z": 2,
      "name": "TFJ_Canopy_Leaves"
    },
    {
      "x": -3,
      "y": 34,
      "z": 2,
      "name": "TFJ_Canopy_Leaves"
    },
    {
      "x": -3,
      "y": 34,
      "z": 4,
      "name": "TFJ_Canopy_Leaves"
    },
    {
      "x": -3,
      "y": 26,
      "z": 5,
      "name": "TFJ_Canopy_Leaves"
    },
    {
      "x": -3,
      "y": 31,
      "z": 5,
      "name": "TFJ_Canopy_Leaves"
    },
    {
      "x": -3,
      "y": 33,
      "z": 5,
      "name": "TFJ_Canopy_Leaves"
    },
    {
      "x": -3,
      "y": 31,
      "z": 6,
      "name": "TFJ_Canopy_Leaves"
    },
    {
      "x": -3,
      "y": 32,
      "z": 6,
      "name": "TFJ_Canopy_Leaves"
    },
    {
      "x": -3,
      "y": 22,
      "z": 7,
      "name": "TFJ_Titanwood_Log",
      "rotation": 5
    },
    {
      "x": -3,
      "y": 26,
      "z": 7,
      "name": "TFJ_Canopy_Leaves"
    },
    {
      "x": -3,
      "y": 27,
      "z": 7,
      "name": "TFJ_Canopy_Leaves"
    },
    {
      "x": -3,
      "y": 31,
      "z": 7,
      "name": "TFJ_Canopy_Leaves"
    },
    {
      "x": -3,
      "y": 32,
      "z": 7,
      "name": "TFJ_Canopy_Leaves"
    },
    {
      "x": -3,
      "y": 26,
      "z": 8,
      "name": "TFJ_Canopy_Leaves"
    },
    {
      "x": -3,
      "y": 27,
      "z": 8,
      "name": "TFJ_Canopy_Leaves"
    },
    {
      "x": -3,
      "y": 26,
      "z": 9,
      "name": "TFJ_Canopy_Leaves"
    },
    {
      "x": -3,
      "y": 25,
      "z": 11,
      "name": "TFJ_Canopy_Leaves"
    },
    {
      "x": -3,
      "y": 21,
      "z": 12,
      "name": "TFJ_Canopy_Leaves"
    },
    {
      "x": -3,
      "y": 22,
      "z": 12,
      "name": "TFJ_Canopy_Leaves"
    },
    {
      "x": -3,
      "y": 23,
      "z": 12,
      "name": "TFJ_Canopy_Leaves"
    },
    {
      "x": -3,
      "y": 24,
      "z": 12,
      "name": "TFJ_Canopy_Leaves"
    },
    {
      "x": -3,
      "y": 21,
      "z": 13,
      "name": "TFJ_Canopy_Leaves"
    },
    {
      "x": -3,
      "y": 22,
      "z": 13,
      "name": "TFJ_Canopy_Leaves"
    },
    {
      "x": -2,
      "y": 25,
      "z": -12,
      "name": "TFJ_Canopy_Leaves"
    },
    {
      "x": -2,
      "y": 26,
      "z": -11,
      "name": "TFJ_Canopy_Leaves"
    },
    {
      "x": -2,
      "y": 26,
      "z": -10,
      "name": "TFJ_Canopy_Leaves"
    },
    {
      "x": -2,
      "y": 27,
      "z": -10,
      "name": "TFJ_Canopy_Leaves"
    },
    {
      "x": -2,
      "y": 26,
      "z": -9,
      "name": "TFJ_Canopy_Leaves"
    },
    {
      "x": -2,
      "y": 27,
      "z": -9,
      "name": "TFJ_Canopy_Leaves"
    },
    {
      "x": -2,
      "y": 29,
      "z": -8,
      "name": "TFJ_Canopy_Leaves"
    },
    {
      "x": -2,
      "y": 30,
      "z": -8,
      "name": "TFJ_Canopy_Leaves"
    },
    {
      "x": -2,
      "y": 28,
      "z": -7,
      "name": "TFJ_Canopy_Leaves"
    },
    {
      "x": -2,
      "y": 29,
      "z": -7,
      "name": "TFJ_Canopy_Leaves"
    },
    {
      "x": -2,
      "y": 30,
      "z": -7,
      "name": "TFJ_Canopy_Leaves"
    },
    {
      "x": -2,
      "y": 31,
      "z": -7,
      "name": "TFJ_Canopy_Leaves"
    },
    {
      "x": -2,
      "y": 24,
      "z": -6,
      "name": "TFJ_Titanwood_Log"
    },
    {
      "x": -2,
      "y": 28,
      "z": -6,
      "name": "TFJ_Canopy_Leaves"
    },
    {
      "x": -2,
      "y": 31,
      "z": -6,
      "name": "TFJ_Canopy_Leaves"
    },
    {
      "x": -2,
      "y": 23,
      "z": -5,
      "name": "TFJ_Titanwood_Log"
    },
    {
      "x": -2,
      "y": 24,
      "z": -5,
      "name": "TFJ_Titanwood_Log"
    },
    {
      "x": -2,
      "y": 28,
      "z": -5,
      "name": "TFJ_Titanwood_Log",
      "rotation": 3
    },
    {
      "x": -2,
      "y": 29,
      "z": -5,
      "name": "TFJ_Titanwood_Log"
    },
    {
      "x": -2,
      "y": 30,
      "z": -5,
      "name": "TFJ_Canopy_Leaves"
    },
    {
      "x": -2,
      "y": 31,
      "z": -5,
      "name": "TFJ_Canopy_Leaves"
    },
    {
      "x": -2,
      "y": 23,
      "z": -4,
      "name": "TFJ_Titanwood_Log"
    },
    {
      "x": -2,
      "y": 30,
      "z": -4,
      "name": "TFJ_Canopy_Leaves"
    },
    {
      "x": -2,
      "y": 28,
      "z": -3,
      "name": "TFJ_Canopy_Leaves"
    },
    {
      "x": -2,
      "y": 29,
      "z": -3,
      "name": "TFJ_Canopy_Leaves"
    },
    {
      "x": -2,
      "y": 30,
      "z": -3,
      "name": "TFJ_Canopy_Leaves"
    },
    {
      "x": -2,
      "y": 31,
      "z": -3,
      "name": "TFJ_Canopy_Leaves"
    },
    {
      "x": -2,
      "y": 8,
      "z": -2,
      "name": "TFJ_Titanwood_Log"
    },
    {
      "x": -2,
      "y": 9,
      "z": -2,
      "name": "TFJ_Titanwood_Log"
    },
    {
      "x": -2,
      "y": 10,
      "z": -2,
      "name": "TFJ_Titanwood_Log"
    },
    {
      "x": -2,
      "y": 11,
      "z": -2,
      "name": "TFJ_Titanwood_Log",
      "rotation": 8
    },
    {
      "x": -2,
      "y": 29,
      "z": -2,
      "name": "TFJ_Canopy_Leaves"
    },
    {
      "x": -2,
      "y": 8,
      "z": -1,
      "name": "TFJ_Titanwood_Log"
    },
    {
      "x": -2,
      "y": 9,
      "z": -1,
      "name": "TFJ_Titanwood_Log"
    },
    {
      "x": -2,
      "y": 10,
      "z": -1,
      "name": "TFJ_Titanwood_Log"
    },
    {
      "x": -2,
      "y": 11,
      "z": -1,
      "name": "TFJ_Titanwood_Log"
    },
    {
      "x": -2,
      "y": 12,
      "z": -1,
      "name": "TFJ_Titanwood_Log"
    },
    {
      "x": -2,
      "y": 13,
      "z": -1,
      "name": "TFJ_Titanwood_Log"
    },
    {
      "x": -2,
      "y": 14,
      "z": -1,
      "name": "TFJ_Titanwood_Log",
      "rotation": 9
    },
    {
      "x": -2,
      "y": 21,
      "z": -1,
      "name": "TFJ_Titanwood_Log"
    },
    {
      "x": -2,
      "y": 22,
      "z": -1,
      "name": "TFJ_Titanwood_Log"
    },
    {
      "x": -2,
      "y": 33,
      "z": -1,
      "name": "TFJ_Canopy_Leaves"
    },
    {
      "x": -2,
      "y": 8,
      "z": 0,
      "name": "TFJ_Titanwood_Log"
    },
    {
      "x": -2,
      "y": 9,
      "z": 0,
      "name": "TFJ_Titanwood_Log"
    },
    {
      "x": -2,
      "y": 10,
      "z": 0,
      "name": "TFJ_Titanwood_Log"
    },
    {
      "x": -2,
      "y": 11,
      "z": 0,
      "name": "TFJ_Titanwood_Log"
    },
    {
      "x": -2,
      "y": 12,
      "z": 0,
      "name": "TFJ_Titanwood_Log"
    },
    {
      "x": -2,
      "y": 13,
      "z": 0,
      "name": "TFJ_Titanwood_Log"
    },
    {
      "x": -2,
      "y": 14,
      "z": 0,
      "name": "TFJ_Titanwood_Log",
      "rotation": 9
    },
    {
      "x": -2,
      "y": 32,
      "z": 0,
      "name": "TFJ_Canopy_Leaves"
    },
    {
      "x": -2,
      "y": 33,
      "z": 0,
      "name": "TFJ_Canopy_Leaves"
    },
    {
      "x": -2,
      "y": 8,
      "z": 1,
      "name": "TFJ_Titanwood_Log"
    },
    {
      "x": -2,
      "y": 9,
      "z": 1,
      "name": "TFJ_Titanwood_Log"
    },
    {
      "x": -2,
      "y": 10,
      "z": 1,
      "name": "TFJ_Titanwood_Log"
    },
    {
      "x": -2,
      "y": 11,
      "z": 1,
      "name": "TFJ_Titanwood_Log"
    },
    {
      "x": -2,
      "y": 12,
      "z": 1,
      "name": "TFJ_Titanwood_Log",
      "rotation": 10
    },
    {
      "x": -2,
      "y": 34,
      "z": 1,
      "name": "TFJ_Canopy_Leaves"
    },
    {
      "x": -2,
      "y": 27,
      "z": 2,
      "name": "TFJ_Titanwood_Log"
    },
    {
      "x": -2,
      "y": 28,
      "z": 2,
      "name": "TFJ_Titanwood_Log"
    },
    {
      "x": -2,
      "y": 29,
      "z": 2,
      "name": "TFJ_Titanwood_Log"
    },
    {
      "x": -2,
      "y": 30,
      "z": 2,
      "name": "TFJ_Titanwood_Log"
    },
    {
      "x": -2,
      "y": 31,
      "z": 2,
      "name": "TFJ_Titanwood_Log"
    },
    {
      "x": -2,
      "y": 32,
      "z": 2,
      "name": "TFJ_Titanwood_Log"
    },
    {
      "x": -2,
      "y": 33,
      "z": 2,
      "name": "TFJ_Titanwood_Log"
    },
    {
      "x": -2,
      "y": 34,
      "z": 2,
      "name": "TFJ_Canopy_Leaves"
    },
    {
      "x": -2,
      "y": 31,
      "z": 3,
      "name": "TFJ_Titanwood_Log",
      "rotation": 4
    },
    {
      "x": -2,
      "y": 34,
      "z": 3,
      "name": "TFJ_Canopy_Leaves"
    },
    {
      "x": -2,
      "y": 31,
      "z": 4,
      "name": "TFJ_Titanwood_Log",
      "rotation": 4
    },
    {
      "x": -2,
      "y": 34,
      "z": 4,
      "name": "TFJ_Canopy_Leaves"
    },
    {
      "x": -2,
      "y": 21,
      "z": 5,
      "name": "TFJ_Titanwood_Log"
    },
    {
      "x": -2,
      "y": 31,
      "z": 5,
      "name": "TFJ_Titanwood_Log"
    },
    {
      "x": -2,
      "y": 32,
      "z": 5,
      "name": "TFJ_Titanwood_Log"
    },
    {
      "x": -2,
      "y": 33,
      "z": 5,
      "name": "TFJ_Canopy_Leaves"
    },
    {
      "x": -2,
      "y": 21,
      "z": 6,
      "name": "TFJ_Titanwood_Log"
    },
    {
      "x": -2,
      "y": 27,
      "z": 6,
      "name": "TFJ_Canopy_Leaves"
    },
    {
      "x": -2,
      "y": 32,
      "z": 6,
      "name": "TFJ_Canopy_Leaves"
    },
    {
      "x": -2,
      "y": 33,
      "z": 6,
      "name": "TFJ_Canopy_Leaves"
    },
    {
      "x": -2,
      "y": 21,
      "z": 7,
      "name": "TFJ_Titanwood_Log"
    },
    {
      "x": -2,
      "y": 22,
      "z": 7,
      "name": "TFJ_Titanwood_Log"
    },
    {
      "x": -2,
      "y": 23,
      "z": 7,
      "name": "TFJ_Titanwood_Log"
    },
    {
      "x": -2,
      "y": 24,
      "z": 7,
      "name": "TFJ_Titanwood_Log"
    },
    {
      "x": -2,
      "y": 25,
      "z": 7,
      "name": "TFJ_Titanwood_Log"
    },
    {
      "x": -2,
      "y": 26,
      "z": 7,
      "name": "TFJ_Canopy_Leaves"
    },
    {
      "x": -2,
      "y": 27,
      "z": 7,
      "name": "TFJ_Canopy_Leaves"
    },
    {
      "x": -2,
      "y": 29,
      "z": 7,
      "name": "TFJ_Canopy_Leaves"
    },
    {
      "x": -2,
      "y": 30,
      "z": 7,
      "name": "TFJ_Canopy_Leaves"
    },
    {
      "x": -2,
      "y": 31,
      "z": 7,
      "name": "TFJ_Canopy_Leaves"
    },
    {
      "x": -2,
      "y": 32,
      "z": 7,
      "name": "TFJ_Canopy_Leaves"
    },
    {
      "x": -2,
      "y": 22,
      "z": 8,
      "name": "TFJ_Titanwood_Log"
    },
    {
      "x": -2,
      "y": 23,
      "z": 8,
      "name": "TFJ_Titanwood_Log"
    },
    {
      "x": -2,
      "y": 24,
      "z": 8,
      "name": "TFJ_Titanwood_Log",
      "rotation": 8
    },
    {
      "x": -2,
      "y": 26,
      "z": 8,
      "name": "TFJ_Canopy_Leaves"
    },
    {
      "x": -2,
      "y": 27,
      "z": 8,
      "name": "TFJ_Canopy_Leaves"
    },
    {
      "x": -2,
      "y": 22,
      "z": 9,
      "name": "TFJ_Titanwood_Log",
      "rotation": 4
    },
    {
      "x": -2,
      "y": 24,
      "z": 9,
      "name": "TFJ_Titanwood_Log"
    },
    {
      "x": -2,
      "y": 25,
      "z": 9,
      "name": "TFJ_Canopy_Leaves"
    },
    {
      "x": -2,
      "y": 26,
      "z": 9,
      "name": "TFJ_Canopy_Leaves"
    },
    {
      "x": -2,
      "y": 27,
      "z": 9,
      "name": "TFJ_Canopy_Leaves"
    },
    {
      "x": -2,
      "y": 22,
      "z": 10,
      "name": "TFJ_Titanwood_Log",
      "rotation": 4
    },
    {
      "x": -2,
      "y": 25,
      "z": 10,
      "name": "TFJ_Canopy_Leaves"
    },
    {
      "x": -2,
      "y": 26,
      "z": 10,
      "name": "TFJ_Canopy_Leaves"
    },
    {
      "x": -2,
      "y": 22,
      "z": 11,
      "name": "TFJ_Titanwood_Log",
      "rotation": 4
    },
    {
      "x": -2,
      "y": 25,
      "z": 11,
      "name": "TFJ_Canopy_Leaves"
    },
    {
      "x": -2,
      "y": 26,
      "z": 11,
      "name": "TFJ_Canopy_Leaves"
    },
    {
      "x": -2,
      "y": 22,
      "z": 12,
      "name": "TFJ_Canopy_Leaves"
    },
    {
      "x": -2,
      "y": 23,
      "z": 12,
      "name": "TFJ_Canopy_Leaves"
    },
    {
      "x": -2,
      "y": 25,
      "z": 12,
      "name": "TFJ_Canopy_Leaves"
    },
    {
      "x": -2,
      "y": 20,
      "z": 13,
      "name": "TFJ_Canopy_Leaves"
    },
    {
      "x": -2,
      "y": 21,
      "z": 13,
      "name": "TFJ_Canopy_Leaves"
    },
    {
      "x": -2,
      "y": 22,
      "z": 13,
      "name": "TFJ_Canopy_Leaves"
    },
    {
      "x": -1,
      "y": 26,
      "z": -10,
      "name": "TFJ_Canopy_Leaves"
    },
    {
      "x": -1,
      "y": 26,
      "z": -9,
      "name": "TFJ_Canopy_Leaves"
    },
    {
      "x": -1,
      "y": 27,
      "z": -9,
      "name": "TFJ_Canopy_Leaves"
    },
    {
      "x": -1,
      "y": 29,
      "z": -9,
      "name": "TFJ_Canopy_Leaves"
    },
    {
      "x": -1,
      "y": 28,
      "z": -8,
      "name": "TFJ_Canopy_Leaves"
    },
    {
      "x": -1,
      "y": 29,
      "z": -8,
      "name": "TFJ_Canopy_Leaves"
    },
    {
      "x": -1,
      "y": 26,
      "z": -7,
      "name": "TFJ_Canopy_Leaves"
    },
    {
      "x": -1,
      "y": 27,
      "z": -7,
      "name": "TFJ_Canopy_Leaves"
    },
    {
      "x": -1,
      "y": 28,
      "z": -7,
      "name": "TFJ_Canopy_Leaves"
    },
    {
      "x": -1,
      "y": 29,
      "z": -7,
      "name": "TFJ_Canopy_Leaves"
    },
    {
      "x": -1,
      "y": 31,
      "z": -7,
      "name": "TFJ_Canopy_Leaves"
    },
    {
      "x": -1,
      "y": 32,
      "z": -6,
      "name": "TFJ_Canopy_Leaves"
    },
    {
      "x": -1,
      "y": 28,
      "z": -5,
      "name": "TFJ_Titanwood_Log",
      "rotation": 5
    },
    {
      "x": -1,
      "y": 32,
      "z": -5,
      "name": "TFJ_Canopy_Leaves"
    },
    {
      "x": -1,
      "y": 22,
      "z": -4,
      "name": "TFJ_Titanwood_Log"
    },
    {
      "x": -1,
      "y": 23,
      "z": -4,
      "name": "TFJ_Titanwood_Log"
    },
    {
      "x": -1,
      "y": 32,
      "z": -4,
      "name": "TFJ_Canopy_Leaves"
    },
    {
      "x": -1,
      "y": 22,
      "z": -3,
      "name": "TFJ_Titanwood_Log"
    },
    {
      "x": -1,
      "y": 23,
      "z": -3,
      "name": "TFJ_Titanwood_Log"
    },
    {
      "x": -1,
      "y": 31,
      "z": -3,
      "name": "TFJ_Canopy_Leaves"
    },
    {
      "x": -1,
      "y": 8,
      "z": -2,
      "name": "TFJ_Titanwood_Log"
    },
    {
      "x": -1,
      "y": 9,
      "z": -2,
      "name": "TFJ_Titanwood_Log"
    },
    {
      "x": -1,
      "y": 10,
      "z": -2,
      "name": "TFJ_Titanwood_Log"
    },
    {
      "x": -1,
      "y": 11,
      "z": -2,
      "name": "TFJ_Titanwood_Log"
    },
    {
      "x": -1,
      "y": 12,
      "z": -2,
      "name": "TFJ_Titanwood_Log"
    },
    {
      "x": -1,
      "y": 13,
      "z": -2,
      "name": "TFJ_Titanwood_Log"
    },
    {
      "x": -1,
      "y": 14,
      "z": -2,
      "name": "TFJ_Titanwood_Log"
    },
    {
      "x": -1,
      "y": 15,
      "z": -2,
      "name": "TFJ_Titanwood_Log",
      "rotation": 8
    },
    {
      "x": -1,
      "y": 21,
      "z": -2,
      "name": "TFJ_Titanwood_Log"
    },
    {
      "x": -1,
      "y": 22,
      "z": -2,
      "name": "TFJ_Titanwood_Log"
    },
    {
      "x": -1,
      "y": 31,
      "z": -2,
      "name": "TFJ_Canopy_Leaves"
    },
    {
      "x": -1,
      "y": 8,
      "z": -1,
      "name": "TFJ_Titanwood_Log"
    },
    {
      "x": -1,
      "y": 9,
      "z": -1,
      "name": "TFJ_Titanwood_Log"
    },
    {
      "x": -1,
      "y": 10,
      "z": -1,
      "name": "TFJ_Titanwood_Log"
    },
    {
      "x": -1,
      "y": 11,
      "z": -1,
      "name": "TFJ_Titanwood_Log"
    },
    {
      "x": -1,
      "y": 12,
      "z": -1,
      "name": "TFJ_Titanwood_Log"
    },
    {
      "x": -1,
      "y": 13,
      "z": -1,
      "name": "TFJ_Titanwood_Log"
    },
    {
      "x": -1,
      "y": 14,
      "z": -1,
      "name": "TFJ_Titanwood_Log"
    },
    {
      "x": -1,
      "y": 15,
      "z": -1,
      "name": "TFJ_Titanwood_Log"
    },
    {
      "x": -1,
      "y": 16,
      "z": -1,
      "name": "TFJ_Titanwood_Log"
    },
    {
      "x": -1,
      "y": 17,
      "z": -1,
      "name": "TFJ_Titanwood_Log"
    },
    {
      "x": -1,
      "y": 18,
      "z": -1,
      "name": "TFJ_Titanwood_Log"
    },
    {
      "x": -1,
      "y": 19,
      "z": -1,
      "name": "TFJ_Titanwood_Log"
    },
    {
      "x": -1,
      "y": 20,
      "z": -1,
      "name": "TFJ_Titanwood_Log"
    },
    {
      "x": -1,
      "y": 21,
      "z": -1,
      "name": "TFJ_Titanwood_Log"
    },
    {
      "x": -1,
      "y": 22,
      "z": -1,
      "name": "TFJ_Titanwood_Log"
    },
    {
      "x": -1,
      "y": 33,
      "z": -1,
      "name": "TFJ_Canopy_Leaves"
    },
    {
      "x": -1,
      "y": 8,
      "z": 0,
      "name": "TFJ_Titanwood_Log"
    },
    {
      "x": -1,
      "y": 9,
      "z": 0,
      "name": "TFJ_Titanwood_Log"
    },
    {
      "x": -1,
      "y": 10,
      "z": 0,
      "name": "TFJ_Titanwood_Log"
    },
    {
      "x": -1,
      "y": 11,
      "z": 0,
      "name": "TFJ_Titanwood_Log"
    },
    {
      "x": -1,
      "y": 12,
      "z": 0,
      "name": "TFJ_Titanwood_Log"
    },
    {
      "x": -1,
      "y": 13,
      "z": 0,
      "name": "TFJ_Titanwood_Log"
    },
    {
      "x": -1,
      "y": 14,
      "z": 0,
      "name": "TFJ_Titanwood_Log"
    },
    {
      "x": -1,
      "y": 15,
      "z": 0,
      "name": "TFJ_Titanwood_Log"
    },
    {
      "x": -1,
      "y": 16,
      "z": 0,
      "name": "TFJ_Titanwood_Log"
    },
    {
      "x": -1,
      "y": 17,
      "z": 0,
      "name": "TFJ_Titanwood_Log"
    },
    {
      "x": -1,
      "y": 18,
      "z": 0,
      "name": "TFJ_Titanwood_Log"
    },
    {
      "x": -1,
      "y": 19,
      "z": 0,
      "name": "TFJ_Titanwood_Log"
    },
    {
      "x": -1,
      "y": 20,
      "z": 0,
      "name": "TFJ_Titanwood_Log"
    },
    {
      "x": -1,
      "y": 21,
      "z": 0,
      "name": "TFJ_Titanwood_Log"
    },
    {
      "x": -1,
      "y": 22,
      "z": 0,
      "name": "TFJ_Titanwood_Log"
    },
    {
      "x": -1,
      "y": 23,
      "z": 0,
      "name": "TFJ_Titanwood_Log"
    },
    {
      "x": -1,
      "y": 24,
      "z": 0,
      "name": "TFJ_Titanwood_Log"
    },
    {
      "x": -1,
      "y": 34,
      "z": 0,
      "name": "TFJ_Canopy_Leaves"
    },
    {
      "x": -1,
      "y": 8,
      "z": 1,
      "name": "TFJ_Titanwood_Log"
    },
    {
      "x": -1,
      "y": 9,
      "z": 1,
      "name": "TFJ_Titanwood_Log"
    },
    {
      "x": -1,
      "y": 10,
      "z": 1,
      "name": "TFJ_Titanwood_Log"
    },
    {
      "x": -1,
      "y": 11,
      "z": 1,
      "name": "TFJ_Titanwood_Log"
    },
    {
      "x": -1,
      "y": 12,
      "z": 1,
      "name": "TFJ_Titanwood_Log"
    },
    {
      "x": -1,
      "y": 13,
      "z": 1,
      "name": "TFJ_Titanwood_Log"
    },
    {
      "x": -1,
      "y": 14,
      "z": 1,
      "name": "TFJ_Titanwood_Log"
    },
    {
      "x": -1,
      "y": 15,
      "z": 1,
      "name": "TFJ_Titanwood_Log"
    },
    {
      "x": -1,
      "y": 16,
      "z": 1,
      "name": "TFJ_Titanwood_Log",
      "rotation": 10
    },
    {
      "x": -1,
      "y": 19,
      "z": 1,
      "name": "TFJ_Titanwood_Log"
    },
    {
      "x": -1,
      "y": 20,
      "z": 1,
      "name": "TFJ_Titanwood_Log"
    },
    {
      "x": -1,
      "y": 24,
      "z": 1,
      "name": "TFJ_Titanwood_Log"
    },
    {
      "x": -1,
      "y": 25,
      "z": 1,
      "name": "TFJ_Titanwood_Log"
    },
    {
      "x": -1,
      "y": 26,
      "z": 1,
      "name": "TFJ_Titanwood_Log"
    },
    {
      "x": -1,
      "y": 27,
      "z": 1,
      "name": "TFJ_Titanwood_Log"
    },
    {
      "x": -1,
      "y": 34,
      "z": 1,
      "name": "TFJ_Canopy_Leaves"
    },
    {
      "x": -1,
      "y": 20,
      "z": 2,
      "name": "TFJ_Titanwood_Log"
    },
    {
      "x": -1,
      "y": 27,
      "z": 2,
      "name": "TFJ_Titanwood_Log"
    },
    {
      "x": -1,
      "y": 34,
      "z": 2,
      "name": "TFJ_Canopy_Leaves"
    },
    {
      "x": -1,
      "y": 20,
      "z": 3,
      "name": "TFJ_Titanwood_Log"
    },
    {
      "x": -1,
      "y": 20,
      "z": 4,
      "name": "TFJ_Titanwood_Log"
    },
    {
      "x": -1,
      "y": 21,
      "z": 4,
      "name": "TFJ_Titanwood_Log"
    },
    {
      "x": -1,
      "y": 34,
      "z": 4,
      "name": "TFJ_Canopy_Leaves"
    },
    {
      "x": -1,
      "y": 21,
      "z": 5,
      "name": "TFJ_Titanwood_Log"
    },
    {
      "x": -1,
      "y": 33,
      "z": 5,
      "name": "TFJ_Canopy_Leaves"
    },
    {
      "x": -1,
      "y": 34,
      "z": 5,
      "name": "TFJ_Canopy_Leaves"
    },
    {
      "x": -1,
      "y": 32,
      "z": 6,
      "name": "TFJ_Canopy_Leaves"
    },
    {
      "x": -1,
      "y": 33,
      "z": 6,
      "name": "TFJ_Canopy_Leaves"
    },
    {
      "x": -1,
      "y": 26,
      "z": 7,
      "name": "TFJ_Canopy_Leaves"
    },
    {
      "x": -1,
      "y": 30,
      "z": 7,
      "name": "TFJ_Canopy_Leaves"
    },
    {
      "x": -1,
      "y": 31,
      "z": 7,
      "name": "TFJ_Canopy_Leaves"
    },
    {
      "x": -1,
      "y": 32,
      "z": 7,
      "name": "TFJ_Canopy_Leaves"
    },
    {
      "x": -1,
      "y": 22,
      "z": 8,
      "name": "TFJ_Titanwood_Log",
      "rotation": 5
    },
    {
      "x": -1,
      "y": 26,
      "z": 9,
      "name": "TFJ_Canopy_Leaves"
    },
    {
      "x": -1,
      "y": 22,
      "z": 11,
      "name": "TFJ_Canopy_Leaves"
    },
    {
      "x": -1,
      "y": 25,
      "z": 11,
      "name": "TFJ_Canopy_Leaves"
    },
    {
      "x": -1,
      "y": 22,
      "z": 12,
      "name": "TFJ_Canopy_Leaves"
    },
    {
      "x": -1,
      "y": 23,
      "z": 12,
      "name": "TFJ_Canopy_Leaves"
    },
    {
      "x": -1,
      "y": 24,
      "z": 12,
      "name": "TFJ_Canopy_Leaves"
    },
    {
      "x": -1,
      "y": 25,
      "z": 12,
      "name": "TFJ_Canopy_Leaves"
    },
    {
      "x": -1,
      "y": 22,
      "z": 13,
      "name": "TFJ_Canopy_Leaves"
    },
    {
      "x": 0,
      "y": 26,
      "z": -9,
      "name": "TFJ_Canopy_Leaves"
    },
    {
      "x": 0,
      "y": 27,
      "z": -9,
      "name": "TFJ_Canopy_Leaves"
    },
    {
      "x": 0,
      "y": 28,
      "z": -9,
      "name": "TFJ_Canopy_Leaves"
    },
    {
      "x": 0,
      "y": 29,
      "z": -9,
      "name": "TFJ_Canopy_Leaves"
    },
    {
      "x": 0,
      "y": 30,
      "z": -9,
      "name": "TFJ_Canopy_Leaves"
    },
    {
      "x": 0,
      "y": 26,
      "z": -8,
      "name": "TFJ_Canopy_Leaves"
    },
    {
      "x": 0,
      "y": 27,
      "z": -8,
      "name": "TFJ_Canopy_Leaves"
    },
    {
      "x": 0,
      "y": 31,
      "z": -8,
      "name": "TFJ_Canopy_Leaves"
    },
    {
      "x": 0,
      "y": 26,
      "z": -7,
      "name": "TFJ_Canopy_Leaves"
    },
    {
      "x": 0,
      "y": 27,
      "z": -7,
      "name": "TFJ_Canopy_Leaves"
    },
    {
      "x": 0,
      "y": 31,
      "z": -7,
      "name": "TFJ_Canopy_Leaves"
    },
    {
      "x": 0,
      "y": 32,
      "z": -7,
      "name": "TFJ_Canopy_Leaves"
    },
    {
      "x": 0,
      "y": 26,
      "z": -6,
      "name": "TFJ_Canopy_Leaves"
    },
    {
      "x": 0,
      "y": 31,
      "z": -6,
      "name": "TFJ_Canopy_Leaves"
    },
    {
      "x": 0,
      "y": 32,
      "z": -6,
      "name": "TFJ_Canopy_Leaves"
    },
    {
      "x": 0,
      "y": 28,
      "z": -5,
      "name": "TFJ_Titanwood_Log",
      "rotation": 5
    },
    {
      "x": 0,
      "y": 25,
      "z": -4,
      "name": "TFJ_Titanwood_Log"
    },
    {
      "x": 0,
      "y": 26,
      "z": -4,
      "name": "TFJ_Titanwood_Log"
    },
    {
      "x": 0,
      "y": 27,
      "z": -4,
      "name": "TFJ_Titanwood_Log"
    },
    {
      "x": 0,
      "y": 32,
      "z": -4,
      "name": "TFJ_Canopy_Leaves"
    },
    {
      "x": 0,
      "y": 8,
      "z": -3,
      "name": "TFJ_Titanwood_Log"
    },
    {
      "x": 0,
      "y": 9,
      "z": -3,
      "name": "TFJ_Titanwood_Log"
    },
    {
      "x": 0,
      "y": 10,
      "z": -3,
      "name": "TFJ_Titanwood_Log"
    },
    {
      "x": 0,
      "y": 11,
      "z": -3,
      "name": "TFJ_Titanwood_Log"
    },
    {
      "x": 0,
      "y": 12,
      "z": -3,
      "name": "TFJ_Titanwood_Log"
    },
    {
      "x": 0,
      "y": 13,
      "z": -3,
      "name": "TFJ_Titanwood_Log",
      "rotation": 8
    },
    {
      "x": 0,
      "y": 24,
      "z": -3,
      "name": "TFJ_Titanwood_Log"
    },
    {
      "x": 0,
      "y": 25,
      "z": -3,
      "name": "TFJ_Titanwood_Log"
    },
    {
      "x": 0,
      "y": 32,
      "z": -3,
      "name": "TFJ_Canopy_Leaves"
    },
    {
      "x": 0,
      "y": 8,
      "z": -2,
      "name": "TFJ_Titanwood_Log"
    },
    {
      "x": 0,
      "y": 9,
      "z": -2,
      "name": "TFJ_Titanwood_Log"
    },
    {
      "x": 0,
      "y": 10,
      "z": -2,
      "name": "TFJ_Titanwood_Log"
    },
    {
      "x": 0,
      "y": 11,
      "z": -2,
      "name": "TFJ_Titanwood_Log"
    },
    {
      "x": 0,
      "y": 12,
      "z": -2,
      "name": "TFJ_Titanwood_Log"
    },
    {
      "x": 0,
      "y": 13,
      "z": -2,
      "name": "TFJ_Titanwood_Log"
    },
    {
      "x": 0,
      "y": 14,
      "z": -2,
      "name": "TFJ_Titanwood_Log"
    },
    {
      "x": 0,
      "y": 15,
      "z": -2,
      "name": "TFJ_Titanwood_Log"
    },
    {
      "x": 0,
      "y": 16,
      "z": -2,
      "name": "TFJ_Titanwood_Log",
      "rotation": 8
    },
    {
      "x": 0,
      "y": 23,
      "z": -2,
      "name": "TFJ_Titanwood_Log"
    },
    {
      "x": 0,
      "y": 24,
      "z": -2,
      "name": "TFJ_Titanwood_Log"
    },
    {
      "x": 0,
      "y": 31,
      "z": -2,
      "name": "TFJ_Canopy_Leaves"
    },
    {
      "x": 0,
      "y": 8,
      "z": -1,
      "name": "TFJ_Titanwood_Log"
    },
    {
      "x": 0,
      "y": 9,
      "z": -1,
      "name": "TFJ_Titanwood_Log"
    },
    {
      "x": 0,
      "y": 10,
      "z": -1,
      "name": "TFJ_Titanwood_Log"
    },
    {
      "x": 0,
      "y": 11,
      "z": -1,
      "name": "TFJ_Titanwood_Log"
    },
    {
      "x": 0,
      "y": 12,
      "z": -1,
      "name": "TFJ_Titanwood_Log"
    },
    {
      "x": 0,
      "y": 13,
      "z": -1,
      "name": "TFJ_Titanwood_Log"
    },
    {
      "x": 0,
      "y": 14,
      "z": -1,
      "name": "TFJ_Titanwood_Log"
    },
    {
      "x": 0,
      "y": 15,
      "z": -1,
      "name": "TFJ_Titanwood_Log"
    },
    {
      "x": 0,
      "y": 16,
      "z": -1,
      "name": "TFJ_Titanwood_Log"
    },
    {
      "x": 0,
      "y": 17,
      "z": -1,
      "name": "TFJ_Titanwood_Log"
    },
    {
      "x": 0,
      "y": 18,
      "z": -1,
      "name": "TFJ_Titanwood_Log"
    },
    {
      "x": 0,
      "y": 19,
      "z": -1,
      "name": "TFJ_Titanwood_Log"
    },
    {
      "x": 0,
      "y": 20,
      "z": -1,
      "name": "TFJ_Titanwood_Log"
    },
    {
      "x": 0,
      "y": 21,
      "z": -1,
      "name": "TFJ_Titanwood_Log"
    },
    {
      "x": 0,
      "y": 22,
      "z": -1,
      "name": "TFJ_Titanwood_Log"
    },
    {
      "x": 0,
      "y": 23,
      "z": -1,
      "name": "TFJ_Titanwood_Log"
    },
    {
      "x": 0,
      "y": 33,
      "z": -1,
      "name": "TFJ_Canopy_Leaves"
    },
    {
      "x": 0,
      "y": 8,
      "z": 0,
      "name": "TFJ_Titanwood_Log"
    },
    {
      "x": 0,
      "y": 9,
      "z": 0,
      "name": "TFJ_Titanwood_Log"
    },
    {
      "x": 0,
      "y": 10,
      "z": 0,
      "name": "TFJ_Titanwood_Log"
    },
    {
      "x": 0,
      "y": 11,
      "z": 0,
      "name": "TFJ_Titanwood_Log"
    },
    {
      "x": 0,
      "y": 12,
      "z": 0,
      "name": "TFJ_Titanwood_Log"
    },
    {
      "x": 0,
      "y": 13,
      "z": 0,
      "name": "TFJ_Titanwood_Log"
    },
    {
      "x": 0,
      "y": 14,
      "z": 0,
      "name": "TFJ_Titanwood_Log"
    },
    {
      "x": 0,
      "y": 15,
      "z": 0,
      "name": "TFJ_Titanwood_Log"
    },
    {
      "x": 0,
      "y": 16,
      "z": 0,
      "name": "TFJ_Titanwood_Log"
    },
    {
      "x": 0,
      "y": 17,
      "z": 0,
      "name": "TFJ_Titanwood_Log"
    },
    {
      "x": 0,
      "y": 18,
      "z": 0,
      "name": "TFJ_Titanwood_Log"
    },
    {
      "x": 0,
      "y": 19,
      "z": 0,
      "name": "TFJ_Titanwood_Log"
    },
    {
      "x": 0,
      "y": 20,
      "z": 0,
      "name": "TFJ_Titanwood_Log"
    },
    {
      "x": 0,
      "y": 21,
      "z": 0,
      "name": "TFJ_Titanwood_Log"
    },
    {
      "x": 0,
      "y": 22,
      "z": 0,
      "name": "TFJ_Titanwood_Log"
    },
    {
      "x": 0,
      "y": 33,
      "z": 0,
      "name": "TFJ_Canopy_Leaves"
    },
    {
      "x": 0,
      "y": 8,
      "z": 1,
      "name": "TFJ_Titanwood_Log"
    },
    {
      "x": 0,
      "y": 9,
      "z": 1,
      "name": "TFJ_Titanwood_Log"
    },
    {
      "x": 0,
      "y": 10,
      "z": 1,
      "name": "TFJ_Titanwood_Log"
    },
    {
      "x": 0,
      "y": 11,
      "z": 1,
      "name": "TFJ_Titanwood_Log"
    },
    {
      "x": 0,
      "y": 12,
      "z": 1,
      "name": "TFJ_Titanwood_Log"
    },
    {
      "x": 0,
      "y": 13,
      "z": 1,
      "name": "TFJ_Titanwood_Log"
    },
    {
      "x": 0,
      "y": 14,
      "z": 1,
      "name": "TFJ_Titanwood_Log"
    },
    {
      "x": 0,
      "y": 15,
      "z": 1,
      "name": "TFJ_Titanwood_Log"
    },
    {
      "x": 0,
      "y": 16,
      "z": 1,
      "name": "TFJ_Titanwood_Log"
    },
    {
      "x": 0,
      "y": 17,
      "z": 1,
      "name": "TFJ_Titanwood_Log",
      "rotation": 10
    },
    {
      "x": 0,
      "y": 8,
      "z": 2,
      "name": "TFJ_Titanwood_Log"
    },
    {
      "x": 0,
      "y": 9,
      "z": 2,
      "name": "TFJ_Titanwood_Log"
    },
    {
      "x": 0,
      "y": 10,
      "z": 2,
      "name": "TFJ_Titanwood_Log"
    },
    {
      "x": 0,
      "y": 11,
      "z": 2,
      "name": "TFJ_Titanwood_Log"
    },
    {
      "x": 0,
      "y": 12,
      "z": 2,
      "name": "TFJ_Titanwood_Log"
    },
    {
      "x": 0,
      "y": 13,
      "z": 2,
      "name": "TFJ_Titanwood_Log",
      "rotation": 10
    },
    {
      "x": 0,
      "y": 34,
      "z": 2,
      "name": "TFJ_Canopy_Leaves"
    },
    {
      "x": 0,
      "y": 34,
      "z": 3,
      "name": "TFJ_Canopy_Leaves"
    },
    {
      "x": 0,
      "y": 34,
      "z": 4,
      "name": "TFJ_Canopy_Leaves"
    },
    {
      "x": 0,
      "y": 33,
      "z": 5,
      "name": "TFJ_Canopy_Leaves"
    },
    {
      "x": 0,
      "y": 32,
      "z": 6,
      "name": "TFJ_Canopy_Leaves"
    },
    {
      "x": 0,
      "y": 33,
      "z": 6,
      "name": "TFJ_Canopy_Leaves"
    },
    {
      "x": 0,
      "y": 26,
      "z": 7,
      "name": "TFJ_Canopy_Leaves"
    },
    {
      "x": 0,
      "y": 30,
      "z": 7,
      "name": "TFJ_Canopy_Leaves"
    },
    {
      "x": 0,
      "y": 31,
      "z": 7,
      "name": "TFJ_Canopy_Leaves"
    },
    {
      "x": 0,
      "y": 32,
      "z": 7,
      "name": "TFJ_Canopy_Leaves"
    },
    {
      "x": 0,
      "y": 22,
      "z": 8,
      "name": "TFJ_Titanwood_Log",
      "rotation": 5
    },
    {
      "x": 0,
      "y": 22,
      "z": 10,
      "name": "TFJ_Canopy_Leaves"
    },
    {
      "x": 0,
      "y": 24,
      "z": 10,
      "name": "TFJ_Canopy_Leaves"
    },
    {
      "x": 0,
      "y": 25,
      "z": 10,
      "name": "TFJ_Canopy_Leaves"
    },
    {
      "x": 0,
      "y": 22,
      "z": 11,
      "name": "TFJ_Canopy_Leaves"
    },
    {
      "x": 0,
      "y": 24,
      "z": 11,
      "name": "TFJ_Canopy_Leaves"
    },
    {
      "x": 0,
      "y": 25,
      "z": 11,
      "name": "TFJ_Canopy_Leaves"
    },
    {
      "x": 0,
      "y": 22,
      "z": 12,
      "name": "TFJ_Canopy_Leaves"
    },
    {
      "x": 0,
      "y": 23,
      "z": 12,
      "name": "TFJ_Canopy_Leaves"
    },
    {
      "x": 1,
      "y": 29,
      "z": -9,
      "name": "TFJ_Canopy_Leaves"
    },
    {
      "x": 1,
      "y": 30,
      "z": -9,
      "name": "TFJ_Canopy_Leaves"
    },
    {
      "x": 1,
      "y": 26,
      "z": -8,
      "name": "TFJ_Canopy_Leaves"
    },
    {
      "x": 1,
      "y": 30,
      "z": -8,
      "name": "TFJ_Canopy_Leaves"
    },
    {
      "x": 1,
      "y": 31,
      "z": -8,
      "name": "TFJ_Canopy_Leaves"
    },
    {
      "x": 1,
      "y": 29,
      "z": -7,
      "name": "TFJ_Titanwood_Log",
      "rotation": 2
    },
    {
      "x": 1,
      "y": 30,
      "z": -7,
      "name": "TFJ_Titanwood_Log"
    },
    {
      "x": 1,
      "y": 31,
      "z": -7,
      "name": "TFJ_Canopy_Leaves"
    },
    {
      "x": 1,
      "y": 32,
      "z": -7,
      "name": "TFJ_Canopy_Leaves"
    },
    {
      "x": 1,
      "y": 29,
      "z": -6,
      "name": "TFJ_Titanwood_Log",
      "rotation": 4
    },
    {
      "x": 1,
      "y": 32,
      "z": -6,
      "name": "TFJ_Canopy_Leaves"
    },
    {
      "x": 1,
      "y": 27,
      "z": -5,
      "name": "TFJ_Titanwood_Log"
    },
    {
      "x": 1,
      "y": 28,
      "z": -5,
      "name": "TFJ_Titanwood_Log"
    },
    {
      "x": 1,
      "y": 29,
      "z": -5,
      "name": "TFJ_Titanwood_Log"
    },
    {
      "x": 1,
      "y": 30,
      "z": -5,
      "name": "TFJ_Titanwood_Log"
    },
    {
      "x": 1,
      "y": 31,
      "z": -5,
      "name": "TFJ_Titanwood_Log"
    },
    {
      "x": 1,
      "y": 32,
      "z": -5,
      "name": "TFJ_Canopy_Leaves"
    },
    {
      "x": 1,
      "y": 27,
      "z": -4,
      "name": "TFJ_Titanwood_Log"
    },
    {
      "x": 1,
      "y": 32,
      "z": -4,
      "name": "TFJ_Canopy_Leaves"
    },
    {
      "x": 1,
      "y": 29,
      "z": -3,
      "name": "TFJ_Canopy_Leaves"
    },
    {
      "x": 1,
      "y": 31,
      "z": -3,
      "name": "TFJ_Canopy_Leaves"
    },
    {
      "x": 1,
      "y": 8,
      "z": -2,
      "name": "TFJ_Titanwood_Log"
    },
    {
      "x": 1,
      "y": 9,
      "z": -2,
      "name": "TFJ_Titanwood_Log"
    },
    {
      "x": 1,
      "y": 10,
      "z": -2,
      "name": "TFJ_Titanwood_Log"
    },
    {
      "x": 1,
      "y": 11,
      "z": -2,
      "name": "TFJ_Titanwood_Log"
    },
    {
      "x": 1,
      "y": 12,
      "z": -2,
      "name": "TFJ_Titanwood_Log"
    },
    {
      "x": 1,
      "y": 13,
      "z": -2,
      "name": "TFJ_Titanwood_Log",
      "rotation": 8
    },
    {
      "x": 1,
      "y": 31,
      "z": -2,
      "name": "TFJ_Canopy_Leaves"
    },
    {
      "x": 1,
      "y": 8,
      "z": -1,
      "name": "TFJ_Titanwood_Log"
    },
    {
      "x": 1,
      "y": 9,
      "z": -1,
      "name": "TFJ_Titanwood_Log"
    },
    {
      "x": 1,
      "y": 10,
      "z": -1,
      "name": "TFJ_Titanwood_Log"
    },
    {
      "x": 1,
      "y": 11,
      "z": -1,
      "name": "TFJ_Titanwood_Log"
    },
    {
      "x": 1,
      "y": 12,
      "z": -1,
      "name": "TFJ_Titanwood_Log"
    },
    {
      "x": 1,
      "y": 13,
      "z": -1,
      "name": "TFJ_Titanwood_Log"
    },
    {
      "x": 1,
      "y": 14,
      "z": -1,
      "name": "TFJ_Titanwood_Log"
    },
    {
      "x": 1,
      "y": 15,
      "z": -1,
      "name": "TFJ_Titanwood_Log",
      "rotation": 11
    },
    {
      "x": 1,
      "y": 23,
      "z": -1,
      "name": "TFJ_Titanwood_Log"
    },
    {
      "x": 1,
      "y": 24,
      "z": -1,
      "name": "TFJ_Titanwood_Log"
    },
    {
      "x": 1,
      "y": 31,
      "z": -1,
      "name": "TFJ_Canopy_Leaves"
    },
    {
      "x": 1,
      "y": 8,
      "z": 0,
      "name": "TFJ_Titanwood_Log"
    },
    {
      "x": 1,
      "y": 9,
      "z": 0,
      "name": "TFJ_Titanwood_Log"
    },
    {
      "x": 1,
      "y": 10,
      "z": 0,
      "name": "TFJ_Titanwood_Log"
    },
    {
      "x": 1,
      "y": 11,
      "z": 0,
      "name": "TFJ_Titanwood_Log"
    },
    {
      "x": 1,
      "y": 12,
      "z": 0,
      "name": "TFJ_Titanwood_Log"
    },
    {
      "x": 1,
      "y": 13,
      "z": 0,
      "name": "TFJ_Titanwood_Log"
    },
    {
      "x": 1,
      "y": 14,
      "z": 0,
      "name": "TFJ_Titanwood_Log"
    },
    {
      "x": 1,
      "y": 15,
      "z": 0,
      "name": "TFJ_Titanwood_Log"
    },
    {
      "x": 1,
      "y": 16,
      "z": 0,
      "name": "TFJ_Titanwood_Log",
      "rotation": 11
    },
    {
      "x": 1,
      "y": 18,
      "z": 0,
      "name": "TFJ_Titanwood_Log"
    },
    {
      "x": 1,
      "y": 19,
      "z": 0,
      "name": "TFJ_Titanwood_Log"
    },
    {
      "x": 1,
      "y": 22,
      "z": 0,
      "name": "TFJ_Titanwood_Log"
    },
    {
      "x": 1,
      "y": 23,
      "z": 0,
      "name": "TFJ_Titanwood_Log"
    },
    {
      "x": 1,
      "y": 31,
      "z": 0,
      "name": "TFJ_Canopy_Leaves"
    },
    {
      "x": 1,
      "y": 33,
      "z": 0,
      "name": "TFJ_Canopy_Leaves"
    },
    {
      "x": 1,
      "y": 23,
      "z": 1,
      "name": "TFJ_Titanwood_Log"
    },
    {
      "x": 1,
      "y": 31,
      "z": 1,
      "name": "TFJ_Canopy_Leaves"
    },
    {
      "x": 1,
      "y": 34,
      "z": 1,
      "name": "TFJ_Canopy_Leaves"
    },
    {
      "x": 1,
      "y": 34,
      "z": 2,
      "name": "TFJ_Canopy_Leaves"
    },
    {
      "x": 1,
      "y": 33,
      "z": 3,
      "name": "TFJ_Canopy_Leaves"
    },
    {
      "x": 1,
      "y": 33,
      "z": 4,
      "name": "TFJ_Canopy_Leaves"
    },
    {
      "x": 1,
      "y": 28,
      "z": 5,
      "name": "TFJ_Canopy_Leaves"
    },
    {
      "x": 1,
      "y": 31,
      "z": 5,
      "name": "TFJ_Canopy_Leaves"
    },
    {
      "x": 1,
      "y": 32,
      "z": 5,
      "name": "TFJ_Canopy_Leaves"
    },
    {
      "x": 1,
      "y": 33,
      "z": 5,
      "name": "TFJ_Canopy_Leaves"
    },
    {
      "x": 1,
      "y": 26,
      "z": 6,
      "name": "TFJ_Canopy_Leaves"
    },
    {
      "x": 1,
      "y": 28,
      "z": 6,
      "name": "TFJ_Canopy_Leaves"
    },
    {
      "x": 1,
      "y": 29,
      "z": 6,
      "name": "TFJ_Canopy_Leaves"
    },
    {
      "x": 1,
      "y": 31,
      "z": 6,
      "name": "TFJ_Canopy_Leaves"
    },
    {
      "x": 1,
      "y": 32,
      "z": 6,
      "name": "TFJ_Canopy_Leaves"
    },
    {
      "x": 1,
      "y": 33,
      "z": 6,
      "name": "TFJ_Canopy_Leaves"
    },
    {
      "x": 1,
      "y": 23,
      "z": 7,
      "name": "TFJ_Canopy_Leaves"
    },
    {
      "x": 1,
      "y": 28,
      "z": 7,
      "name": "TFJ_Canopy_Leaves"
    },
    {
      "x": 1,
      "y": 29,
      "z": 7,
      "name": "TFJ_Canopy_Leaves"
    },
    {
      "x": 1,
      "y": 31,
      "z": 7,
      "name": "TFJ_Canopy_Leaves"
    },
    {
      "x": 1,
      "y": 22,
      "z": 8,
      "name": "TFJ_Titanwood_Log",
      "rotation": 1
    },
    {
      "x": 1,
      "y": 23,
      "z": 8,
      "name": "TFJ_Canopy_Leaves"
    },
    {
      "x": 1,
      "y": 25,
      "z": 8,
      "name": "TFJ_Canopy_Leaves"
    },
    {
      "x": 1,
      "y": 28,
      "z": 8,
      "name": "TFJ_Canopy_Leaves"
    },
    {
      "x": 1,
      "y": 21,
      "z": 9,
      "name": "TFJ_Canopy_Leaves"
    },
    {
      "x": 1,
      "y": 22,
      "z": 9,
      "name": "TFJ_Canopy_Leaves"
    },
    {
      "x": 1,
      "y": 25,
      "z": 9,
      "name": "TFJ_Canopy_Leaves"
    },
    {
      "x": 1,
      "y": 22,
      "z": 10,
      "name": "TFJ_Canopy_Leaves"
    },
    {
      "x": 1,
      "y": 23,
      "z": 10,
      "name": "TFJ_Canopy_Leaves"
    },
    {
      "x": 1,
      "y": 27,
      "z": 10,
      "name": "TFJ_Canopy_Leaves"
    },
    {
      "x": 1,
      "y": 21,
      "z": 11,
      "name": "TFJ_Canopy_Leaves"
    },
    {
      "x": 1,
      "y": 22,
      "z": 11,
      "name": "TFJ_Canopy_Leaves"
    },
    {
      "x": 1,
      "y": 22,
      "z": 12,
      "name": "TFJ_Canopy_Leaves"
    },
    {
      "x": 2,
      "y": 28,
      "z": -9,
      "name": "TFJ_Canopy_Leaves"
    },
    {
      "x": 2,
      "y": 29,
      "z": -9,
      "name": "TFJ_Canopy_Leaves"
    },
    {
      "x": 2,
      "y": 29,
      "z": -8,
      "name": "TFJ_Canopy_Leaves"
    },
    {
      "x": 2,
      "y": 30,
      "z": -8,
      "name": "TFJ_Canopy_Leaves"
    },
    {
      "x": 2,
      "y": 31,
      "z": -8,
      "name": "TFJ_Canopy_Leaves"
    },
    {
      "x": 2,
      "y": 32,
      "z": -7,
      "name": "TFJ_Canopy_Leaves"
    },
    {
      "x": 2,
      "y": 32,
      "z": -6,
      "name": "TFJ_Canopy_Leaves"
    },
    {
      "x": 2,
      "y": 32,
      "z": -5,
      "name": "TFJ_Canopy_Leaves"
    },
    {
      "x": 2,
      "y": 29,
      "z": -4,
      "name": "TFJ_Canopy_Leaves"
    },
    {
      "x": 2,
      "y": 28,
      "z": -3,
      "name": "TFJ_Canopy_Leaves"
    },
    {
      "x": 2,
      "y": 29,
      "z": -3,
      "name": "TFJ_Canopy_Leaves"
    },
    {
      "x": 2,
      "y": 30,
      "z": -3,
      "name": "TFJ_Canopy_Leaves"
    },
    {
      "x": 2,
      "y": 31,
      "z": -3,
      "name": "TFJ_Canopy_Leaves"
    },
    {
      "x": 2,
      "y": 31,
      "z": -2,
      "name": "TFJ_Canopy_Leaves"
    },
    {
      "x": 2,
      "y": 8,
      "z": -1,
      "name": "TFJ_Titanwood_Log"
    },
    {
      "x": 2,
      "y": 9,
      "z": -1,
      "name": "TFJ_Titanwood_Log"
    },
    {
      "x": 2,
      "y": 10,
      "z": -1,
      "name": "TFJ_Titanwood_Log"
    },
    {
      "x": 2,
      "y": 11,
      "z": -1,
      "name": "TFJ_Titanwood_Log"
    },
    {
      "x": 2,
      "y": 12,
      "z": -1,
      "name": "TFJ_Titanwood_Log"
    },
    {
      "x": 2,
      "y": 13,
      "z": -1,
      "name": "TFJ_Titanwood_Log",
      "rotation": 11
    },
    {
      "x": 2,
      "y": 24,
      "z": -1,
      "name": "TFJ_Titanwood_Log"
    },
    {
      "x": 2,
      "y": 25,
      "z": -1,
      "name": "TFJ_Titanwood_Log"
    },
    {
      "x": 2,
      "y": 26,
      "z": -1,
      "name": "TFJ_Titanwood_Log"
    },
    {
      "x": 2,
      "y": 32,
      "z": -1,
      "name": "TFJ_Canopy_Leaves"
    },
    {
      "x": 2,
      "y": 8,
      "z": 0,
      "name": "TFJ_Titanwood_Log"
    },
    {
      "x": 2,
      "y": 9,
      "z": 0,
      "name": "TFJ_Titanwood_Log"
    },
    {
      "x": 2,
      "y": 10,
      "z": 0,
      "name": "TFJ_Titanwood_Log"
    },
    {
      "x": 2,
      "y": 11,
      "z": 0,
      "name": "TFJ_Titanwood_Log"
    },
    {
      "x": 2,
      "y": 12,
      "z": 0,
      "name": "TFJ_Titanwood_Log",
      "rotation": 11
    },
    {
      "x": 2,
      "y": 19,
      "z": 0,
      "name": "TFJ_Titanwood_Log"
    },
    {
      "x": 2,
      "y": 20,
      "z": 0,
      "name": "TFJ_Titanwood_Log"
    },
    {
      "x": 2,
      "y": 31,
      "z": 0,
      "name": "TFJ_Canopy_Leaves"
    },
    {
      "x": 2,
      "y": 33,
      "z": 0,
      "name": "TFJ_Canopy_Leaves"
    },
    {
      "x": 2,
      "y": 23,
      "z": 1,
      "name": "TFJ_Titanwood_Log"
    },
    {
      "x": 2,
      "y": 24,
      "z": 1,
      "name": "TFJ_Titanwood_Log"
    },
    {
      "x": 2,
      "y": 31,
      "z": 1,
      "name": "TFJ_Canopy_Leaves"
    },
    {
      "x": 2,
      "y": 33,
      "z": 1,
      "name": "TFJ_Canopy_Leaves"
    },
    {
      "x": 2,
      "y": 24,
      "z": 2,
      "name": "TFJ_Titanwood_Log"
    },
    {
      "x": 2,
      "y": 31,
      "z": 2,
      "name": "TFJ_Canopy_Leaves"
    },
    {
      "x": 2,
      "y": 24,
      "z": 3,
      "name": "TFJ_Titanwood_Log"
    },
    {
      "x": 2,
      "y": 25,
      "z": 3,
      "name": "TFJ_Titanwood_Log"
    },
    {
      "x": 2,
      "y": 30,
      "z": 3,
      "name": "TFJ_Canopy_Leaves"
    },
    {
      "x": 2,
      "y": 31,
      "z": 3,
      "name": "TFJ_Canopy_Leaves"
    },
    {
      "x": 2,
      "y": 32,
      "z": 3,
      "name": "TFJ_Canopy_Leaves"
    },
    {
      "x": 2,
      "y": 33,
      "z": 3,
      "name": "TFJ_Canopy_Leaves"
    },
    {
      "x": 2,
      "y": 31,
      "z": 4,
      "name": "TFJ_Canopy_Leaves"
    },
    {
      "x": 2,
      "y": 32,
      "z": 4,
      "name": "TFJ_Canopy_Leaves"
    },
    {
      "x": 2,
      "y": 33,
      "z": 4,
      "name": "TFJ_Canopy_Leaves"
    },
    {
      "x": 2,
      "y": 31,
      "z": 5,
      "name": "TFJ_Canopy_Leaves"
    },
    {
      "x": 2,
      "y": 32,
      "z": 5,
      "name": "TFJ_Canopy_Leaves"
    },
    {
      "x": 2,
      "y": 22,
      "z": 6,
      "name": "TFJ_Canopy_Leaves"
    },
    {
      "x": 2,
      "y": 28,
      "z": 6,
      "name": "TFJ_Canopy_Leaves"
    },
    {
      "x": 2,
      "y": 29,
      "z": 6,
      "name": "TFJ_Canopy_Leaves"
    },
    {
      "x": 2,
      "y": 30,
      "z": 6,
      "name": "TFJ_Canopy_Leaves"
    },
    {
      "x": 2,
      "y": 31,
      "z": 6,
      "name": "TFJ_Canopy_Leaves"
    },
    {
      "x": 2,
      "y": 22,
      "z": 7,
      "name": "TFJ_Canopy_Leaves"
    },
    {
      "x": 2,
      "y": 23,
      "z": 7,
      "name": "TFJ_Canopy_Leaves"
    },
    {
      "x": 2,
      "y": 30,
      "z": 7,
      "name": "TFJ_Canopy_Leaves"
    },
    {
      "x": 2,
      "y": 22,
      "z": 8,
      "name": "TFJ_Canopy_Leaves"
    },
    {
      "x": 2,
      "y": 23,
      "z": 8,
      "name": "TFJ_Canopy_Leaves"
    },
    {
      "x": 2,
      "y": 24,
      "z": 8,
      "name": "TFJ_Canopy_Leaves"
    },
    {
      "x": 2,
      "y": 28,
      "z": 8,
      "name": "TFJ_Canopy_Leaves"
    },
    {
      "x": 2,
      "y": 29,
      "z": 8,
      "name": "TFJ_Canopy_Leaves"
    },
    {
      "x": 2,
      "y": 20,
      "z": 9,
      "name": "TFJ_Canopy_Leaves"
    },
    {
      "x": 2,
      "y": 21,
      "z": 9,
      "name": "TFJ_Canopy_Leaves"
    },
    {
      "x": 2,
      "y": 22,
      "z": 9,
      "name": "TFJ_Canopy_Leaves"
    },
    {
      "x": 2,
      "y": 27,
      "z": 9,
      "name": "TFJ_Canopy_Leaves"
    },
    {
      "x": 2,
      "y": 28,
      "z": 9,
      "name": "TFJ_Canopy_Leaves"
    },
    {
      "x": 2,
      "y": 21,
      "z": 10,
      "name": "TFJ_Canopy_Leaves"
    },
    {
      "x": 2,
      "y": 22,
      "z": 10,
      "name": "TFJ_Canopy_Leaves"
    },
    {
      "x": 2,
      "y": 23,
      "z": 10,
      "name": "TFJ_Canopy_Leaves"
    },
    {
      "x": 2,
      "y": 24,
      "z": 10,
      "name": "TFJ_Canopy_Leaves"
    },
    {
      "x": 2,
      "y": 26,
      "z": 10,
      "name": "TFJ_Canopy_Leaves"
    },
    {
      "x": 2,
      "y": 27,
      "z": 10,
      "name": "TFJ_Canopy_Leaves"
    },
    {
      "x": 2,
      "y": 20,
      "z": 11,
      "name": "TFJ_Canopy_Leaves"
    },
    {
      "x": 2,
      "y": 21,
      "z": 11,
      "name": "TFJ_Canopy_Leaves"
    },
    {
      "x": 2,
      "y": 23,
      "z": 11,
      "name": "TFJ_Canopy_Leaves"
    },
    {
      "x": 3,
      "y": 29,
      "z": -8,
      "name": "TFJ_Canopy_Leaves"
    },
    {
      "x": 3,
      "y": 30,
      "z": -7,
      "name": "TFJ_Canopy_Leaves"
    },
    {
      "x": 3,
      "y": 31,
      "z": -7,
      "name": "TFJ_Canopy_Leaves"
    },
    {
      "x": 3,
      "y": 30,
      "z": -6,
      "name": "TFJ_Canopy_Leaves"
    },
    {
      "x": 3,
      "y": 31,
      "z": -6,
      "name": "TFJ_Canopy_Leaves"
    },
    {
      "x": 3,
      "y": 32,
      "z": -6,
      "name": "TFJ_Canopy_Leaves"
    },
    {
      "x": 3,
      "y": 31,
      "z": -5,
      "name": "TFJ_Canopy_Leaves"
    },
    {
      "x": 3,
      "y": 28,
      "z": -4,
      "name": "TFJ_Canopy_Leaves"
    },
    {
      "x": 3,
      "y": 30,
      "z": -4,
      "name": "TFJ_Canopy_Leaves"
    },
    {
      "x": 3,
      "y": 31,
      "z": -4,
      "name": "TFJ_Canopy_Leaves"
    },
    {
      "x": 3,
      "y": 30,
      "z": -3,
      "name": "TFJ_Canopy_Leaves"
    },
    {
      "x": 3,
      "y": 31,
      "z": -3,
      "name": "TFJ_Canopy_Leaves"
    },
    {
      "x": 3,
      "y": 32,
      "z": -2,
      "name": "TFJ_Canopy_Leaves"
    },
    {
      "x": 3,
      "y": 25,
      "z": -1,
      "name": "TFJ_Titanwood_Log"
    },
    {
      "x": 3,
      "y": 26,
      "z": -1,
      "name": "TFJ_Titanwood_Log"
    },
    {
      "x": 3,
      "y": 27,
      "z": -1,
      "name": "TFJ_Titanwood_Log"
    },
    {
      "x": 3,
      "y": 32,
      "z": -1,
      "name": "TFJ_Canopy_Leaves"
    },
    {
      "x": 3,
      "y": 19,
      "z": 0,
      "name": "TFJ_Titanwood_Log"
    },
    {
      "x": 3,
      "y": 20,
      "z": 0,
      "name": "TFJ_Titanwood_Log"
    },
    {
      "x": 3,
      "y": 27,
      "z": 0,
      "name": "TFJ_Titanwood_Log"
    },
    {
      "x": 3,
      "y": 32,
      "z": 0,
      "name": "TFJ_Canopy_Leaves"
    },
    {
      "x": 3,
      "y": 31,
      "z": 2,
      "name": "TFJ_Canopy_Leaves"
    },
    {
      "x": 3,
      "y": 25,
      "z": 3,
      "name": "TFJ_Titanwood_Log"
    },
    {
      "x": 3,
      "y": 30,
      "z": 3,
      "name": "TFJ_Canopy_Leaves"
    },
    {
      "x": 3,
      "y": 31,
      "z": 3,
      "name": "TFJ_Canopy_Leaves"
    },
    {
      "x": 3,
      "y": 25,
      "z": 4,
      "name": "TFJ_Titanwood_Log"
    },
    {
      "x": 3,
      "y": 26,
      "z": 4,
      "name": "TFJ_Titanwood_Log"
    },
    {
      "x": 3,
      "y": 29,
      "z": 4,
      "name": "TFJ_Canopy_Leaves"
    },
    {
      "x": 3,
      "y": 30,
      "z": 4,
      "name": "TFJ_Canopy_Leaves"
    },
    {
      "x": 3,
      "y": 31,
      "z": 4,
      "name": "TFJ_Canopy_Leaves"
    },
    {
      "x": 3,
      "y": 26,
      "z": 5,
      "name": "TFJ_Titanwood_Log"
    },
    {
      "x": 3,
      "y": 30,
      "z": 5,
      "name": "TFJ_Canopy_Leaves"
    },
    {
      "x": 3,
      "y": 30,
      "z": 6,
      "name": "TFJ_Canopy_Leaves"
    },
    {
      "x": 3,
      "y": 21,
      "z": 7,
      "name": "TFJ_Canopy_Leaves"
    },
    {
      "x": 3,
      "y": 22,
      "z": 7,
      "name": "TFJ_Canopy_Leaves"
    },
    {
      "x": 3,
      "y": 20,
      "z": 8,
      "name": "TFJ_Canopy_Leaves"
    },
    {
      "x": 3,
      "y": 21,
      "z": 8,
      "name": "TFJ_Canopy_Leaves"
    },
    {
      "x": 3,
      "y": 22,
      "z": 8,
      "name": "TFJ_Canopy_Leaves"
    },
    {
      "x": 3,
      "y": 28,
      "z": 8,
      "name": "TFJ_Canopy_Leaves"
    },
    {
      "x": 3,
      "y": 29,
      "z": 8,
      "name": "TFJ_Canopy_Leaves"
    },
    {
      "x": 3,
      "y": 20,
      "z": 9,
      "name": "TFJ_Canopy_Leaves"
    },
    {
      "x": 3,
      "y": 22,
      "z": 9,
      "name": "TFJ_Canopy_Leaves"
    },
    {
      "x": 3,
      "y": 27,
      "z": 9,
      "name": "TFJ_Canopy_Leaves"
    },
    {
      "x": 3,
      "y": 28,
      "z": 9,
      "name": "TFJ_Canopy_Leaves"
    },
    {
      "x": 3,
      "y": 29,
      "z": 9,
      "name": "TFJ_Canopy_Leaves"
    },
    {
      "x": 3,
      "y": 27,
      "z": 10,
      "name": "TFJ_Canopy_Leaves"
    },
    {
      "x": 3,
      "y": 28,
      "z": 10,
      "name": "TFJ_Canopy_Leaves"
    },
    {
      "x": 3,
      "y": 25,
      "z": 11,
      "name": "TFJ_Canopy_Leaves"
    },
    {
      "x": 3,
      "y": 26,
      "z": 11,
      "name": "TFJ_Canopy_Leaves"
    },
    {
      "x": 4,
      "y": 29,
      "z": -7,
      "name": "TFJ_Canopy_Leaves"
    },
    {
      "x": 4,
      "y": 27,
      "z": -6,
      "name": "TFJ_Canopy_Leaves"
    },
    {
      "x": 4,
      "y": 28,
      "z": -6,
      "name": "TFJ_Canopy_Leaves"
    },
    {
      "x": 4,
      "y": 29,
      "z": -6,
      "name": "TFJ_Canopy_Leaves"
    },
    {
      "x": 4,
      "y": 30,
      "z": -6,
      "name": "TFJ_Canopy_Leaves"
    },
    {
      "x": 4,
      "y": 31,
      "z": -5,
      "name": "TFJ_Canopy_Leaves"
    },
    {
      "x": 4,
      "y": 28,
      "z": -4,
      "name": "TFJ_Canopy_Leaves"
    },
    {
      "x": 4,
      "y": 29,
      "z": -4,
      "name": "TFJ_Canopy_Leaves"
    },
    {
      "x": 4,
      "y": 30,
      "z": -4,
      "name": "TFJ_Canopy_Leaves"
    },
    {
      "x": 4,
      "y": 31,
      "z": -4,
      "name": "TFJ_Canopy_Leaves"
    },
    {
      "x": 4,
      "y": 28,
      "z": -3,
      "name": "TFJ_Titanwood_Log",
      "rotation": 2
    },
    {
      "x": 4,
      "y": 29,
      "z": -3,
      "name": "TFJ_Titanwood_Log"
    },
    {
      "x": 4,
      "y": 30,
      "z": -3,
      "name": "TFJ_Canopy_Leaves"
    },
    {
      "x": 4,
      "y": 31,
      "z": -3,
      "name": "TFJ_Canopy_Leaves"
    },
    {
      "x": 4,
      "y": 28,
      "z": -2,
      "name": "TFJ_Titanwood_Log",
      "rotation": 4
    },
    {
      "x": 4,
      "y": 32,
      "z": -2,
      "name": "TFJ_Canopy_Leaves"
    },
    {
      "x": 4,
      "y": 28,
      "z": -1,
      "name": "TFJ_Titanwood_Log",
      "rotation": 4
    },
    {
      "x": 4,
      "y": 20,
      "z": 0,
      "name": "TFJ_Titanwood_Log"
    },
    {
      "x": 4,
      "y": 27,
      "z": 0,
      "name": "TFJ_Titanwood_Log"
    },
    {
      "x": 4,
      "y": 28,
      "z": 0,
      "name": "TFJ_Titanwood_Log"
    },
    {
      "x": 4,
      "y": 29,
      "z": 0,
      "name": "TFJ_Titanwood_Log"
    },
    {
      "x": 4,
      "y": 30,
      "z": 0,
      "name": "TFJ_Titanwood_Log"
    },
    {
      "x": 4,
      "y": 31,
      "z": 0,
      "name": "TFJ_Titanwood_Log"
    },
    {
      "x": 4,
      "y": 32,
      "z": 0,
      "name": "TFJ_Canopy_Leaves"
    },
    {
      "x": 4,
      "y": 32,
      "z": 1,
      "name": "TFJ_Canopy_Leaves"
    },
    {
      "x": 4,
      "y": 31,
      "z": 2,
      "name": "TFJ_Canopy_Leaves"
    },
    {
      "x": 4,
      "y": 31,
      "z": 3,
      "name": "TFJ_Canopy_Leaves"
    },
    {
      "x": 4,
      "y": 26,
      "z": 5,
      "name": "TFJ_Titanwood_Log"
    },
    {
      "x": 4,
      "y": 27,
      "z": 5,
      "name": "TFJ_Titanwood_Log"
    },
    {
      "x": 4,
      "y": 30,
      "z": 5,
      "name": "TFJ_Canopy_Leaves"
    },
    {
      "x": 4,
      "y": 30,
      "z": 6,
      "name": "TFJ_Canopy_Leaves"
    },
    {
      "x": 4,
      "y": 30,
      "z": 8,
      "name": "TFJ_Canopy_Leaves"
    },
    {
      "x": 4,
      "y": 28,
      "z": 9,
      "name": "TFJ_Canopy_Leaves"
    },
    {
      "x": 4,
      "y": 29,
      "z": 9,
      "name": "TFJ_Canopy_Leaves"
    },
    {
      "x": 4,
      "y": 26,
      "z": 10,
      "name": "TFJ_Canopy_Leaves"
    },
    {
      "x": 4,
      "y": 27,
      "z": 10,
      "name": "TFJ_Canopy_Leaves"
    },
    {
      "x": 4,
      "y": 28,
      "z": 10,
      "name": "TFJ_Canopy_Leaves"
    },
    {
      "x": 4,
      "y": 29,
      "z": 10,
      "name": "TFJ_Canopy_Leaves"
    },
    {
      "x": 4,
      "y": 25,
      "z": 11,
      "name": "TFJ_Canopy_Leaves"
    },
    {
      "x": 4,
      "y": 26,
      "z": 11,
      "name": "TFJ_Canopy_Leaves"
    },
    {
      "x": 4,
      "y": 27,
      "z": 11,
      "name": "TFJ_Canopy_Leaves"
    },
    {
      "x": 5,
      "y": 27,
      "z": -4,
      "name": "TFJ_Canopy_Leaves"
    },
    {
      "x": 5,
      "y": 28,
      "z": -4,
      "name": "TFJ_Canopy_Leaves"
    },
    {
      "x": 5,
      "y": 29,
      "z": -4,
      "name": "TFJ_Canopy_Leaves"
    },
    {
      "x": 5,
      "y": 30,
      "z": -4,
      "name": "TFJ_Canopy_Leaves"
    },
    {
      "x": 5,
      "y": 31,
      "z": -3,
      "name": "TFJ_Canopy_Leaves"
    },
    {
      "x": 5,
      "y": 32,
      "z": -2,
      "name": "TFJ_Canopy_Leaves"
    },
    {
      "x": 5,
      "y": 31,
      "z": -1,
      "name": "TFJ_Canopy_Leaves"
    },
    {
      "x": 5,
      "y": 32,
      "z": -1,
      "name": "TFJ_Canopy_Leaves"
    },
    {
      "x": 5,
      "y": 19,
      "z": 0,
      "name": "TFJ_Titanwood_Log"
    },
    {
      "x": 5,
      "y": 20,
      "z": 0,
      "name": "TFJ_Titanwood_Log"
    },
    {
      "x": 5,
      "y": 29,
      "z": 0,
      "name": "TFJ_Titanwood_Log",
      "rotation": 5
    },
    {
      "x": 5,
      "y": 32,
      "z": 0,
      "name": "TFJ_Canopy_Leaves"
    },
    {
      "x": 5,
      "y": 32,
      "z": 1,
      "name": "TFJ_Canopy_Leaves"
    },
    {
      "x": 5,
      "y": 25,
      "z": 2,
      "name": "TFJ_Canopy_Leaves"
    },
    {
      "x": 5,
      "y": 30,
      "z": 2,
      "name": "TFJ_Canopy_Leaves"
    },
    {
      "x": 5,
      "y": 31,
      "z": 2,
      "name": "TFJ_Canopy_Leaves"
    },
    {
      "x": 5,
      "y": 32,
      "z": 2,
      "name": "TFJ_Canopy_Leaves"
    },
    {
      "x": 5,
      "y": 25,
      "z": 3,
      "name": "TFJ_Canopy_Leaves"
    },
    {
      "x": 5,
      "y": 27,
      "z": 3,
      "name": "TFJ_Canopy_Leaves"
    },
    {
      "x": 5,
      "y": 28,
      "z": 3,
      "name": "TFJ_Canopy_Leaves"
    },
    {
      "x": 5,
      "y": 29,
      "z": 3,
      "name": "TFJ_Canopy_Leaves"
    },
    {
      "x": 5,
      "y": 30,
      "z": 3,
      "name": "TFJ_Canopy_Leaves"
    },
    {
      "x": 5,
      "y": 23,
      "z": 4,
      "name": "TFJ_Canopy_Leaves"
    },
    {
      "x": 5,
      "y": 24,
      "z": 4,
      "name": "TFJ_Canopy_Leaves"
    },
    {
      "x": 5,
      "y": 22,
      "z": 5,
      "name": "TFJ_Canopy_Leaves"
    },
    {
      "x": 5,
      "y": 23,
      "z": 5,
      "name": "TFJ_Canopy_Leaves"
    },
    {
      "x": 5,
      "y": 24,
      "z": 5,
      "name": "TFJ_Canopy_Leaves"
    },
    {
      "x": 5,
      "y": 27,
      "z": 5,
      "name": "TFJ_Titanwood_Log"
    },
    {
      "x": 5,
      "y": 30,
      "z": 5,
      "name": "TFJ_Canopy_Leaves"
    },
    {
      "x": 5,
      "y": 20,
      "z": 6,
      "name": "TFJ_Canopy_Leaves"
    },
    {
      "x": 5,
      "y": 21,
      "z": 6,
      "name": "TFJ_Canopy_Leaves"
    },
    {
      "x": 5,
      "y": 23,
      "z": 6,
      "name": "TFJ_Canopy_Leaves"
    },
    {
      "x": 5,
      "y": 27,
      "z": 6,
      "name": "TFJ_Titanwood_Log"
    },
    {
      "x": 5,
      "y": 30,
      "z": 6,
      "name": "TFJ_Canopy_Leaves"
    },
    {
      "x": 5,
      "y": 29,
      "z": 7,
      "name": "TFJ_Canopy_Leaves"
    },
    {
      "x": 5,
      "y": 30,
      "z": 7,
      "name": "TFJ_Canopy_Leaves"
    },
    {
      "x": 5,
      "y": 29,
      "z": 8,
      "name": "TFJ_Canopy_Leaves"
    },
    {
      "x": 5,
      "y": 30,
      "z": 8,
      "name": "TFJ_Canopy_Leaves"
    },
    {
      "x": 5,
      "y": 29,
      "z": 9,
      "name": "TFJ_Canopy_Leaves"
    },
    {
      "x": 5,
      "y": 27,
      "z": 10,
      "name": "TFJ_Canopy_Leaves"
    },
    {
      "x": 5,
      "y": 28,
      "z": 10,
      "name": "TFJ_Canopy_Leaves"
    },
    {
      "x": 5,
      "y": 25,
      "z": 11,
      "name": "TFJ_Canopy_Leaves"
    },
    {
      "x": 5,
      "y": 26,
      "z": 11,
      "name": "TFJ_Canopy_Leaves"
    },
    {
      "x": 5,
      "y": 27,
      "z": 11,
      "name": "TFJ_Canopy_Leaves"
    },
    {
      "x": 6,
      "y": 28,
      "z": -4,
      "name": "TFJ_Canopy_Leaves"
    },
    {
      "x": 6,
      "y": 29,
      "z": -4,
      "name": "TFJ_Canopy_Leaves"
    },
    {
      "x": 6,
      "y": 30,
      "z": -4,
      "name": "TFJ_Canopy_Leaves"
    },
    {
      "x": 6,
      "y": 28,
      "z": -3,
      "name": "TFJ_Canopy_Leaves"
    },
    {
      "x": 6,
      "y": 29,
      "z": -3,
      "name": "TFJ_Canopy_Leaves"
    },
    {
      "x": 6,
      "y": 30,
      "z": -3,
      "name": "TFJ_Canopy_Leaves"
    },
    {
      "x": 6,
      "y": 31,
      "z": -3,
      "name": "TFJ_Canopy_Leaves"
    },
    {
      "x": 6,
      "y": 29,
      "z": -2,
      "name": "TFJ_Canopy_Leaves"
    },
    {
      "x": 6,
      "y": 31,
      "z": -2,
      "name": "TFJ_Canopy_Leaves"
    },
    {
      "x": 6,
      "y": 31,
      "z": -1,
      "name": "TFJ_Canopy_Leaves"
    },
    {
      "x": 6,
      "y": 32,
      "z": -1,
      "name": "TFJ_Canopy_Leaves"
    },
    {
      "x": 6,
      "y": 20,
      "z": 0,
      "name": "TFJ_Titanwood_Log"
    },
    {
      "x": 6,
      "y": 25,
      "z": 0,
      "name": "TFJ_Canopy_Leaves"
    },
    {
      "x": 6,
      "y": 29,
      "z": 0,
      "name": "TFJ_Titanwood_Log",
      "rotation": 1
    },
    {
      "x": 6,
      "y": 30,
      "z": 0,
      "name": "TFJ_Titanwood_Log"
    },
    {
      "x": 6,
      "y": 31,
      "z": 0,
      "name": "TFJ_Canopy_Leaves"
    },
    {
      "x": 6,
      "y": 32,
      "z": 0,
      "name": "TFJ_Canopy_Leaves"
    },
    {
      "x": 6,
      "y": 20,
      "z": 1,
      "name": "TFJ_Titanwood_Log"
    },
    {
      "x": 6,
      "y": 25,
      "z": 1,
      "name": "TFJ_Canopy_Leaves"
    },
    {
      "x": 6,
      "y": 32,
      "z": 1,
      "name": "TFJ_Canopy_Leaves"
    },
    {
      "x": 6,
      "y": 25,
      "z": 2,
      "name": "TFJ_Canopy_Leaves"
    },
    {
      "x": 6,
      "y": 30,
      "z": 2,
      "name": "TFJ_Canopy_Leaves"
    },
    {
      "x": 6,
      "y": 31,
      "z": 2,
      "name": "TFJ_Canopy_Leaves"
    },
    {
      "x": 6,
      "y": 25,
      "z": 3,
      "name": "TFJ_Canopy_Leaves"
    },
    {
      "x": 6,
      "y": 29,
      "z": 3,
      "name": "TFJ_Canopy_Leaves"
    },
    {
      "x": 6,
      "y": 24,
      "z": 4,
      "name": "TFJ_Canopy_Leaves"
    },
    {
      "x": 6,
      "y": 21,
      "z": 5,
      "name": "TFJ_Canopy_Leaves"
    },
    {
      "x": 6,
      "y": 22,
      "z": 5,
      "name": "TFJ_Canopy_Leaves"
    },
    {
      "x": 6,
      "y": 24,
      "z": 5,
      "name": "TFJ_Canopy_Leaves"
    },
    {
      "x": 6,
      "y": 25,
      "z": 5,
      "name": "TFJ_Canopy_Leaves"
    },
    {
      "x": 6,
      "y": 30,
      "z": 5,
      "name": "TFJ_Canopy_Leaves"
    },
    {
      "x": 6,
      "y": 20,
      "z": 6,
      "name": "TFJ_Canopy_Leaves"
    },
    {
      "x": 6,
      "y": 23,
      "z": 6,
      "name": "TFJ_Canopy_Leaves"
    },
    {
      "x": 6,
      "y": 24,
      "z": 6,
      "name": "TFJ_Canopy_Leaves"
    },
    {
      "x": 6,
      "y": 29,
      "z": 7,
      "name": "TFJ_Canopy_Leaves"
    },
    {
      "x": 6,
      "y": 30,
      "z": 7,
      "name": "TFJ_Canopy_Leaves"
    },
    {
      "x": 6,
      "y": 29,
      "z": 8,
      "name": "TFJ_Canopy_Leaves"
    },
    {
      "x": 6,
      "y": 28,
      "z": 9,
      "name": "TFJ_Canopy_Leaves"
    },
    {
      "x": 6,
      "y": 29,
      "z": 9,
      "name": "TFJ_Canopy_Leaves"
    },
    {
      "x": 6,
      "y": 25,
      "z": 10,
      "name": "TFJ_Canopy_Leaves"
    },
    {
      "x": 6,
      "y": 26,
      "z": 10,
      "name": "TFJ_Canopy_Leaves"
    },
    {
      "x": 6,
      "y": 27,
      "z": 10,
      "name": "TFJ_Canopy_Leaves"
    },
    {
      "x": 6,
      "y": 28,
      "z": 10,
      "name": "TFJ_Canopy_Leaves"
    },
    {
      "x": 6,
      "y": 25,
      "z": 11,
      "name": "TFJ_Canopy_Leaves"
    },
    {
      "x": 7,
      "y": 20,
      "z": -4,
      "name": "TFJ_Canopy_Leaves"
    },
    {
      "x": 7,
      "y": 22,
      "z": -4,
      "name": "TFJ_Canopy_Leaves"
    },
    {
      "x": 7,
      "y": 22,
      "z": -3,
      "name": "TFJ_Canopy_Leaves"
    },
    {
      "x": 7,
      "y": 23,
      "z": -3,
      "name": "TFJ_Canopy_Leaves"
    },
    {
      "x": 7,
      "y": 29,
      "z": -3,
      "name": "TFJ_Canopy_Leaves"
    },
    {
      "x": 7,
      "y": 30,
      "z": -3,
      "name": "TFJ_Canopy_Leaves"
    },
    {
      "x": 7,
      "y": 22,
      "z": -2,
      "name": "TFJ_Canopy_Leaves"
    },
    {
      "x": 7,
      "y": 23,
      "z": -2,
      "name": "TFJ_Canopy_Leaves"
    },
    {
      "x": 7,
      "y": 24,
      "z": -2,
      "name": "TFJ_Canopy_Leaves"
    },
    {
      "x": 7,
      "y": 29,
      "z": -2,
      "name": "TFJ_Canopy_Leaves"
    },
    {
      "x": 7,
      "y": 25,
      "z": -1,
      "name": "TFJ_Canopy_Leaves"
    },
    {
      "x": 7,
      "y": 31,
      "z": -1,
      "name": "TFJ_Canopy_Leaves"
    },
    {
      "x": 7,
      "y": 25,
      "z": 0,
      "name": "TFJ_Canopy_Leaves"
    },
    {
      "x": 7,
      "y": 30,
      "z": 0,
      "name": "TFJ_Canopy_Leaves"
    },
    {
      "x": 7,
      "y": 31,
      "z": 0,
      "name": "TFJ_Canopy_Leaves"
    },
    {
      "x": 7,
      "y": 20,
      "z": 1,
      "name": "TFJ_Titanwood_Log"
    },
    {
      "x": 7,
      "y": 21,
      "z": 1,
      "name": "TFJ_Titanwood_Log"
    },
    {
      "x": 7,
      "y": 22,
      "z": 1,
      "name": "TFJ_Titanwood_Log"
    },
    {
      "x": 7,
      "y": 23,
      "z": 1,
      "name": "TFJ_Titanwood_Log"
    },
    {
      "x": 7,
      "y": 24,
      "z": 1,
      "name": "TFJ_Titanwood_Log"
    },
    {
      "x": 7,
      "y": 25,
      "z": 1,
      "name": "TFJ_Canopy_Leaves"
    },
    {
      "x": 7,
      "y": 29,
      "z": 1,
      "name": "TFJ_Canopy_Leaves"
    },
    {
      "x": 7,
      "y": 30,
      "z": 1,
      "name": "TFJ_Canopy_Leaves"
    },
    {
      "x": 7,
      "y": 31,
      "z": 1,
      "name": "TFJ_Canopy_Leaves"
    },
    {
      "x": 7,
      "y": 21,
      "z": 2,
      "name": "TFJ_Titanwood_Log",
      "rotation": 4
    },
    {
      "x": 7,
      "y": 25,
      "z": 2,
      "name": "TFJ_Canopy_Leaves"
    },
    {
      "x": 7,
      "y": 29,
      "z": 2,
      "name": "TFJ_Canopy_Leaves"
    },
    {
      "x": 7,
      "y": 21,
      "z": 3,
      "name": "TFJ_Titanwood_Log",
      "rotation": 4
    },
    {
      "x": 7,
      "y": 24,
      "z": 3,
      "name": "TFJ_Canopy_Leaves"
    },
    {
      "x": 7,
      "y": 25,
      "z": 3,
      "name": "TFJ_Canopy_Leaves"
    },
    {
      "x": 7,
      "y": 21,
      "z": 4,
      "name": "TFJ_Titanwood_Log"
    },
    {
      "x": 7,
      "y": 22,
      "z": 4,
      "name": "TFJ_Titanwood_Log"
    },
    {
      "x": 7,
      "y": 23,
      "z": 4,
      "name": "TFJ_Canopy_Leaves"
    },
    {
      "x": 7,
      "y": 24,
      "z": 4,
      "name": "TFJ_Canopy_Leaves"
    },
    {
      "x": 7,
      "y": 19,
      "z": 5,
      "name": "TFJ_Canopy_Leaves"
    },
    {
      "x": 7,
      "y": 20,
      "z": 5,
      "name": "TFJ_Canopy_Leaves"
    },
    {
      "x": 7,
      "y": 22,
      "z": 5,
      "name": "TFJ_Canopy_Leaves"
    },
    {
      "x": 7,
      "y": 24,
      "z": 5,
      "name": "TFJ_Canopy_Leaves"
    },
    {
      "x": 7,
      "y": 28,
      "z": 5,
      "name": "TFJ_Canopy_Leaves"
    },
    {
      "x": 7,
      "y": 29,
      "z": 5,
      "name": "TFJ_Canopy_Leaves"
    },
    {
      "x": 7,
      "y": 19,
      "z": 6,
      "name": "TFJ_Canopy_Leaves"
    },
    {
      "x": 7,
      "y": 20,
      "z": 6,
      "name": "TFJ_Canopy_Leaves"
    },
    {
      "x": 7,
      "y": 21,
      "z": 6,
      "name": "TFJ_Canopy_Leaves"
    },
    {
      "x": 7,
      "y": 22,
      "z": 6,
      "name": "TFJ_Canopy_Leaves"
    },
    {
      "x": 7,
      "y": 28,
      "z": 6,
      "name": "TFJ_Canopy_Leaves"
    },
    {
      "x": 7,
      "y": 29,
      "z": 6,
      "name": "TFJ_Canopy_Leaves"
    },
    {
      "x": 7,
      "y": 25,
      "z": 7,
      "name": "TFJ_Canopy_Leaves"
    },
    {
      "x": 7,
      "y": 28,
      "z": 7,
      "name": "TFJ_Canopy_Leaves"
    },
    {
      "x": 7,
      "y": 29,
      "z": 7,
      "name": "TFJ_Canopy_Leaves"
    },
    {
      "x": 7,
      "y": 24,
      "z": 8,
      "name": "TFJ_Canopy_Leaves"
    },
    {
      "x": 7,
      "y": 25,
      "z": 8,
      "name": "TFJ_Canopy_Leaves"
    },
    {
      "x": 7,
      "y": 27,
      "z": 8,
      "name": "TFJ_Canopy_Leaves"
    },
    {
      "x": 7,
      "y": 28,
      "z": 8,
      "name": "TFJ_Canopy_Leaves"
    },
    {
      "x": 7,
      "y": 29,
      "z": 8,
      "name": "TFJ_Canopy_Leaves"
    },
    {
      "x": 7,
      "y": 26,
      "z": 9,
      "name": "TFJ_Canopy_Leaves"
    },
    {
      "x": 7,
      "y": 27,
      "z": 9,
      "name": "TFJ_Canopy_Leaves"
    },
    {
      "x": 7,
      "y": 28,
      "z": 9,
      "name": "TFJ_Canopy_Leaves"
    },
    {
      "x": 7,
      "y": 24,
      "z": 10,
      "name": "TFJ_Canopy_Leaves"
    },
    {
      "x": 7,
      "y": 25,
      "z": 10,
      "name": "TFJ_Canopy_Leaves"
    },
    {
      "x": 7,
      "y": 26,
      "z": 10,
      "name": "TFJ_Canopy_Leaves"
    },
    {
      "x": 7,
      "y": 27,
      "z": 10,
      "name": "TFJ_Canopy_Leaves"
    },
    {
      "x": 8,
      "y": 19,
      "z": -4,
      "name": "TFJ_Canopy_Leaves"
    },
    {
      "x": 8,
      "y": 20,
      "z": -4,
      "name": "TFJ_Canopy_Leaves"
