{
  "version": 8,
  "blockIdVersion": 11,
  "anchorX": 0,
  "anchorY": 0,
  "anchorZ": 0,
  "blocks": [
    {
      "x": -8,
      "y": 21,
      "z": 1,
      "name": "TFJ_Canopy_Leaves"
    },
    {
      "x": -8,
      "y": 22,
      "z": 1,
      "name": "TFJ_Canopy_Leaves"
    },
    {
      "x": -8,
      "y": 23,
      "z": 1,
      "name": "TFJ_Canopy_Leaves"
    },
    {
      "x": -8,
      "y": 21,
      "z": 2,
      "name": "TFJ_Canopy_Leaves"
    },
    {
      "x": -8,
      "y": 22,
      "z": 2,
      "name": "TFJ_Canopy_Leaves"
    },
    {
      "x": -8,
      "y": 23,
      "z": 2,
      "name": "TFJ_Canopy_Leaves"
    },
    {
      "x": -8,
      "y": 21,
      "z": 3,
      "name": "TFJ_Canopy_Leaves"
    },
    {
      "x": -8,
      "y": 22,
      "z": 3,
      "name": "TFJ_Canopy_Leaves"
    },
    {
      "x": -7,
      "y": 21,
      "z": 0,
      "name": "TFJ_Canopy_Leaves"
    },
    {
      "x": -7,
      "y": 22,
      "z": 0,
      "name": "TFJ_Canopy_Leaves"
    },
    {
      "x": -7,
      "y": 23,
      "z": 0,
      "name": "TFJ_Canopy_Leaves"
    },
    {
      "x": -7,
      "y": 20,
      "z": 1,
      "name": "TFJ_Canopy_Leaves"
    },
    {
      "x": -7,
      "y": 21,
      "z": 1,
      "name": "TFJ_Canopy_Leaves"
    },
    {
      "x": -7,
      "y": 22,
      "z": 1,
      "name": "TFJ_Canopy_Leaves"
    },
    {
      "x": -7,
      "y": 23,
      "z": 1,
      "name": "TFJ_Canopy_Leaves"
    },
    {
      "x": -7,
      "y": 24,
      "z": 1,
      "name": "TFJ_Canopy_Leaves"
    },
    {
      "x": -7,
      "y": 20,
      "z": 2,
      "name": "TFJ_Canopy_Leaves"
    },
    {
      "x": -7,
      "y": 21,
      "z": 2,
      "name": "TFJ_Canopy_Leaves"
    },
    {
      "x": -7,
      "y": 22,
      "z": 2,
      "name": "TFJ_Canopy_Leaves"
    },
    {
      "x": -7,
      "y": 23,
      "z": 2,
      "name": "TFJ_Canopy_Leaves"
    },
    {
      "x": -7,
      "y": 24,
      "z": 2,
      "name": "TFJ_Canopy_Leaves"
    },
    {
      "x": -7,
      "y": 25,
      "z": 2,
      "name": "TFJ_Canopy_Leaves"
    },
    {
      "x": -7,
      "y": 20,
      "z": 3,
      "name": "TFJ_Canopy_Leaves"
    },
    {
      "x": -7,
      "y": 21,
      "z": 3,
      "name": "TFJ_Canopy_Leaves"
    },
    {
      "x": -7,
      "y": 22,
      "z": 3,
      "name": "TFJ_Canopy_Leaves"
    },
    {
      "x": -7,
      "y": 23,
      "z": 3,
      "name": "TFJ_Canopy_Leaves"
    },
    {
      "x": -7,
      "y": 24,
      "z": 3,
      "name": "TFJ_Canopy_Leaves"
    },
    {
      "x": -7,
      "y": 21,
      "z": 4,
      "name": "TFJ_Canopy_Leaves"
    },
    {
      "x": -7,
      "y": 22,
      "z": 4,
      "name": "TFJ_Canopy_Leaves"
    },
    {
      "x": -7,
      "y": 23,
      "z": 4,
      "name": "TFJ_Canopy_Leaves"
    },
    {
      "x": -6,
      "y": 23,
      "z": -5,
      "name": "TFJ_Canopy_Leaves"
    },
    {
      "x": -6,
      "y": 24,
      "z": -5,
      "name": "TFJ_Canopy_Leaves"
    },
    {
      "x": -6,
      "y": 23,
      "z": -4,
      "name": "TFJ_Canopy_Leaves"
    },
    {
      "x": -6,
      "y": 24,
      "z": -4,
      "name": "TFJ_Canopy_Leaves"
    },
    {
      "x": -6,
      "y": 25,
      "z": -4,
      "name": "TFJ_Canopy_Leaves"
    },
    {
      "x": -6,
      "y": 23,
      "z": -3,
      "name": "TFJ_Canopy_Leaves"
    },
    {
      "x": -6,
      "y": 24,
      "z": -3,
      "name": "TFJ_Canopy_Leaves"
    },
    {
      "x": -6,
      "y": 25,
      "z": -3,
      "name": "TFJ_Canopy_Leaves"
    },
    {
      "x": -6,
      "y": 22,
      "z": 0,
      "name": "TFJ_Canopy_Leaves"
    },
    {
      "x": -6,
      "y": 23,
      "z": 0,
      "name": "TFJ_Canopy_Leaves"
    },
    {
      "x": -6,
      "y": 24,
      "z": 0,
      "name": "TFJ_Canopy_Leaves"
    },
    {
      "x": -6,
      "y": 25,
      "z": 0,
      "name": "TFJ_Canopy_Leaves"
    },
    {
      "x": -6,
      "y": 21,
      "z": 1,
      "name": "Empty"
    },
    {
      "x": -6,
      "y": 22,
      "z": 1,
      "name": "TFJ_Canopy_Leaves"
    },
    {
      "x": -6,
      "y": 23,
      "z": 1,
      "name": "TFJ_Canopy_Leaves"
    },
    {
      "x": -6,
      "y": 24,
      "z": 1,
      "name": "TFJ_Canopy_Leaves"
    },
    {
      "x": -6,
      "y": 25,
      "z": 1,
      "name": "TFJ_Canopy_Leaves"
    },
    {
      "x": -6,
      "y": 19,
      "z": 2,
      "name": "TFJ_Titanwood_Log",
      "rotation": 3
    },
    {
      "x": -6,
      "y": 20,
      "z": 2,
      "name": "TFJ_Titanwood_Log"
    },
    {
      "x": -6,
      "y": 21,
      "z": 2,
      "name": "TFJ_Titanwood_Log"
    },
    {
      "x": -6,
      "y": 22,
      "z": 2,
      "name": "TFJ_Titanwood_Log"
    },
    {
      "x": -6,
      "y": 23,
      "z": 2,
      "name": "TFJ_Canopy_Leaves"
    },
    {
      "x": -6,
      "y": 24,
      "z": 2,
      "name": "TFJ_Canopy_Leaves"
    },
    {
      "x": -6,
      "y": 25,
      "z": 2,
      "name": "TFJ_Canopy_Leaves"
    },
    {
      "x": -6,
      "y": 20,
      "z": 3,
      "name": "TFJ_Canopy_Leaves"
    },
    {
      "x": -6,
      "y": 21,
      "z": 3,
      "name": "TFJ_Canopy_Leaves"
    },
    {
      "x": -6,
      "y": 22,
      "z": 3,
      "name": "TFJ_Canopy_Leaves"
    },
    {
      "x": -6,
      "y": 23,
      "z": 3,
      "name": "TFJ_Canopy_Leaves"
    },
    {
      "x": -6,
      "y": 24,
      "z": 3,
      "name": "TFJ_Canopy_Leaves"
    },
    {
      "x": -6,
      "y": 25,
      "z": 3,
      "name": "TFJ_Canopy_Leaves"
    },
    {
      "x": -6,
      "y": 21,
      "z": 4,
      "name": "TFJ_Canopy_Leaves"
    },
    {
      "x": -6,
      "y": 22,
      "z": 4,
      "name": "TFJ_Canopy_Leaves"
    },
    {
      "x": -6,
      "y": 23,
      "z": 4,
      "name": "TFJ_Canopy_Leaves"
    },
    {
      "x": -5,
      "y": 23,
      "z": -6,
      "name": "TFJ_Canopy_Leaves"
    },
    {
      "x": -5,
      "y": 24,
      "z": -6,
      "name": "TFJ_Canopy_Leaves"
    },
    {
      "x": -5,
      "y": 25,
      "z": -6,
      "name": "TFJ_Canopy_Leaves"
    },
    {
      "x": -5,
      "y": 22,
      "z": -5,
      "name": "TFJ_Canopy_Leaves"
    },
    {
      "x": -5,
      "y": 23,
      "z": -5,
      "name": "TFJ_Canopy_Leaves"
    },
    {
      "x": -5,
      "y": 24,
      "z": -5,
      "name": "TFJ_Canopy_Leaves"
    },
    {
      "x": -5,
      "y": 25,
      "z": -5,
      "name": "TFJ_Canopy_Leaves"
    },
    {
      "x": -5,
      "y": 26,
      "z": -5,
      "name": "TFJ_Canopy_Leaves"
    },
    {
      "x": -5,
      "y": 21,
      "z": -4,
      "name": "TFJ_Canopy_Leaves"
    },
    {
      "x": -5,
      "y": 22,
      "z": -4,
      "name": "TFJ_Canopy_Leaves"
    },
    {
      "x": -5,
      "y": 23,
      "z": -4,
      "name": "TFJ_Canopy_Leaves"
    },
    {
      "x": -5,
      "y": 24,
      "z": -4,
      "name": "TFJ_Canopy_Leaves"
    },
    {
      "x": -5,
      "y": 25,
      "z": -4,
      "name": "TFJ_Canopy_Leaves"
    },
    {
      "x": -5,
      "y": 26,
      "z": -4,
      "name": "TFJ_Canopy_Leaves"
    },
    {
      "x": -5,
      "y": 22,
      "z": -3,
      "name": "TFJ_Canopy_Leaves"
    },
    {
      "x": -5,
      "y": 23,
      "z": -3,
      "name": "TFJ_Canopy_Leaves"
    },
    {
      "x": -5,
      "y": 24,
      "z": -3,
      "name": "TFJ_Canopy_Leaves"
    },
    {
      "x": -5,
      "y": 25,
      "z": -3,
      "name": "TFJ_Canopy_Leaves"
    },
    {
      "x": -5,
      "y": 26,
      "z": -3,
      "name": "TFJ_Canopy_Leaves"
    },
    {
      "x": -5,
      "y": 23,
      "z": -2,
      "name": "TFJ_Canopy_Leaves"
    },
    {
      "x": -5,
      "y": 24,
      "z": -2,
      "name": "TFJ_Canopy_Leaves"
    },
    {
      "x": -5,
      "y": 25,
      "z": -2,
      "name": "TFJ_Canopy_Leaves"
    },
    {
      "x": -5,
      "y": 23,
      "z": -1,
      "name": "TFJ_Canopy_Leaves"
    },
    {
      "x": -5,
      "y": 24,
      "z": -1,
      "name": "TFJ_Canopy_Leaves"
    },
    {
      "x": -5,
      "y": 25,
      "z": -1,
      "name": "TFJ_Canopy_Leaves"
    },
    {
      "x": -5,
      "y": 23,
      "z": 0,
      "name": "TFJ_Canopy_Leaves"
    },
    {
      "x": -5,
      "y": 24,
      "z": 0,
      "name": "TFJ_Canopy_Leaves"
    },
    {
      "x": -5,
      "y": 25,
      "z": 0,
      "name": "TFJ_Canopy_Leaves"
    },
    {
      "x": -5,
      "y": 26,
      "z": 0,
      "name": "TFJ_Canopy_Leaves"
    },
    {
      "x": -5,
      "y": 23,
      "z": 1,
      "name": "Empty"
    },
    {
      "x": -5,
      "y": 24,
      "z": 1,
      "name": "TFJ_Canopy_Leaves"
    },
    {
      "x": -5,
      "y": 25,
      "z": 1,
      "name": "TFJ_Canopy_Leaves"
    },
    {
      "x": -5,
      "y": 26,
      "z": 1,
      "name": "TFJ_Canopy_Leaves"
    },
    {
      "x": -5,
      "y": 27,
      "z": 1,
      "name": "TFJ_Canopy_Leaves"
    },
    {
      "x": -5,
      "y": 19,
      "z": 2,
      "name": "TFJ_Titanwood_Log",
      "rotation": 5
    },
    {
      "x": -5,
      "y": 22,
      "z": 2,
      "name": "Empty"
    },
    {
      "x": -5,
      "y": 23,
      "z": 2,
      "name": "TFJ_Canopy_Leaves"
    },
    {
      "x": -5,
      "y": 24,
      "z": 2,
      "name": "TFJ_Canopy_Leaves"
    },
    {
      "x": -5,
      "y": 25,
      "z": 2,
      "name": "TFJ_Canopy_Leaves"
    },
    {
      "x": -5,
      "y": 26,
      "z": 2,
      "name": "TFJ_Canopy_Leaves"
    },
    {
      "x": -5,
      "y": 22,
      "z": 3,
      "name": "TFJ_Canopy_Leaves"
    },
    {
      "x": -5,
      "y": 23,
      "z": 3,
      "name": "TFJ_Canopy_Leaves"
    },
    {
      "x": -5,
      "y": 24,
      "z": 3,
      "name": "TFJ_Canopy_Leaves"
    },
    {
      "x": -5,
      "y": 25,
      "z": 3,
      "name": "TFJ_Canopy_Leaves"
    },
    {
      "x": -5,
      "y": 21,
      "z": 4,
      "name": "TFJ_Canopy_Leaves"
    },
    {
      "x": -5,
      "y": 22,
      "z": 4,
      "name": "TFJ_Canopy_Leaves"
    },
    {
      "x": -5,
      "y": 23,
      "z": 4,
      "name": "TFJ_Canopy_Leaves"
    },
    {
      "x": -5,
      "y": 24,
      "z": 4,
      "name": "TFJ_Canopy_Leaves"
    },
    {
      "x": -5,
      "y": 25,
      "z": 4,
      "name": "TFJ_Canopy_Leaves"
    },
    {
      "x": -4,
      "y": 22,
      "z": -7,
      "name": "TFJ_Canopy_Leaves"
    },
    {
      "x": -4,
      "y": 23,
      "z": -7,
      "name": "TFJ_Canopy_Leaves"
    },
    {
      "x": -4,
      "y": 24,
      "z": -7,
      "name": "TFJ_Canopy_Leaves"
    },
    {
      "x": -4,
      "y": 22,
      "z": -6,
      "name": "TFJ_Canopy_Leaves"
    },
    {
      "x": -4,
      "y": 23,
      "z": -6,
      "name": "TFJ_Canopy_Leaves"
    },
    {
      "x": -4,
      "y": 24,
      "z": -6,
      "name": "TFJ_Canopy_Leaves"
    },
    {
      "x": -4,
      "y": 25,
      "z": -6,
      "name": "TFJ_Canopy_Leaves"
    },
    {
      "x": -4,
      "y": 22,
      "z": -5,
      "name": "TFJ_Canopy_Leaves"
    },
    {
      "x": -4,
      "y": 23,
      "z": -5,
      "name": "TFJ_Canopy_Leaves"
    },
    {
      "x": -4,
      "y": 24,
      "z": -5,
      "name": "TFJ_Canopy_Leaves"
    },
    {
      "x": -4,
      "y": 25,
      "z": -5,
      "name": "TFJ_Canopy_Leaves"
    },
    {
      "x": -4,
      "y": 26,
      "z": -5,
      "name": "TFJ_Canopy_Leaves"
    },
    {
      "x": -4,
      "y": 27,
      "z": -5,
      "name": "TFJ_Canopy_Leaves"
    },
    {
      "x": -4,
      "y": 22,
      "z": -4,
      "name": "TFJ_Canopy_Leaves"
    },
    {
      "x": -4,
      "y": 23,
      "z": -4,
      "name": "TFJ_Canopy_Leaves"
    },
    {
      "x": -4,
      "y": 24,
      "z": -4,
      "name": "TFJ_Canopy_Leaves"
    },
    {
      "x": -4,
      "y": 25,
      "z": -4,
      "name": "TFJ_Canopy_Leaves"
    },
    {
      "x": -4,
      "y": 26,
      "z": -4,
      "name": "TFJ_Canopy_Leaves"
    },
    {
      "x": -4,
      "y": 27,
      "z": -4,
      "name": "TFJ_Canopy_Leaves"
    },
    {
      "x": -4,
      "y": 22,
      "z": -3,
      "name": "TFJ_Canopy_Leaves"
    },
    {
      "x": -4,
      "y": 23,
      "z": -3,
      "name": "TFJ_Canopy_Leaves"
    },
    {
      "x": -4,
      "y": 24,
      "z": -3,
      "name": "TFJ_Canopy_Leaves"
    },
    {
      "x": -4,
      "y": 25,
      "z": -3,
      "name": "TFJ_Canopy_Leaves"
    },
    {
      "x": -4,
      "y": 26,
      "z": -3,
      "name": "TFJ_Canopy_Leaves"
    },
    {
      "x": -4,
      "y": 27,
      "z": -3,
      "name": "TFJ_Canopy_Leaves"
    },
    {
      "x": -4,
      "y": 23,
      "z": -2,
      "name": "TFJ_Canopy_Leaves"
    },
    {
      "x": -4,
      "y": 24,
      "z": -2,
      "name": "TFJ_Canopy_Leaves"
    },
    {
      "x": -4,
      "y": 25,
      "z": -2,
      "name": "TFJ_Canopy_Leaves"
    },
    {
      "x": -4,
      "y": 23,
      "z": -1,
      "name": "TFJ_Canopy_Leaves"
    },
    {
      "x": -4,
      "y": 24,
      "z": -1,
      "name": "TFJ_Canopy_Leaves"
    },
    {
      "x": -4,
      "y": 25,
      "z": -1,
      "name": "TFJ_Canopy_Leaves"
    },
    {
      "x": -4,
      "y": 24,
      "z": 0,
      "name": "TFJ_Canopy_Leaves"
    },
    {
      "x": -4,
      "y": 25,
      "z": 0,
      "name": "TFJ_Canopy_Leaves"
    },
    {
      "x": -4,
      "y": 26,
      "z": 0,
      "name": "TFJ_Canopy_Leaves"
    },
    {
      "x": -4,
      "y": 27,
      "z": 0,
      "name": "TFJ_Canopy_Leaves"
    },
    {
      "x": -4,
      "y": 19,
      "z": 1,
      "name": "TFJ_Titanwood_Log"
    },
    {
      "x": -4,
      "y": 20,
      "z": 1,
      "name": "TFJ_Titanwood_Log"
    },
    {
      "x": -4,
      "y": 21,
      "z": 1,
      "name": "TFJ_Titanwood_Log"
    },
    {
      "x": -4,
      "y": 22,
      "z": 1,
      "name": "TFJ_Titanwood_Log"
    },
    {
      "x": -4,
      "y": 23,
      "z": 1,
      "name": "TFJ_Titanwood_Log"
    },
    {
      "x": -4,
      "y": 24,
      "z": 1,
      "name": "TFJ_Titanwood_Log"
    },
    {
      "x": -4,
      "y": 25,
      "z": 1,
      "name": "TFJ_Canopy_Leaves"
    },
    {
      "x": -4,
      "y": 26,
      "z": 1,
      "name": "TFJ_Canopy_Leaves"
    },
    {
      "x": -4,
      "y": 27,
      "z": 1,
      "name": "TFJ_Canopy_Leaves"
    },
    {
      "x": -4,
      "y": 16,
      "z": 2,
      "name": "TFJ_Titanwood_Log"
    },
    {
      "x": -4,
      "y": 17,
      "z": 2,
      "name": "TFJ_Titanwood_Log"
    },
    {
      "x": -4,
      "y": 18,
      "z": 2,
      "name": "TFJ_Titanwood_Log"
    },
    {
      "x": -4,
      "y": 19,
      "z": 2,
      "name": "TFJ_Titanwood_Log"
    },
    {
      "x": -4,
      "y": 24,
      "z": 2,
      "name": "TFJ_Canopy_Leaves"
    },
    {
      "x": -4,
      "y": 25,
      "z": 2,
      "name": "TFJ_Canopy_Leaves"
    },
    {
      "x": -4,
      "y": 26,
      "z": 2,
      "name": "TFJ_Canopy_Leaves"
    },
    {
      "x": -4,
      "y": 27,
      "z": 2,
      "name": "TFJ_Canopy_Leaves"
    },
    {
      "x": -4,
      "y": 17,
      "z": 3,
      "name": "TFJ_Titanwood_Log"
    },
    {
      "x": -4,
      "y": 22,
      "z": 3,
      "name": "TFJ_Canopy_Leaves"
    },
    {
      "x": -4,
      "y": 23,
      "z": 3,
      "name": "TFJ_Canopy_Leaves"
    },
    {
      "x": -4,
      "y": 24,
      "z": 3,
      "name": "TFJ_Canopy_Leaves"
    },
    {
      "x": -4,
      "y": 25,
      "z": 3,
      "name": "TFJ_Canopy_Leaves"
    },
    {
      "x": -4,
      "y": 26,
      "z": 3,
      "name": "TFJ_Canopy_Leaves"
    },
    {
      "x": -4,
      "y": 27,
      "z": 3,
      "name": "TFJ_Canopy_Leaves"
    },
    {
      "x": -4,
      "y": 22,
      "z": 4,
      "name": "TFJ_Canopy_Leaves"
    },
    {
      "x": -4,
      "y": 23,
      "z": 4,
      "name": "TFJ_Canopy_Leaves"
    },
    {
      "x": -4,
      "y": 24,
      "z": 4,
      "name": "TFJ_Canopy_Leaves"
    },
    {
      "x": -4,
      "y": 25,
      "z": 4,
      "name": "TFJ_Canopy_Leaves"
    },
    {
      "x": -4,
      "y": 26,
      "z": 4,
      "name": "TFJ_Canopy_Leaves"
    },
    {
      "x": -4,
      "y": 22,
      "z": 5,
      "name": "TFJ_Canopy_Leaves"
    },
    {
      "x": -4,
      "y": 23,
      "z": 5,
      "name": "TFJ_Canopy_Leaves"
    },
    {
      "x": -4,
      "y": 24,
      "z": 5,
      "name": "TFJ_Canopy_Leaves"
    },
    {
      "x": -4,
      "y": 25,
      "z": 5,
      "name": "TFJ_Canopy_Leaves"
    },
    {
      "x": -4,
      "y": 22,
      "z": 6,
      "name": "TFJ_Canopy_Leaves"
    },
    {
      "x": -4,
      "y": 23,
      "z": 6,
      "name": "TFJ_Canopy_Leaves"
    },
    {
      "x": -4,
      "y": 24,
      "z": 6,
      "name": "TFJ_Canopy_Leaves"
    },
    {
      "x": -4,
      "y": 21,
      "z": 7,
      "name": "TFJ_Canopy_Leaves"
    },
    {
      "x": -4,
      "y": 22,
      "z": 7,
      "name": "TFJ_Canopy_Leaves"
    },
    {
      "x": -4,
      "y": 23,
      "z": 7,
      "name": "TFJ_Canopy_Leaves"
    },
    {
      "x": -4,
      "y": 24,
      "z": 7,
      "name": "TFJ_Canopy_Leaves"
    },
    {
      "x": -4,
      "y": 21,
      "z": 8,
      "name": "TFJ_Canopy_Leaves"
    },
    {
      "x": -4,
      "y": 22,
      "z": 8,
      "name": "TFJ_Canopy_Leaves"
    },
    {
      "x": -4,
      "y": 23,
      "z": 8,
      "name": "TFJ_Canopy_Leaves"
    },
    {
      "x": -3,
      "y": 22,
      "z": -8,
      "name": "TFJ_Canopy_Leaves"
    },
    {
      "x": -3,
      "y": 23,
      "z": -8,
      "name": "TFJ_Canopy_Leaves"
    },
    {
      "x": -3,
      "y": 24,
      "z": -8,
      "name": "TFJ_Canopy_Leaves"
    },
    {
      "x": -3,
      "y": 21,
      "z": -7,
      "name": "TFJ_Canopy_Leaves"
    },
    {
      "x": -3,
      "y": 22,
      "z": -7,
      "name": "TFJ_Canopy_Leaves"
    },
    {
      "x": -3,
      "y": 23,
      "z": -7,
      "name": "TFJ_Canopy_Leaves"
    },
    {
      "x": -3,
      "y": 24,
      "z": -7,
      "name": "TFJ_Canopy_Leaves"
    },
    {
      "x": -3,
      "y": 25,
      "z": -7,
      "name": "TFJ_Canopy_Leaves"
    },
    {
      "x": -3,
      "y": 22,
      "z": -6,
      "name": "TFJ_Canopy_Leaves"
    },
    {
      "x": -3,
      "y": 23,
      "z": -6,
      "name": "TFJ_Canopy_Leaves"
    },
    {
      "x": -3,
      "y": 24,
      "z": -6,
      "name": "TFJ_Canopy_Leaves"
    },
    {
      "x": -3,
      "y": 25,
      "z": -6,
      "name": "TFJ_Canopy_Leaves"
    },
    {
      "x": -3,
      "y": 26,
      "z": -6,
      "name": "TFJ_Canopy_Leaves"
    },
    {
      "x": -3,
      "y": 23,
      "z": -5,
      "name": "TFJ_Canopy_Leaves"
    },
    {
      "x": -3,
      "y": 24,
      "z": -5,
      "name": "TFJ_Canopy_Leaves"
    },
    {
      "x": -3,
      "y": 25,
      "z": -5,
      "name": "TFJ_Canopy_Leaves"
    },
    {
      "x": -3,
      "y": 26,
      "z": -5,
      "name": "TFJ_Canopy_Leaves"
    },
    {
      "x": -3,
      "y": 24,
      "z": -4,
      "name": "TFJ_Canopy_Leaves"
    },
    {
      "x": -3,
      "y": 25,
      "z": -4,
      "name": "TFJ_Canopy_Leaves"
    },
    {
      "x": -3,
      "y": 26,
      "z": -4,
      "name": "TFJ_Canopy_Leaves"
    },
    {
      "x": -3,
      "y": 27,
      "z": -4,
      "name": "TFJ_Canopy_Leaves"
    },
    {
      "x": -3,
      "y": 23,
      "z": -3,
      "name": "TFJ_Canopy_Leaves"
    },
    {
      "x": -3,
      "y": 24,
      "z": -3,
      "name": "TFJ_Canopy_Leaves"
    },
    {
      "x": -3,
      "y": 25,
      "z": -3,
      "name": "TFJ_Canopy_Leaves"
    },
    {
      "x": -3,
      "y": 26,
      "z": -3,
      "name": "TFJ_Canopy_Leaves"
    },
    {
      "x": -3,
      "y": 23,
      "z": -2,
      "name": "TFJ_Canopy_Leaves"
    },
    {
      "x": -3,
      "y": 24,
      "z": -2,
      "name": "TFJ_Canopy_Leaves"
    },
    {
      "x": -3,
      "y": 25,
      "z": -2,
      "name": "TFJ_Canopy_Leaves"
    },
    {
      "x": -3,
      "y": 23,
      "z": -1,
      "name": "TFJ_Canopy_Leaves"
    },
    {
      "x": -3,
      "y": 24,
      "z": -1,
      "name": "TFJ_Canopy_Leaves"
    },
    {
      "x": -3,
      "y": 25,
      "z": -1,
      "name": "TFJ_Canopy_Leaves"
    },
    {
      "x": -3,
      "y": 23,
      "z": 0,
      "name": "TFJ_Canopy_Leaves"
    },
    {
      "x": -3,
      "y": 24,
      "z": 0,
      "name": "TFJ_Canopy_Leaves"
    },
    {
      "x": -3,
      "y": 25,
      "z": 0,
      "name": "TFJ_Canopy_Leaves"
    },
    {
      "x": -3,
      "y": 26,
      "z": 0,
      "name": "TFJ_Canopy_Leaves"
    },
    {
      "x": -3,
      "y": 24,
      "z": 1,
      "name": "TFJ_Canopy_Leaves"
    },
    {
      "x": -3,
      "y": 25,
      "z": 1,
      "name": "TFJ_Canopy_Leaves"
    },
    {
      "x": -3,
      "y": 26,
      "z": 1,
      "name": "TFJ_Canopy_Leaves"
    },
    {
      "x": -3,
      "y": 27,
      "z": 1,
      "name": "TFJ_Canopy_Leaves"
    },
    {
      "x": -3,
      "y": 23,
      "z": 2,
      "name": "TFJ_Canopy_Leaves"
    },
    {
      "x": -3,
      "y": 24,
      "z": 2,
      "name": "TFJ_Canopy_Leaves"
    },
    {
      "x": -3,
      "y": 25,
      "z": 2,
      "name": "TFJ_Canopy_Leaves"
    },
    {
      "x": -3,
      "y": 26,
      "z": 2,
      "name": "TFJ_Canopy_Leaves"
    },
    {
      "x": -3,
      "y": 27,
      "z": 2,
      "name": "TFJ_Canopy_Leaves"
    },
    {
      "x": -3,
      "y": 16,
      "z": 3,
      "name": "TFJ_Titanwood_Log"
    },
    {
      "x": -3,
      "y": 17,
      "z": 3,
      "name": "TFJ_Titanwood_Log"
    },
    {
      "x": -3,
      "y": 18,
      "z": 3,
      "name": "TFJ_Titanwood_Log"
    },
    {
      "x": -3,
      "y": 19,
      "z": 3,
      "name": "TFJ_Titanwood_Log"
    },
    {
      "x": -3,
      "y": 20,
      "z": 3,
      "name": "TFJ_Titanwood_Log"
    },
    {
      "x": -3,
      "y": 21,
      "z": 3,
      "name": "TFJ_Titanwood_Log"
    },
    {
      "x": -3,
      "y": 22,
      "z": 3,
      "name": "TFJ_Titanwood_Log"
    },
    {
      "x": -3,
      "y": 23,
      "z": 3,
      "name": "TFJ_Titanwood_Log"
    },
    {
      "x": -3,
      "y": 24,
      "z": 3,
      "name": "TFJ_Titanwood_Log"
    },
    {
      "x": -3,
      "y": 25,
      "z": 3,
      "name": "TFJ_Canopy_Leaves"
    },
    {
      "x": -3,
      "y": 26,
      "z": 3,
      "name": "TFJ_Canopy_Leaves"
    },
    {
      "x": -3,
      "y": 27,
      "z": 3,
      "name": "TFJ_Canopy_Leaves"
    },
    {
      "x": -3,
      "y": 21,
      "z": 4,
      "name": "TFJ_Canopy_Leaves"
    },
    {
      "x": -3,
      "y": 22,
      "z": 4,
      "name": "TFJ_Canopy_Leaves"
    },
    {
      "x": -3,
      "y": 23,
      "z": 4,
      "name": "TFJ_Canopy_Leaves"
    },
    {
      "x": -3,
      "y": 24,
      "z": 4,
      "name": "TFJ_Canopy_Leaves"
    },
    {
      "x": -3,
      "y": 25,
      "z": 4,
      "name": "TFJ_Canopy_Leaves"
    },
    {
      "x": -3,
      "y": 26,
      "z": 4,
      "name": "TFJ_Canopy_Leaves"
    },
    {
      "x": -3,
      "y": 27,
      "z": 4,
      "name": "TFJ_Canopy_Leaves"
    },
    {
      "x": -3,
      "y": 21,
      "z": 5,
      "name": "TFJ_Canopy_Leaves"
    },
    {
      "x": -3,
      "y": 22,
      "z": 5,
      "name": "TFJ_Canopy_Leaves"
    },
    {
      "x": -3,
      "y": 23,
      "z": 5,
      "name": "TFJ_Canopy_Leaves"
    },
    {
      "x": -3,
      "y": 24,
      "z": 5,
      "name": "TFJ_Canopy_Leaves"
    },
    {
      "x": -3,
      "y": 25,
      "z": 5,
      "name": "TFJ_Canopy_Leaves"
    },
    {
      "x": -3,
      "y": 26,
      "z": 5,
      "name": "TFJ_Canopy_Leaves"
    },
    {
      "x": -3,
      "y": 20,
      "z": 6,
      "name": "TFJ_Canopy_Leaves"
    },
    {
      "x": -3,
      "y": 21,
      "z": 6,
      "name": "TFJ_Canopy_Leaves"
    },
    {
      "x": -3,
      "y": 22,
      "z": 6,
      "name": "TFJ_Canopy_Leaves"
    },
    {
      "x": -3,
      "y": 23,
      "z": 6,
      "name": "TFJ_Canopy_Leaves"
    },
    {
      "x": -3,
      "y": 24,
      "z": 6,
      "name": "TFJ_Canopy_Leaves"
    },
    {
      "x": -3,
      "y": 25,
      "z": 6,
      "name": "TFJ_Canopy_Leaves"
    },
    {
      "x": -3,
      "y": 26,
      "z": 6,
      "name": "TFJ_Canopy_Leaves"
    },
    {
      "x": -3,
      "y": 20,
      "z": 7,
      "name": "TFJ_Canopy_Leaves"
    },
    {
      "x": -3,
      "y": 21,
      "z": 7,
      "name": "TFJ_Canopy_Leaves"
    },
    {
      "x": -3,
      "y": 22,
      "z": 7,
      "name": "TFJ_Canopy_Leaves"
    },
    {
      "x": -3,
      "y": 23,
      "z": 7,
      "name": "TFJ_Canopy_Leaves"
    },
    {
      "x": -3,
      "y": 24,
      "z": 7,
      "name": "TFJ_Canopy_Leaves"
    },
    {
      "x": -3,
      "y": 25,
      "z": 7,
      "name": "TFJ_Canopy_Leaves"
    },
    {
      "x": -3,
      "y": 20,
      "z": 8,
      "name": "TFJ_Canopy_Leaves"
    },
    {
      "x": -3,
      "y": 21,
      "z": 8,
      "name": "TFJ_Canopy_Leaves"
    },
    {
      "x": -3,
      "y": 22,
      "z": 8,
      "name": "TFJ_Canopy_Leaves"
    },
    {
      "x": -3,
      "y": 23,
      "z": 8,
      "name": "TFJ_Canopy_Leaves"
    },
    {
      "x": -3,
      "y": 24,
      "z": 8,
      "name": "TFJ_Canopy_Leaves"
    },
    {
      "x": -3,
      "y": 25,
      "z": 8,
      "name": "TFJ_Canopy_Leaves"
    },
    {
      "x": -3,
      "y": 22,
      "z": 9,
      "name": "TFJ_Canopy_Leaves"
    },
    {
      "x": -3,
      "y": 23,
      "z": 9,
      "name": "TFJ_Canopy_Leaves"
    },
    {
      "x": -2,
      "y": 22,
      "z": -8,
      "name": "TFJ_Canopy_Leaves"
    },
    {
      "x": -2,
      "y": 23,
      "z": -8,
      "name": "TFJ_Canopy_Leaves"
    },
    {
      "x": -2,
      "y": 24,
      "z": -8,
      "name": "TFJ_Canopy_Leaves"
    },
    {
      "x": -2,
      "y": 21,
      "z": -7,
      "name": "TFJ_Canopy_Leaves"
    },
    {
      "x": -2,
      "y": 22,
      "z": -7,
      "name": "TFJ_Canopy_Leaves"
    },
    {
      "x": -2,
      "y": 23,
      "z": -7,
      "name": "TFJ_Canopy_Leaves"
    },
    {
      "x": -2,
      "y": 24,
      "z": -7,
      "name": "TFJ_Canopy_Leaves"
    },
    {
      "x": -2,
      "y": 25,
      "z": -7,
      "name": "TFJ_Canopy_Leaves"
    },
    {
      "x": -2,
      "y": 26,
      "z": -7,
      "name": "TFJ_Canopy_Leaves"
    },
    {
      "x": -2,
      "y": 21,
      "z": -6,
      "name": "TFJ_Titanwood_Log",
      "rotation": 2
    },
    {
      "x": -2,
      "y": 22,
      "z": -6,
      "name": "TFJ_Titanwood_Log"
    },
    {
      "x": -2,
      "y": 23,
      "z": -6,
      "name": "TFJ_Titanwood_Log"
    },
    {
      "x": -2,
      "y": 24,
      "z": -6,
      "name": "TFJ_Canopy_Leaves"
    },
    {
      "x": -2,
      "y": 25,
      "z": -6,
      "name": "TFJ_Canopy_Leaves"
    },
    {
      "x": -2,
      "y": 26,
      "z": -6,
      "name": "TFJ_Canopy_Leaves"
    },
    {
      "x": -2,
      "y": 21,
      "z": -5,
      "name": "TFJ_Titanwood_Log",
      "rotation": 4
    },
    {
      "x": -2,
      "y": 24,
      "z": -5,
      "name": "TFJ_Canopy_Leaves"
    },
    {
      "x": -2,
      "y": 25,
      "z": -5,
      "name": "TFJ_Canopy_Leaves"
    },
    {
      "x": -2,
      "y": 26,
      "z": -5,
      "name": "TFJ_Canopy_Leaves"
    },
    {
      "x": -2,
      "y": 27,
      "z": -5,
      "name": "TFJ_Canopy_Leaves"
    },
    {
      "x": -2,
      "y": 18,
      "z": -4,
      "name": "TFJ_Titanwood_Log"
    },
    {
      "x": -2,
      "y": 19,
      "z": -4,
      "name": "TFJ_Titanwood_Log"
    },
    {
      "x": -2,
      "y": 20,
      "z": -4,
      "name": "TFJ_Titanwood_Log"
    },
    {
      "x": -2,
      "y": 21,
      "z": -4,
      "name": "TFJ_Titanwood_Log"
    },
    {
      "x": -2,
      "y": 22,
      "z": -4,
      "name": "TFJ_Titanwood_Log"
    },
    {
      "x": -2,
      "y": 23,
      "z": -4,
      "name": "TFJ_Titanwood_Log"
    },
    {
      "x": -2,
      "y": 24,
      "z": -4,
      "name": "TFJ_Titanwood_Log"
    },
    {
      "x": -2,
      "y": 25,
      "z": -4,
      "name": "TFJ_Canopy_Leaves"
    },
    {
      "x": -2,
      "y": 26,
      "z": -4,
      "name": "TFJ_Canopy_Leaves"
    },
    {
      "x": -2,
      "y": 27,
      "z": -4,
      "name": "TFJ_Canopy_Leaves"
    },
    {
      "x": -2,
      "y": 18,
      "z": -3,
      "name": "TFJ_Titanwood_Log"
    },
    {
      "x": -2,
      "y": 19,
      "z": -3,
      "name": "TFJ_Titanwood_Log"
    },
    {
      "x": -2,
      "y": 24,
      "z": -3,
      "name": "TFJ_Canopy_Leaves"
    },
    {
      "x": -2,
      "y": 25,
      "z": -3,
      "name": "TFJ_Canopy_Leaves"
    },
    {
      "x": -2,
      "y": 26,
      "z": -3,
      "name": "TFJ_Canopy_Leaves"
    },
    {
      "x": -2,
      "y": 27,
      "z": -3,
      "name": "TFJ_Canopy_Leaves"
    },
    {
      "x": -2,
      "y": 23,
      "z": -2,
      "name": "TFJ_Canopy_Leaves"
    },
    {
      "x": -2,
      "y": 24,
      "z": -2,
      "name": "TFJ_Canopy_Leaves"
    },
    {
      "x": -2,
      "y": 25,
      "z": -2,
      "name": "TFJ_Canopy_Leaves"
    },
    {
      "x": -2,
      "y": 0,
      "z": 0,
      "name": "TFJ_Titanwood_Log"
    },
    {
      "x": -2,
      "y": 1,
      "z": 0,
      "name": "TFJ_Titanwood_Log"
    },
    {
      "x": -2,
      "y": 2,
      "z": 0,
      "name": "TFJ_Titanwood_Log"
    },
    {
      "x": -2,
      "y": 3,
      "z": 0,
      "name": "TFJ_Titanwood_Log",
      "rotation": 9
    },
    {
      "x": -2,
      "y": 23,
      "z": 0,
      "name": "TFJ_Canopy_Leaves"
    },
    {
      "x": -2,
      "y": 24,
      "z": 0,
      "name": "TFJ_Canopy_Leaves"
    },
    {
      "x": -2,
      "y": 25,
      "z": 0,
      "name": "TFJ_Canopy_Leaves"
    },
    {
      "x": -2,
      "y": 23,
      "z": 1,
      "name": "TFJ_Canopy_Leaves"
    },
    {
      "x": -2,
      "y": 24,
      "z": 1,
      "name": "TFJ_Canopy_Leaves"
    },
    {
      "x": -2,
      "y": 25,
      "z": 1,
      "name": "TFJ_Canopy_Leaves"
    },
    {
      "x": -2,
      "y": 23,
      "z": 2,
      "name": "TFJ_Canopy_Leaves"
    },
    {
      "x": -2,
      "y": 24,
      "z": 2,
      "name": "TFJ_Canopy_Leaves"
    },
    {
      "x": -2,
      "y": 25,
      "z": 2,
      "name": "TFJ_Canopy_Leaves"
    },
    {
      "x": -2,
      "y": 26,
      "z": 2,
      "name": "TFJ_Canopy_Leaves"
    },
    {
      "x": -2,
      "y": 16,
      "z": 3,
      "name": "TFJ_Titanwood_Log"
    },
    {
      "x": -2,
      "y": 23,
      "z": 3,
      "name": "TFJ_Canopy_Leaves"
    },
    {
      "x": -2,
      "y": 24,
      "z": 3,
      "name": "TFJ_Canopy_Leaves"
    },
    {
      "x": -2,
      "y": 25,
      "z": 3,
      "name": "TFJ_Canopy_Leaves"
    },
    {
      "x": -2,
      "y": 26,
      "z": 3,
      "name": "TFJ_Canopy_Leaves"
    },
    {
      "x": -2,
      "y": 27,
      "z": 3,
      "name": "TFJ_Canopy_Leaves"
    },
    {
      "x": -2,
      "y": 16,
      "z": 4,
      "name": "TFJ_Titanwood_Log"
    },
    {
      "x": -2,
      "y": 23,
      "z": 4,
      "name": "TFJ_Canopy_Leaves"
    },
    {
      "x": -2,
      "y": 24,
      "z": 4,
      "name": "TFJ_Canopy_Leaves"
    },
    {
      "x": -2,
      "y": 25,
      "z": 4,
      "name": "TFJ_Canopy_Leaves"
    },
    {
      "x": -2,
      "y": 26,
      "z": 4,
      "name": "TFJ_Canopy_Leaves"
    },
    {
      "x": -2,
      "y": 27,
      "z": 4,
      "name": "TFJ_Canopy_Leaves"
    },
    {
      "x": -2,
      "y": 28,
      "z": 4,
      "name": "TFJ_Canopy_Leaves"
    },
    {
      "x": -2,
      "y": 15,
      "z": 5,
      "name": "TFJ_Titanwood_Log"
    },
    {
      "x": -2,
      "y": 16,
      "z": 5,
      "name": "TFJ_Titanwood_Log"
    },
    {
      "x": -2,
      "y": 17,
      "z": 5,
      "name": "TFJ_Titanwood_Log"
    },
    {
      "x": -2,
      "y": 23,
      "z": 5,
      "name": "TFJ_Canopy_Leaves"
    },
    {
      "x": -2,
      "y": 24,
      "z": 5,
      "name": "TFJ_Canopy_Leaves"
    },
    {
      "x": -2,
      "y": 25,
      "z": 5,
      "name": "TFJ_Canopy_Leaves"
    },
    {
      "x": -2,
      "y": 26,
      "z": 5,
      "name": "TFJ_Canopy_Leaves"
    },
    {
      "x": -2,
      "y": 27,
      "z": 5,
      "name": "TFJ_Canopy_Leaves"
    },
    {
      "x": -2,
      "y": 17,
      "z": 6,
      "name": "TFJ_Titanwood_Log"
    },
    {
      "x": -2,
      "y": 18,
      "z": 6,
      "name": "TFJ_Titanwood_Log"
    },
    {
      "x": -2,
      "y": 19,
      "z": 6,
      "name": "TFJ_Titanwood_Log"
    },
    {
      "x": -2,
      "y": 20,
      "z": 6,
      "name": "TFJ_Titanwood_Log"
    },
    {
      "x": -2,
      "y": 21,
      "z": 6,
      "name": "TFJ_Titanwood_Log"
    },
    {
      "x": -2,
      "y": 22,
      "z": 6,
      "name": "TFJ_Titanwood_Log"
    },
    {
      "x": -2,
      "y": 23,
      "z": 6,
      "name": "TFJ_Titanwood_Log"
    },
    {
      "x": -2,
      "y": 24,
      "z": 6,
      "name": "TFJ_Canopy_Leaves"
    },
    {
      "x": -2,
      "y": 25,
      "z": 6,
      "name": "TFJ_Canopy_Leaves"
    },
    {
      "x": -2,
      "y": 26,
      "z": 6,
      "name": "TFJ_Canopy_Leaves"
    },
    {
      "x": -2,
      "y": 19,
      "z": 7,
      "name": "TFJ_Titanwood_Log",
      "rotation": 4
    },
    {
      "x": -2,
      "y": 20,
      "z": 7,
      "name": "TFJ_Canopy_Leaves"
    },
    {
      "x": -2,
      "y": 21,
      "z": 7,
      "name": "TFJ_Canopy_Leaves"
    },
    {
      "x": -2,
      "y": 22,
      "z": 7,
      "name": "TFJ_Canopy_Leaves"
    },
    {
      "x": -2,
      "y": 23,
      "z": 7,
      "name": "TFJ_Canopy_Leaves"
    },
    {
      "x": -2,
      "y": 24,
      "z": 7,
      "name": "TFJ_Canopy_Leaves"
    },
    {
      "x": -2,
      "y": 25,
      "z": 7,
      "name": "TFJ_Canopy_Leaves"
    },
    {
      "x": -2,
      "y": 26,
      "z": 7,
      "name": "TFJ_Canopy_Leaves"
    },
    {
      "x": -2,
      "y": 19,
      "z": 8,
      "name": "TFJ_Titanwood_Log"
    },
    {
      "x": -2,
      "y": 20,
      "z": 8,
      "name": "TFJ_Titanwood_Log"
    },
    {
      "x": -2,
      "y": 21,
      "z": 8,
      "name": "TFJ_Titanwood_Log"
    },
    {
      "x": -2,
      "y": 22,
      "z": 8,
      "name": "TFJ_Titanwood_Log"
    },
    {
      "x": -2,
      "y": 23,
      "z": 8,
      "name": "TFJ_Canopy_Leaves"
    },
    {
      "x": -2,
      "y": 24,
      "z": 8,
      "name": "TFJ_Canopy_Leaves"
    },
    {
      "x": -2,
      "y": 25,
      "z": 8,
      "name": "TFJ_Canopy_Leaves"
    },
    {
      "x": -2,
      "y": 21,
      "z": 9,
      "name": "TFJ_Canopy_Leaves"
    },
    {
      "x": -2,
      "y": 22,
      "z": 9,
      "name": "TFJ_Canopy_Leaves"
    },
    {
      "x": -2,
      "y": 23,
      "z": 9,
      "name": "TFJ_Canopy_Leaves"
    },
    {
      "x": -2,
      "y": 24,
      "z": 9,
      "name": "TFJ_Canopy_Leaves"
    },
    {
      "x": -1,
      "y": 22,
      "z": -8,
      "name": "TFJ_Canopy_Leaves"
    },
    {
      "x": -1,
      "y": 23,
      "z": -8,
      "name": "TFJ_Canopy_Leaves"
    },
    {
      "x": -1,
      "y": 24,
      "z": -8,
      "name": "TFJ_Canopy_Leaves"
    },
    {
      "x": -1,
      "y": 21,
      "z": -7,
      "name": "TFJ_Canopy_Leaves"
    },
    {
      "x": -1,
      "y": 22,
      "z": -7,
      "name": "TFJ_Canopy_Leaves"
    },
    {
      "x": -1,
      "y": 23,
      "z": -7,
      "name": "TFJ_Canopy_Leaves"
    },
    {
      "x": -1,
      "y": 24,
      "z": -7,
      "name": "TFJ_Canopy_Leaves"
    },
    {
      "x": -1,
      "y": 25,
      "z": -7,
      "name": "TFJ_Canopy_Leaves"
    },
    {
      "x": -1,
      "y": 22,
      "z": -6,
      "name": "TFJ_Canopy_Leaves"
    },
    {
      "x": -1,
      "y": 23,
      "z": -6,
      "name": "TFJ_Canopy_Leaves"
    },
    {
      "x": -1,
      "y": 24,
      "z": -6,
      "name": "TFJ_Canopy_Leaves"
    },
    {
      "x": -1,
      "y": 25,
      "z": -6,
      "name": "TFJ_Canopy_Leaves"
    },
    {
      "x": -1,
      "y": 26,
      "z": -6,
      "name": "TFJ_Canopy_Leaves"
    },
    {
      "x": -1,
      "y": 23,
      "z": -5,
      "name": "TFJ_Canopy_Leaves"
    },
    {
      "x": -1,
      "y": 24,
      "z": -5,
      "name": "TFJ_Canopy_Leaves"
    },
    {
      "x": -1,
      "y": 25,
      "z": -5,
      "name": "TFJ_Canopy_Leaves"
    },
    {
      "x": -1,
      "y": 26,
      "z": -5,
      "name": "TFJ_Canopy_Leaves"
    },
    {
      "x": -1,
      "y": 24,
      "z": -4,
      "name": "TFJ_Canopy_Leaves"
    },
    {
      "x": -1,
      "y": 25,
      "z": -4,
      "name": "TFJ_Canopy_Leaves"
    },
    {
      "x": -1,
      "y": 26,
      "z": -4,
      "name": "TFJ_Canopy_Leaves"
    },
    {
      "x": -1,
      "y": 27,
      "z": -4,
      "name": "TFJ_Canopy_Leaves"
    },
    {
      "x": -1,
      "y": 19,
      "z": -3,
      "name": "TFJ_Titanwood_Log"
    },
    {
      "x": -1,
      "y": 23,
      "z": -3,
      "name": "TFJ_Canopy_Leaves"
    },
    {
      "x": -1,
      "y": 24,
      "z": -3,
      "name": "TFJ_Canopy_Leaves"
    },
    {
      "x": -1,
      "y": 25,
      "z": -3,
      "name": "TFJ_Canopy_Leaves"
    },
    {
      "x": -1,
      "y": 26,
      "z": -3,
      "name": "TFJ_Canopy_Leaves"
    },
    {
      "x": -1,
      "y": 18,
      "z": -2,
      "name": "TFJ_Titanwood_Log"
    },
    {
      "x": -1,
      "y": 19,
      "z": -2,
      "name": "TFJ_Titanwood_Log"
    },
    {
      "x": -1,
      "y": 20,
      "z": -2,
      "name": "TFJ_Titanwood_Log"
    },
    {
      "x": -1,
      "y": 21,
      "z": -2,
      "name": "TFJ_Titanwood_Log"
    },
    {
      "x": -1,
      "y": 22,
      "z": -2,
      "name": "TFJ_Titanwood_Log"
    },
    {
      "x": -1,
      "y": 23,
      "z": -2,
      "name": "TFJ_Titanwood_Log"
    },
    {
      "x": -1,
      "y": 24,
      "z": -2,
      "name": "TFJ_Titanwood_Log"
    },
    {
      "x": -1,
      "y": 25,
      "z": -2,
      "name": "TFJ_Canopy_Leaves"
    },
    {
      "x": -1,
      "y": 26,
      "z": -2,
      "name": "TFJ_Canopy_Leaves"
    },
    {
      "x": -1,
      "y": 0,
      "z": -1,
      "name": "TFJ_Titanwood_Log"
    },
    {
      "x": -1,
      "y": 1,
      "z": -1,
      "name": "TFJ_Titanwood_Log"
    },
    {
      "x": -1,
      "y": 2,
      "z": -1,
      "name": "TFJ_Titanwood_Log"
    },
    {
      "x": -1,
      "y": 3,
      "z": -1,
      "name": "TFJ_Titanwood_Log",
      "rotation": 9
    },
    {
      "x": -1,
      "y": 17,
      "z": -1,
      "name": "TFJ_Titanwood_Log"
    },
    {
      "x": -1,
      "y": 18,
      "z": -1,
      "name": "TFJ_Titanwood_Log"
    },
    {
      "x": -1,
      "y": 24,
      "z": -1,
      "name": "TFJ_Canopy_Leaves"
    },
    {
      "x": -1,
      "y": 25,
      "z": -1,
      "name": "TFJ_Canopy_Leaves"
    },
    {
      "x": -1,
      "y": 26,
      "z": -1,
      "name": "TFJ_Canopy_Leaves"
    },
    {
      "x": -1,
      "y": 0,
      "z": 0,
      "name": "TFJ_Titanwood_Log"
    },
    {
      "x": -1,
      "y": 1,
      "z": 0,
      "name": "TFJ_Titanwood_Log"
    },
    {
      "x": -1,
      "y": 2,
      "z": 0,
      "name": "TFJ_Titanwood_Log"
    },
    {
      "x": -1,
      "y": 3,
      "z": 0,
      "name": "TFJ_Titanwood_Log"
    },
    {
      "x": -1,
      "y": 4,
      "z": 0,
      "name": "TFJ_Titanwood_Log"
    },
    {
      "x": -1,
      "y": 5,
      "z": 0,
      "name": "TFJ_Titanwood_Log"
    },
    {
      "x": -1,
      "y": 6,
      "z": 0,
      "name": "TFJ_Titanwood_Log",
      "rotation": 9
    },
    {
      "x": -1,
      "y": 24,
      "z": 0,
      "name": "TFJ_Canopy_Leaves"
    },
    {
      "x": -1,
      "y": 25,
      "z": 0,
      "name": "TFJ_Canopy_Leaves"
    },
    {
      "x": -1,
      "y": 26,
      "z": 0,
      "name": "TFJ_Canopy_Leaves"
    },
    {
      "x": -1,
      "y": 27,
      "z": 0,
      "name": "TFJ_Canopy_Leaves"
    },
    {
      "x": -1,
      "y": 0,
      "z": 1,
      "name": "TFJ_Titanwood_Log"
    },
    {
      "x": -1,
      "y": 1,
      "z": 1,
      "name": "TFJ_Titanwood_Log"
    },
    {
      "x": -1,
      "y": 2,
      "z": 1,
      "name": "TFJ_Titanwood_Log"
    },
    {
      "x": -1,
      "y": 3,
      "z": 1,
      "name": "TFJ_Titanwood_Log"
    },
    {
      "x": -1,
      "y": 4,
      "z": 1,
      "name": "TFJ_Titanwood_Log"
    },
    {
      "x": -1,
      "y": 5,
      "z": 1,
      "name": "TFJ_Titanwood_Log",
      "rotation": 9
    },
    {
      "x": -1,
      "y": 25,
      "z": 1,
      "name": "TFJ_Canopy_Leaves"
    },
    {
      "x": -1,
      "y": 26,
      "z": 1,
      "name": "TFJ_Canopy_Leaves"
    },
    {
      "x": -1,
      "y": 27,
      "z": 1,
      "name": "TFJ_Canopy_Leaves"
    },
    {
      "x": -1,
      "y": 0,
      "z": 2,
      "name": "TFJ_Titanwood_Log"
    },
    {
      "x": -1,
      "y": 1,
      "z": 2,
      "name": "TFJ_Titanwood_Log",
      "rotation": 9
    },
    {
      "x": -1,
      "y": 14,
      "z": 2,
      "name": "TFJ_Titanwood_Log"
    },
    {
      "x": -1,
      "y": 15,
      "z": 2,
      "name": "TFJ_Titanwood_Log"
    },
    {
      "x": -1,
      "y": 24,
      "z": 2,
      "name": "TFJ_Canopy_Leaves"
    },
    {
      "x": -1,
      "y": 25,
      "z": 2,
      "name": "TFJ_Canopy_Leaves"
    },
    {
      "x": -1,
      "y": 26,
      "z": 2,
      "name": "TFJ_Canopy_Leaves"
    },
    {
      "x": -1,
      "y": 27,
      "z": 2,
      "name": "TFJ_Canopy_Leaves"
    },
    {
      "x": -1,
      "y": 15,
      "z": 3,
      "name": "TFJ_Titanwood_Log"
    },
    {
      "x": -1,
      "y": 16,
      "z": 3,
      "name": "TFJ_Titanwood_Log"
    },
    {
      "x": -1,
      "y": 21,
      "z": 3,
      "name": "TFJ_Titanwood_Log",
      "rotation": 3
    },
    {
      "x": -1,
      "y": 22,
      "z": 3,
      "name": "TFJ_Titanwood_Log"
    },
    {
      "x": -1,
      "y": 23,
      "z": 3,
      "name": "TFJ_Titanwood_Log"
    },
    {
      "x": -1,
      "y": 24,
      "z": 3,
      "name": "TFJ_Titanwood_Log"
    },
    {
      "x": -1,
      "y": 25,
      "z": 3,
      "name": "TFJ_Canopy_Leaves"
    },
    {
      "x": -1,
      "y": 26,
      "z": 3,
      "name": "TFJ_Canopy_Leaves"
    },
    {
      "x": -1,
      "y": 27,
      "z": 3,
      "name": "TFJ_Canopy_Leaves"
    },
    {
      "x": -1,
      "y": 28,
      "z": 3,
      "name": "TFJ_Canopy_Leaves"
    },
    {
      "x": -1,
      "y": 24,
      "z": 4,
      "name": "TFJ_Canopy_Leaves"
    },
    {
      "x": -1,
      "y": 25,
      "z": 4,
      "name": "TFJ_Canopy_Leaves"
    },
    {
      "x": -1,
      "y": 26,
      "z": 4,
      "name": "TFJ_Canopy_Leaves"
    },
    {
      "x": -1,
      "y": 27,
      "z": 4,
      "name": "TFJ_Canopy_Leaves"
    },
    {
      "x": -1,
      "y": 28,
      "z": 4,
      "name": "TFJ_Canopy_Leaves"
    },
    {
      "x": -1,
      "y": 23,
      "z": 5,
      "name": "TFJ_Canopy_Leaves"
    },
    {
      "x": -1,
      "y": 24,
      "z": 5,
      "name": "TFJ_Canopy_Leaves"
    },
    {
      "x": -1,
      "y": 25,
      "z": 5,
      "name": "TFJ_Canopy_Leaves"
    },
    {
      "x": -1,
      "y": 26,
      "z": 5,
      "name": "TFJ_Canopy_Leaves"
    },
    {
      "x": -1,
      "y": 27,
      "z": 5,
      "name": "TFJ_Canopy_Leaves"
    },
    {
      "x": -1,
      "y": 28,
      "z": 5,
      "name": "TFJ_Canopy_Leaves"
    },
    {
      "x": -1,
      "y": 20,
      "z": 6,
      "name": "TFJ_Canopy_Leaves"
    },
    {
      "x": -1,
      "y": 21,
      "z": 6,
      "name": "TFJ_Canopy_Leaves"
    },
    {
      "x": -1,
      "y": 22,
      "z": 6,
      "name": "TFJ_Canopy_Leaves"
    },
    {
      "x": -1,
      "y": 23,
      "z": 6,
      "name": "TFJ_Canopy_Leaves"
    },
    {
      "x": -1,
      "y": 24,
      "z": 6,
      "name": "TFJ_Canopy_Leaves"
    },
    {
      "x": -1,
      "y": 25,
      "z": 6,
      "name": "TFJ_Canopy_Leaves"
    },
    {
      "x": -1,
      "y": 26,
      "z": 6,
      "name": "TFJ_Canopy_Leaves"
    },
    {
      "x": -1,
      "y": 21,
      "z": 7,
      "name": "TFJ_Canopy_Leaves"
    },
    {
      "x": -1,
      "y": 22,
      "z": 7,
      "name": "TFJ_Canopy_Leaves"
    },
    {
      "x": -1,
      "y": 23,
      "z": 7,
      "name": "TFJ_Canopy_Leaves"
    },
    {
      "x": -1,
      "y": 24,
      "z": 7,
      "name": "TFJ_Canopy_Leaves"
    },
    {
      "x": -1,
      "y": 25,
      "z": 7,
      "name": "TFJ_Canopy_Leaves"
    },
    {
      "x": -1,
      "y": 21,
      "z": 8,
      "name": "TFJ_Canopy_Leaves"
    },
    {
      "x": -1,
      "y": 22,
      "z": 8,
      "name": "TFJ_Canopy_Leaves"
    },
    {
      "x": -1,
      "y": 23,
      "z": 8,
      "name": "TFJ_Canopy_Leaves"
    },
    {
      "x": -1,
      "y": 24,
      "z": 8,
      "name": "TFJ_Canopy_Leaves"
    },
    {
      "x": -1,
      "y": 25,
      "z": 8,
      "name": "TFJ_Canopy_Leaves"
    },
    {
      "x": -1,
      "y": 21,
      "z": 9,
      "name": "TFJ_Canopy_Leaves"
    },
    {
      "x": -1,
      "y": 22,
      "z": 9,
      "name": "TFJ_Canopy_Leaves"
    },
    {
      "x": -1,
      "y": 23,
      "z": 9,
      "name": "TFJ_Canopy_Leaves"
    },
    {
      "x": 0,
      "y": 22,
      "z": -7,
      "name": "TFJ_Canopy_Leaves"
    },
    {
      "x": 0,
      "y": 23,
      "z": -7,
      "name": "TFJ_Canopy_Leaves"
    },
    {
      "x": 0,
      "y": 24,
      "z": -7,
      "name": "TFJ_Canopy_Leaves"
    },
    {
      "x": 0,
      "y": 22,
      "z": -6,
      "name": "TFJ_Canopy_Leaves"
    },
    {
      "x": 0,
      "y": 23,
      "z": -6,
      "name": "TFJ_Canopy_Leaves"
    },
    {
      "x": 0,
      "y": 24,
      "z": -6,
      "name": "TFJ_Canopy_Leaves"
    },
    {
      "x": 0,
      "y": 22,
      "z": -5,
      "name": "TFJ_Canopy_Leaves"
    },
    {
      "x": 0,
      "y": 23,
      "z": -5,
      "name": "TFJ_Canopy_Leaves"
    },
    {
      "x": 0,
      "y": 24,
      "z": -5,
      "name": "TFJ_Canopy_Leaves"
    },
    {
      "x": 0,
      "y": 25,
      "z": -5,
      "name": "TFJ_Canopy_Leaves"
    },
    {
      "x": 0,
      "y": 22,
      "z": -4,
      "name": "TFJ_Canopy_Leaves"
    },
    {
      "x": 0,
      "y": 23,
      "z": -4,
      "name": "TFJ_Canopy_Leaves"
    },
    {
      "x": 0,
      "y": 24,
      "z": -4,
      "name": "TFJ_Canopy_Leaves"
    },
    {
      "x": 0,
      "y": 25,
      "z": -4,
      "name": "TFJ_Canopy_Leaves"
    },
    {
      "x": 0,
      "y": 24,
      "z": -3,
      "name": "TFJ_Canopy_Leaves"
    },
    {
      "x": 0,
      "y": 25,
      "z": -3,
      "name": "TFJ_Canopy_Leaves"
    },
    {
      "x": 0,
      "y": 26,
      "z": -3,
      "name": "TFJ_Canopy_Leaves"
    },
    {
      "x": 0,
      "y": 0,
      "z": -2,
      "name": "TFJ_Titanwood_Log"
    },
    {
      "x": 0,
      "y": 1,
      "z": -2,
      "name": "TFJ_Titanwood_Log"
    },
    {
      "x": 0,
      "y": 2,
      "z": -2,
      "name": "TFJ_Titanwood_Log"
    },
    {
      "x": 0,
      "y": 3,
      "z": -2,
      "name": "TFJ_Titanwood_Log",
      "rotation": 8
    },
    {
      "x": 0,
      "y": 17,
      "z": -2,
      "name": "TFJ_Titanwood_Log"
    },
    {
      "x": 0,
      "y": 18,
      "z": -2,
      "name": "TFJ_Titanwood_Log"
    },
    {
      "x": 0,
      "y": 24,
      "z": -2,
      "name": "Empty"
    },
    {
      "x": 0,
      "y": 25,
      "z": -2,
      "name": "TFJ_Canopy_Leaves"
    },
    {
      "x": 0,
      "y": 26,
      "z": -2,
      "name": "TFJ_Canopy_Leaves"
    },
    {
      "x": 0,
      "y": 27,
      "z": -2,
      "name": "TFJ_Canopy_Leaves"
    },
    {
      "x": 0,
      "y": 0,
      "z": -1,
      "name": "TFJ_Titanwood_Log"
    },
    {
      "x": 0,
      "y": 1,
      "z": -1,
      "name": "TFJ_Titanwood_Log"
    },
    {
      "x": 0,
      "y": 2,
      "z": -1,
      "name": "TFJ_Titanwood_Log"
    },
    {
      "x": 0,
      "y": 3,
      "z": -1,
      "name": "TFJ_Titanwood_Log"
    },
    {
      "x": 0,
      "y": 4,
      "z": -1,
      "name": "TFJ_Titanwood_Log"
    },
    {
      "x": 0,
      "y": 5,
      "z": -1,
      "name": "TFJ_Titanwood_Log",
      "rotation": 8
    },
    {
      "x": 0,
      "y": 17,
      "z": -1,
      "name": "TFJ_Titanwood_Log"
    },
    {
      "x": 0,
      "y": 18,
      "z": -1,
      "name": "TFJ_Titanwood_Log"
    },
    {
      "x": 0,
      "y": 19,
      "z": -1,
      "name": "TFJ_Titanwood_Log"
    },
    {
      "x": 0,
      "y": 26,
      "z": -1,
      "name": "TFJ_Canopy_Leaves"
    },
    {
      "x": 0,
      "y": 27,
      "z": -1,
      "name": "TFJ_Canopy_Leaves"
    },
    {
      "x": 0,
      "y": 28,
      "z": -1,
      "name": "TFJ_Canopy_Leaves"
    },
    {
      "x": 0,
      "y": 0,
      "z": 0,
      "name": "TFJ_Titanwood_Log"
    },
    {
      "x": 0,
      "y": 1,
      "z": 0,
      "name": "TFJ_Titanwood_Log"
    },
    {
      "x": 0,
      "y": 2,
      "z": 0,
      "name": "TFJ_Titanwood_Log"
    },
    {
      "x": 0,
      "y": 3,
      "z": 0,
      "name": "TFJ_Titanwood_Log"
    },
    {
      "x": 0,
      "y": 4,
      "z": 0,
      "name": "TFJ_Titanwood_Log"
    },
    {
      "x": 0,
      "y": 5,
      "z": 0,
      "name": "TFJ_Titanwood_Log"
    },
    {
      "x": 0,
      "y": 6,
      "z": 0,
      "name": "TFJ_Titanwood_Log"
    },
    {
      "x": 0,
      "y": 7,
      "z": 0,
      "name": "TFJ_Titanwood_Log"
    },
    {
      "x": 0,
      "y": 8,
      "z": 0,
      "name": "TFJ_Titanwood_Log"
    },
    {
      "x": 0,
      "y": 9,
      "z": 0,
      "name": "TFJ_Titanwood_Log"
    },
    {
      "x": 0,
      "y": 10,
      "z": 0,
      "name": "TFJ_Titanwood_Log"
    },
    {
      "x": 0,
      "y": 11,
      "z": 0,
      "name": "TFJ_Titanwood_Log"
    },
    {
      "x": 0,
      "y": 12,
      "z": 0,
      "name": "TFJ_Titanwood_Log"
    },
    {
      "x": 0,
      "y": 13,
      "z": 0,
      "name": "TFJ_Titanwood_Log"
    },
    {
      "x": 0,
      "y": 14,
      "z": 0,
      "name": "TFJ_Titanwood_Log"
    },
    {
      "x": 0,
      "y": 15,
      "z": 0,
      "name": "TFJ_Titanwood_Log"
    },
    {
      "x": 0,
      "y": 16,
      "z": 0,
      "name": "TFJ_Titanwood_Log"
    },
    {
      "x": 0,
      "y": 17,
      "z": 0,
      "name": "TFJ_Titanwood_Log"
    },
    {
      "x": 0,
      "y": 18,
      "z": 0,
      "name": "TFJ_Titanwood_Log"
    },
    {
      "x": 0,
      "y": 25,
      "z": 0,
      "name": "TFJ_Canopy_Leaves"
    },
    {
      "x": 0,
      "y": 26,
      "z": 0,
      "name": "TFJ_Canopy_Leaves"
    },
    {
      "x": 0,
      "y": 27,
      "z": 0,
      "name": "TFJ_Canopy_Leaves"
    },
    {
      "x": 0,
      "y": 28,
      "z": 0,
      "name": "TFJ_Canopy_Leaves"
    },
    {
      "x": 0,
      "y": 0,
      "z": 1,
      "name": "TFJ_Titanwood_Log"
    },
    {
      "x": 0,
      "y": 1,
      "z": 1,
      "name": "TFJ_Titanwood_Log"
    },
    {
      "x": 0,
      "y": 2,
      "z": 1,
      "name": "TFJ_Titanwood_Log"
    },
    {
      "x": 0,
      "y": 3,
      "z": 1,
      "name": "TFJ_Titanwood_Log"
    },
    {
      "x": 0,
      "y": 4,
      "z": 1,
      "name": "TFJ_Titanwood_Log"
    },
    {
      "x": 0,
      "y": 5,
      "z": 1,
      "name": "TFJ_Titanwood_Log"
    },
    {
      "x": 0,
      "y": 6,
      "z": 1,
      "name": "TFJ_Titanwood_Log"
    },
    {
      "x": 0,
      "y": 7,
      "z": 1,
      "name": "TFJ_Titanwood_Log"
    },
    {
      "x": 0,
      "y": 8,
      "z": 1,
      "name": "TFJ_Titanwood_Log"
    },
    {
      "x": 0,
      "y": 9,
      "z": 1,
      "name": "TFJ_Titanwood_Log"
    },
    {
      "x": 0,
      "y": 10,
      "z": 1,
      "name": "TFJ_Titanwood_Log"
    },
    {
      "x": 0,
      "y": 11,
      "z": 1,
      "name": "TFJ_Titanwood_Log"
    },
    {
      "x": 0,
      "y": 12,
      "z": 1,
      "name": "TFJ_Titanwood_Log"
    },
    {
      "x": 0,
      "y": 13,
      "z": 1,
      "name": "TFJ_Titanwood_Log"
    },
    {
      "x": 0,
      "y": 14,
      "z": 1,
      "name": "TFJ_Titanwood_Log"
    },
    {
      "x": 0,
      "y": 15,
      "z": 1,
      "name": "TFJ_Titanwood_Log"
    },
    {
      "x": 0,
      "y": 16,
      "z": 1,
      "name": "TFJ_Titanwood_Log"
    },
    {
      "x": 0,
      "y": 24,
      "z": 1,
      "name": "TFJ_Canopy_Leaves"
    },
    {
      "x": 0,
      "y": 25,
      "z": 1,
      "name": "TFJ_Canopy_Leaves"
    },
    {
      "x": 0,
      "y": 26,
      "z": 1,
      "name": "TFJ_Canopy_Leaves"
    },
    {
      "x": 0,
      "y": 27,
      "z": 1,
      "name": "TFJ_Canopy_Leaves"
    },
    {
      "x": 0,
      "y": 28,
      "z": 1,
      "name": "TFJ_Canopy_Leaves"
    },
    {
      "x": 0,
      "y": 29,
      "z": 1,
      "name": "TFJ_Canopy_Leaves"
    },
    {
      "x": 0,
      "y": 0,
      "z": 2,
      "name": "TFJ_Titanwood_Log"
    },
    {
      "x": 0,
      "y": 1,
      "z": 2,
      "name": "TFJ_Titanwood_Log"
    },
    {
      "x": 0,
      "y": 2,
      "z": 2,
      "name": "TFJ_Titanwood_Log"
    },
    {
      "x": 0,
      "y": 3,
      "z": 2,
      "name": "TFJ_Titanwood_Log"
    },
    {
      "x": 0,
      "y": 4,
      "z": 2,
      "name": "TFJ_Titanwood_Log",
      "rotation": 10
    },
    {
      "x": 0,
      "y": 12,
      "z": 2,
      "name": "TFJ_Titanwood_Log"
    },
    {
      "x": 0,
      "y": 13,
      "z": 2,
      "name": "TFJ_Titanwood_Log"
    },
    {
      "x": 0,
      "y": 14,
      "z": 2,
      "name": "TFJ_Titanwood_Log"
    },
    {
      "x": 0,
      "y": 15,
      "z": 2,
      "name": "TFJ_Titanwood_Log"
    },
    {
      "x": 0,
      "y": 25,
      "z": 2,
      "name": "TFJ_Canopy_Leaves"
    },
    {
      "x": 0,
      "y": 26,
      "z": 2,
      "name": "TFJ_Canopy_Leaves"
    },
    {
      "x": 0,
      "y": 27,
      "z": 2,
      "name": "TFJ_Canopy_Leaves"
    },
    {
      "x": 0,
      "y": 28,
      "z": 2,
      "name": "TFJ_Canopy_Leaves"
    },
    {
      "x": 0,
      "y": 19,
      "z": 3,
      "name": "TFJ_Titanwood_Log"
    },
    {
      "x": 0,
      "y": 20,
      "z": 3,
      "name": "TFJ_Titanwood_Log"
    },
    {
      "x": 0,
      "y": 21,
      "z": 3,
      "name": "TFJ_Titanwood_Log"
    },
    {
      "x": 0,
      "y": 25,
      "z": 3,
      "name": "TFJ_Canopy_Leaves"
    },
    {
      "x": 0,
      "y": 26,
      "z": 3,
      "name": "TFJ_Canopy_Leaves"
    },
    {
      "x": 0,
      "y": 27,
      "z": 3,
      "name": "TFJ_Canopy_Leaves"
    },
    {
      "x": 0,
      "y": 21,
      "z": 4,
      "name": "TFJ_Titanwood_Log"
    },
    {
      "x": 0,
      "y": 22,
      "z": 4,
      "name": "TFJ_Titanwood_Log"
    },
    {
      "x": 0,
      "y": 25,
      "z": 4,
      "name": "TFJ_Canopy_Leaves"
    },
    {
      "x": 0,
      "y": 26,
      "z": 4,
      "name": "TFJ_Canopy_Leaves"
    },
    {
      "x": 0,
      "y": 27,
      "z": 4,
      "name": "TFJ_Canopy_Leaves"
    },
    {
      "x": 0,
      "y": 28,
      "z": 4,
      "name": "TFJ_Canopy_Leaves"
    },
    {
      "x": 0,
      "y": 22,
      "z": 5,
      "name": "TFJ_Titanwood_Log"
    },
    {
      "x": 0,
      "y": 23,
      "z": 5,
      "name": "TFJ_Titanwood_Log"
    },
    {
      "x": 0,
      "y": 24,
      "z": 5,
      "name": "TFJ_Titanwood_Log"
    },
    {
      "x": 0,
      "y": 25,
      "z": 5,
      "name": "TFJ_Canopy_Leaves"
    },
    {
      "x": 0,
      "y": 26,
      "z": 5,
      "name": "TFJ_Canopy_Leaves"
    },
    {
      "x": 0,
      "y": 27,
      "z": 5,
      "name": "TFJ_Canopy_Leaves"
    },
    {
      "x": 0,
      "y": 22,
      "z": 6,
      "name": "TFJ_Canopy_Leaves"
    },
    {
      "x": 0,
      "y": 23,
      "z": 6,
      "name": "TFJ_Canopy_Leaves"
    },
    {
      "x": 0,
      "y": 24,
      "z": 6,
      "name": "TFJ_Canopy_Leaves"
    },
    {
      "x": 0,
      "y": 25,
      "z": 6,
      "name": "TFJ_Canopy_Leaves"
    },
    {
      "x": 0,
      "y": 26,
      "z": 6,
      "name": "TFJ_Canopy_Leaves"
    },
    {
      "x": 0,
      "y": 21,
      "z": 7,
      "name": "TFJ_Canopy_Leaves"
    },
    {
      "x": 0,
      "y": 22,
      "z": 7,
      "name": "TFJ_Canopy_Leaves"
    },
    {
      "x": 0,
      "y": 23,
      "z": 7,
      "name": "TFJ_Canopy_Leaves"
    },
    {
      "x": 0,
      "y": 24,
      "z": 7,
      "name": "TFJ_Canopy_Leaves"
    },
    {
      "x": 0,
      "y": 25,
      "z": 7,
      "name": "TFJ_Canopy_Leaves"
    },
    {
      "x": 0,
      "y": 21,
      "z": 8,
      "name": "TFJ_Canopy_Leaves"
    },
    {
      "x": 0,
      "y": 22,
      "z": 8,
      "name": "TFJ_Canopy_Leaves"
    },
    {
      "x": 0,
      "y": 23,
      "z": 8,
      "name": "TFJ_Canopy_Leaves"
    },
    {
      "x": 0,
      "y": 24,
      "z": 8,
      "name": "TFJ_Canopy_Leaves"
    },
    {
      "x": 1,
      "y": 22,
      "z": -6,
      "name": "TFJ_Canopy_Leaves"
    },
    {
      "x": 1,
      "y": 23,
      "z": -6,
      "name": "TFJ_Canopy_Leaves"
    },
    {
      "x": 1,
      "y": 24,
      "z": -6,
      "name": "TFJ_Canopy_Leaves"
    },
    {
      "x": 1,
      "y": 22,
      "z": -5,
      "name": "TFJ_Canopy_Leaves"
    },
    {
      "x": 1,
      "y": 23,
      "z": -5,
      "name": "TFJ_Canopy_Leaves"
    },
    {
      "x": 1,
      "y": 24,
      "z": -5,
      "name": "TFJ_Canopy_Leaves"
    },
    {
      "x": 1,
      "y": 23,
      "z": -4,
      "name": "TFJ_Canopy_Leaves"
    },
    {
      "x": 1,
      "y": 24,
      "z": -4,
      "name": "TFJ_Canopy_Leaves"
    },
    {
      "x": 1,
      "y": 25,
      "z": -4,
      "name": "TFJ_Canopy_Leaves"
    },
    {
      "x": 1,
      "y": 23,
      "z": -3,
      "name": "Empty"
    },
    {
      "x": 1,
      "y": 24,
      "z": -3,
      "name": "TFJ_Canopy_Leaves"
    },
    {
      "x": 1,
      "y": 25,
      "z": -3,
      "name": "TFJ_Canopy_Leaves"
    },
    {
      "x": 1,
      "y": 26,
      "z": -3,
      "name": "TFJ_Canopy_Leaves"
    },
    {
      "x": 1,
      "y": 0,
      "z": -2,
      "name": "TFJ_Titanwood_Log"
    },
    {
      "x": 1,
      "y": 1,
      "z": -2,
      "name": "TFJ_Titanwood_Log"
    },
    {
      "x": 1,
      "y": 2,
      "z": -2,
      "name": "TFJ_Titanwood_Log",
      "rotation": 8
    },
    {
      "x": 1,
      "y": 26,
      "z": -2,
      "name": "TFJ_Canopy_Leaves"
    },
    {
      "x": 1,
      "y": 27,
      "z": -2,
      "name": "TFJ_Canopy_Leaves"
    },
    {
      "x": 1,
      "y": 28,
      "z": -2,
      "name": "TFJ_Canopy_Leaves"
    },
    {
      "x": 1,
      "y": 0,
      "z": -1,
      "name": "TFJ_Titanwood_Log"
    },
    {
      "x": 1,
      "y": 1,
      "z": -1,
      "name": "TFJ_Titanwood_Log"
    },
    {
      "x": 1,
      "y": 2,
      "z": -1,
      "name": "TFJ_Titanwood_Log"
    },
    {
      "x": 1,
      "y": 3,
      "z": -1,
      "name": "TFJ_Titanwood_Log"
    },
    {
      "x": 1,
      "y": 4,
      "z": -1,
      "name": "TFJ_Titanwood_Log"
    },
    {
      "x": 1,
      "y": 5,
      "z": -1,
      "name": "TFJ_Titanwood_Log"
    },
    {
      "x": 1,
      "y": 6,
      "z": -1,
      "name": "TFJ_Titanwood_Log",
      "rotation": 8
    },
    {
      "x": 1,
      "y": 18,
      "z": -1,
      "name": "TFJ_Titanwood_Log"
    },
    {
      "x": 1,
      "y": 19,
      "z": -1,
      "name": "TFJ_Titanwood_Log"
    },
    {
      "x": 1,
      "y": 20,
      "z": -1,
      "name": "TFJ_Titanwood_Log"
    },
    {
      "x": 1,
      "y": 21,
      "z": -1,
      "name": "TFJ_Titanwood_Log"
    },
    {
      "x": 1,
      "y": 22,
      "z": -1,
      "name": "TFJ_Titanwood_Log"
    },
    {
      "x": 1,
      "y": 23,
      "z": -1,
      "name": "TFJ_Titanwood_Log"
    },
    {
      "x": 1,
      "y": 24,
      "z": -1,
      "name": "TFJ_Titanwood_Log"
    },
    {
      "x": 1,
      "y": 25,
      "z": -1,
      "name": "TFJ_Titanwood_Log"
    },
    {
      "x": 1,
      "y": 26,
      "z": -1,
      "name": "TFJ_Canopy_Leaves"
    },
    {
      "x": 1,
      "y": 27,
      "z": -1,
      "name": "TFJ_Canopy_Leaves"
    },
    {
      "x": 1,
      "y": 28,
      "z": -1,
      "name": "TFJ_Canopy_Leaves"
    },
    {
      "x": 1,
      "y": 0,
      "z": 0,
      "name": "TFJ_Titanwood_Log"
    },
    {
      "x": 1,
      "y": 1,
      "z": 0,
      "name": "TFJ_Titanwood_Log"
    },
    {
      "x": 1,
      "y": 2,
      "z": 0,
      "name": "TFJ_Titanwood_Log"
    },
    {
      "x": 1,
      "y": 3,
      "z": 0,
      "name": "TFJ_Titanwood_Log"
    },
    {
      "x": 1,
      "y": 4,
      "z": 0,
      "name": "TFJ_Titanwood_Log"
    },
    {
      "x": 1,
      "y": 5,
      "z": 0,
      "name": "TFJ_Titanwood_Log"
    },
    {
      "x": 1,
      "y": 6,
      "z": 0,
      "name": "TFJ_Titanwood_Log"
    },
    {
      "x": 1,
      "y": 7,
      "z": 0,
      "name": "TFJ_Titanwood_Log"
    },
    {
      "x": 1,
      "y": 8,
      "z": 0,
      "name": "TFJ_Titanwood_Log"
    },
    {
      "x": 1,
      "y": 9,
      "z": 0,
      "name": "TFJ_Titanwood_Log"
    },
    {
      "x": 1,
      "y": 10,
      "z": 0,
      "name": "TFJ_Titanwood_Log"
    },
    {
      "x": 1,
      "y": 11,
      "z": 0,
      "name": "TFJ_Titanwood_Log"
    },
    {
      "x": 1,
      "y": 12,
      "z": 0,
      "name": "TFJ_Titanwood_Log"
    },
    {
      "x": 1,
      "y": 13,
      "z": 0,
      "name": "TFJ_Titanwood_Log"
    },
    {
      "x": 1,
      "y": 14,
      "z": 0,
      "name": "TFJ_Titanwood_Log"
    },
    {
      "x": 1,
      "y": 15,
      "z": 0,
      "name": "TFJ_Titanwood_Log"
    },
    {
      "x": 1,
      "y": 16,
      "z": 0,
      "name": "TFJ_Titanwood_Log"
    },
    {
      "x": 1,
      "y": 17,
      "z": 0,
      "name": "TFJ_Titanwood_Log"
    },
    {
      "x": 1,
      "y": 18,
      "z": 0,
      "name": "TFJ_Titanwood_Log"
    },
    {
      "x": 1,
      "y": 26,
      "z": 0,
      "name": "TFJ_Canopy_Leaves"
    },
    {
      "x": 1,
      "y": 27,
      "z": 0,
      "name": "TFJ_Canopy_Leaves"
    },
    {
      "x": 1,
      "y": 28,
      "z": 0,
      "name": "TFJ_Canopy_Leaves"
    },
    {
      "x": 1,
      "y": 29,
      "z": 0,
      "name": "TFJ_Canopy_Leaves"
    },
    {
      "x": 1,
      "y": 0,
      "z": 1,
      "name": "TFJ_Titanwood_Log"
    },
    {
      "x": 1,
      "y": 1,
      "z": 1,
      "name": "TFJ_Titanwood_Log"
    },
    {
      "x": 1,
      "y": 2,
      "z": 1,
      "name": "TFJ_Titanwood_Log"
    },
    {
      "x": 1,
      "y": 3,
      "z": 1,
      "name": "TFJ_Titanwood_Log"
    },
    {
      "x": 1,
      "y": 4,
      "z": 1,
      "name": "TFJ_Titanwood_Log"
    },
    {
      "x": 1,
      "y": 5,
      "z": 1,
      "name": "TFJ_Titanwood_Log"
    },
    {
      "x": 1,
      "y": 6,
      "z": 1,
      "name": "TFJ_Titanwood_Log"
    },
    {
      "x": 1,
      "y": 7,
      "z": 1,
      "name": "TFJ_Titanwood_Log"
    },
    {
      "x": 1,
      "y": 8,
      "z": 1,
      "name": "TFJ_Titanwood_Log"
    },
    {
      "x": 1,
      "y": 9,
      "z": 1,
      "name": "TFJ_Titanwood_Log"
    },
    {
      "x": 1,
      "y": 10,
      "z": 1,
      "name": "TFJ_Titanwood_Log"
    },
    {
      "x": 1,
      "y": 11,
      "z": 1,
      "name": "TFJ_Titanwood_Log"
    },
    {
      "x": 1,
      "y": 12,
      "z": 1,
      "name": "TFJ_Titanwood_Log"
    },
    {
      "x": 1,
      "y": 13,
      "z": 1,
      "name": "TFJ_Titanwood_Log"
    },
    {
      "x": 1,
      "y": 14,
      "z": 1,
      "name": "TFJ_Titanwood_Log"
    },
    {
      "x": 1,
      "y": 15,
      "z": 1,
      "name": "TFJ_Titanwood_Log"
    },
    {
      "x": 1,
      "y": 16,
      "z": 1,
      "name": "TFJ_Titanwood_Log"
    },
    {
      "x": 1,
      "y": 17,
      "z": 1,
      "name": "TFJ_Titanwood_Log"
    },
    {
      "x": 1,
      "y": 18,
      "z": 1,
      "name": "TFJ_Titanwood_Log"
    },
    {
      "x": 1,
      "y": 19,
      "z": 1,
      "name": "TFJ_Titanwood_Log"
    },
    {
      "x": 1,
      "y": 25,
      "z": 1,
      "name": "TFJ_Canopy_Leaves"
    },
    {
      "x": 1,
      "y": 26,
      "z": 1,
      "name": "TFJ_Canopy_Leaves"
    },
    {
      "x": 1,
      "y": 27,
      "z": 1,
      "name": "TFJ_Canopy_Leaves"
    },
    {
      "x": 1,
      "y": 28,
      "z": 1,
      "name": "TFJ_Canopy_Leaves"
    },
    {
      "x": 1,
      "y": 29,
      "z": 1,
      "name": "TFJ_Canopy_Leaves"
    },
    {
      "x": 1,
      "y": 0,
      "z": 2,
      "name": "TFJ_Titanwood_Log"
    },
    {
      "x": 1,
      "y": 1,
      "z": 2,
      "name": "TFJ_Titanwood_Log"
    },
    {
      "x": 1,
      "y": 2,
      "z": 2,
      "name": "TFJ_Titanwood_Log"
    },
    {
      "x": 1,
      "y": 3,
      "z": 2,
      "name": "TFJ_Titanwood_Log"
    },
    {
      "x": 1,
      "y": 4,
      "z": 2,
      "name": "TFJ_Titanwood_Log",
      "rotation": 10
    },
    {
      "x": 1,
      "y": 19,
      "z": 2,
      "name": "TFJ_Titanwood_Log"
    },
    {
      "x": 1,
      "y": 20,
      "z": 2,
      "name": "TFJ_Titanwood_Log"
    },
    {
      "x": 1,
      "y": 21,
      "z": 2,
      "name": "TFJ_Titanwood_Log"
    },
    {
      "x": 1,
      "y": 22,
      "z": 2,
      "name": "TFJ_Titanwood_Log"
    },
    {
      "x": 1,
      "y": 23,
      "z": 2,
      "name": "TFJ_Titanwood_Log"
    },
    {
      "x": 1,
      "y": 24,
      "z": 2,
      "name": "TFJ_Titanwood_Log"
    },
    {
      "x": 1,
      "y": 25,
      "z": 2,
      "name": "TFJ_Titanwood_Log"
    },
    {
      "x": 1,
      "y": 26,
      "z": 2,
      "name": "TFJ_Canopy_Leaves"
    },
    {
      "x": 1,
      "y": 27,
      "z": 2,
      "name": "TFJ_Canopy_Leaves"
    },
    {
      "x": 1,
      "y": 28,
      "z": 2,
      "name": "TFJ_Canopy_Leaves"
    },
    {
      "x": 1,
      "y": 29,
      "z": 2,
      "name": "TFJ_Canopy_Leaves"
    },
    {
      "x": 1,
      "y": 0,
      "z": 3,
      "name": "TFJ_Titanwood_Log"
    },
    {
      "x": 1,
      "y": 1,
      "z": 3,
      "name": "TFJ_Titanwood_Log"
    },
    {
      "x": 1,
      "y": 2,
      "z": 3,
      "name": "TFJ_Titanwood_Log",
      "rotation": 10
    },
    {
      "x": 1,
      "y": 20,
      "z": 3,
      "name": "TFJ_Titanwood_Log"
    },
    {
      "x": 1,
      "y": 24,
      "z": 3,
      "name": "Empty"
    },
    {
      "x": 1,
      "y": 25,
      "z": 3,
      "name": "TFJ_Canopy_Leaves"
    },
    {
      "x": 1,
      "y": 26,
      "z": 3,
      "name": "TFJ_Canopy_Leaves"
    },
    {
      "x": 1,
      "y": 27,
      "z": 3,
      "name": "TFJ_Canopy_Leaves"
    },
    {
      "x": 1,
      "y": 23,
      "z": 4,
      "name": "Empty"
    },
    {
      "x": 1,
      "y": 24,
      "z": 4,
      "name": "TFJ_Canopy_Leaves"
    },
    {
      "x": 1,
      "y": 25,
      "z": 4,
      "name": "TFJ_Canopy_Leaves"
    },
    {
      "x": 1,
      "y": 26,
      "z": 4,
      "name": "TFJ_Canopy_Leaves"
    },
    {
      "x": 1,
      "y": 27,
      "z": 4,
      "name": "TFJ_Canopy_Leaves"
    },
    {
      "x": 1,
      "y": 23,
      "z": 5,
      "name": "TFJ_Canopy_Leaves"
    },
    {
      "x": 1,
      "y": 24,
      "z": 5,
      "name": "TFJ_Canopy_Leaves"
    },
    {
      "x": 1,
      "y": 25,
      "z": 5,
      "name": "TFJ_Canopy_Leaves"
    },
    {
      "x": 1,
      "y": 26,
      "z": 5,
      "name": "TFJ_Canopy_Leaves"
    },
    {
      "x": 1,
      "y": 27,
      "z": 5,
      "name": "TFJ_Canopy_Leaves"
    },
    {
      "x": 1,
      "y": 22,
      "z": 6,
      "name": "TFJ_Canopy_Leaves"
    },
    {
      "x": 1,
      "y": 23,
      "z": 6,
      "name": "TFJ_Canopy_Leaves"
    },
    {
      "x": 1,
      "y": 24,
      "z": 6,
      "name": "TFJ_Canopy_Leaves"
    },
    {
      "x": 1,
      "y": 25,
      "z": 6,
      "name": "TFJ_Canopy_Leaves"
    },
    {
      "x": 1,
      "y": 26,
      "z": 6,
      "name": "TFJ_Canopy_Leaves"
    },
    {
      "x": 1,
      "y": 27,
      "z": 6,
      "name": "TFJ_Canopy_Leaves"
    },
    {
      "x": 1,
      "y": 22,
      "z": 7,
      "name": "TFJ_Canopy_Leaves"
    },
    {
      "x": 1,
      "y": 23,
      "z": 7,
      "name": "TFJ_Canopy_Leaves"
    },
    {
      "x": 1,
      "y": 24,
      "z": 7,
      "name": "TFJ_Canopy_Leaves"
    },
    {
      "x": 1,
      "y": 25,
      "z": 7,
      "name": "TFJ_Canopy_Leaves"
    },
    {
      "x": 1,
      "y": 26,
      "z": 7,
      "name": "TFJ_Canopy_Leaves"
    },
    {
      "x": 2,
      "y": 22,
      "z": -7,
      "name": "TFJ_Canopy_Leaves"
    },
    {
      "x": 2,
      "y": 23,
      "z": -7,
      "name": "TFJ_Canopy_Leaves"
    },
    {
      "x": 2,
      "y": 24,
      "z": -7,
      "name": "TFJ_Canopy_Leaves"
    },
    {
      "x": 2,
      "y": 21,
      "z": -6,
      "name": "TFJ_Canopy_Leaves"
    },
    {
      "x": 2,
      "y": 22,
      "z": -6,
      "name": "TFJ_Canopy_Leaves"
    },
    {
      "x": 2,
      "y": 23,
      "z": -6,
      "name": "TFJ_Canopy_Leaves"
    },
    {
      "x": 2,
      "y": 24,
      "z": -6,
      "name": "TFJ_Canopy_Leaves"
    },
    {
      "x": 2,
      "y": 25,
      "z": -6,
      "name": "TFJ_Canopy_Leaves"
    },
    {
      "x": 2,
      "y": 20,
      "z": -5,
      "name": "TFJ_Canopy_Leaves"
    },
    {
      "x": 2,
      "y": 21,
      "z": -5,
      "name": "TFJ_Canopy_Leaves"
    },
    {
      "x": 2,
      "y": 22,
      "z": -5,
      "name": "TFJ_Canopy_Leaves"
    },
    {
      "x": 2,
      "y": 23,
      "z": -5,
      "name": "TFJ_Canopy_Leaves"
    },
    {
      "x": 2,
      "y": 24,
      "z": -5,
      "name": "TFJ_Canopy_Leaves"
    },
    {
      "x": 2,
      "y": 25,
      "z": -5,
      "name": "TFJ_Canopy_Leaves"
    },
    {
      "x": 2,
      "y": 26,
      "z": -5,
      "name": "TFJ_Canopy_Leaves"
    },
    {
      "x": 2,
      "y": 23,
      "z": -4,
      "name": "TFJ_Canopy_Leaves"
    },
    {
      "x": 2,
      "y": 24,
      "z": -4,
      "name": "TFJ_Canopy_Leaves"
    },
    {
      "x": 2,
      "y": 25,
      "z": -4,
      "name": "TFJ_Canopy_Leaves"
    },
    {
      "x": 2,
      "y": 26,
      "z": -4,
      "name": "TFJ_Canopy_Leaves"
    },
    {
      "x": 2,
      "y": 21,
      "z": -3,
      "name": "TFJ_Titanwood_Log",
      "rotation": 2
    },
    {
      "x": 2,
      "y": 22,
      "z": -3,
      "name": "TFJ_Titanwood_Log"
    },
    {
      "x": 2,
      "y": 23,
      "z": -3,
      "name": "TFJ_Titanwood_Log"
    },
    {
      "x": 2,
      "y": 24,
      "z": -3,
      "name": "TFJ_Canopy_Leaves"
    },
    {
      "x": 2,
      "y": 25,
      "z": -3,
      "name": "TFJ_Canopy_Leaves"
    },
    {
      "x": 2,
      "y": 26,
      "z": -3,
      "name": "TFJ_Canopy_Leaves"
    },
    {
      "x": 2,
      "y": 20,
      "z": -2,
      "name": "TFJ_Titanwood_Log"
    },
    {
      "x": 2,
      "y": 21,
      "z": -2,
      "name": "TFJ_Titanwood_Log"
    },
    {
      "x": 2,
      "y": 25,
      "z": -2,
      "name": "TFJ_Canopy_Leaves"
    },
    {
      "x": 2,
      "y": 26,
      "z": -2,
      "name": "TFJ_Canopy_Leaves"
    },
    {
      "x": 2,
      "y": 27,
      "z": -2,
      "name": "TFJ_Canopy_Leaves"
    },
    {
      "x": 2,
      "y": 20,
      "z": -1,
      "name": "TFJ_Titanwood_Log"
    },
    {
      "x": 2,
      "y": 26,
      "z": -1,
      "name": "TFJ_Canopy_Leaves"
    },
    {
      "x": 2,
      "y": 27,
      "z": -1,
      "name": "TFJ_Canopy_Leaves"
    },
    {
      "x": 2,
      "y": 28,
      "z": -1,
      "name": "TFJ_Canopy_Leaves"
    },
    {
      "x": 2,
      "y": 0,
      "z": 0,
      "name": "TFJ_Titanwood_Log"
    },
    {
      "x": 2,
      "y": 1,
      "z": 0,
      "name": "TFJ_Titanwood_Log"
    },
    {
      "x": 2,
      "y": 2,
      "z": 0,
      "name": "TFJ_Titanwood_Log"
    },
    {
      "x": 2,
      "y": 3,
      "z": 0,
      "name": "TFJ_Titanwood_Log"
    },
    {
      "x": 2,
      "y": 4,
      "z": 0,
      "name": "TFJ_Titanwood_Log"
    },
    {
      "x": 2,
      "y": 5,
      "z": 0,
      "name": "TFJ_Titanwood_Log"
    },
    {
      "x": 2,
      "y": 6,
      "z": 0,
      "name": "TFJ_Titanwood_Log"
    },
    {
      "x": 2,
      "y": 7,
      "z": 0,
      "name": "TFJ_Titanwood_Log",
      "rotation": 11
    },
    {
      "x": 2,
      "y": 25,
      "z": 0,
      "name": "TFJ_Canopy_Leaves"
    },
    {
      "x": 2,
      "y": 26,
      "z": 0,
      "name": "TFJ_Canopy_Leaves"
    },
    {
      "x": 2,
      "y": 27,
      "z": 0,
      "name": "TFJ_Canopy_Leaves"
    },
    {
      "x": 2,
      "y": 28,
      "z": 0,
      "name": "TFJ_Canopy_Leaves"
    },
    {
      "x": 2,
      "y": 0,
      "z": 1,
      "name": "TFJ_Titanwood_Log"
    },
    {
      "x": 2,
      "y": 1,
      "z": 1,
      "name": "TFJ_Titanwood_Log"
    },
    {
      "x": 2,
      "y": 2,
      "z": 1,
      "name": "TFJ_Titanwood_Log"
    },
    {
      "x": 2,
      "y": 3,
      "z": 1,
      "name": "TFJ_Titanwood_Log"
    },
    {
      "x": 2,
      "y": 4,
      "z": 1,
      "name": "TFJ_Titanwood_Log"
    },
    {
      "x": 2,
      "y": 5,
      "z": 1,
      "name": "TFJ_Titanwood_Log"
    },
    {
      "x": 2,
      "y": 6,
      "z": 1,
      "name": "TFJ_Titanwood_Log",
      "rotation": 11
    },
    {
      "x": 2,
      "y": 13,
      "z": 1,
      "name": "TFJ_Titanwood_Log"
    },
    {
      "x": 2,
      "y": 14,
      "z": 1,
      "name": "TFJ_Titanwood_Log"
    },
    {
      "x": 2,
      "y": 15,
      "z": 1,
      "name": "TFJ_Titanwood_Log"
    },
    {
      "x": 2,
      "y": 16,
      "z": 1,
      "name": "TFJ_Titanwood_Log"
    },
    {
      "x": 2,
      "y": 17,
      "z": 1,
      "name": "TFJ_Titanwood_Log"
    },
    {
      "x": 2,
      "y": 24,
      "z": 1,
      "name": "TFJ_Canopy_Leaves"
    },
    {
      "x": 2,
      "y": 25,
      "z": 1,
      "name": "TFJ_Canopy_Leaves"
    },
    {
      "x": 2,
      "y": 26,
      "z": 1,
      "name": "TFJ_Canopy_Leaves"
    },
    {
      "x": 2,
      "y": 27,
      "z": 1,
      "name": "TFJ_Canopy_Leaves"
    },
    {
      "x": 2,
      "y": 28,
      "z": 1,
      "name": "TFJ_Canopy_Leaves"
    },
    {
      "x": 2,
      "y": 29,
      "z": 1,
      "name": "TFJ_Canopy_Leaves"
    },
    {
      "x": 2,
      "y": 0,
      "z": 2,
      "name": "TFJ_Titanwood_Log"
    },
    {
      "x": 2,
      "y": 1,
      "z": 2,
      "name": "TFJ_Titanwood_Log"
    },
    {
      "x": 2,
      "y": 2,
      "z": 2,
      "name": "TFJ_Titanwood_Log",
      "rotation": 11
    },
    {
      "x": 2,
      "y": 25,
      "z": 2,
      "name": "TFJ_Canopy_Leaves"
    },
    {
      "x": 2,
      "y": 26,
      "z": 2,
      "name": "TFJ_Canopy_Leaves"
    },
    {
      "x": 2,
      "y": 27,
      "z": 2,
      "name": "TFJ_Canopy_Leaves"
    },
    {
      "x": 2,
      "y": 28,
      "z": 2,
      "name": "TFJ_Canopy_Leaves"
    },
    {
      "x": 2,
      "y": 23,
      "z": 3,
      "name": "Empty"
    },
    {
      "x": 2,
      "y": 24,
      "z": 3,
      "name": "TFJ_Canopy_Leaves"
    },
    {
      "x": 2,
      "y": 25,
      "z": 3,
      "name": "TFJ_Canopy_Leaves"
    },
    {
      "x": 2,
      "y": 26,
      "z": 3,
      "name": "TFJ_Canopy_Leaves"
    },
    {
      "x": 2,
      "y": 27,
      "z": 3,
      "name": "TFJ_Canopy_Leaves"
    },
    {
      "x": 2,
      "y": 23,
      "z": 4,
      "name": "TFJ_Canopy_Leaves"
    },
    {
      "x": 2,
      "y": 24,
      "z": 4,
      "name": "TFJ_Canopy_Leaves"
    },
    {
      "x": 2,
      "y": 25,
      "z": 4,
      "name": "TFJ_Canopy_Leaves"
    },
    {
      "x": 2,
      "y": 26,
      "z": 4,
      "name": "TFJ_Canopy_Leaves"
    },
    {
      "x": 2,
      "y": 23,
      "z": 5,
      "name": "TFJ_Canopy_Leaves"
    },
    {
      "x": 2,
      "y": 24,
      "z": 5,
      "name": "TFJ_Canopy_Leaves"
    },
    {
      "x": 2,
      "y": 25,
      "z": 5,
      "name": "TFJ_Canopy_Leaves"
    },
    {
      "x": 2,
      "y": 26,
      "z": 5,
      "name": "TFJ_Canopy_Leaves"
    },
    {
      "x": 2,
      "y": 27,
      "z": 5,
      "name": "TFJ_Canopy_Leaves"
    },
    {
      "x": 2,
      "y": 22,
      "z": 6,
      "name": "TFJ_Canopy_Leaves"
    },
    {
      "x": 2,
      "y": 23,
      "z": 6,
      "name": "TFJ_Canopy_Leaves"
    },
    {
      "x": 2,
      "y": 24,
      "z": 6,
      "name": "TFJ_Canopy_Leaves"
    },
    {
      "x": 2,
      "y": 25,
      "z": 6,
      "name": "TFJ_Canopy_Leaves"
    },
    {
      "x": 2,
      "y": 26,
      "z": 6,
      "name": "TFJ_Canopy_Leaves"
    },
    {
      "x": 2,
      "y": 22,
      "z": 7,
      "name": "TFJ_Canopy_Leaves"
    },
    {
      "x": 2,
      "y": 23,
      "z": 7,
      "name": "TFJ_Canopy_Leaves"
    },
    {
      "x": 2,
      "y": 24,
      "z": 7,
      "name": "TFJ_Canopy_Leaves"
    },
    {
      "x": 2,
      "y": 25,
      "z": 7,
      "name": "TFJ_Canopy_Leaves"
    },
    {
      "x": 2,
      "y": 26,
      "z": 7,
      "name": "TFJ_Canopy_Leaves"
    },
    {
      "x": 2,
      "y": 22,
      "z": 8,
      "name": "TFJ_Canopy_Leaves"
    },
    {
      "x": 2,
      "y": 23,
      "z": 8,
      "name": "TFJ_Canopy_Leaves"
    },
    {
      "x": 2,
      "y": 24,
      "z": 8,
      "name": "TFJ_Canopy_Leaves"
    },
    {
      "x": 2,
      "y": 25,
      "z": 8,
      "name": "TFJ_Canopy_Leaves"
    },
    {
      "x": 2,
      "y": 26,
      "z": 8,
      "name": "TFJ_Canopy_Leaves"
    },
    {
      "x": 3,
      "y": 22,
      "z": -7,
      "name": "TFJ_Canopy_Leaves"
    },
    {
      "x": 3,
      "y": 23,
      "z": -7,
      "name": "TFJ_Canopy_Leaves"
    },
    {
      "x": 3,
      "y": 24,
      "z": -7,
      "name": "TFJ_Canopy_Leaves"
    },
    {
      "x": 3,
      "y": 20,
      "z": -6,
      "name": "TFJ_Canopy_Leaves"
    },
    {
      "x": 3,
      "y": 21,
      "z": -6,
      "name": "TFJ_Canopy_Leaves"
    },
    {
      "x": 3,
      "y": 22,
      "z": -6,
      "name": "TFJ_Canopy_Leaves"
    },
    {
      "x": 3,
      "y": 23,
      "z": -6,
      "name": "TFJ_Canopy_Leaves"
    },
    {
      "x": 3,
      "y": 24,
      "z": -6,
      "name": "TFJ_Canopy_Leaves"
    },
    {
      "x": 3,
      "y": 25,
      "z": -6,
      "name": "TFJ_Canopy_Leaves"
    },
    {
      "x": 3,
      "y": 26,
      "z": -6,
      "name": "TFJ_Canopy_Leaves"
    },
    {
      "x": 3,
      "y": 20,
      "z": -5,
      "name": "TFJ_Canopy_Leaves"
    },
    {
      "x": 3,
      "y": 21,
      "z": -5,
      "name": "TFJ_Canopy_Leaves"
    },
    {
      "x": 3,
      "y": 22,
      "z": -5,
      "name": "TFJ_Canopy_Leaves"
    },
    {
      "x": 3,
      "y": 23,
      "z": -5,
      "name": "TFJ_Canopy_Leaves"
    },
    {
      "x": 3,
      "y": 24,
      "z": -5,
      "name": "TFJ_Canopy_Leaves"
    },
    {
      "x": 3,
      "y": 25,
      "z": -5,
      "name": "TFJ_Canopy_Leaves"
    },
    {
      "x": 3,
      "y": 26,
      "z": -5,
      "name": "TFJ_Canopy_Leaves"
    },
    {
      "x": 3,
      "y": 23,
      "z": -4,
      "name": "TFJ_Canopy_Leaves"
    },
    {
      "x": 3,
      "y": 24,
      "z": -4,
      "name": "TFJ_Canopy_Leaves"
    },
    {
      "x": 3,
      "y": 25,
      "z": -4,
      "name": "TFJ_Canopy_Leaves"
    },
    {
      "x": 3,
      "y": 26,
      "z": -4,
      "name": "TFJ_Canopy_Leaves"
    },
    {
      "x": 3,
      "y": 23,
      "z": -3,
      "name": "Empty"
    },
    {
      "x": 3,
      "y": 24,
      "z": -3,
      "name": "TFJ_Canopy_Leaves"
    },
    {
      "x": 3,
      "y": 25,
      "z": -3,
      "name": "TFJ_Canopy_Leaves"
    },
    {
      "x": 3,
      "y": 26,
      "z": -3,
      "name": "TFJ_Canopy_Leaves"
    },
    {
      "x": 3,
      "y": 25,
      "z": -2,
      "name": "TFJ_Canopy_Leaves"
    },
    {
      "x": 3,
      "y": 26,
      "z": -2,
      "name": "TFJ_Canopy_Leaves"
    },
    {
      "x": 3,
      "y": 24,
      "z": -1,
      "name": "TFJ_Canopy_Leaves"
    },
    {
      "x": 3,
      "y": 25,
      "z": -1,
      "name": "TFJ_Canopy_Leaves"
    },
    {
      "x": 3,
      "y": 26,
      "z": -1,
      "name": "TFJ_Canopy_Leaves"
    },
    {
      "x": 3,
      "y": 0,
      "z": 0,
      "name": "TFJ_Titanwood_Log"
    },
    {
      "x": 3,
      "y": 1,
      "z": 0,
      "name": "TFJ_Titanwood_Log"
    },
    {
      "x": 3,
      "y": 2,
      "z": 0,
      "name": "TFJ_Titanwood_Log"
    },
    {
      "x": 3,
      "y": 3,
      "z": 0,
      "name": "TFJ_Titanwood_Log",
      "rotation": 11
    },
    {
      "x": 3,
      "y": 18,
      "z": 0,
      "name": "TFJ_Titanwood_Log"
    },
    {
      "x": 3,
      "y": 19,
      "z": 0,
      "name": "TFJ_Titanwood_Log"
    },
    {
      "x": 3,
      "y": 20,
      "z": 0,
      "name": "TFJ_Titanwood_Log"
    },
    {
      "x": 3,
      "y": 21,
      "z": 0,
      "name": "TFJ_Titanwood_Log"
    },
    {
      "x": 3,
      "y": 22,
      "z": 0,
      "name": "TFJ_Titanwood_Log"
    },
    {
      "x": 3,
      "y": 23,
      "z": 0,
      "name": "TFJ_Titanwood_Log"
    },
    {
      "x": 3,
      "y": 24,
      "z": 0,
      "name": "TFJ_Titanwood_Log"
    },
    {
      "x": 3,
      "y": 25,
      "z": 0,
      "name": "TFJ_Canopy_Leaves"
    },
    {
      "x": 3,
      "y": 26,
      "z": 0,
      "name": "TFJ_Canopy_Leaves"
    },
    {
      "x": 3,
      "y": 27,
      "z": 0,
      "name": "TFJ_Canopy_Leaves"
    },
    {
      "x": 3,
      "y": 17,
      "z": 1,
      "name": "TFJ_Titanwood_Log"
    },
    {
      "x": 3,
      "y": 18,
      "z": 1,
      "name": "TFJ_Titanwood_Log"
    },
    {
      "x": 3,
      "y": 23,
      "z": 1,
      "name": "TFJ_Canopy_Leaves"
    },
    {
      "x": 3,
      "y": 24,
      "z": 1,
      "name": "TFJ_Canopy_Leaves"
    },
    {
      "x": 3,
      "y": 25,
      "z": 1,
      "name": "TFJ_Canopy_Leaves"
    },
    {
      "x": 3,
      "y": 26,
      "z": 1,
      "name": "TFJ_Canopy_Leaves"
    },
    {
      "x": 3,
      "y": 27,
      "z": 1,
      "name": "TFJ_Canopy_Leaves"
    },
    {
      "x": 3,
      "y": 18,
      "z": 2,
      "name": "TFJ_Titanwood_Log"
    },
    {
      "x": 3,
      "y": 24,
      "z": 2,
      "name": "TFJ_Canopy_Leaves"
    },
    {
      "x": 3,
      "y": 25,
      "z": 2,
      "name": "TFJ_Canopy_Leaves"
    },
    {
      "x": 3,
      "y": 26,
      "z": 2,
      "name": "TFJ_Canopy_Leaves"
    },
    {
      "x": 3,
      "y": 27,
      "z": 2,
      "name": "TFJ_Canopy_Leaves"
    },
    {
      "x": 3,
      "y": 23,
      "z": 3,
      "name": "TFJ_Canopy_Leaves"
    },
    {
      "x": 3,
      "y": 24,
      "z": 3,
      "name": "TFJ_Canopy_Leaves"
    },
    {
      "x": 3,
      "y": 25,
      "z": 3,
      "name": "TFJ_Canopy_Leaves"
    },
    {
      "x": 3,
      "y": 26,
      "z": 3,
      "name": "TFJ_Canopy_Leaves"
    },
    {
      "x": 3,
      "y": 22,
      "z": 4,
      "name": "TFJ_Canopy_Leaves"
    },
    {
      "x": 3,
      "y": 23,
      "z": 4,
      "name": "TFJ_Canopy_Leaves"
    },
    {
      "x": 3,
      "y": 24,
      "z": 4,
      "name": "TFJ_Canopy_Leaves"
    },
    {
      "x": 3,
      "y": 25,
      "z": 4,
      "name": "TFJ_Canopy_Leaves"
    },
    {
      "x": 3,
      "y": 22,
      "z": 5,
      "name": "TFJ_Canopy_Leaves"
    },
    {
      "x": 3,
      "y": 23,
      "z": 5,
      "name": "TFJ_Canopy_Leaves"
    },
    {
      "x": 3,
      "y": 24,
      "z": 5,
      "name": "TFJ_Canopy_Leaves"
    },
    {
      "x": 3,
      "y": 25,
      "z": 5,
      "name": "TFJ_Canopy_Leaves"
    },
    {
      "x": 3,
      "y": 26,
      "z": 5,
      "name": "TFJ_Canopy_Leaves"
    },
    {
      "x": 3,
      "y": 22,
      "z": 6,
      "name": "TFJ_Canopy_Leaves"
    },
    {
      "x": 3,
      "y": 23,
      "z": 6,
      "name": "TFJ_Canopy_Leaves"
    },
    {
      "x": 3,
      "y": 24,
      "z": 6,
      "name": "TFJ_Canopy_Leaves"
    },
    {
      "x": 3,
      "y": 25,
      "z": 6,
      "name": "TFJ_Canopy_Leaves"
    },
    {
      "x": 3,
      "y": 22,
      "z": 7,
      "name": "TFJ_Canopy_Leaves"
    },
    {
      "x": 3,
      "y": 23,
      "z": 7,
      "name": "TFJ_Canopy_Leaves"
    },
    {
      "x": 3,
      "y": 24,
      "z": 7,
      "name": "TFJ_Canopy_Leaves"
    },
    {
      "x": 3,
      "y": 25,
      "z": 7,
      "name": "TFJ_Canopy_Leaves"
    },
    {
      "x": 3,
      "y": 26,
      "z": 7,
      "name": "TFJ_Canopy_Leaves"
    },
    {
      "x": 3,
      "y": 22,
      "z": 8,
      "name": "TFJ_Canopy_Leaves"
    },
    {
      "x": 3,
      "y": 23,
      "z": 8,
      "name": "TFJ_Canopy_Leaves"
    },
    {
      "x": 3,
      "y": 24,
      "z": 8,
      "name": "TFJ_Canopy_Leaves"
    },
    {
      "x": 3,
      "y": 25,
      "z": 8,
      "name": "TFJ_Canopy_Leaves"
    },
    {
      "x": 4,
      "y": 22,
      "z": -7,
      "name": "TFJ_Canopy_Leaves"
    },
    {
      "x": 4,
      "y": 23,
      "z": -7,
      "name": "TFJ_Canopy_Leaves"
    },
    {
      "x": 4,
      "y": 24,
      "z": -7,
      "name": "TFJ_Canopy_Leaves"
    },
    {
      "x": 4,
      "y": 21,
      "z": -6,
      "name": "TFJ_Canopy_Leaves"
    },
    {
      "x": 4,
      "y": 22,
      "z": -6,
      "name": "TFJ_Canopy_Leaves"
    },
    {
      "x": 4,
      "y": 23,
      "z": -6,
      "name": "TFJ_Canopy_Leaves"
    },
    {
      "x": 4,
      "y": 24,
      "z": -6,
      "name": "TFJ_Canopy_Leaves"
    },
    {
      "x": 4,
      "y": 25,
      "z": -6,
      "name": "TFJ_Canopy_Leaves"
    },
    {
      "x": 4,
      "y": 20,
      "z": -5,
      "name": "TFJ_Canopy_Leaves"
    },
    {
      "x": 4,
      "y": 21,
      "z": -5,
      "name": "TFJ_Canopy_Leaves"
    },
    {
      "x": 4,
      "y": 22,
      "z": -5,
      "name": "TFJ_Canopy_Leaves"
    },
    {
      "x": 4,
      "y": 23,
      "z": -5,
      "name": "TFJ_Canopy_Leaves"
    },
    {
      "x": 4,
      "y": 24,
      "z": -5,
      "name": "TFJ_Canopy_Leaves"
    },
    {
      "x": 4,
      "y": 25,
      "z": -5,
      "name": "TFJ_Canopy_Leaves"
    },
    {
      "x": 4,
      "y": 26,
      "z": -5,
      "name": "TFJ_Canopy_Leaves"
    },
    {
      "x": 4,
      "y": 21,
      "z": -4,
      "name": "TFJ_Canopy_Leaves"
    },
    {
      "x": 4,
      "y": 22,
      "z": -4,
      "name": "TFJ_Canopy_Leaves"
    },
    {
      "x": 4,
      "y": 23,
      "z": -4,
      "name": "TFJ_Canopy_Leaves"
    },
    {
      "x": 4,
      "y": 24,
      "z": -4,
      "name": "TFJ_Canopy_Leaves"
    },
    {
      "x": 4,
      "y": 25,
      "z": -4,
      "name": "TFJ_Canopy_Leaves"
    },
    {
      "x": 4,
      "y": 23,
      "z": -3,
      "name": "TFJ_Canopy_Leaves"
    },
    {
      "x": 4,
      "y": 24,
      "z": -3,
      "name": "TFJ_Canopy_Leaves"
    },
    {
      "x": 4,
      "y": 23,
      "z": -2,
      "name": "TFJ_Canopy_Leaves"
    },
    {
      "x": 4,
      "y": 24,
      "z": -2,
      "name": "TFJ_Canopy_Leaves"
    },
    {
      "x": 4,
      "y": 25,
      "z": -2,
      "name": "TFJ_Canopy_Leaves"
    },
    {
      "x": 4,
      "y": 23,
      "z": -1,
      "name": "TFJ_Canopy_Leaves"
    },
    {
      "x": 4,
      "y": 24,
      "z": -1,
      "name": "TFJ_Canopy_Leaves"
    },
    {
      "x": 4,
      "y": 18,
      "z": 0,
      "name": "TFJ_Titanwood_Log"
    },
    {
      "x": 4,
      "y": 22,
      "z": 0,
      "name": "TFJ_Canopy_Leaves"
    },
    {
      "x": 4,
      "y": 23,
      "z": 0,
      "name": "TFJ_Canopy_Leaves"
    },
    {
      "x": 4,
      "y": 24,
      "z": 0,
      "name": "TFJ_Canopy_Leaves"
    },
    {
      "x": 4,
      "y": 25,
      "z": 0,
      "name": "TFJ_Canopy_Leaves"
    },
    {
      "x": 4,
      "y": 24,
      "z": 1,
      "name": "TFJ_Canopy_Leaves"
    },
    {
      "x": 4,
      "y": 25,
      "z": 1,
      "name": "TFJ_Canopy_Leaves"
    },
    {
      "x": 4,
      "y": 26,
      "z": 1,
      "name": "TFJ_Canopy_Leaves"
    },
    {
      "x": 4,
      "y": 27,
      "z": 1,
      "name": "TFJ_Canopy_Leaves"
    },
    {
      "x": 4,
      "y": 17,
      "z": 2,
      "name": "TFJ_Titanwood_Log"
    },
    {
      "x": 4,
      "y": 18,
      "z": 2,
      "name": "TFJ_Titanwood_Log"
    },
    {
      "x": 4,
      "y": 19,
      "z": 2,
      "name": "TFJ_Titanwood_Log"
    },
    {
      "x": 4,
      "y": 20,
      "z": 2,
      "name": "TFJ_Titanwood_Log"
    },
    {
      "x": 4,
      "y": 21,
      "z": 2,
      "name": "TFJ_Titanwood_Log"
    },
    {
      "x": 4,
      "y": 22,
      "z": 2,
      "name": "TFJ_Titanwood_Log"
    },
    {
      "x": 4,
      "y": 23,
      "z": 2,
      "name": "TFJ_Titanwood_Log"
    },
    {
      "x": 4,
      "y": 24,
      "z": 2,
      "name": "TFJ_Titanwood_Log"
    },
    {
      "x": 4,
      "y": 25,
      "z": 2,
      "name": "TFJ_Canopy_Leaves"
    },
    {
      "x": 4,
      "y": 26,
      "z": 2,
      "name": "TFJ_Canopy_Leaves"
    },
    {
      "x": 4,
      "y": 27,
      "z": 2,
      "name": "TFJ_Canopy_Leaves"
    },
    {
      "x": 4,
      "y": 20,
      "z": 3,
      "name": "TFJ_Titanwood_Log"
    },
    {
      "x": 4,
      "y": 21,
      "z": 3,
      "name": "TFJ_Titanwood_Log"
    },
    {
      "x": 4,
      "y": 24,
      "z": 3,
      "name": "TFJ_Canopy_Leaves"
    },
    {
      "x": 4,
      "y": 25,
      "z": 3,
      "name": "TFJ_Canopy_Leaves"
    },
    {
      "x": 4,
      "y": 26,
      "z": 3,
      "name": "TFJ_Canopy_Leaves"
    },
    {
      "x": 4,
      "y": 27,
      "z": 3,
      "name": "TFJ_Canopy_Leaves"
    },
    {
      "x": 4,
      "y": 21,
      "z": 4,
      "name": "TFJ_Titanwood_Log",
      "rotation": 4
    },
    {
      "x": 4,
      "y": 22,
      "z": 4,
      "name": "TFJ_Canopy_Leaves"
    },
    {
      "x": 4,
      "y": 23,
      "z": 4,
      "name": "TFJ_Canopy_Leaves"
    },
    {
      "x": 4,
      "y": 24,
      "z": 4,
      "name": "TFJ_Canopy_Leaves"
    },
    {
      "x": 4,
      "y": 25,
      "z": 4,
      "name": "TFJ_Canopy_Leaves"
    },
    {
      "x": 4,
      "y": 26,
      "z": 4,
      "name": "TFJ_Canopy_Leaves"
    },
    {
      "x": 4,
      "y": 21,
      "z": 5,
      "name": "TFJ_Titanwood_Log"
    },
    {
      "x": 4,
      "y": 22,
      "z": 5,
      "name": "TFJ_Titanwood_Log"
    },
    {
      "x": 4,
      "y": 23,
      "z": 5,
      "name": "TFJ_Titanwood_Log"
    },
    {
      "x": 4,
      "y": 24,
      "z": 5,
      "name": "TFJ_Canopy_Leaves"
    },
    {
      "x": 4,
      "y": 25,
      "z": 5,
      "name": "TFJ_Canopy_Leaves"
    },
    {
      "x": 4,
      "y": 26,
      "z": 5,
      "name": "TFJ_Canopy_Leaves"
    },
    {
      "x": 4,
      "y": 22,
      "z": 6,
      "name": "TFJ_Canopy_Leaves"
    },
    {
      "x": 4,
      "y": 23,
      "z": 6,
      "name": "TFJ_Canopy_Leaves"
    },
    {
      "x": 4,
      "y": 24,
      "z": 6,
      "name": "TFJ_Canopy_Leaves"
    },
    {
      "x": 4,
      "y": 25,
      "z": 6,
      "name": "TFJ_Canopy_Leaves"
    },
    {
      "x": 4,
      "y": 26,
      "z": 6,
      "name": "TFJ_Canopy_Leaves"
    },
    {
      "x": 4,
      "y": 22,
      "z": 7,
      "name": "TFJ_Canopy_Leaves"
    },
    {
      "x": 4,
      "y": 23,
      "z": 7,
      "name": "TFJ_Canopy_Leaves"
    },
    {
      "x": 4,
      "y": 24,
      "z": 7,
      "name": "TFJ_Canopy_Leaves"
    },
    {
      "x": 4,
      "y": 25,
      "z": 7,
      "name": "TFJ_Canopy_Leaves"
    },
    {
      "x": 4,
      "y": 22,
      "z": 8,
      "name": "TFJ_Canopy_Leaves"
    },
    {
      "x": 4,
      "y": 23,
      "z": 8,
      "name": "TFJ_Canopy_Leaves"
    },
    {
      "x": 4,
      "y": 24,
      "z": 8,
      "name": "TFJ_Canopy_Leaves"
    },
    {
      "x": 5,
      "y": 22,
      "z": -6,
      "name": "TFJ_Canopy_Leaves"
    },
    {
      "x": 5,
      "y": 23,
      "z": -6,
      "name": "TFJ_Canopy_Leaves"
    },
    {
      "x": 5,
      "y": 24,
      "z": -6,
      "name": "TFJ_Canopy_Leaves"
    },
    {
      "x": 5,
      "y": 22,
      "z": -5,
      "name": "TFJ_Canopy_Leaves"
    },
    {
      "x": 5,
      "y": 23,
      "z": -5,
      "name": "TFJ_Canopy_Leaves"
    },
    {
      "x": 5,
      "y": 24,
      "z": -5,
      "name": "TFJ_Canopy_Leaves"
    },
    {
      "x": 5,
      "y": 21,
      "z": -4,
      "name": "TFJ_Canopy_Leaves"
    },
    {
      "x": 5,
      "y": 22,
      "z": -4,
      "name": "TFJ_Canopy_Leaves"
    },
    {
      "x": 5,
      "y": 23,
      "z": -4,
      "name": "TFJ_Canopy_Leaves"
    },
    {
      "x": 5,
      "y": 24,
      "z": -4,
      "name": "TFJ_Canopy_Leaves"
    },
    {
      "x": 5,
      "y": 21,
      "z": -3,
      "name": "TFJ_Canopy_Leaves"
    },
    {
      "x": 5,
      "y": 22,
      "z": -3,
      "name": "TFJ_Canopy_Leaves"
    },
    {
      "x": 5,
      "y": 23,
      "z": -3,
      "name": "TFJ_Canopy_Leaves"
    },
    {
      "x": 5,
      "y": 24,
      "z": -3,
      "name": "TFJ_Canopy_Leaves"
    },
    {
      "x": 5,
      "y": 25,
      "z": -3,
      "name": "TFJ_Canopy_Leaves"
    },
    {
      "x": 5,
      "y": 19,
      "z": -2,
      "name": "TFJ_Titanwood_Log",
      "rotation": 2
    },
    {
      "x": 5,
      "y": 20,
      "z": -2,
      "name": "TFJ_Titanwood_Log"
    },
    {
      "x": 5,
      "y": 21,
      "z": -2,
      "name": "TFJ_Titanwood_Log"
    },
    {
      "x": 5,
      "y": 22,
      "z": -2,
      "name": "TFJ_Titanwood_Log"
    },
    {
      "x": 5,
      "y": 23,
      "z": -2,
      "name": "TFJ_Canopy_Leaves"
    },
    {
      "x": 5,
      "y": 24,
      "z": -2,
      "name": "TFJ_Canopy_Leaves"
    },
    {
      "x": 5,
      "y": 25,
      "z": -2,
      "name": "TFJ_Canopy_Leaves"
    },
    {
      "x": 5,
      "y": 18,
      "z": -1,
      "name": "TFJ_Titanwood_Log"
    },
    {
      "x": 5,
      "y": 19,
      "z": -1,
      "name": "TFJ_Titanwood_Log"
    },
    {
      "x": 5,
      "y": 23,
      "z": -1,
      "name": "TFJ_Canopy_Leaves"
    },
    {
      "x": 5,
      "y": 24,
      "z": -1,
      "name": "TFJ_Canopy_Leaves"
    },
    {
      "x": 5,
      "y": 25,
      "z": -1,
      "name": "TFJ_Canopy_Leaves"
    },
    {
      "x": 5,
      "y": 17,
      "z": 0,
      "name": "TFJ_Titanwood_Log"
    },
    {
      "x": 5,
      "y": 18,
      "z": 0,
      "name": "TFJ_Titanwood_Log"
    },
    {
      "x": 5,
      "y": 23,
      "z": 0,
      "name": "TFJ_Canopy_Leaves"
    },
    {
      "x": 5,
      "y": 24,
      "z": 0,
      "name": "TFJ_Canopy_Leaves"
    },
    {
      "x": 5,
      "y": 25,
      "z": 0,
      "name": "TFJ_Canopy_Leaves"
    },
    {
      "x": 5,
      "y": 23,
      "z": 1,
      "name": "TFJ_Canopy_Leaves"
    },
    {
      "x": 5,
      "y": 24,
      "z": 1,
      "name": "TFJ_Canopy_Leaves"
    },
    {
      "x": 5,
      "y": 25,
      "z": 1,
      "name": "TFJ_Canopy_Leaves"
    },
    {
      "x": 5,
      "y": 26,
      "z": 1,
      "name": "TFJ_Canopy_Leaves"
    },
    {
      "x": 5,
      "y": 24,
      "z": 2,
      "name": "TFJ_Canopy_Leaves"
    },
    {
      "x": 5,
      "y": 25,
      "z": 2,
      "name": "TFJ_Canopy_Leaves"
    },
    {
      "x": 5,
      "y": 26,
      "z": 2,
      "name": "TFJ_Canopy_Leaves"
    },
    {
      "x": 5,
      "y": 27,
      "z": 2,
      "name": "TFJ_Canopy_Leaves"
    },
    {
      "x": 5,
      "y": 23,
      "z": 3,
      "name": "TFJ_Canopy_Leaves"
    },
    {
      "x": 5,
      "y": 24,
      "z": 3,
      "name": "TFJ_Canopy_Leaves"
    },
    {
      "x": 5,
      "y": 25,
      "z": 3,
      "name": "TFJ_Canopy_Leaves"
    },
    {
      "x": 5,
      "y": 26,
      "z": 3,
      "name": "TFJ_Canopy_Leaves"
    },
    {
      "x": 5,
      "y": 22,
      "z": 4,
      "name": "TFJ_Canopy_Leaves"
    },
    {
      "x": 5,
      "y": 23,
      "z": 4,
      "name": "TFJ_Canopy_Leaves"
    },
    {
      "x": 5,
      "y": 24,
      "z": 4,
      "name": "TFJ_Canopy_Leaves"
    },
    {
      "x": 5,
      "y": 25,
      "z": 4,
      "name": "TFJ_Canopy_Leaves"
    },
    {
      "x": 5,
      "y": 22,
      "z": 5,
      "name": "TFJ_Canopy_Leaves"
    },
    {
      "x": 5,
      "y": 23,
      "z": 5,
      "name": "TFJ_Canopy_Leaves"
    },
    {
      "x": 5,
      "y": 24,
      "z": 5,
      "name": "TFJ_Canopy_Leaves"
    },
    {
      "x": 5,
      "y": 25,
      "z": 5,
      "name": "TFJ_Canopy_Leaves"
    },
    {
      "x": 5,
      "y": 22,
      "z": 6,
      "name": "TFJ_Canopy_Leaves"
    },
    {
      "x": 5,
      "y": 23,
      "z": 6,
      "name": "TFJ_Canopy_Leaves"
    },
    {
      "x": 5,
      "y": 24,
      "z": 6,
      "name": "TFJ_Canopy_Leaves"
    },
    {
      "x": 5,
      "y": 22,
      "z": 7,
      "name": "TFJ_Canopy_Leaves"
    },
    {
      "x": 5,
      "y": 23,
      "z": 7,
      "name": "TFJ_Canopy_Leaves"
    },
    {
      "x": 5,
      "y": 24,
      "z": 7,
      "name": "TFJ_Canopy_Leaves"
    },
    {
      "x": 6,
      "y": 21,
      "z": -4,
      "name": "TFJ_Canopy_Leaves"
    },
    {
      "x": 6,
      "y": 22,
      "z": -4,
      "name": "TFJ_Canopy_Leaves"
    },
    {
      "x": 6,
      "y": 23,
      "z": -4,
      "name": "TFJ_Canopy_Leaves"
    },
    {
      "x": 6,
      "y": 21,
      "z": -3,
      "name": "TFJ_Canopy_Leaves"
    },
    {
      "x": 6,
      "y": 22,
      "z": -3,
      "name": "TFJ_Canopy_Leaves"
    },
    {
      "x": 6,
      "y": 23,
      "z": -3,
      "name": "TFJ_Canopy_Leaves"
    },
    {
      "x": 6,
      "y": 24,
      "z": -3,
      "name": "TFJ_Canopy_Leaves"
    },
    {
      "x": 6,
      "y": 22,
      "z": -2,
      "name": "TFJ_Canopy_Leaves"
    },
    {
      "x": 6,
      "y": 23,
      "z": -2,
      "name": "TFJ_Canopy_Leaves"
    },
    {
      "x": 6,
      "y": 24,
      "z": -2,
      "name": "TFJ_Canopy_Leaves"
    },
    {
      "x": 6,
      "y": 25,
      "z": -2,
      "name": "TFJ_Canopy_Leaves"
    },
    {
      "x": 6,
      "y": 19,
      "z": -1,
      "name": "TFJ_Titanwood_Log",
      "rotation": 5
    },
    {
      "x": 6,
      "y": 23,
      "z": -1,
      "name": "TFJ_Canopy_Leaves"
    },
    {
      "x": 6,
      "y": 24,
      "z": -1,
      "name": "TFJ_Canopy_Leaves"
    },
    {
      "x": 6,
      "y": 22,
      "z": 0,
      "name": "TFJ_Canopy_Leaves"
    },
    {
      "x": 6,
      "y": 23,
      "z": 0,
      "name": "TFJ_Canopy_Leaves"
    },
    {
      "x": 6,
      "y": 23,
      "z": 1,
      "name": "TFJ_Canopy_Leaves"
    },
    {
      "x": 6,
      "y": 24,
      "z": 1,
      "name": "TFJ_Canopy_Leaves"
    },
    {
      "x": 6,
      "y": 23,
      "z": 2,
      "name": "TFJ_Canopy_Leaves"
    },
    {
      "x": 6,
      "y": 24,
      "z": 2,
      "name": "TFJ_Canopy_Leaves"
    },
    {
      "x": 6,
      "y": 25,
      "z": 2,
      "name": "TFJ_Canopy_Leaves"
    },
    {
      "x": 6,
      "y": 23,
      "z": 3,
      "name": "TFJ_Canopy_Leaves"
    },
    {
      "x": 6,
      "y": 24,
      "z": 3,
      "name": "TFJ_Canopy_Leaves"
    },
    {
      "x": 6,
      "y": 25,
