{
  "version": 8,
  "blockIdVersion": 11,
  "anchorX": 0,
  "anchorY": 0,
  "anchorZ": 0,
  "blocks": [
    {
      "x": -11,
      "y": 14,
      "z": -4,
      "name": "TFJ_Canopy_Leaves"
    },
    {
      "x": -11,
      "y": 12,
      "z": -1,
      "name": "TFJ_Canopy_Leaves"
    },
    {
      "x": -11,
      "y": 14,
      "z": -1,
      "name": "TFJ_Canopy_Leaves"
    },
    {
      "x": -11,
      "y": 14,
      "z": 0,
      "name": "TFJ_Canopy_Leaves"
    },
    {
      "x": -11,
      "y": 15,
      "z": 0,
      "name": "TFJ_Canopy_Leaves"
    },
    {
      "x": -11,
      "y": 12,
      "z": 1,
      "name": "TFJ_Canopy_Leaves"
    },
    {
      "x": -11,
      "y": 13,
      "z": 1,
      "name": "TFJ_Canopy_Leaves"
    },
    {
      "x": -11,
      "y": 14,
      "z": 1,
      "name": "TFJ_Canopy_Leaves"
    },
    {
      "x": -11,
      "y": 13,
      "z": 2,
      "name": "TFJ_Canopy_Leaves"
    },
    {
      "x": -10,
      "y": 13,
      "z": -4,
      "name": "TFJ_Canopy_Leaves"
    },
    {
      "x": -10,
      "y": 14,
      "z": -4,
      "name": "TFJ_Canopy_Leaves"
    },
    {
      "x": -10,
      "y": 16,
      "z": -4,
      "name": "TFJ_Canopy_Leaves"
    },
    {
      "x": -10,
      "y": 11,
      "z": -3,
      "name": "TFJ_Canopy_Leaves"
    },
    {
      "x": -10,
      "y": 12,
      "z": -3,
      "name": "TFJ_Canopy_Leaves"
    },
    {
      "x": -10,
      "y": 14,
      "z": -3,
      "name": "TFJ_Canopy_Leaves"
    },
    {
      "x": -10,
      "y": 13,
      "z": -1,
      "name": "TFJ_Canopy_Leaves"
    },
    {
      "x": -10,
      "y": 17,
      "z": -1,
      "name": "TFJ_Canopy_Leaves"
    },
    {
      "x": -10,
      "y": 9,
      "z": 0,
      "name": "TFJ_Canopy_Leaves"
    },
    {
      "x": -10,
      "y": 12,
      "z": 0,
      "name": "TFJ_Canopy_Leaves"
    },
    {
      "x": -10,
      "y": 13,
      "z": 0,
      "name": "TFJ_Canopy_Leaves"
    },
    {
      "x": -10,
      "y": 14,
      "z": 0,
      "name": "TFJ_Canopy_Leaves"
    },
    {
      "x": -10,
      "y": 16,
      "z": 0,
      "name": "TFJ_Canopy_Leaves"
    },
    {
      "x": -10,
      "y": 17,
      "z": 0,
      "name": "TFJ_Canopy_Leaves"
    },
    {
      "x": -10,
      "y": 18,
      "z": 0,
      "name": "TFJ_Canopy_Leaves"
    },
    {
      "x": -10,
      "y": 8,
      "z": 1,
      "name": "TFJ_Canopy_Leaves"
    },
    {
      "x": -10,
      "y": 9,
      "z": 1,
      "name": "TFJ_Canopy_Leaves"
    },
    {
      "x": -10,
      "y": 10,
      "z": 1,
      "name": "TFJ_Canopy_Leaves"
    },
    {
      "x": -10,
      "y": 12,
      "z": 1,
      "name": "TFJ_Canopy_Leaves"
    },
    {
      "x": -10,
      "y": 13,
      "z": 1,
      "name": "TFJ_Titanwood_Log",
      "rotation": 5
    },
    {
      "x": -10,
      "y": 14,
      "z": 1,
      "name": "TFJ_Canopy_Leaves"
    },
    {
      "x": -10,
      "y": 15,
      "z": 1,
      "name": "TFJ_Canopy_Leaves"
    },
    {
      "x": -10,
      "y": 17,
      "z": 1,
      "name": "TFJ_Canopy_Leaves"
    },
    {
      "x": -10,
      "y": 18,
      "z": 1,
      "name": "TFJ_Canopy_Leaves"
    },
    {
      "x": -10,
      "y": 9,
      "z": 2,
      "name": "TFJ_Canopy_Leaves"
    },
    {
      "x": -10,
      "y": 12,
      "z": 2,
      "name": "TFJ_Canopy_Leaves"
    },
    {
      "x": -10,
      "y": 13,
      "z": 2,
      "name": "TFJ_Canopy_Leaves"
    },
    {
      "x": -10,
      "y": 14,
      "z": 2,
      "name": "TFJ_Canopy_Leaves"
    },
    {
      "x": -10,
      "y": 13,
      "z": 3,
      "name": "TFJ_Canopy_Leaves"
    },
    {
      "x": -9,
      "y": 13,
      "z": -7,
      "name": "TFJ_Canopy_Leaves"
    },
    {
      "x": -9,
      "y": 11,
      "z": -6,
      "name": "TFJ_Canopy_Leaves"
    },
    {
      "x": -9,
      "y": 14,
      "z": -6,
      "name": "TFJ_Canopy_Leaves"
    },
    {
      "x": -9,
      "y": 15,
      "z": -6,
      "name": "TFJ_Canopy_Leaves"
    },
    {
      "x": -9,
      "y": 13,
      "z": -5,
      "name": "TFJ_Canopy_Leaves"
    },
    {
      "x": -9,
      "y": 14,
      "z": -5,
      "name": "TFJ_Canopy_Leaves"
    },
    {
      "x": -9,
      "y": 15,
      "z": -5,
      "name": "TFJ_Canopy_Leaves"
    },
    {
      "x": -9,
      "y": 11,
      "z": -4,
      "name": "TFJ_Canopy_Leaves"
    },
    {
      "x": -9,
      "y": 12,
      "z": -4,
      "name": "TFJ_Canopy_Leaves"
    },
    {
      "x": -9,
      "y": 13,
      "z": -4,
      "name": "TFJ_Canopy_Leaves"
    },
    {
      "x": -9,
      "y": 14,
      "z": -4,
      "name": "TFJ_Canopy_Leaves"
    },
    {
      "x": -9,
      "y": 15,
      "z": -4,
      "name": "TFJ_Canopy_Leaves"
    },
    {
      "x": -9,
      "y": 16,
      "z": -4,
      "name": "TFJ_Canopy_Leaves"
    },
    {
      "x": -9,
      "y": 11,
      "z": -3,
      "name": "TFJ_Canopy_Leaves"
    },
    {
      "x": -9,
      "y": 13,
      "z": -3,
      "name": "TFJ_Canopy_Leaves"
    },
    {
      "x": -9,
      "y": 14,
      "z": -3,
      "name": "TFJ_Canopy_Leaves"
    },
    {
      "x": -9,
      "y": 15,
      "z": -3,
      "name": "TFJ_Canopy_Leaves"
    },
    {
      "x": -9,
      "y": 17,
      "z": -2,
      "name": "TFJ_Canopy_Leaves"
    },
    {
      "x": -9,
      "y": 9,
      "z": -1,
      "name": "TFJ_Canopy_Leaves"
    },
    {
      "x": -9,
      "y": 16,
      "z": -1,
      "name": "TFJ_Canopy_Leaves"
    },
    {
      "x": -9,
      "y": 17,
      "z": -1,
      "name": "TFJ_Canopy_Leaves"
    },
    {
      "x": -9,
      "y": 18,
      "z": -1,
      "name": "TFJ_Canopy_Leaves"
    },
    {
      "x": -9,
      "y": 8,
      "z": 0,
      "name": "TFJ_Canopy_Leaves"
    },
    {
      "x": -9,
      "y": 9,
      "z": 0,
      "name": "TFJ_Canopy_Leaves"
    },
    {
      "x": -9,
      "y": 10,
      "z": 0,
      "name": "TFJ_Canopy_Leaves"
    },
    {
      "x": -9,
      "y": 16,
      "z": 0,
      "name": "TFJ_Canopy_Leaves"
    },
    {
      "x": -9,
      "y": 17,
      "z": 0,
      "name": "TFJ_Canopy_Leaves"
    },
    {
      "x": -9,
      "y": 18,
      "z": 0,
      "name": "TFJ_Canopy_Leaves"
    },
    {
      "x": -9,
      "y": 19,
      "z": 0,
      "name": "TFJ_Canopy_Leaves"
    },
    {
      "x": -9,
      "y": 7,
      "z": 1,
      "name": "TFJ_Canopy_Leaves"
    },
    {
      "x": -9,
      "y": 8,
      "z": 1,
      "name": "TFJ_Canopy_Leaves"
    },
    {
      "x": -9,
      "y": 9,
      "z": 1,
      "name": "TFJ_Canopy_Leaves"
    },
    {
      "x": -9,
      "y": 10,
      "z": 1,
      "name": "TFJ_Canopy_Leaves"
    },
    {
      "x": -9,
      "y": 12,
      "z": 1,
      "name": "TFJ_Titanwood_Log",
      "rotation": 3
    },
    {
      "x": -9,
      "y": 13,
      "z": 1,
      "name": "TFJ_Titanwood_Log",
      "rotation": 11
    },
    {
      "x": -9,
      "y": 16,
      "z": 1,
      "name": "TFJ_Canopy_Leaves"
    },
    {
      "x": -9,
      "y": 17,
      "z": 1,
      "name": "TFJ_Canopy_Leaves"
    },
    {
      "x": -9,
      "y": 18,
      "z": 1,
      "name": "TFJ_Canopy_Leaves"
    },
    {
      "x": -9,
      "y": 19,
      "z": 1,
      "name": "TFJ_Canopy_Leaves"
    },
    {
      "x": -9,
      "y": 8,
      "z": 2,
      "name": "TFJ_Canopy_Leaves"
    },
    {
      "x": -9,
      "y": 9,
      "z": 2,
      "name": "TFJ_Canopy_Leaves"
    },
    {
      "x": -9,
      "y": 10,
      "z": 2,
      "name": "TFJ_Canopy_Leaves"
    },
    {
      "x": -9,
      "y": 15,
      "z": 2,
      "name": "TFJ_Canopy_Leaves"
    },
    {
      "x": -9,
      "y": 17,
      "z": 2,
      "name": "TFJ_Canopy_Leaves"
    },
    {
      "x": -9,
      "y": 18,
      "z": 2,
      "name": "TFJ_Canopy_Leaves"
    },
    {
      "x": -9,
      "y": 9,
      "z": 3,
      "name": "TFJ_Canopy_Leaves"
    },
    {
      "x": -9,
      "y": 10,
      "z": 3,
      "name": "TFJ_Canopy_Leaves"
    },
    {
      "x": -9,
      "y": 11,
      "z": 3,
      "name": "TFJ_Canopy_Leaves"
    },
    {
      "x": -9,
      "y": 14,
      "z": 3,
      "name": "TFJ_Canopy_Leaves"
    },
    {
      "x": -9,
      "y": 10,
      "z": 4,
      "name": "TFJ_Canopy_Leaves"
    },
    {
      "x": -9,
      "y": 11,
      "z": 4,
      "name": "TFJ_Canopy_Leaves"
    },
    {
      "x": -9,
      "y": 12,
      "z": 4,
      "name": "TFJ_Canopy_Leaves"
    },
    {
      "x": -9,
      "y": 16,
      "z": 4,
      "name": "TFJ_Canopy_Leaves"
    },
    {
      "x": -9,
      "y": 9,
      "z": 5,
      "name": "TFJ_Canopy_Leaves"
    },
    {
      "x": -9,
      "y": 10,
      "z": 5,
      "name": "TFJ_Canopy_Leaves"
    },
    {
      "x": -9,
      "y": 11,
      "z": 5,
      "name": "TFJ_Canopy_Leaves"
    },
    {
      "x": -9,
      "y": 16,
      "z": 5,
      "name": "TFJ_Canopy_Leaves"
    },
    {
      "x": -9,
      "y": 17,
      "z": 5,
      "name": "TFJ_Canopy_Leaves"
    },
    {
      "x": -9,
      "y": 10,
      "z": 6,
      "name": "TFJ_Canopy_Leaves"
    },
    {
      "x": -8,
      "y": 12,
      "z": -7,
      "name": "TFJ_Canopy_Leaves"
    },
    {
      "x": -8,
      "y": 13,
      "z": -7,
      "name": "TFJ_Canopy_Leaves"
    },
    {
      "x": -8,
      "y": 11,
      "z": -6,
      "name": "TFJ_Canopy_Leaves"
    },
    {
      "x": -8,
      "y": 12,
      "z": -6,
      "name": "TFJ_Canopy_Leaves"
    },
    {
      "x": -8,
      "y": 13,
      "z": -6,
      "name": "TFJ_Canopy_Leaves"
    },
    {
      "x": -8,
      "y": 14,
      "z": -6,
      "name": "TFJ_Canopy_Leaves"
    },
    {
      "x": -8,
      "y": 15,
      "z": -6,
      "name": "TFJ_Canopy_Leaves"
    },
    {
      "x": -8,
      "y": 10,
      "z": -5,
      "name": "TFJ_Canopy_Leaves"
    },
    {
      "x": -8,
      "y": 11,
      "z": -5,
      "name": "TFJ_Canopy_Leaves"
    },
    {
      "x": -8,
      "y": 12,
      "z": -5,
      "name": "TFJ_Canopy_Leaves"
    },
    {
      "x": -8,
      "y": 14,
      "z": -5,
      "name": "TFJ_Canopy_Leaves"
    },
    {
      "x": -8,
      "y": 15,
      "z": -5,
      "name": "TFJ_Canopy_Leaves"
    },
    {
      "x": -8,
      "y": 16,
      "z": -5,
      "name": "TFJ_Canopy_Leaves"
    },
    {
      "x": -8,
      "y": 14,
      "z": -4,
      "name": "TFJ_Titanwood_Log",
      "rotation": 5
    },
    {
      "x": -8,
      "y": 16,
      "z": -4,
      "name": "TFJ_Canopy_Leaves"
    },
    {
      "x": -8,
      "y": 11,
      "z": -3,
      "name": "TFJ_Titanwood_Log",
      "rotation": 5
    },
    {
      "x": -8,
      "y": 18,
      "z": -2,
      "name": "TFJ_Canopy_Leaves"
    },
    {
      "x": -8,
      "y": 8,
      "z": -1,
      "name": "TFJ_Canopy_Leaves"
    },
    {
      "x": -8,
      "y": 18,
      "z": -1,
      "name": "TFJ_Canopy_Leaves"
    },
    {
      "x": -8,
      "y": 19,
      "z": -1,
      "name": "TFJ_Canopy_Leaves"
    },
    {
      "x": -8,
      "y": 7,
      "z": 0,
      "name": "TFJ_Canopy_Leaves"
    },
    {
      "x": -8,
      "y": 8,
      "z": 0,
      "name": "TFJ_Canopy_Leaves"
    },
    {
      "x": -8,
      "y": 18,
      "z": 0,
      "name": "TFJ_Canopy_Leaves"
    },
    {
      "x": -8,
      "y": 19,
      "z": 0,
      "name": "TFJ_Canopy_Leaves"
    },
    {
      "x": -8,
      "y": 7,
      "z": 1,
      "name": "TFJ_Canopy_Leaves"
    },
    {
      "x": -8,
      "y": 8,
      "z": 1,
      "name": "TFJ_Canopy_Leaves"
    },
    {
      "x": -8,
      "y": 9,
      "z": 1,
      "name": "TFJ_Titanwood_Log",
      "rotation": 5
    },
    {
      "x": -8,
      "y": 12,
      "z": 1,
      "name": "TFJ_Titanwood_Log",
      "rotation": 5
    },
    {
      "x": -8,
      "y": 17,
      "z": 1,
      "name": "TFJ_Titanwood_Log",
      "rotation": 3
    },
    {
      "x": -8,
      "y": 18,
      "z": 1,
      "name": "TFJ_Titanwood_Log",
      "rotation": 11
    },
    {
      "x": -8,
      "y": 19,
      "z": 1,
      "name": "TFJ_Canopy_Leaves"
    },
    {
      "x": -8,
      "y": 7,
      "z": 2,
      "name": "TFJ_Canopy_Leaves"
    },
    {
      "x": -8,
      "y": 8,
      "z": 2,
      "name": "TFJ_Canopy_Leaves"
    },
    {
      "x": -8,
      "y": 18,
      "z": 2,
      "name": "TFJ_Canopy_Leaves"
    },
    {
      "x": -8,
      "y": 8,
      "z": 3,
      "name": "TFJ_Canopy_Leaves"
    },
    {
      "x": -8,
      "y": 9,
      "z": 3,
      "name": "TFJ_Canopy_Leaves"
    },
    {
      "x": -8,
      "y": 11,
      "z": 3,
      "name": "TFJ_Canopy_Leaves"
    },
    {
      "x": -8,
      "y": 9,
      "z": 4,
      "name": "TFJ_Canopy_Leaves"
    },
    {
      "x": -8,
      "y": 10,
      "z": 4,
      "name": "TFJ_Canopy_Leaves"
    },
    {
      "x": -8,
      "y": 11,
      "z": 4,
      "name": "TFJ_Canopy_Leaves"
    },
    {
      "x": -8,
      "y": 16,
      "z": 4,
      "name": "TFJ_Canopy_Leaves"
    },
    {
      "x": -8,
      "y": 17,
      "z": 4,
      "name": "TFJ_Canopy_Leaves"
    },
    {
      "x": -8,
      "y": 8,
      "z": 5,
      "name": "TFJ_Canopy_Leaves"
    },
    {
      "x": -8,
      "y": 9,
      "z": 5,
      "name": "TFJ_Canopy_Leaves"
    },
    {
      "x": -8,
      "y": 10,
      "z": 5,
      "name": "TFJ_Canopy_Leaves"
    },
    {
      "x": -8,
      "y": 11,
      "z": 5,
      "name": "TFJ_Canopy_Leaves"
    },
    {
      "x": -8,
      "y": 12,
      "z": 5,
      "name": "TFJ_Canopy_Leaves"
    },
    {
      "x": -8,
      "y": 13,
      "z": 5,
      "name": "TFJ_Canopy_Leaves"
    },
    {
      "x": -8,
      "y": 16,
      "z": 5,
      "name": "TFJ_Canopy_Leaves"
    },
    {
      "x": -8,
      "y": 17,
      "z": 5,
      "name": "TFJ_Canopy_Leaves"
    },
    {
      "x": -8,
      "y": 18,
      "z": 5,
      "name": "TFJ_Canopy_Leaves"
    },
    {
      "x": -8,
      "y": 9,
      "z": 6,
      "name": "TFJ_Canopy_Leaves"
    },
    {
      "x": -8,
      "y": 10,
      "z": 6,
      "name": "TFJ_Canopy_Leaves"
    },
    {
      "x": -8,
      "y": 11,
      "z": 6,
      "name": "TFJ_Canopy_Leaves"
    },
    {
      "x": -8,
      "y": 16,
      "z": 6,
      "name": "TFJ_Canopy_Leaves"
    },
    {
      "x": -8,
      "y": 17,
      "z": 6,
      "name": "TFJ_Canopy_Leaves"
    },
    {
      "x": -8,
      "y": 10,
      "z": 7,
      "name": "TFJ_Canopy_Leaves"
    },
    {
      "x": -8,
      "y": 16,
      "z": 7,
      "name": "TFJ_Canopy_Leaves"
    },
    {
      "x": -7,
      "y": 14,
      "z": -8,
      "name": "TFJ_Canopy_Leaves"
    },
    {
      "x": -7,
      "y": 11,
      "z": -7,
      "name": "TFJ_Canopy_Leaves"
    },
    {
      "x": -7,
      "y": 13,
      "z": -7,
      "name": "TFJ_Canopy_Leaves"
    },
    {
      "x": -7,
      "y": 14,
      "z": -7,
      "name": "TFJ_Canopy_Leaves"
    },
    {
      "x": -7,
      "y": 10,
      "z": -6,
      "name": "TFJ_Canopy_Leaves"
    },
    {
      "x": -7,
      "y": 11,
      "z": -6,
      "name": "TFJ_Canopy_Leaves"
    },
    {
      "x": -7,
      "y": 13,
      "z": -6,
      "name": "TFJ_Canopy_Leaves"
    },
    {
      "x": -7,
      "y": 14,
      "z": -6,
      "name": "TFJ_Titanwood_Log",
      "rotation": 5
    },
    {
      "x": -7,
      "y": 16,
      "z": -6,
      "name": "TFJ_Canopy_Leaves"
    },
    {
      "x": -7,
      "y": 10,
      "z": -5,
      "name": "TFJ_Canopy_Leaves"
    },
    {
      "x": -7,
      "y": 11,
      "z": -5,
      "name": "TFJ_Titanwood_Log",
      "rotation": 5
    },
    {
      "x": -7,
      "y": 16,
      "z": -5,
      "name": "TFJ_Canopy_Leaves"
    },
    {
      "x": -7,
      "y": 17,
      "z": -5,
      "name": "TFJ_Canopy_Leaves"
    },
    {
      "x": -7,
      "y": 19,
      "z": -5,
      "name": "TFJ_Canopy_Leaves"
    },
    {
      "x": -7,
      "y": 14,
      "z": -4,
      "name": "TFJ_Titanwood_Log",
      "rotation": 5
    },
    {
      "x": -7,
      "y": 18,
      "z": -4,
      "name": "TFJ_Canopy_Leaves"
    },
    {
      "x": -7,
      "y": 19,
      "z": -4,
      "name": "TFJ_Canopy_Leaves"
    },
    {
      "x": -7,
      "y": 20,
      "z": -4,
      "name": "TFJ_Canopy_Leaves"
    },
    {
      "x": -7,
      "y": 10,
      "z": -3,
      "name": "TFJ_Titanwood_Log",
      "rotation": 3
    },
    {
      "x": -7,
      "y": 11,
      "z": -3,
      "name": "TFJ_Titanwood_Log",
      "rotation": 11
    },
    {
      "x": -7,
      "y": 19,
      "z": -3,
      "name": "TFJ_Canopy_Leaves"
    },
    {
      "x": -7,
      "y": 19,
      "z": 0,
      "name": "TFJ_Canopy_Leaves"
    },
    {
      "x": -7,
      "y": 7,
      "z": 1,
      "name": "TFJ_Canopy_Leaves"
    },
    {
      "x": -7,
      "y": 9,
      "z": 1,
      "name": "TFJ_Titanwood_Log"
    },
    {
      "x": -7,
      "y": 10,
      "z": 1,
      "name": "TFJ_Titanwood_Log"
    },
    {
      "x": -7,
      "y": 11,
      "z": 1,
      "name": "TFJ_Titanwood_Log"
    },
    {
      "x": -7,
      "y": 12,
      "z": 1,
      "name": "TFJ_Titanwood_Log",
      "rotation": 11
    },
    {
      "x": -7,
      "y": 17,
      "z": 1,
      "name": "TFJ_Titanwood_Log",
      "rotation": 5
    },
    {
      "x": -7,
      "y": 8,
      "z": 4,
      "name": "TFJ_Canopy_Leaves"
    },
    {
      "x": -7,
      "y": 10,
      "z": 4,
      "name": "TFJ_Titanwood_Log",
      "rotation": 5
    },
    {
      "x": -7,
      "y": 18,
      "z": 4,
      "name": "TFJ_Canopy_Leaves"
    },
    {
      "x": -7,
      "y": 8,
      "z": 5,
      "name": "TFJ_Canopy_Leaves"
    },
    {
      "x": -7,
      "y": 9,
      "z": 5,
      "name": "TFJ_Canopy_Leaves"
    },
    {
      "x": -7,
      "y": 17,
      "z": 5,
      "name": "TFJ_Canopy_Leaves"
    },
    {
      "x": -7,
      "y": 18,
      "z": 5,
      "name": "TFJ_Canopy_Leaves"
    },
    {
      "x": -7,
      "y": 19,
      "z": 5,
      "name": "TFJ_Canopy_Leaves"
    },
    {
      "x": -7,
      "y": 8,
      "z": 6,
      "name": "TFJ_Canopy_Leaves"
    },
    {
      "x": -7,
      "y": 9,
      "z": 6,
      "name": "TFJ_Canopy_Leaves"
    },
    {
      "x": -7,
      "y": 10,
      "z": 6,
      "name": "TFJ_Canopy_Leaves"
    },
    {
      "x": -7,
      "y": 11,
      "z": 6,
      "name": "TFJ_Canopy_Leaves"
    },
    {
      "x": -7,
      "y": 12,
      "z": 6,
      "name": "TFJ_Canopy_Leaves"
    },
    {
      "x": -7,
      "y": 13,
      "z": 6,
      "name": "TFJ_Canopy_Leaves"
    },
    {
      "x": -7,
      "y": 16,
      "z": 6,
      "name": "TFJ_Canopy_Leaves"
    },
    {
      "x": -7,
      "y": 17,
      "z": 6,
      "name": "TFJ_Canopy_Leaves"
    },
    {
      "x": -7,
      "y": 18,
      "z": 6,
      "name": "TFJ_Canopy_Leaves"
    },
    {
      "x": -7,
      "y": 19,
      "z": 6,
      "name": "TFJ_Canopy_Leaves"
    },
    {
      "x": -7,
      "y": 9,
      "z": 7,
      "name": "TFJ_Canopy_Leaves"
    },
    {
      "x": -7,
      "y": 10,
      "z": 7,
      "name": "TFJ_Canopy_Leaves"
    },
    {
      "x": -7,
      "y": 11,
      "z": 7,
      "name": "TFJ_Canopy_Leaves"
    },
    {
      "x": -7,
      "y": 12,
      "z": 7,
      "name": "TFJ_Canopy_Leaves"
    },
    {
      "x": -7,
      "y": 14,
      "z": 7,
      "name": "TFJ_Canopy_Leaves"
    },
    {
      "x": -7,
      "y": 16,
      "z": 7,
      "name": "TFJ_Canopy_Leaves"
    },
    {
      "x": -7,
      "y": 17,
      "z": 7,
      "name": "TFJ_Canopy_Leaves"
    },
    {
      "x": -6,
      "y": 15,
      "z": -9,
      "name": "TFJ_Canopy_Leaves"
    },
    {
      "x": -6,
      "y": 14,
      "z": -8,
      "name": "TFJ_Canopy_Leaves"
    },
    {
      "x": -6,
      "y": 15,
      "z": -8,
      "name": "TFJ_Canopy_Leaves"
    },
    {
      "x": -6,
      "y": 16,
      "z": -8,
      "name": "TFJ_Canopy_Leaves"
    },
    {
      "x": -6,
      "y": 13,
      "z": -7,
      "name": "TFJ_Canopy_Leaves"
    },
    {
      "x": -6,
      "y": 14,
      "z": -7,
      "name": "TFJ_Canopy_Leaves"
    },
    {
      "x": -6,
      "y": 15,
      "z": -7,
      "name": "TFJ_Canopy_Leaves"
    },
    {
      "x": -6,
      "y": 13,
      "z": -6,
      "name": "TFJ_Canopy_Leaves"
    },
    {
      "x": -6,
      "y": 14,
      "z": -6,
      "name": "TFJ_Titanwood_Log",
      "rotation": 5
    },
    {
      "x": -6,
      "y": 15,
      "z": -6,
      "name": "TFJ_Canopy_Leaves"
    },
    {
      "x": -6,
      "y": 19,
      "z": -6,
      "name": "TFJ_Canopy_Leaves"
    },
    {
      "x": -6,
      "y": 10,
      "z": -5,
      "name": "TFJ_Titanwood_Log",
      "rotation": 2
    },
    {
      "x": -6,
      "y": 11,
      "z": -5,
      "name": "TFJ_Titanwood_Log",
      "rotation": 11
    },
    {
      "x": -6,
      "y": 13,
      "z": -5,
      "name": "TFJ_Canopy_Leaves"
    },
    {
      "x": -6,
      "y": 18,
      "z": -5,
      "name": "TFJ_Canopy_Leaves"
    },
    {
      "x": -6,
      "y": 19,
      "z": -5,
      "name": "TFJ_Canopy_Leaves"
    },
    {
      "x": -6,
      "y": 20,
      "z": -5,
      "name": "TFJ_Canopy_Leaves"
    },
    {
      "x": -6,
      "y": 10,
      "z": -4,
      "name": "TFJ_Titanwood_Log",
      "rotation": 4
    },
    {
      "x": -6,
      "y": 13,
      "z": -4,
      "name": "TFJ_Titanwood_Log",
      "rotation": 3
    },
    {
      "x": -6,
      "y": 14,
      "z": -4,
      "name": "TFJ_Titanwood_Log",
      "rotation": 11
    },
    {
      "x": -6,
      "y": 19,
      "z": -4,
      "name": "TFJ_Canopy_Leaves"
    },
    {
      "x": -6,
      "y": 20,
      "z": -4,
      "name": "TFJ_Canopy_Leaves"
    },
    {
      "x": -6,
      "y": 21,
      "z": -4,
      "name": "TFJ_Canopy_Leaves"
    },
    {
      "x": -6,
      "y": 8,
      "z": -3,
      "name": "TFJ_Titanwood_Log"
    },
    {
      "x": -6,
      "y": 9,
      "z": -3,
      "name": "TFJ_Titanwood_Log"
    },
    {
      "x": -6,
      "y": 10,
      "z": -3,
      "name": "TFJ_Titanwood_Log"
    },
    {
      "x": -6,
      "y": 19,
      "z": -3,
      "name": "TFJ_Canopy_Leaves"
    },
    {
      "x": -6,
      "y": 20,
      "z": -3,
      "name": "TFJ_Canopy_Leaves"
    },
    {
      "x": -6,
      "y": 9,
      "z": -2,
      "name": "TFJ_Titanwood_Log"
    },
    {
      "x": -6,
      "y": 8,
      "z": -1,
      "name": "TFJ_Titanwood_Log"
    },
    {
      "x": -6,
      "y": 9,
      "z": -1,
      "name": "TFJ_Titanwood_Log"
    },
    {
      "x": -6,
      "y": 8,
      "z": 1,
      "name": "TFJ_Titanwood_Log"
    },
    {
      "x": -6,
      "y": 9,
      "z": 1,
      "name": "TFJ_Titanwood_Log"
    },
    {
      "x": -6,
      "y": 17,
      "z": 1,
      "name": "TFJ_Titanwood_Log",
      "rotation": 5
    },
    {
      "x": -6,
      "y": 20,
      "z": 1,
      "name": "TFJ_Canopy_Leaves"
    },
    {
      "x": -6,
      "y": 20,
      "z": 2,
      "name": "TFJ_Canopy_Leaves"
    },
    {
      "x": -6,
      "y": 21,
      "z": 2,
      "name": "TFJ_Canopy_Leaves"
    },
    {
      "x": -6,
      "y": 17,
      "z": 3,
      "name": "TFJ_Titanwood_Log"
    },
    {
      "x": -6,
      "y": 20,
      "z": 3,
      "name": "TFJ_Canopy_Leaves"
    },
    {
      "x": -6,
      "y": 10,
      "z": 4,
      "name": "TFJ_Titanwood_Log",
      "rotation": 5
    },
    {
      "x": -6,
      "y": 17,
      "z": 4,
      "name": "TFJ_Titanwood_Log"
    },
    {
      "x": -6,
      "y": 18,
      "z": 4,
      "name": "TFJ_Titanwood_Log",
      "rotation": 8
    },
    {
      "x": -6,
      "y": 8,
      "z": 5,
      "name": "TFJ_Canopy_Leaves"
    },
    {
      "x": -6,
      "y": 18,
      "z": 5,
      "name": "TFJ_Titanwood_Log",
      "rotation": 4
    },
    {
      "x": -6,
      "y": 9,
      "z": 6,
      "name": "TFJ_Canopy_Leaves"
    },
    {
      "x": -6,
      "y": 18,
      "z": 6,
      "name": "TFJ_Titanwood_Log",
      "rotation": 4
    },
    {
      "x": -6,
      "y": 19,
      "z": 6,
      "name": "TFJ_Canopy_Leaves"
    },
    {
      "x": -6,
      "y": 10,
      "z": 7,
      "name": "TFJ_Canopy_Leaves"
    },
    {
      "x": -6,
      "y": 12,
      "z": 7,
      "name": "TFJ_Canopy_Leaves"
    },
    {
      "x": -6,
      "y": 13,
      "z": 7,
      "name": "TFJ_Canopy_Leaves"
    },
    {
      "x": -6,
      "y": 14,
      "z": 7,
      "name": "TFJ_Canopy_Leaves"
    },
    {
      "x": -6,
      "y": 16,
      "z": 7,
      "name": "TFJ_Canopy_Leaves"
    },
    {
      "x": -6,
      "y": 17,
      "z": 7,
      "name": "TFJ_Canopy_Leaves"
    },
    {
      "x": -6,
      "y": 18,
      "z": 7,
      "name": "TFJ_Canopy_Leaves"
    },
    {
      "x": -6,
      "y": 11,
      "z": 8,
      "name": "TFJ_Canopy_Leaves"
    },
    {
      "x": -6,
      "y": 12,
      "z": 8,
      "name": "TFJ_Canopy_Leaves"
    },
    {
      "x": -6,
      "y": 13,
      "z": 8,
      "name": "TFJ_Canopy_Leaves"
    },
    {
      "x": -6,
      "y": 14,
      "z": 8,
      "name": "TFJ_Canopy_Leaves"
    },
    {
      "x": -6,
      "y": 12,
      "z": 9,
      "name": "TFJ_Canopy_Leaves"
    },
    {
      "x": -5,
      "y": 15,
      "z": -10,
      "name": "TFJ_Canopy_Leaves"
    },
    {
      "x": -5,
      "y": 10,
      "z": -9,
      "name": "TFJ_Canopy_Leaves"
    },
    {
      "x": -5,
      "y": 14,
      "z": -9,
      "name": "TFJ_Canopy_Leaves"
    },
    {
      "x": -5,
      "y": 15,
      "z": -9,
      "name": "TFJ_Canopy_Leaves"
    },
    {
      "x": -5,
      "y": 16,
      "z": -9,
      "name": "TFJ_Canopy_Leaves"
    },
    {
      "x": -5,
      "y": 9,
      "z": -8,
      "name": "TFJ_Canopy_Leaves"
    },
    {
      "x": -5,
      "y": 10,
      "z": -8,
      "name": "TFJ_Canopy_Leaves"
    },
    {
      "x": -5,
      "y": 11,
      "z": -8,
      "name": "TFJ_Canopy_Leaves"
    },
    {
      "x": -5,
      "y": 13,
      "z": -8,
      "name": "TFJ_Canopy_Leaves"
    },
    {
      "x": -5,
      "y": 14,
      "z": -8,
      "name": "TFJ_Canopy_Leaves"
    },
    {
      "x": -5,
      "y": 15,
      "z": -8,
      "name": "TFJ_Canopy_Leaves"
    },
    {
      "x": -5,
      "y": 16,
      "z": -8,
      "name": "TFJ_Canopy_Leaves"
    },
    {
      "x": -5,
      "y": 17,
      "z": -8,
      "name": "TFJ_Canopy_Leaves"
    },
    {
      "x": -5,
      "y": 11,
      "z": -7,
      "name": "TFJ_Canopy_Leaves"
    },
    {
      "x": -5,
      "y": 15,
      "z": -7,
      "name": "TFJ_Canopy_Leaves"
    },
    {
      "x": -5,
      "y": 16,
      "z": -7,
      "name": "TFJ_Canopy_Leaves"
    },
    {
      "x": -5,
      "y": 17,
      "z": -7,
      "name": "TFJ_Canopy_Leaves"
    },
    {
      "x": -5,
      "y": 14,
      "z": -6,
      "name": "TFJ_Titanwood_Log"
    },
    {
      "x": -5,
      "y": 18,
      "z": -6,
      "name": "TFJ_Canopy_Leaves"
    },
    {
      "x": -5,
      "y": 19,
      "z": -6,
      "name": "TFJ_Canopy_Leaves"
    },
    {
      "x": -5,
      "y": 20,
      "z": -6,
      "name": "TFJ_Canopy_Leaves"
    },
    {
      "x": -5,
      "y": 19,
      "z": -5,
      "name": "TFJ_Canopy_Leaves"
    },
    {
      "x": -5,
      "y": 20,
      "z": -5,
      "name": "TFJ_Canopy_Leaves"
    },
    {
      "x": -5,
      "y": 21,
      "z": -5,
      "name": "TFJ_Canopy_Leaves"
    },
    {
      "x": -5,
      "y": 13,
      "z": -4,
      "name": "TFJ_Titanwood_Log",
      "rotation": 5
    },
    {
      "x": -5,
      "y": 20,
      "z": -4,
      "name": "TFJ_Canopy_Leaves"
    },
    {
      "x": -5,
      "y": 21,
      "z": -4,
      "name": "TFJ_Canopy_Leaves"
    },
    {
      "x": -5,
      "y": 18,
      "z": -3,
      "name": "TFJ_Titanwood_Log",
      "rotation": 3
    },
    {
      "x": -5,
      "y": 19,
      "z": -3,
      "name": "TFJ_Titanwood_Log"
    },
    {
      "x": -5,
      "y": 20,
      "z": -3,
      "name": "TFJ_Canopy_Leaves"
    },
    {
      "x": -5,
      "y": 21,
      "z": -3,
      "name": "TFJ_Canopy_Leaves"
    },
    {
      "x": -5,
      "y": 20,
      "z": -2,
      "name": "TFJ_Canopy_Leaves"
    },
    {
      "x": -5,
      "y": 8,
      "z": -1,
      "name": "TFJ_Titanwood_Log"
    },
    {
      "x": -5,
      "y": 8,
      "z": 0,
      "name": "TFJ_Titanwood_Log"
    },
    {
      "x": -5,
      "y": 8,
      "z": 1,
      "name": "TFJ_Titanwood_Log"
    },
    {
      "x": -5,
      "y": 16,
      "z": 1,
      "name": "TFJ_Titanwood_Log"
    },
    {
      "x": -5,
      "y": 17,
      "z": 1,
      "name": "TFJ_Titanwood_Log"
    },
    {
      "x": -5,
      "y": 21,
      "z": 1,
      "name": "TFJ_Canopy_Leaves"
    },
    {
      "x": -5,
      "y": 17,
      "z": 2,
      "name": "TFJ_Titanwood_Log"
    },
    {
      "x": -5,
      "y": 20,
      "z": 2,
      "name": "TFJ_Canopy_Leaves"
    },
    {
      "x": -5,
      "y": 21,
      "z": 2,
      "name": "TFJ_Canopy_Leaves"
    },
    {
      "x": -5,
      "y": 22,
      "z": 2,
      "name": "TFJ_Canopy_Leaves"
    },
    {
      "x": -5,
      "y": -5,
      "z": 3,
      "name": "TFJ_Titanwood_Log",
      "rotation": 3
    },
    {
      "x": -5,
      "y": -4,
      "z": 3,
      "name": "TFJ_Titanwood_Log",
      "rotation": 9
    },
    {
      "x": -5,
      "y": 16,
      "z": 3,
      "name": "TFJ_Titanwood_Log"
    },
    {
      "x": -5,
      "y": 17,
      "z": 3,
      "name": "TFJ_Titanwood_Log"
    },
    {
      "x": -5,
      "y": 18,
      "z": 3,
      "name": "TFJ_Titanwood_Log"
    },
    {
      "x": -5,
      "y": 19,
      "z": 3,
      "name": "TFJ_Titanwood_Log"
    },
    {
      "x": -5,
      "y": 20,
      "z": 3,
      "name": "TFJ_Canopy_Leaves"
    },
    {
      "x": -5,
      "y": 21,
      "z": 3,
      "name": "TFJ_Canopy_Leaves"
    },
    {
      "x": -5,
      "y": 10,
      "z": 4,
      "name": "TFJ_Titanwood_Log"
    },
    {
      "x": -5,
      "y": 11,
      "z": 4,
      "name": "TFJ_Titanwood_Log"
    },
    {
      "x": -5,
      "y": 12,
      "z": 4,
      "name": "TFJ_Titanwood_Log",
      "rotation": 8
    },
    {
      "x": -5,
      "y": 20,
      "z": 4,
      "name": "TFJ_Canopy_Leaves"
    },
    {
      "x": -5,
      "y": 12,
      "z": 5,
      "name": "TFJ_Titanwood_Log",
      "rotation": 4
    },
    {
      "x": -5,
      "y": 19,
      "z": 5,
      "name": "TFJ_Canopy_Leaves"
    },
    {
      "x": -5,
      "y": 7,
      "z": 6,
      "name": "TFJ_Canopy_Leaves"
    },
    {
      "x": -5,
      "y": 8,
      "z": 6,
      "name": "TFJ_Canopy_Leaves"
    },
    {
      "x": -5,
      "y": 12,
      "z": 6,
      "name": "TFJ_Titanwood_Log",
      "rotation": 4
    },
    {
      "x": -5,
      "y": 18,
      "z": 6,
      "name": "TFJ_Canopy_Leaves"
    },
    {
      "x": -5,
      "y": 19,
      "z": 6,
      "name": "TFJ_Canopy_Leaves"
    },
    {
      "x": -5,
      "y": 20,
      "z": 6,
      "name": "TFJ_Canopy_Leaves"
    },
    {
      "x": -5,
      "y": 8,
      "z": 7,
      "name": "TFJ_Canopy_Leaves"
    },
    {
      "x": -5,
      "y": 9,
      "z": 7,
      "name": "TFJ_Canopy_Leaves"
    },
    {
      "x": -5,
      "y": 12,
      "z": 7,
      "name": "TFJ_Titanwood_Log"
    },
    {
      "x": -5,
      "y": 13,
      "z": 7,
      "name": "TFJ_Titanwood_Log",
      "rotation": 8
    },
    {
      "x": -5,
      "y": 17,
      "z": 7,
      "name": "TFJ_Canopy_Leaves"
    },
    {
      "x": -5,
      "y": 18,
      "z": 7,
      "name": "TFJ_Canopy_Leaves"
    },
    {
      "x": -5,
      "y": 19,
      "z": 7,
      "name": "TFJ_Canopy_Leaves"
    },
    {
      "x": -5,
      "y": 10,
      "z": 8,
      "name": "TFJ_Canopy_Leaves"
    },
    {
      "x": -5,
      "y": 11,
      "z": 8,
      "name": "TFJ_Canopy_Leaves"
    },
    {
      "x": -5,
      "y": 12,
      "z": 8,
      "name": "TFJ_Canopy_Leaves"
    },
    {
      "x": -5,
      "y": 13,
      "z": 8,
      "name": "TFJ_Canopy_Leaves"
    },
    {
      "x": -5,
      "y": 14,
      "z": 8,
      "name": "TFJ_Canopy_Leaves"
    },
    {
      "x": -5,
      "y": 18,
      "z": 8,
      "name": "TFJ_Canopy_Leaves"
    },
    {
      "x": -5,
      "y": 11,
      "z": 9,
      "name": "TFJ_Canopy_Leaves"
    },
    {
      "x": -5,
      "y": 12,
      "z": 9,
      "name": "TFJ_Canopy_Leaves"
    },
    {
      "x": -5,
      "y": 13,
      "z": 9,
      "name": "TFJ_Canopy_Leaves"
    },
    {
      "x": -5,
      "y": 12,
      "z": 10,
      "name": "TFJ_Canopy_Leaves"
    },
    {
      "x": -4,
      "y": 10,
      "z": -10,
      "name": "TFJ_Canopy_Leaves"
    },
    {
      "x": -4,
      "y": 14,
      "z": -10,
      "name": "TFJ_Canopy_Leaves"
    },
    {
      "x": -4,
      "y": 15,
      "z": -10,
      "name": "TFJ_Canopy_Leaves"
    },
    {
      "x": -4,
      "y": 16,
      "z": -10,
      "name": "TFJ_Canopy_Leaves"
    },
    {
      "x": -4,
      "y": 9,
      "z": -9,
      "name": "TFJ_Canopy_Leaves"
    },
    {
      "x": -4,
      "y": 10,
      "z": -9,
      "name": "TFJ_Canopy_Leaves"
    },
    {
      "x": -4,
      "y": 11,
      "z": -9,
      "name": "TFJ_Canopy_Leaves"
    },
    {
      "x": -4,
      "y": 12,
      "z": -9,
      "name": "TFJ_Canopy_Leaves"
    },
    {
      "x": -4,
      "y": 14,
      "z": -9,
      "name": "TFJ_Canopy_Leaves"
    },
    {
      "x": -4,
      "y": 15,
      "z": -9,
      "name": "TFJ_Canopy_Leaves"
    },
    {
      "x": -4,
      "y": 16,
      "z": -9,
      "name": "TFJ_Canopy_Leaves"
    },
    {
      "x": -4,
      "y": 17,
      "z": -9,
      "name": "TFJ_Canopy_Leaves"
    },
    {
      "x": -4,
      "y": 8,
      "z": -8,
      "name": "TFJ_Canopy_Leaves"
    },
    {
      "x": -4,
      "y": 9,
      "z": -8,
      "name": "TFJ_Canopy_Leaves"
    },
    {
      "x": -4,
      "y": 10,
      "z": -8,
      "name": "TFJ_Canopy_Leaves"
    },
    {
      "x": -4,
      "y": 11,
      "z": -8,
      "name": "TFJ_Canopy_Leaves"
    },
    {
      "x": -4,
      "y": 14,
      "z": -8,
      "name": "TFJ_Titanwood_Log",
      "rotation": 4
    },
    {
      "x": -4,
      "y": 16,
      "z": -8,
      "name": "TFJ_Canopy_Leaves"
    },
    {
      "x": -4,
      "y": 17,
      "z": -8,
      "name": "TFJ_Canopy_Leaves"
    },
    {
      "x": -4,
      "y": 18,
      "z": -8,
      "name": "TFJ_Canopy_Leaves"
    },
    {
      "x": -4,
      "y": 11,
      "z": -7,
      "name": "TFJ_Canopy_Leaves"
    },
    {
      "x": -4,
      "y": 14,
      "z": -7,
      "name": "TFJ_Titanwood_Log",
      "rotation": 4
    },
    {
      "x": -4,
      "y": 16,
      "z": -7,
      "name": "TFJ_Titanwood_Log",
      "rotation": 4
    },
    {
      "x": -4,
      "y": 14,
      "z": -6,
      "name": "TFJ_Titanwood_Log"
    },
    {
      "x": -4,
      "y": 15,
      "z": -6,
      "name": "TFJ_Titanwood_Log"
    },
    {
      "x": -4,
      "y": 16,
      "z": -6,
      "name": "TFJ_Titanwood_Log",
      "rotation": 10
    },
    {
      "x": -4,
      "y": 19,
      "z": -6,
      "name": "TFJ_Canopy_Leaves"
    },
    {
      "x": -4,
      "y": 13,
      "z": -5,
      "name": "TFJ_Titanwood_Log"
    },
    {
      "x": -4,
      "y": 14,
      "z": -5,
      "name": "TFJ_Titanwood_Log"
    },
    {
      "x": -4,
      "y": 18,
      "z": -5,
      "name": "TFJ_Titanwood_Log",
      "rotation": 2
    },
    {
      "x": -4,
      "y": 19,
      "z": -5,
      "name": "TFJ_Titanwood_Log",
      "rotation": 10
    },
    {
      "x": -4,
      "y": 20,
      "z": -5,
      "name": "TFJ_Canopy_Leaves"
    },
    {
      "x": -4,
      "y": 13,
      "z": -4,
      "name": "TFJ_Titanwood_Log",
      "rotation": 5
    },
    {
      "x": -4,
      "y": 18,
      "z": -4,
      "name": "TFJ_Titanwood_Log",
      "rotation": 4
    },
    {
      "x": -4,
      "y": 20,
      "z": -4,
      "name": "TFJ_Canopy_Leaves"
    },
    {
      "x": -4,
      "y": 21,
      "z": -4,
      "name": "TFJ_Canopy_Leaves"
    },
    {
      "x": -4,
      "y": 18,
      "z": -3,
      "name": "TFJ_Titanwood_Log"
    },
    {
      "x": -4,
      "y": 21,
      "z": 0,
      "name": "TFJ_Canopy_Leaves"
    },
    {
      "x": -4,
      "y": 7,
      "z": 1,
      "name": "TFJ_Titanwood_Log"
    },
    {
      "x": -4,
      "y": 8,
      "z": 1,
      "name": "TFJ_Titanwood_Log"
    },
    {
      "x": -4,
      "y": 16,
      "z": 1,
      "name": "TFJ_Titanwood_Log"
    },
    {
      "x": -4,
      "y": 17,
      "z": 1,
      "name": "TFJ_Titanwood_Log"
    },
    {
      "x": -4,
      "y": 18,
      "z": 1,
      "name": "TFJ_Titanwood_Log"
    },
    {
      "x": -4,
      "y": 19,
      "z": 1,
      "name": "TFJ_Titanwood_Log"
    },
    {
      "x": -4,
      "y": 20,
      "z": 1,
      "name": "TFJ_Titanwood_Log"
    },
    {
      "x": -4,
      "y": 21,
      "z": 1,
      "name": "TFJ_Titanwood_Log"
    },
    {
      "x": -4,
      "y": 22,
      "z": 1,
      "name": "TFJ_Canopy_Leaves"
    },
    {
      "x": -4,
      "y": 7,
      "z": 2,
      "name": "TFJ_Titanwood_Log"
    },
    {
      "x": -4,
      "y": 8,
      "z": 2,
      "name": "TFJ_Titanwood_Log"
    },
    {
      "x": -4,
      "y": 21,
      "z": 2,
      "name": "TFJ_Canopy_Leaves"
    },
    {
      "x": -4,
      "y": 22,
      "z": 2,
      "name": "TFJ_Canopy_Leaves"
    },
    {
      "x": -4,
      "y": -5,
      "z": 3,
      "name": "TFJ_Titanwood_Log",
      "rotation": 5
    },
    {
      "x": -4,
      "y": -4,
      "z": 3,
      "name": "TFJ_Titanwood_Log",
      "rotation": 1
    },
    {
      "x": -4,
      "y": -3,
      "z": 3,
      "name": "TFJ_Titanwood_Log",
      "rotation": 11
    },
    {
      "x": -4,
      "y": 8,
      "z": 3,
      "name": "TFJ_Titanwood_Log"
    },
    {
      "x": -4,
      "y": 9,
      "z": 3,
      "name": "TFJ_Titanwood_Log"
    },
    {
      "x": -4,
      "y": 10,
      "z": 3,
      "name": "TFJ_Titanwood_Log"
    },
    {
      "x": -4,
      "y": 21,
      "z": 3,
      "name": "TFJ_Canopy_Leaves"
    },
    {
      "x": -4,
      "y": 22,
      "z": 3,
      "name": "TFJ_Canopy_Leaves"
    },
    {
      "x": -4,
      "y": 9,
      "z": 4,
      "name": "TFJ_Titanwood_Log",
      "rotation": 4
    },
    {
      "x": -4,
      "y": 20,
      "z": 4,
      "name": "TFJ_Canopy_Leaves"
    },
    {
      "x": -4,
      "y": 21,
      "z": 4,
      "name": "TFJ_Canopy_Leaves"
    },
    {
      "x": -4,
      "y": 9,
      "z": 5,
      "name": "TFJ_Titanwood_Log",
      "rotation": 4
    },
    {
      "x": -4,
      "y": 20,
      "z": 5,
      "name": "TFJ_Canopy_Leaves"
    },
    {
      "x": -4,
      "y": 7,
      "z": 6,
      "name": "TFJ_Canopy_Leaves"
    },
    {
      "x": -4,
      "y": 9,
      "z": 6,
      "name": "TFJ_Titanwood_Log",
      "rotation": 4
    },
    {
      "x": -4,
      "y": 19,
      "z": 6,
      "name": "TFJ_Canopy_Leaves"
    },
    {
      "x": -4,
      "y": 20,
      "z": 6,
      "name": "TFJ_Canopy_Leaves"
    },
    {
      "x": -4,
      "y": 7,
      "z": 7,
      "name": "TFJ_Canopy_Leaves"
    },
    {
      "x": -4,
      "y": 8,
      "z": 7,
      "name": "TFJ_Canopy_Leaves"
    },
    {
      "x": -4,
      "y": 9,
      "z": 7,
      "name": "TFJ_Titanwood_Log"
    },
    {
      "x": -4,
      "y": 10,
      "z": 7,
      "name": "TFJ_Titanwood_Log",
      "rotation": 8
    },
    {
      "x": -4,
      "y": 18,
      "z": 7,
      "name": "TFJ_Canopy_Leaves"
    },
    {
      "x": -4,
      "y": 20,
      "z": 7,
      "name": "TFJ_Canopy_Leaves"
    },
    {
      "x": -4,
      "y": 8,
      "z": 8,
      "name": "TFJ_Canopy_Leaves"
    },
    {
      "x": -4,
      "y": 9,
      "z": 8,
      "name": "TFJ_Canopy_Leaves"
    },
    {
      "x": -4,
      "y": 10,
      "z": 8,
      "name": "TFJ_Canopy_Leaves"
    },
    {
      "x": -4,
      "y": 17,
      "z": 8,
      "name": "TFJ_Canopy_Leaves"
    },
    {
      "x": -4,
      "y": 18,
      "z": 8,
      "name": "TFJ_Canopy_Leaves"
    },
    {
      "x": -4,
      "y": 19,
      "z": 8,
      "name": "TFJ_Canopy_Leaves"
    },
    {
      "x": -4,
      "y": 10,
      "z": 9,
      "name": "TFJ_Canopy_Leaves"
    },
    {
      "x": -4,
      "y": 11,
      "z": 9,
      "name": "TFJ_Canopy_Leaves"
    },
    {
      "x": -4,
      "y": 12,
      "z": 9,
      "name": "TFJ_Canopy_Leaves"
    },
    {
      "x": -4,
      "y": 13,
      "z": 9,
      "name": "TFJ_Canopy_Leaves"
    },
    {
      "x": -4,
      "y": 15,
      "z": 9,
      "name": "TFJ_Canopy_Leaves"
    },
    {
      "x": -4,
      "y": 11,
      "z": 10,
      "name": "TFJ_Canopy_Leaves"
    },
    {
      "x": -4,
      "y": 12,
      "z": 10,
      "name": "TFJ_Canopy_Leaves"
    },
    {
      "x": -4,
      "y": 13,
      "z": 10,
      "name": "TFJ_Canopy_Leaves"
    },
    {
      "x": -4,
      "y": 14,
      "z": 10,
      "name": "TFJ_Canopy_Leaves"
    },
    {
      "x": -3,
      "y": 9,
      "z": -10,
      "name": "TFJ_Canopy_Leaves"
    },
    {
      "x": -3,
      "y": 10,
      "z": -10,
      "name": "TFJ_Canopy_Leaves"
    },
    {
      "x": -3,
      "y": 11,
      "z": -10,
      "name": "TFJ_Canopy_Leaves"
    },
    {
      "x": -3,
      "y": 15,
      "z": -10,
      "name": "TFJ_Canopy_Leaves"
    },
    {
      "x": -3,
      "y": 8,
      "z": -9,
      "name": "TFJ_Canopy_Leaves"
    },
    {
      "x": -3,
      "y": 10,
      "z": -9,
      "name": "TFJ_Canopy_Leaves"
    },
    {
      "x": -3,
      "y": 11,
      "z": -9,
      "name": "TFJ_Titanwood_Log",
      "rotation": 4
    },
    {
      "x": -3,
      "y": 12,
      "z": -9,
      "name": "TFJ_Canopy_Leaves"
    },
    {
      "x": -3,
      "y": 14,
      "z": -9,
      "name": "TFJ_Canopy_Leaves"
    },
    {
      "x": -3,
      "y": 15,
      "z": -9,
      "name": "TFJ_Canopy_Leaves"
    },
    {
      "x": -3,
      "y": 16,
      "z": -9,
      "name": "TFJ_Canopy_Leaves"
    },
    {
      "x": -3,
      "y": 17,
      "z": -9,
      "name": "TFJ_Canopy_Leaves"
    },
    {
      "x": -3,
      "y": 8,
      "z": -8,
      "name": "TFJ_Canopy_Leaves"
    },
    {
      "x": -3,
      "y": 9,
      "z": -8,
      "name": "TFJ_Canopy_Leaves"
    },
    {
      "x": -3,
      "y": 10,
      "z": -8,
      "name": "TFJ_Titanwood_Log",
      "rotation": 3
    },
    {
      "x": -3,
      "y": 11,
      "z": -8,
      "name": "TFJ_Titanwood_Log",
      "rotation": 10
    },
    {
      "x": -3,
      "y": 12,
      "z": -8,
      "name": "TFJ_Canopy_Leaves"
    },
    {
      "x": -3,
      "y": 17,
      "z": -8,
      "name": "TFJ_Canopy_Leaves"
    },
    {
      "x": -3,
      "y": 8,
      "z": -7,
      "name": "TFJ_Canopy_Leaves"
    },
    {
      "x": -3,
      "y": 19,
      "z": -7,
      "name": "TFJ_Canopy_Leaves"
    },
    {
      "x": -3,
      "y": 19,
      "z": -6,
      "name": "TFJ_Canopy_Leaves"
    },
    {
      "x": -3,
      "y": 20,
      "z": -6,
      "name": "TFJ_Canopy_Leaves"
    },
    {
      "x": -3,
      "y": 13,
      "z": -5,
      "name": "TFJ_Titanwood_Log"
    },
    {
      "x": -3,
      "y": 19,
      "z": -5,
      "name": "TFJ_Canopy_Leaves"
    },
    {
      "x": -3,
      "y": 13,
      "z": -4,
      "name": "TFJ_Titanwood_Log"
    },
    {
      "x": -3,
      "y": 11,
      "z": -3,
      "name": "TFJ_Titanwood_Log"
    },
    {
      "x": -3,
      "y": 12,
      "z": -3,
      "name": "TFJ_Titanwood_Log"
    },
    {
      "x": -3,
      "y": 13,
      "z": -3,
      "name": "TFJ_Titanwood_Log"
    },
    {
      "x": -3,
      "y": 16,
      "z": -3,
      "name": "TFJ_Titanwood_Log"
    },
    {
      "x": -3,
      "y": 17,
      "z": -3,
      "name": "TFJ_Titanwood_Log"
    },
    {
      "x": -3,
      "y": 18,
      "z": -3,
      "name": "TFJ_Titanwood_Log"
    },
    {
      "x": -3,
      "y": 21,
      "z": -3,
      "name": "TFJ_Canopy_Leaves"
    },
    {
      "x": -3,
      "y": 18,
      "z": -2,
      "name": "TFJ_Titanwood_Log"
    },
    {
      "x": -3,
      "y": 21,
      "z": -2,
      "name": "TFJ_Canopy_Leaves"
    },
    {
      "x": -3,
      "y": -5,
      "z": -1,
      "name": "TFJ_Titanwood_Log"
    },
    {
      "x": -3,
      "y": -4,
      "z": -1,
      "name": "TFJ_Titanwood_Log"
    },
    {
      "x": -3,
      "y": -3,
      "z": -1,
      "name": "TFJ_Titanwood_Log"
    },
    {
      "x": -3,
      "y": 21,
      "z": -1,
      "name": "TFJ_Canopy_Leaves"
    },
    {
      "x": -3,
      "y": 22,
      "z": -1,
      "name": "TFJ_Canopy_Leaves"
    },
    {
      "x": -3,
      "y": 23,
      "z": -1,
      "name": "TFJ_Canopy_Leaves"
    },
    {
      "x": -3,
      "y": 15,
      "z": 0,
      "name": "TFJ_Titanwood_Log"
    },
    {
      "x": -3,
      "y": 16,
      "z": 0,
      "name": "TFJ_Titanwood_Log"
    },
    {
      "x": -3,
      "y": 21,
      "z": 0,
      "name": "TFJ_Canopy_Leaves"
    },
    {
      "x": -3,
      "y": 22,
      "z": 0,
      "name": "TFJ_Canopy_Leaves"
    },
    {
      "x": -3,
      "y": 16,
      "z": 1,
      "name": "TFJ_Titanwood_Log"
    },
    {
      "x": -3,
      "y": 21,
      "z": 1,
      "name": "TFJ_Canopy_Leaves"
    },
    {
      "x": -3,
      "y": 22,
      "z": 1,
      "name": "TFJ_Canopy_Leaves"
    },
    {
      "x": -3,
      "y": 6,
      "z": 2,
      "name": "TFJ_Titanwood_Log"
    },
    {
      "x": -3,
      "y": 7,
      "z": 2,
      "name": "TFJ_Titanwood_Log"
    },
    {
      "x": -3,
      "y": 21,
      "z": 2,
      "name": "TFJ_Canopy_Leaves"
    },
    {
      "x": -3,
      "y": 22,
      "z": 2,
      "name": "TFJ_Canopy_Leaves"
    },
    {
      "x": -3,
      "y": -5,
      "z": 3,
      "name": "TFJ_Titanwood_Log",
      "rotation": 1
    },
    {
      "x": -3,
      "y": -4,
      "z": 3,
      "name": "TFJ_Titanwood_Log"
    },
    {
      "x": -3,
      "y": -3,
      "z": 3,
      "name": "TFJ_Titanwood_Log",
      "rotation": 9
    },
    {
      "x": -3,
      "y": 21,
      "z": 3,
      "name": "TFJ_Canopy_Leaves"
    },
    {
      "x": -3,
      "y": 6,
      "z": 5,
      "name": "TFJ_Canopy_Leaves"
    },
    {
      "x": -3,
      "y": 7,
      "z": 6,
      "name": "TFJ_Canopy_Leaves"
    },
    {
      "x": -3,
      "y": 14,
      "z": 6,
      "name": "TFJ_Titanwood_Log"
    },
    {
      "x": -3,
      "y": 15,
      "z": 6,
      "name": "TFJ_Titanwood_Log"
    },
    {
      "x": -3,
      "y": 16,
      "z": 6,
      "name": "TFJ_Titanwood_Log"
    },
    {
      "x": -3,
      "y": 17,
      "z": 6,
      "name": "TFJ_Titanwood_Log",
      "rotation": 8
    },
    {
      "x": -3,
      "y": 19,
      "z": 6,
      "name": "TFJ_Canopy_Leaves"
    },
    {
      "x": -3,
      "y": 20,
      "z": 6,
      "name": "TFJ_Canopy_Leaves"
    },
    {
      "x": -3,
      "y": 7,
      "z": 7,
      "name": "TFJ_Canopy_Leaves"
    },
    {
      "x": -3,
      "y": 8,
      "z": 7,
      "name": "TFJ_Canopy_Leaves"
    },
    {
      "x": -3,
      "y": 10,
      "z": 7,
      "name": "TFJ_Canopy_Leaves"
    },
    {
      "x": -3,
      "y": 14,
      "z": 7,
      "name": "TFJ_Titanwood_Log",
      "rotation": 4
    },
    {
      "x": -3,
      "y": 17,
      "z": 7,
      "name": "TFJ_Titanwood_Log"
    },
    {
      "x": -3,
      "y": 18,
      "z": 7,
      "name": "TFJ_Titanwood_Log",
      "rotation": 11
    },
    {
      "x": -3,
      "y": 19,
      "z": 7,
      "name": "TFJ_Canopy_Leaves"
    },
    {
      "x": -3,
      "y": 7,
      "z": 8,
      "name": "TFJ_Canopy_Leaves"
    },
    {
      "x": -3,
      "y": 8,
      "z": 8,
      "name": "TFJ_Canopy_Leaves"
    },
    {
      "x": -3,
      "y": 9,
      "z": 8,
      "name": "TFJ_Canopy_Leaves"
    },
    {
      "x": -3,
      "y": 10,
      "z": 8,
      "name": "TFJ_Canopy_Leaves"
    },
    {
      "x": -3,
      "y": 14,
      "z": 8,
      "name": "TFJ_Titanwood_Log",
      "rotation": 4
    },
    {
      "x": -3,
      "y": 18,
      "z": 8,
      "name": "TFJ_Canopy_Leaves"
    },
    {
      "x": -3,
      "y": 11,
      "z": 9,
      "name": "TFJ_Canopy_Leaves"
    },
    {
      "x": -3,
      "y": 12,
      "z": 9,
      "name": "TFJ_Canopy_Leaves"
    },
    {
      "x": -3,
      "y": 13,
      "z": 9,
      "name": "TFJ_Canopy_Leaves"
    },
    {
      "x": -3,
      "y": 14,
      "z": 9,
      "name": "TFJ_Canopy_Leaves"
    },
    {
      "x": -3,
      "y": 16,
      "z": 9,
      "name": "TFJ_Canopy_Leaves"
    },
    {
      "x": -3,
      "y": 12,
      "z": 10,
      "name": "TFJ_Canopy_Leaves"
    },
    {
      "x": -2,
      "y": 10,
      "z": -10,
      "name": "TFJ_Canopy_Leaves"
    },
    {
      "x": -2,
      "y": 11,
      "z": -10,
      "name": "TFJ_Canopy_Leaves"
    },
    {
      "x": -2,
      "y": 9,
      "z": -9,
      "name": "TFJ_Canopy_Leaves"
    },
    {
      "x": -2,
      "y": 10,
      "z": -9,
      "name": "TFJ_Canopy_Leaves"
    },
    {
      "x": -2,
      "y": 11,
      "z": -9,
      "name": "TFJ_Canopy_Leaves"
    },
    {
      "x": -2,
      "y": 12,
      "z": -9,
      "name": "TFJ_Canopy_Leaves"
    },
    {
      "x": -2,
      "y": 13,
      "z": -9,
      "name": "TFJ_Canopy_Leaves"
    },
    {
      "x": -2,
      "y": 15,
      "z": -9,
      "name": "TFJ_Canopy_Leaves"
    },
    {
      "x": -2,
      "y": 16,
      "z": -9,
      "name": "TFJ_Canopy_Leaves"
    },
    {
      "x": -2,
      "y": 9,
      "z": -8,
      "name": "TFJ_Titanwood_Log",
      "rotation": 2
    },
    {
      "x": -2,
      "y": 10,
      "z": -8,
      "name": "TFJ_Titanwood_Log",
      "rotation": 11
    },
    {
      "x": -2,
      "y": 11,
      "z": -8,
      "name": "TFJ_Canopy_Leaves"
    },
    {
      "x": -2,
      "y": 9,
      "z": -7,
      "name": "TFJ_Titanwood_Log",
      "rotation": 4
    },
    {
      "x": -2,
      "y": 8,
      "z": -6,
      "name": "TFJ_Titanwood_Log",
      "rotation": 3
    },
    {
      "x": -2,
      "y": 9,
      "z": -6,
      "name": "TFJ_Titanwood_Log",
      "rotation": 10
    },
    {
      "x": -2,
      "y": 19,
      "z": -6,
      "name": "TFJ_Canopy_Leaves"
    },
    {
      "x": -2,
      "y": 21,
      "z": -4,
      "name": "TFJ_Canopy_Leaves"
    },
    {
      "x": -2,
      "y": 22,
      "z": -4,
      "name": "TFJ_Canopy_Leaves"
    },
    {
      "x": -2,
      "y": 12,
      "z": -3,
      "name": "TFJ_Titanwood_Log"
    },
    {
      "x": -2,
      "y": 13,
      "z": -3,
      "name": "TFJ_Titanwood_Log"
    },
    {
      "x": -2,
      "y": 14,
      "z": -3,
      "name": "TFJ_Titanwood_Log"
    },
    {
      "x": -2,
      "y": 15,
      "z": -3,
      "name": "TFJ_Titanwood_Log"
    },
    {
      "x": -2,
      "y": 16,
      "z": -3,
      "name": "TFJ_Titanwood_Log"
    },
    {
      "x": -2,
      "y": 21,
      "z": -3,
      "name": "TFJ_Canopy_Leaves"
    },
    {
      "x": -2,
      "y": 22,
      "z": -3,
      "name": "TFJ_Canopy_Leaves"
    },
    {
      "x": -2,
      "y": 12,
      "z": -2,
      "name": "TFJ_Titanwood_Log"
    },
    {
      "x": -2,
      "y": 18,
      "z": -2,
      "name": "TFJ_Titanwood_Log",
      "rotation": 1
    },
    {
      "x": -2,
      "y": 19,
      "z": -2,
      "name": "TFJ_Titanwood_Log"
    },
    {
      "x": -2,
      "y": 20,
      "z": -2,
      "name": "TFJ_Titanwood_Log",
      "rotation": 9
    },
    {
      "x": -2,
      "y": 22,
      "z": -2,
      "name": "TFJ_Canopy_Leaves"
    },
    {
      "x": -2,
      "y": -3,
      "z": -1,
      "name": "TFJ_Titanwood_Log"
    },
    {
      "x": -2,
      "y": -2,
      "z": -1,
      "name": "TFJ_Titanwood_Log"
    },
    {
      "x": -2,
      "y": 5,
      "z": -1,
      "name": "Plant_Crop_Mushroom_Shelve_Brown"
    },
    {
      "x": -2,
      "y": 22,
      "z": -1,
      "name": "TFJ_Canopy_Leaves"
    },
    {
      "x": -2,
      "y": 23,
      "z": -1,
      "name": "TFJ_Canopy_Leaves"
    },
    {
      "x": -2,
      "y": 6,
      "z": 0,
      "name": "Plant_Crop_Mushroom_Shelve_Brown"
    },
    {
      "x": -2,
      "y": 7,
      "z": 0,
      "name": "Plant_Crop_Mushroom_Shelve_Brown"
    },
    {
      "x": -2,
      "y": 14,
      "z": 0,
      "name": "TFJ_Titanwood_Log"
    },
    {
      "x": -2,
      "y": 15,
      "z": 0,
      "name": "TFJ_Titanwood_Log"
    },
    {
      "x": -2,
      "y": 19,
      "z": 0,
      "name": "TFJ_Titanwood_Log",
      "rotation": 3
    },
    {
      "x": -2,
      "y": 20,
      "z": 0,
      "name": "TFJ_Titanwood_Log"
    },
    {
      "x": -2,
      "y": 21,
      "z": 0,
      "name": "TFJ_Titanwood_Log"
    },
    {
      "x": -2,
      "y": 22,
      "z": 0,
      "name": "TFJ_Titanwood_Log"
    },
    {
      "x": -2,
      "y": 23,
      "z": 0,
      "name": "TFJ_Canopy_Leaves"
    },
    {
      "x": -2,
      "y": 6,
      "z": 1,
      "name": "TFJ_Titanwood_Log"
    },
    {
      "x": -2,
      "y": 7,
      "z": 1,
      "name": "TFJ_Titanwood_Log"
    },
    {
      "x": -2,
      "y": 22,
      "z": 1,
      "name": "TFJ_Canopy_Leaves"
    },
    {
      "x": -2,
      "y": 23,
      "z": 1,
      "name": "TFJ_Canopy_Leaves"
    },
    {
      "x": -2,
      "y": -2,
      "z": 2,
      "name": "TFJ_Titanwood_Log"
    },
    {
      "x": -2,
      "y": -1,
      "z": 2,
      "name": "TFJ_Titanwood_Log"
    },
    {
      "x": -2,
      "y": 7,
      "z": 2,
      "name": "TFJ_Titanwood_Log"
    },
    {
      "x": -2,
      "y": 24,
      "z": 2,
      "name": "TFJ_Canopy_Leaves"
    },
    {
      "x": -2,
      "y": -5,
      "z": 3,
      "name": "TFJ_Titanwood_Log"
    },
    {
      "x": -2,
      "y": -4,
      "z": 3,
      "name": "TFJ_Titanwood_Log"
    },
    {
      "x": -2,
      "y": -3,
      "z": 3,
      "name": "TFJ_Titanwood_Log"
    },
    {
      "x": -2,
      "y": -2,
      "z": 3,
      "name": "TFJ_Titanwood_Log"
    },
    {
      "x": -2,
      "y": 23,
      "z": 3,
      "name": "TFJ_Canopy_Leaves"
    },
    {
      "x": -2,
      "y": 6,
      "z": 6,
      "name": "TFJ_Canopy_Leaves"
    },
    {
      "x": -2,
      "y": 14,
      "z": 6,
      "name": "TFJ_Titanwood_Log"
    },
    {
      "x": -2,
      "y": 7,
      "z": 7,
      "name": "TFJ_Canopy_Leaves"
    },
    {
      "x": -2,
      "y": 19,
      "z": 7,
      "name": "TFJ_Canopy_Leaves"
    },
    {
      "x": -2,
      "y": 8,
      "z": 8,
      "name": "TFJ_Canopy_Leaves"
    },
    {
      "x": -2,
      "y": 18,
      "z": 8,
      "name": "TFJ_Canopy_Leaves"
    },
    {
      "x": -2,
      "y": 14,
      "z": 9,
      "name": "TFJ_Canopy_Leaves"
    },
    {
      "x": -2,
      "y": 13,
      "z": 10,
      "name": "TFJ_Canopy_Leaves"
    },
    {
      "x": -2,
      "y": 14,
      "z": 10,
      "name": "TFJ_Canopy_Leaves"
    },
    {
      "x": -2,
      "y": 15,
      "z": 10,
      "name": "TFJ_Canopy_Leaves"
    },
    {
      "x": -2,
      "y": 13,
      "z": 11,
      "name": "TFJ_Canopy_Leaves"
    },
    {
      "x": -1,
      "y": 11,
      "z": -10,
      "name": "TFJ_Canopy_Leaves"
    },
    {
      "x": -1,
      "y": 12,
      "z": -10,
      "name": "TFJ_Canopy_Leaves"
    },
    {
      "x": -1,
      "y": 8,
      "z": -9,
      "name": "TFJ_Canopy_Leaves"
    },
    {
      "x": -1,
      "y": 10,
      "z": -9,
      "name": "TFJ_Canopy_Leaves"
    },
    {
      "x": -1,
      "y": 11,
      "z": -9,
      "name": "TFJ_Canopy_Leaves"
    },
    {
      "x": -1,
      "y": 8,
      "z": -8,
      "name": "TFJ_Canopy_Leaves"
    },
    {
      "x": -1,
      "y": 17,
      "z": -7,
      "name": "TFJ_Canopy_Leaves"
    },
    {
      "x": -1,
      "y": 8,
      "z": -6,
      "name": "TFJ_Titanwood_Log"
    },
    {
      "x": -1,
      "y": -5,
      "z": -4,
      "name": "TFJ_Titanwood_Log",
      "rotation": 3
    },
    {
      "x": -1,
      "y": -4,
      "z": -4,
      "name": "TFJ_Titanwood_Log",
      "rotation": 9
    },
    {
      "x": -1,
      "y": -3,
      "z": -4,
      "name": "TFJ_Titanwood_Log",
      "rotation": 3
    },
    {
      "x": -1,
      "y": -2,
      "z": -4,
      "name": "TFJ_Titanwood_Log"
    },
    {
      "x": -1,
      "y": 22,
      "z": -4,
      "name": "TFJ_Canopy_Leaves"
    },
    {
      "x": -1,
      "y": 23,
      "z": -4,
      "name": "TFJ_Canopy_Leaves"
    },
    {
      "x": -1,
      "y": -2,
      "z": -3,
      "name": "TFJ_Titanwood_Log"
    },
    {
      "x": -1,
      "y": -1,
      "z": -3,
      "name": "TFJ_Titanwood_Log"
    },
    {
      "x": -1,
      "y": 21,
      "z": -3,
      "name": "TFJ_Canopy_Leaves"
    },
    {
      "x": -1,
      "y": 22,
      "z": -3,
      "name": "TFJ_Canopy_Leaves"
    },
    {
      "x": -1,
      "y": 5,
      "z": -2,
      "name": "Plant_Crop_Mushroom_Shelve_Brown"
    },
    {
      "x": -1,
      "y": 6,
      "z": -2,
      "name": "Plant_Crop_Mushroom_Shelve_Brown"
    },
    {
      "x": -1,
      "y": 7,
      "z": -2,
      "name": "Plant_Crop_Mushroom_Shelve_Brown"
    },
    {
      "x": -1,
      "y": 11,
      "z": -2,
      "name": "TFJ_Titanwood_Log"
    },
    {
      "x": -1,
      "y": 12,
      "z": -2,
      "name": "TFJ_Titanwood_Log"
    },
    {
      "x": -1,
      "y": 20,
      "z": -2,
      "name": "TFJ_Titanwood_Log",
      "rotation": 1
    },
    {
      "x": -1,
      "y": 21,
      "z": -2,
      "name": "TFJ_Titanwood_Log"
    },
    {
      "x": -1,
      "y": 22,
      "z": -2,
      "name": "TFJ_Canopy_Leaves"
    },
    {
      "x": -1,
      "y": 23,
      "z": -2,
      "name": "TFJ_Canopy_Leaves"
    },
    {
      "x": -1,
      "y": 24,
      "z": -2,
      "name": "TFJ_Canopy_Leaves"
    },
    {
      "x": -1,
      "y": -3,
      "z": -1,
      "name": "TFJ_Titanwood_Log"
    },
    {
      "x": -1,
      "y": -2,
      "z": -1,
      "name": "TFJ_Titanwood_Log"
    },
    {
      "x": -1,
      "y": -1,
      "z": -1,
      "name": "TFJ_Titanwood_Log"
    },
    {
      "x": -1,
      "y": 3,
      "z": -1,
      "name": "TFJ_Titanwood_Log"
    },
    {
      "x": -1,
      "y": 4,
      "z": -1,
      "name": "TFJ_Titanwood_Log"
    },
    {
      "x": -1,
      "y": 5,
      "z": -1,
      "name": "TFJ_Titanwood_Log"
    },
    {
      "x": -1,
      "y": 6,
      "z": -1,
      "name": "Plant_Crop_Mushroom_Shelve_Brown"
    },
    {
      "x": -1,
      "y": 7,
      "z": -1,
      "name": "Plant_Crop_Mushroom_Shelve_Brown"
    },
    {
      "x": -1,
      "y": 10,
      "z": -1,
      "name": "TFJ_Titanwood_Log"
    },
    {
      "x": -1,
      "y": 11,
      "z": -1,
      "name": "TFJ_Titanwood_Log"
    },
    {
      "x": -1,
      "y": 12,
      "z": -1,
      "name": "TFJ_Titanwood_Log"
    },
    {
      "x": -1,
      "y": 22,
      "z": -1,
      "name": "TFJ_Canopy_Leaves"
    },
    {
      "x": -1,
      "y": 23,
      "z": -1,
      "name": "TFJ_Canopy_Leaves"
    },
    {
      "x": -1,
      "y": -2,
      "z": 0,
      "name": "TFJ_Titanwood_Log"
    },
    {
      "x": -1,
      "y": -1,
      "z": 0,
      "name": "TFJ_Titanwood_Log"
    },
    {
      "x": -1,
      "y": 0,
      "z": 0,
      "name": "TFJ_Titanwood_Log"
    },
    {
      "x": -1,
      "y": 1,
      "z": 0,
      "name": "TFJ_Titanwood_Log"
    },
    {
      "x": -1,
      "y": 2,
      "z": 0,
      "name": "TFJ_Titanwood_Log"
    },
    {
      "x": -1,
      "y": 3,
      "z": 0,
      "name": "TFJ_Titanwood_Log"
    },
    {
      "x": -1,
      "y": 4,
      "z": 0,
      "name": "TFJ_Titanwood_Log"
    },
    {
      "x": -1,
      "y": 5,
      "z": 0,
      "name": "TFJ_Titanwood_Log"
    },
    {
      "x": -1,
      "y": 6,
      "z": 0,
      "name": "TFJ_Titanwood_Log"
    },
    {
      "x": -1,
      "y": 7,
      "z": 0,
      "name": "TFJ_Titanwood_Log"
    },
    {
      "x": -1,
      "y": 8,
      "z": 0,
      "name": "TFJ_Titanwood_Log"
    },
    {
      "x": -1,
      "y": 9,
      "z": 0,
      "name": "TFJ_Titanwood_Log"
    },
    {
      "x": -1,
      "y": 10,
      "z": 0,
      "name": "TFJ_Titanwood_Log"
    },
    {
      "x": -1,
      "y": 11,
      "z": 0,
      "name": "TFJ_Titanwood_Log"
    },
    {
      "x": -1,
      "y": 12,
      "z": 0,
      "name": "TFJ_Titanwood_Log"
    },
    {
      "x": -1,
      "y": 13,
      "z": 0,
      "name": "TFJ_Titanwood_Log"
    },
    {
      "x": -1,
      "y": 14,
      "z": 0,
      "name": "TFJ_Titanwood_Log"
    },
    {
      "x": -1,
      "y": 15,
      "z": 0,
      "name": "TFJ_Titanwood_Log"
    },
    {
      "x": -1,
      "y": 16,
      "z": 0,
      "name": "TFJ_Titanwood_Log"
    },
    {
      "x": -1,
      "y": 17,
      "z": 0,
      "name": "TFJ_Titanwood_Log"
    },
    {
      "x": -1,
      "y": 19,
      "z": 0,
      "name": "TFJ_Titanwood_Log",
      "rotation": 5
    },
    {
      "x": -1,
      "y": 22,
      "z": 0,
      "name": "TFJ_Canopy_Leaves"
    },
    {
      "x": -1,
      "y": 23,
      "z": 0,
      "name": "TFJ_Canopy_Leaves"
    },
    {
      "x": -1,
      "y": 24,
      "z": 0,
      "name": "TFJ_Canopy_Leaves"
    },
    {
      "x": -1,
      "y": -2,
      "z": 1,
      "name": "TFJ_Titanwood_Log"
    },
    {
      "x": -1,
      "y": -1,
      "z": 1,
      "name": "TFJ_Titanwood_Log"
    },
    {
      "x": -1,
      "y": 0,
      "z": 1,
      "name": "TFJ_Titanwood_Log"
    },
    {
      "x": -1,
      "y": 3,
      "z": 1,
      "name": "Plant_Crop_Mushroom_Shelve_Brown"
    },
    {
      "x": -1,
      "y": 4,
      "z": 1,
      "name": "TFJ_Titanwood_Log"
    },
    {
      "x": -1,
      "y": 5,
      "z": 1,
      "name": "TFJ_Titanwood_Log"
    },
    {
      "x": -1,
      "y": 6,
      "z": 1,
      "name": "TFJ_Titanwood_Log"
    },
    {
      "x": -1,
      "y": 7,
      "z": 1,
      "name": "TFJ_Titanwood_Log"
    },
    {
      "x": -1,
      "y": 16,
      "z": 1,
      "name": "TFJ_Titanwood_Log"
    },
    {
      "x": -1,
      "y": 22,
      "z": 1,
      "name": "TFJ_Canopy_Leaves"
    },
    {
      "x": -1,
      "y": 24,
      "z": 1,
      "name": "TFJ_Canopy_Leaves"
    },
    {
      "x": -1,
      "y": 4,
      "z": 2,
      "name": "Plant_Crop_Mushroom_Shelve_Brown"
    },
    {
      "x": -1,
      "y": 22,
      "z": 2,
      "name": "TFJ_Canopy_Leaves"
    },
    {
      "x": -1,
      "y": 24,
      "z": 2,
      "name": "TFJ_Canopy_Leaves"
    },
    {
      "x": -1,
      "y": 22,
      "z": 3,
      "name": "TFJ_Canopy_Leaves"
    },
    {
      "x": -1,
      "y": 23,
      "z": 3,
      "name": "TFJ_Canopy_Leaves"
    },
    {
      "x": -1,
      "y": 24,
      "z": 3,
      "name": "TFJ_Canopy_Leaves"
    },
    {
      "x": -1,
      "y": 21,
      "z": 4,
      "name": "TFJ_Canopy_Leaves"
    },
    {
      "x": -1,
      "y": 14,
      "z": 5,
      "name": "TFJ_Titanwood_Log"
    },
    {
      "x": -1,
      "y": 14,
      "z": 6,
      "name": "TFJ_Titanwood_Log"
    },
    {
      "x": -1,
      "y": 21,
      "z": 7,
      "name": "TFJ_Canopy_Leaves"
    },
    {
      "x": -1,
      "y": 19,
      "z": 8,
      "name": "TFJ_Canopy_Leaves"
    },
    {
      "x": -1,
      "y": 18,
      "z": 9,
      "name": "TFJ_Canopy_Leaves"
    },
    {
      "x": -1,
      "y": 12,
      "z": 10,
      "name": "TFJ_Canopy_Leaves"
    },
    {
      "x": -1,
      "y": 13,
      "z": 10,
      "name": "TFJ_Canopy_Leaves"
    },
    {
      "x": -1,
      "y": 14,
      "z": 10,
      "name": "TFJ_Canopy_Leaves"
    },
    {
      "x": -1,
      "y": 15,
      "z": 10,
      "name": "TFJ_Canopy_Leaves"
    },
    {
      "x": -1,
      "y": 16,
      "z": 10,
      "name": "TFJ_Canopy_Leaves"
    },
    {
      "x": -1,
      "y": 13,
      "z": 11,
      "name": "TFJ_Canopy_Leaves"
    },
    {
      "x": 0,
      "y": 11,
      "z": -10,
      "name": "TFJ_Canopy_Leaves"
    },
    {
      "x": 0,
      "y": 15,
      "z": -10,
      "name": "TFJ_Canopy_Leaves"
    },
    {
      "x": 0,
      "y": 9,
      "z": -9,
      "name": "TFJ_Canopy_Leaves"
    },
    {
      "x": 0,
      "y": 10,
      "z": -9,
      "name": "TFJ_Canopy_Leaves"
    },
    {
      "x": 0,
      "y": 16,
      "z": -9,
      "name": "TFJ_Canopy_Leaves"
    },
    {
      "x": 0,
      "y": 8,
      "z": -8,
      "name": "TFJ_Canopy_Leaves"
    },
    {
      "x": 0,
      "y": 17,
      "z": -8,
      "name": "TFJ_Canopy_Leaves"
    },
    {
      "x": 0,
      "y": 17,
      "z": -7,
      "name": "TFJ_Canopy_Leaves"
    },
    {
      "x": 0,
      "y": 18,
      "z": -7,
      "name": "TFJ_Canopy_Leaves"
    },
    {
      "x": 0,
      "y": 8,
      "z": -6,
      "name": "TFJ_Titanwood_Log"
    },
    {
      "x": 0,
      "y": 8,
      "z": -5,
      "name": "TFJ_Titanwood_Log"
    },
    {
      "x": 0,
      "y": -5,
      "z": -4,
      "name": "TFJ_Titanwood_Log",
      "rotation": 1
    },
    {
      "x": 0,
      "y": -4,
      "z": -4,
      "name": "TFJ_Titanwood_Log"
    },
    {
      "x": 0,
      "y": -3,
      "z": -4,
      "name": "TFJ_Titanwood_Log",
      "rotation": 11
    },
    {
      "x": 0,
      "y": 6,
      "z": -4,
      "name": "TFJ_Titanwood_Log"
    },
    {
      "x": 0,
      "y": 7,
      "z": -4,
      "name": "TFJ_Titanwood_Log"
    },
    {
      "x": 0,
      "y": 8,
      "z": -4,
      "name": "TFJ_Titanwood_Log"
    },
    {
      "x": 0,
      "y": 22,
      "z": -4,
      "name": "TFJ_Canopy_Leaves"
    },
    {
      "x": 0,
      "y": -1,
      "z": -3,
      "name": "TFJ_Titanwood_Log"
    },
    {
      "x": 0,
      "y": 7,
      "z": -3,
      "name": "TFJ_Titanwood_Log"
    },
    {
      "x": 0,
      "y": 21,
      "z": -3,
      "name": "TFJ_Canopy_Leaves"
    },
    {
      "x": 0,
      "y": 22,
      "z": -3,
      "name": "TFJ_Canopy_Leaves"
    },
    {
      "x": 0,
      "y": -2,
      "z": -2,
      "name": "TFJ_Titanwood_Log"
    },
    {
      "x": 0,
      "y": -1,
      "z": -2,
      "name": "TFJ_Titanwood_Log"
    },
    {
      "x": 0,
      "y": 0,
      "z": -2,
      "name": "TFJ_Titanwood_Log"
    },
    {
      "x": 0,
      "y": 6,
      "z": -2,
      "name": "TFJ_Titanwood_Log"
    },
    {
      "x": 0,
      "y": 7,
      "z": -2,
      "name": "TFJ_Titanwood_Log"
    },
    {
      "x": 0,
      "y": 22,
      "z": -2,
      "name": "TFJ_Canopy_Leaves"
    },
    {
      "x": 0,
      "y": 23,
      "z": -2,
      "name": "TFJ_Canopy_Leaves"
    },
    {
      "x": 0,
      "y": -4,
      "z": -1,
      "name": "TFJ_Titanwood_Log"
    },
    {
      "x": 0,
      "y": -3,
      "z": -1,
      "name": "TFJ_Titanwood_Log"
    },
    {
      "x": 0,
      "y": -2,
      "z": -1,
      "name": "TFJ_Titanwood_Log"
    },
    {
      "x": 0,
      "y": -1,
      "z": -1,
      "name": "TFJ_Titanwood_Log"
    },
    {
      "x": 0,
      "y": 0,
      "z": -1,
      "name": "TFJ_Titanwood_Log"
    },
    {
      "x": 0,
      "y": 1,
      "z": -1,
      "name": "TFJ_Titanwood_Log"
    },
    {
      "x": 0,
      "y": 2,
      "z": -1,
      "name": "TFJ_Titanwood_Log"
    },
    {
      "x": 0,
      "y": 3,
      "z": -1,
      "name": "TFJ_Titanwood_Log"
    },
    {
      "x": 0,
      "y": 4,
      "z": -1,
      "name": "TFJ_Titanwood_Log"
    },
    {
      "x": 0,
      "y": 5,
      "z": -1,
      "name": "TFJ_Titanwood_Log"
    },
    {
      "x": 0,
      "y": 6,
      "z": -1,
      "name": "TFJ_Titanwood_Log"
    },
    {
      "x": 0,
      "y": 7,
      "z": -1,
      "name": "TFJ_Titanwood_Log"
    },
    {
      "x": 0,
      "y": 8,
      "z": -1,
      "name": "TFJ_Titanwood_Log"
    },
    {
      "x": 0,
      "y": 9,
      "z": -1,
      "name": "TFJ_Titanwood_Log"
    },
    {
      "x": 0,
      "y": 10,
      "z": -1,
      "name": "TFJ_Titanwood_Log"
    },
    {
      "x": 0,
      "y": 11,
      "z": -1,
      "name": "TFJ_Titanwood_Log"
    },
    {
      "x": 0,
      "y": 12,
      "z": -1,
      "name": "TFJ_Titanwood_Log"
    },
    {
      "x": 0,
      "y": 13,
      "z": -1,
      "name": "TFJ_Titanwood_Log"
    },
    {
      "x": 0,
      "y": 14,
      "z": -1,
      "name": "TFJ_Titanwood_Log"
    },
    {
      "x": 0,
      "y": 19,
      "z": -1,
      "name": "TFJ_Titanwood_Log"
    },
    {
      "x": 0,
      "y": 22,
      "z": -1,
      "name": "TFJ_Canopy_Leaves"
    },
    {
      "x": 0,
      "y": 23,
      "z": -1,
      "name": "TFJ_Canopy_Leaves"
    },
    {
      "x": 0,
      "y": -3,
      "z": 0,
      "name": "TFJ_Titanwood_Log"
    },
    {
      "x": 0,
      "y": -2,
      "z": 0,
      "name": "TFJ_Titanwood_Log"
    },
    {
      "x": 0,
      "y": -1,
      "z": 0,
      "name": "TFJ_Titanwood_Log"
    },
    {
      "x": 0,
      "y": 0,
      "z": 0,
      "name": "TFJ_Titanwood_Log"
    },
    {
      "x": 0,
      "y": 1,
      "z": 0,
      "name": "TFJ_Titanwood_Log"
    },
    {
      "x": 0,
      "y": 2,
      "z": 0,
      "name": "TFJ_Titanwood_Log"
    },
    {
      "x": 0,
      "y": 3,
      "z": 0,
      "name": "TFJ_Titanwood_Log"
    },
    {
      "x": 0,
      "y": 4,
      "z": 0,
      "name": "TFJ_Titanwood_Log"
    },
    {
      "x": 0,
      "y": 5,
      "z": 0,
      "name": "TFJ_Titanwood_Log"
    },
    {
      "x": 0,
      "y": 6,
      "z": 0,
      "name": "TFJ_Titanwood_Log"
    },
    {
      "x": 0,
      "y": 7,
      "z": 0,
      "name": "TFJ_Titanwood_Log"
    },
    {
      "x": 0,
      "y": 8,
      "z": 0,
      "name": "TFJ_Titanwood_Log"
    },
    {
      "x": 0,
      "y": 9,
      "z": 0,
      "name": "TFJ_Titanwood_Log"
    },
    {
      "x": 0,
      "y": 10,
      "z": 0,
      "name": "TFJ_Titanwood_Log"
    },
    {
      "x": 0,
      "y": 11,
      "z": 0,
      "name": "TFJ_Titanwood_Log"
    },
    {
      "x": 0,
      "y": 12,
      "z": 0,
      "name": "TFJ_Titanwood_Log"
    },
    {
      "x": 0,
      "y": 13,
      "z": 0,
      "name": "TFJ_Titanwood_Log"
    },
    {
      "x": 0,
      "y": 14,
      "z": 0,
      "name": "TFJ_Titanwood_Log"
    },
    {
      "x": 0,
      "y": 15,
      "z": 0,
      "name": "TFJ_Titanwood_Log"
    },
    {
      "x": 0,
      "y": 16,
      "z": 0,
      "name": "TFJ_Titanwood_Log"
    },
    {
      "x": 0,
      "y": 17,
      "z": 0,
      "name": "TFJ_Titanwood_Log"
    },
    {
      "x": 0,
      "y": 18,
      "z": 0,
      "name": "TFJ_Titanwood_Log"
    },
    {
      "x": 0,
      "y": 19,
      "z": 0,
      "name": "TFJ_Titanwood_Log"
    },
    {
      "x": 0,
      "y": 20,
      "z": 0,
      "name": "TFJ_Titanwood_Log"
    },
    {
      "x": 0,
      "y": 21,
      "z": 0,
      "name": "TFJ_Titanwood_Log"
    },
    {
      "x": 0,
      "y": 22,
      "z": 0,
      "name": "TFJ_Canopy_Leaves"
    },
    {
      "x": 0,
      "y": 23,
      "z": 0,
      "name": "TFJ_Canopy_Leaves"
    },
    {
      "x": 0,
      "y": -5,
      "z": 1,
      "name": "TFJ_Titanwood_Log"
    },
    {
      "x": 0,
      "y": -4,
      "z": 1,
      "name": "TFJ_Titanwood_Log"
    },
    {
      "x": 0,
      "y": -3,
      "z": 1,
      "name": "TFJ_Titanwood_Log"
    },
    {
      "x": 0,
      "y": -2,
      "z": 1,
      "name": "TFJ_Titanwood_Log"
    },
    {
      "x": 0,
      "y": -1,
      "z": 1,
      "name": "TFJ_Titanwood_Log"
    },
    {
      "x": 0,
      "y": 0,
      "z": 1,
      "name": "TFJ_Titanwood_Log"
    },
    {
      "x": 0,
      "y": 1,
      "z": 1,
      "name": "TFJ_Titanwood_Log"
    },
    {
      "x": 0,
      "y": 2,
      "z": 1,
      "name": "TFJ_Titanwood_Log"
    },
    {
      "x": 0,
      "y": 3,
      "z": 1,
      "name": "TFJ_Titanwood_Log"
    },
    {
      "x": 0,
      "y": 4,
      "z": 1,
      "name": "TFJ_Titanwood_Log"
    },
    {
      "x": 0,
      "y": 5,
      "z": 1,
      "name": "TFJ_Titanwood_Log"
    },
    {
      "x": 0,
      "y": 6,
      "z": 1,
      "name": "TFJ_Titanwood_Log"
    },
    {
      "x": 0,
      "y": 7,
      "z": 1,
      "name": "TFJ_Titanwood_Log"
    },
    {
      "x": 0,
      "y": 11,
      "z": 1,
      "name": "TFJ_Titanwood_Log"
    },
    {
      "x": 0,
      "y": 12,
      "z": 1,
      "name": "TFJ_Titanwood_Log"
    },
    {
      "x": 0,
      "y": 15,
      "z": 1,
      "name": "TFJ_Titanwood_Log"
    },
    {
      "x": 0,
      "y": 16,
      "z": 1,
      "name": "TFJ_Titanwood_Log"
    },
    {
      "x": 0,
      "y": 17,
      "z": 1,
      "name": "TFJ_Titanwood_Log"
    },
    {
      "x": 0,
      "y": 18,
      "z": 1,
      "name": "TFJ_Titanwood_Log"
    },
    {
      "x": 0,
      "y": 22,
      "z": 1,
      "name": "TFJ_Canopy_Leaves"
    },
    {
      "x": 0,
      "y": 23,
      "z": 1,
      "name": "TFJ_Canopy_Leaves"
    },
    {
      "x": 0,
      "y": 24,
      "z": 1,
      "name": "TFJ_Canopy_Leaves"
    },
    {
      "x": 0,
      "y": 2,
      "z": 2,
      "name": "Plant_Crop_Mushroom_Shelve_Brown"
    },
    {
      "x": 0,
      "y": 3,
      "z": 2,
      "name": "Plant_Crop_Mushroom_Shelve_Brown"
    },
    {
      "x": 0,
      "y": 6,
      "z": 2,
      "name": "TFJ_Titanwood_Log"
    },
    {
      "x": 0,
      "y": 7,
      "z": 2,
      "name": "TFJ_Titanwood_Log"
    },
    {
      "x": 0,
      "y": 12,
      "z": 2,
      "name": "TFJ_Titanwood_Log"
    },
    {
      "x": 0,
      "y": 13,
      "z": 2,
      "name": "TFJ_Titanwood_Log"
    },
    {
      "x": 0,
      "y": 18,
      "z": 2,
      "name": "TFJ_Titanwood_Log"
    },
    {
      "x": 0,
      "y": 19,
      "z": 2,
      "name": "TFJ_Titanwood_Log"
    },
    {
      "x": 0,
      "y": 20,
      "z": 2,
      "name": "TFJ_Titanwood_Log"
    },
    {
      "x": 0,
      "y": 21,
      "z": 2,
      "name": "TFJ_Titanwood_Log"
    },
    {
      "x": 0,
      "y": 22,
      "z": 2,
      "name": "TFJ_Titanwood_Log"
    },
    {
      "x": 0,
      "y": 23,
      "z": 2,
      "name": "TFJ_Titanwood_Log"
    },
    {
      "x": 0,
      "y": 24,
      "z": 2,
      "name": "TFJ_Canopy_Leaves"
    },
    {
      "x": 0,
      "y": 7,
      "z": 3,
      "name": "TFJ_Titanwood_Log"
    },
    {
      "x": 0,
      "y": 13,
      "z": 3,
      "name": "TFJ_Titanwood_Log"
    },
    {
      "x": 0,
      "y": 19,
      "z": 3,
      "name": "TFJ_Titanwood_Log",
      "rotation": 4
    },
    {
      "x": 0,
      "y": 21,
      "z": 3,
      "name": "TFJ_Canopy_Leaves"
    },
    {
      "x": 0,
      "y": 23,
      "z": 3,
      "name": "TFJ_Canopy_Leaves"
    },
    {
      "x": 0,
      "y": 7,
      "z": 4,
      "name": "TFJ_Titanwood_Log"
    },
    {
      "x": 0,
      "y": 8,
      "z": 4,
      "name": "TFJ_Titanwood_Log"
    },
    {
      "x": 0,
      "y": 13,
      "z": 4,
      "name": "TFJ_Titanwood_Log"
    },
    {
      "x": 0,
      "y": 14,
      "z": 4,
      "name": "TFJ_Titanwood_Log"
    },
    {
      "x": 0,
      "y": 19,
      "z": 4,
      "name": "TFJ_Titanwood_Log"
    },
    {
      "x": 0,
      "y": 20,
      "z": 4,
      "name": "TFJ_Titanwood_Log"
    },
    {
      "x": 0,
      "y": 21,
      "z": 4,
      "name": "TFJ_Canopy_Leaves"
    },
    {
      "x": 0,
      "y": 22,
      "z": 4,
      "name": "TFJ_Canopy_Leaves"
    },
    {
      "x": 0,
      "y": 14,
      "z": 5,
      "name": "TFJ_Titanwood_Log"
    },
    {
      "x": 0,
      "y": 15,
      "z": 5,
      "name": "TFJ_Titanwood_Log"
    },
    {
      "x": 0,
      "y": 21,
      "z": 5,
      "name": "TFJ_Canopy_Leaves"
    },
    {
      "x": 0,
      "y": 14,
      "z": 6,
      "name": "TFJ_Titanwood_Log",
      "rotation": 4
    },
    {
      "x": 0,
      "y": 20,
      "z": 6,
      "name": "TFJ_Canopy_Leaves"
    },
    {
      "x": 0,
      "y": 9,
      "z": 7,
      "name": "TFJ_Canopy_Leaves"
    },
    {
      "x": 0,
      "y": 14,
      "z": 7,
      "name": "TFJ_Titanwood_Log",
      "rotation": 4
    },
    {
      "x": 0,
      "y": 19,
      "z": 7,
      "name": "TFJ_Canopy_Leaves"
    },
    {
      "x": 0,
      "y": 20,
      "z": 7,
      "name": "TFJ_Canopy_Leaves"
    },
    {
      "x": 0,
      "y": 21,
      "z": 7,
      "name": "TFJ_Canopy_Leaves"
    },
    {
      "x": 0,
      "y": 8,
      "z": 8,
      "name": "TFJ_Canopy_Leaves"
    },
    {
      "x": 0,
      "y": 9,
      "z": 8,
      "name": "TFJ_Canopy_Leaves"
    },
    {
      "x": 0,
      "y": 14,
      "z": 8,
      "name": "TFJ_Titanwood_Log"
    },
    {
      "x": 0,
      "y": 15,
      "z": 8,
      "name": "TFJ_Titanwood_Log",
      "rotation": 8
    },
    {
      "x": 0,
      "y": 18,
      "z": 8,
      "name": "TFJ_Canopy_Leaves"
    },
    {
      "x": 0,
      "y": 19,
      "z": 8,
      "name": "TFJ_Canopy_Leaves"
    },
    {
      "x": 0,
      "y": 10,
      "z": 9,
      "name": "TFJ_Canopy_Leaves"
    },
    {
      "x": 0,
      "y": 15,
      "z": 9,
      "name": "TFJ_Titanwood_Log",
      "rotation": 4
    },
    {
      "x": 0,
      "y": 16,
      "z": 9,
      "name": "TFJ_Canopy_Leaves"
    },
    {
      "x": 0,
      "y": 18,
      "z": 9,
      "name": "TFJ_Canopy_Leaves"
    },
    {
      "x": 0,
      "y": 19,
      "z": 9,
      "name": "TFJ_Canopy_Leaves"
    },
    {
      "x": 0,
      "y": 12,
      "z": 10,
      "name": "TFJ_Canopy_Leaves"
    },
    {
      "x": 0,
      "y": 13,
      "z": 10,
      "name": "TFJ_Canopy_Leaves"
    },
    {
      "x": 0,
      "y": 14,
      "z": 10,
      "name": "TFJ_Canopy_Leaves"
    },
    {
      "x": 0,
      "y": 15,
      "z": 10,
      "name": "TFJ_Canopy_Leaves"
    },
    {
      "x": 0,
      "y": 16,
      "z": 10,
      "name": "TFJ_Canopy_Leaves"
    },
    {
      "x": 0,
      "y": 18,
      "z": 10,
      "name": "TFJ_Canopy_Leaves"
    },
    {
      "x": 0,
      "y": 12,
      "z": 11,
      "name": "TFJ_Canopy_Leaves"
    },
    {
      "x": 0,
      "y": 13,
      "z": 11,
      "name": "TFJ_Canopy_Leaves"
    },
    {
      "x": 0,
      "y": 14,
      "z": 11,
      "name": "TFJ_Canopy_Leaves"
    },
    {
      "x": 0,
      "y": 15,
      "z": 11,
      "name": "TFJ_Canopy_Leaves"
    },
    {
      "x": 1,
      "y": 14,
      "z": -11,
      "name": "TFJ_Canopy_Leaves"
    },
    {
      "x": 1,
      "y": 15,
      "z": -11,
      "name": "TFJ_Canopy_Leaves"
    },
    {
      "x": 1,
      "y": 9,
      "z": -10,
      "name": "TFJ_Canopy_Leaves"
    },
    {
      "x": 1,
      "y": 10,
      "z": -10,
      "name": "TFJ_Canopy_Leaves"
    },
    {
      "x": 1,
      "y": 11,
      "z": -10,
      "name": "TFJ_Canopy_Leaves"
    },
    {
      "x": 1,
      "y": 12,
      "z": -10,
      "name": "TFJ_Canopy_Leaves"
    },
    {
      "x": 1,
      "y": 14,
      "z": -10,
      "name": "TFJ_Canopy_Leaves"
    },
    {
      "x": 1,
      "y": 15,
      "z": -10,
      "name": "TFJ_Canopy_Leaves"
    },
    {
      "x": 1,
      "y": 16,
      "z": -10,
      "name": "TFJ_Canopy_Leaves"
    },
    {
      "x": 1,
      "y": 8,
      "z": -9,
      "name": "TFJ_Canopy_Leaves"
    },
    {
      "x": 1,
      "y": 9,
      "z": -9,
      "name": "TFJ_Titanwood_Log",
      "rotation": 4
    },
    {
      "x": 1,
      "y": 10,
      "z": -9,
      "name": "TFJ_Canopy_Leaves"
    },
    {
      "x": 1,
      "y": 11,
      "z": -9,
      "name": "TFJ_Canopy_Leaves"
    },
    {
      "x": 1,
      "y": 15,
      "z": -9,
      "name": "TFJ_Canopy_Leaves"
    },
    {
      "x": 1,
      "y": 16,
      "z": -9,
      "name": "TFJ_Canopy_Leaves"
    },
    {
      "x": 1,
      "y": 7,
      "z": -8,
      "name": "TFJ_Canopy_Leaves"
    },
    {
      "x": 1,
      "y": 8,
      "z": -8,
      "name": "TFJ_Canopy_Leaves"
    },
    {
      "x": 1,
      "y": 9,
      "z": -8,
      "name": "TFJ_Titanwood_Log",
      "rotation": 4
    },
    {
      "x": 1,
      "y": 17,
      "z": -8,
      "name": "TFJ_Canopy_Leaves"
    },
    {
      "x": 1,
      "y": 9,
      "z": -7,
      "name": "TFJ_Titanwood_Log"
    },
    {
      "x": 1,
      "y": 16,
      "z": -7,
      "name": "TFJ_Canopy_Leaves"
    },
    {
      "x": 1,
      "y": 17,
      "z": -7,
      "name": "TFJ_Canopy_Leaves"
    },
    {
      "x": 1,
      "y": 18,
      "z": -7,
      "name": "TFJ_Canopy_Leaves"
    },
    {
      "x": 1,
      "y": 19,
      "z": -7,
      "name": "TFJ_Canopy_Leaves"
    },
    {
      "x": 1,
      "y": 8,
      "z": -6,
      "name": "TFJ_Titanwood_Log"
    },
    {
      "x": 1,
      "y": 9,
      "z": -6,
      "name": "TFJ_Titanwood_Log"
    },
    {
      "x": 1,
      "y": 19,
      "z": -6,
      "name": "TFJ_Canopy_Leaves"
    },
    {
      "x": 1,
      "y": 20,
      "z": -6,
      "name": "TFJ_Canopy_Leaves"
    },
    {
      "x": 1,
      "y": 22,
      "z": -5,
      "name": "TFJ_Canopy_Leaves"
    },
    {
      "x": 1,
      "y": 22,
      "z": -4,
      "name": "TFJ_Canopy_Leaves"
    },
    {
      "x": 1,
      "y": 22,
      "z": -3,
      "name": "TFJ_Canopy_Leaves"
    },
    {
      "x": 1,
      "y": 23,
      "z": -3,
      "name": "TFJ_Canopy_Leaves"
    },
    {
      "x": 1,
      "y": 7,
      "z": -2,
      "name": "Plant_Crop_Mushroom_Shelve_Brown"
    },
    {
      "x": 1,
      "y": 23,
      "z": -2,
      "name": "TFJ_Canopy_Leaves"
    },
    {
      "x": 1,
      "y": 24,
      "z": -2,
      "name": "TFJ_Canopy_Leaves"
    },
    {
      "x": 1,
      "y": -5,
      "z": -1,
      "name": "TFJ_Titanwood_Log"
    },
    {
      "x": 1,
      "y": -4,
      "z": -1,
      "name": "TFJ_Titanwood_Log"
    },
    {
      "x": 1,
      "y": -2,
      "z": -1,
      "name": "TFJ_Titanwood_Log"
    },
    {
      "x": 1,
      "y": -1,
      "z": -1,
      "name": "TFJ_Titanwood_Log"
    },
    {
      "x": 1,
      "y": 6,
      "z": -1,
      "name": "Plant_Crop_Mushroom_Shelve_Brown"
    },
    {
      "x": 1,
      "y": 7,
      "z": -1,
      "name": "TFJ_Titanwood_Log"
    },
    {
      "x": 1,
      "y": 8,
      "z": -1,
      "name": "TFJ_Titanwood_Log"
    },
    {
      "x": 1,
      "y": 11,
      "z": -1,
      "name": "TFJ_Titanwood_Log"
    },
    {
      "x": 1,
      "y": 12,
      "z": -1,
      "name": "TFJ_Titanwood_Log"
    },
    {
      "x": 1,
      "y": 19,
      "z": -1,
      "name": "TFJ_Titanwood_Log"
    },
    {
      "x": 1,
      "y": 20,
      "z": -1,
      "name": "TFJ_Titanwood_Log"
    },
    {
      "x": 1,
      "y": 21,
      "z": -1,
      "name": "TFJ_Titanwood_Log"
    },
    {
      "x": 1,
      "y": 22,
      "z": -1,
      "name": "TFJ_Titanwood_Log"
    },
    {
      "x": 1,
      "y": 23,
      "z": -1,
      "name": "TFJ_Titanwood_Log"
    },
    {
      "x": 1,
      "y": 24,
      "z": -1,
      "name": "TFJ_Canopy_Leaves"
    },
    {
      "x": 1,
      "y": -2,
      "z": 0,
      "name": "TFJ_Titanwood_Log"
    },
    {
      "x": 1,
      "y": -1,
      "z": 0,
      "name": "TFJ_Titanwood_Log"
    },
    {
      "x": 1,
      "y": 0,
      "z": 0,
      "name": "TFJ_Titanwood_Log"
    },
    {
      "x": 1,
      "y": 1,
      "z": 0,
      "name": "TFJ_Titanwood_Log"
    },
    {
      "x": 1,
      "y": 2,
      "z": 0,
      "name": "TFJ_Titanwood_Log"
    },
    {
      "x": 1,
      "y": 3,
      "z": 0,
      "name": "TFJ_Titanwood_Log"
    },
    {
      "x": 1,
      "y": 6,
      "z": 0,
      "name": "TFJ_Titanwood_Log"
    },
    {
      "x": 1,
      "y": 7,
      "z": 0,
      "name": "TFJ_Titanwood_Log"
    },
    {
      "x": 1,
      "y": 8,
      "z": 0,
      "name": "TFJ_Titanwood_Log"
    },
    {
      "x": 1,
      "y": 9,
      "z": 0,
      "name": "TFJ_Titanwood_Log"
    },
    {
      "x": 1,
      "y": 10,
      "z": 0,
      "name": "TFJ_Titanwood_Log"
    },
    {
      "x": 1,
      "y": 11,
      "z": 0,
      "name": "TFJ_Titanwood_Log"
    },
    {
      "x": 1,
      "y": 12,
      "z": 0,
      "name": "TFJ_Titanwood_Log"
    },
    {
      "x": 1,
      "y": 13,
      "z": 0,
      "name": "TFJ_Titanwood_Log"
    },
    {
      "x": 1,
      "y": 14,
      "z": 0,
      "name": "TFJ_Titanwood_Log"
    },
    {
      "x": 1,
      "y": 15,
      "z": 0,
      "name": "TFJ_Titanwood_Log"
    },
    {
      "x": 1,
      "y": 16,
      "z": 0,
      "name": "TFJ_Titanwood_Log"
    },
    {
      "x": 1,
      "y": 22,
      "z": 0,
      "name": "TFJ_Canopy_Leaves"
    },
    {
      "x": 1,
      "y": -2,
      "z": 1,
      "name": "TFJ_Titanwood_Log"
    },
    {
      "x": 1,
      "y": -1,
      "z": 1,
      "name": "TFJ_Titanwood_Log"
    },
    {
      "x": 1,
      "y": 0,
      "z": 1,
      "name": "TFJ_Titanwood_Log"
    },
    {
      "x": 1,
      "y": 1,
      "z": 1,
      "name": "TFJ_Titanwood_Log"
    },
    {
      "x": 1,
      "y": 2,
      "z": 1,
      "name": "TFJ_Titanwood_Log"
    },
    {
      "x": 1,
      "y": 3,
      "z": 1,
      "name": "Plant_Crop_Mushroom_Shelve_Brown"
    },
    {
      "x": 1,
      "y": 22,
      "z": 1,
      "name": "TFJ_Canopy_Leaves"
    },
    {
      "x": 1,
      "y": 23,
      "z": 1,
      "name": "TFJ_Canopy_Leaves"
    },
    {
      "x": 1,
      "y": 24,
      "z": 1,
      "name": "TFJ_Canopy_Leaves"
    },
    {
      "x": 1,
      "y": -2,
      "z": 2,
      "name": "TFJ_Titanwood_Log"
    },
    {
      "x": 1,
      "y": -1,
      "z": 2,
      "name": "TFJ_Titanwood_Log"
    },
    {
      "x": 1,
      "y": 0,
      "z": 2,
      "name": "TFJ_Titanwood_Log"
    },
    {
      "x": 1,
      "y": 1,
      "z": 2,
      "name": "Plant_Crop_Mushroom_Shelve_Brown"
    },
    {
      "x": 1,
      "y": 2,
      "z": 2,
      "name": "Plant_Crop_Mushroom_Shelve_Brown"
    },
    {
      "x": 1,
      "y": 22,
      "z": 2,
      "name": "TFJ_Canopy_Leaves"
    },
    {
      "x": 1,
      "y": 24,
      "z": 2,
      "name": "TFJ_Canopy_Leaves"
    },
    {
      "x": 1,
      "y": -3,
      "z": 3,
      "name": "TFJ_Titanwood_Log"
    },
    {
      "x": 1,
      "y": -2,
      "z": 3,
      "name": "TFJ_Titanwood_Log"
    },
    {
      "x": 1,
      "y": 21,
      "z": 3,
      "name": "TFJ_Canopy_Leaves"
    },
    {
      "x": 1,
      "y": 22,
      "z": 3,
      "name": "TFJ_Canopy_Leaves"
    },
    {
      "x": 1,
      "y": 23,
      "z": 3,
      "name": "TFJ_Canopy_Leaves"
    },
    {
      "x": 1,
      "y": 24,
      "z": 3,
      "name": "TFJ_Canopy_Leaves"
    },
    {
      "x": 1,
      "y": 8,
      "z": 4,
      "name": "TFJ_Titanwood_Log"
    },
    {
      "x": 1,
      "y": 9,
      "z": 4,
      "name": "TFJ_Titanwood_Log"
    },
    {
      "x": 1,
      "y": 21,
      "z": 4,
      "name": "TFJ_Canopy_Leaves"
    },
    {
      "x": 1,
      "y": 22,
      "z": 4,
      "name": "TFJ_Canopy_Leaves"
    },
    {
      "x": 1,
      "y": 23,
      "z": 4,
      "name": "TFJ_Canopy_Leaves"
    },
    {
      "x": 1,
      "y": 7,
      "z": 5,
      "name": "TFJ_Titanwood_Log"
    },
    {
      "x": 1,
      "y": 8,
      "z": 5,
      "name": "TFJ_Titanwood_Log"
    },
    {
      "x": 1,
      "y": 15,
      "z": 5,
      "name": "TFJ_Titanwood_Log"
    },
    {
      "x": 1,
      "y": 16,
      "z": 5,
      "name": "TFJ_Titanwood_Log"
    },
    {
      "x": 1,
      "y": 21,
      "z": 5,
      "name": "TFJ_Canopy_Leaves"
    },
    {
      "x": 1,
      "y": 22,
      "z": 5,
      "name": "TFJ_Canopy_Leaves"
    },
    {
      "x": 1,
      "y": 8,
      "z": 6,
      "name": "TFJ_Titanwood_Log"
    },
    {
      "x": 1,
      "y": 9,
      "z": 6,
      "name": "TFJ_Titanwood_Log",
      "rotation": 8
    },
    {
      "x": 1,
      "y": 15,
      "z": 6,
      "name": "TFJ_Titanwood_Log"
    },
    {
      "x": 1,
      "y": 18,
      "z": 6,
      "name": "TFJ_Canopy_Leaves"
    },
    {
      "x": 1,
      "y": 20,
      "z": 6,
      "name": "TFJ_Canopy_Leaves"
    },
    {
      "x": 1,
      "y": 21,
      "z": 6,
      "name": "TFJ_Canopy_Leaves"
    },
    {
      "x": 1,
      "y": 9,
      "z": 7,
      "name": "TFJ_Titanwood_Log",
      "rotation": 4
    },
    {
      "x": 1,
      "y": 15,
      "z": 7,
      "name": "TFJ_Titanwood_Log"
    },
    {
      "x": 1,
      "y": 16,
      "z": 7,
      "name": "TFJ_Titanwood_Log"
    },
    {
      "x": 1,
      "y": 17,
      "z": 7,
      "name": "TFJ_Titanwood_Log"
    },
    {
      "x": 1,
      "y": 18,
      "z": 7,
      "name": "TFJ_Titanwood_Log",
      "rotation": 8
    },
    {
      "x": 1,
      "y": 19,
      "z": 7,
      "name": "TFJ_Canopy_Leaves"
    },
    {
      "x": 1,
      "y": 20,
      "z": 7,
      "name": "TFJ_Canopy_Leaves"
    },
    {
      "x": 1,
      "y": 21,
      "z": 7,
      "name": "TFJ_Canopy_Leaves"
    },
    {
      "x": 1,
      "y": 7,
      "z": 8,
      "name": "TFJ_Canopy_Leaves"
    },
    {
      "x": 1,
      "y": 8,
      "z": 8,
      "name": "TFJ_Canopy_Leaves"
    },
    {
      "x": 1,
      "y": 9,
      "z": 8,
      "name": "TFJ_Titanwood_Log",
      "rotation": 4
    },
    {
      "x": 1,
      "y": 17,
      "z": 8,
      "name": "TFJ_Canopy_Leaves"
    },
    {
      "x": 1,
      "y": 18,
      "z": 8,
      "name": "TFJ_Canopy_Leaves"
    },
    {
      "x": 1,
      "y": 19,
      "z": 8,
      "name": "TFJ_Canopy_Leaves"
    },
    {
      "x": 1,
      "y": 20,
      "z": 8,
      "name": "TFJ_Canopy_Leaves"
    },
    {
      "x": 1,
      "y": 8,
      "z": 9,
      "name": "TFJ_Canopy_Leaves"
    },
    {
      "x": 1,
      "y": 9,
      "z": 9,
      "name": "TFJ_Canopy_Leaves"
    },
    {
      "x": 1,
      "y": 10,
      "z": 9,
      "name": "TFJ_Canopy_Leaves"
    },
    {
      "x": 1,
      "y": 14,
      "z": 9,
      "name": "TFJ_Canopy_Leaves"
    },
    {
      "x": 1,
      "y": 18,
      "z": 9,
      "name": "TFJ_Canopy_Leaves"
    },
    {
      "x": 1,
      "y": 10,
      "z": 10,
      "name": "TFJ_Canopy_Leaves"
    },
    {
      "x": 1,
      "y": 12,
      "z": 10,
      "name": "TFJ_Canopy_Leaves"
    },
    {
      "x": 1,
      "y": 13,
      "z": 10,
      "name": "TFJ_Canopy_Leaves"
    },
    {
      "x": 1,
      "y": 14,
      "z": 10,
      "name": "TFJ_Canopy_Leaves"
    },
    {
      "x": 1,
      "y": 15,
      "z": 10,
      "name": "TFJ_Canopy_Leaves"
    },
    {
      "x": 1,
      "y": 13,
      "z": 11,
      "name": "TFJ_Canopy_Leaves"
    },
    {
      "x": 1,
      "y": 14,
      "z": 11,
      "name": "TFJ_Canopy_Leaves"
    },
    {
      "x": 2,
      "y": 14,
      "z": -11,
      "name": "TFJ_Canopy_Leaves"
    },
    {
      "x": 2,
      "y": 8,
      "z": -10,
      "name": "TFJ_Canopy_Leaves"
    },
    {
      "x": 2,
      "y": 9,
      "z": -10,
      "name": "TFJ_Canopy_Leaves"
    },
    {
      "x": 2,
      "y": 10,
      "z": -10,
      "name": "TFJ_Canopy_Leaves"
    },
    {
      "x": 2,
      "y": 14,
      "z": -10,
      "name": "TFJ_Canopy_Leaves"
    },
    {
      "x": 2,
      "y": 15,
      "z": -10,
      "name": "TFJ_Canopy_Leaves"
    },
    {
      "x": 2,
      "y": 16,
      "z": -10,
      "name": "TFJ_Canopy_Leaves"
    },
    {
      "x": 2,
      "y": 17,
      "z": -10,
      "name": "TFJ_Canopy_Leaves"
    },
    {
      "x": 2,
      "y": 8,
      "z": -9,
      "name": "TFJ_Canopy_Leaves"
    },
    {
      "x": 2,
      "y": 9,
      "z": -9,
      "name": "TFJ_Canopy_Leaves"
    },
    {
      "x": 2,
      "y": 10,
      "z": -9,
      "name": "TFJ_Canopy_Leaves"
    },
    {
      "x": 2,
      "y": 11,
      "z": -9,
      "name": "TFJ_Canopy_Leaves"
    },
    {
      "x": 2,
      "y": 12,
      "z": -9,
      "name": "TFJ_Canopy_Leaves"
    },
    {
      "x": 2,
      "y": 15,
      "z": -9,
      "name": "TFJ_Canopy_Leaves"
    },
    {
      "x": 2,
      "y": 16,
      "z": -9,
      "name": "TFJ_Titanwood_Log",
      "rotation": 4
    },
    {
      "x": 2,
      "y": 17,
      "z": -9,
      "name": "TFJ_Canopy_Leaves"
    },
    {
      "x": 2,
      "y": 7,
      "z": -8,
      "name": "TFJ_Canopy_Leaves"
    },
    {
      "x": 2,
      "y": 8,
      "z": -8,
      "name": "TFJ_Canopy_Leaves"
    },
    {
      "x": 2,
      "y": 10,
      "z": -8,
      "name": "TFJ_Titanwood_Log",
      "rotation": 4
    },
    {
      "x": 2,
      "y": 15,
      "z": -8,
      "name": "TFJ_Canopy_Leaves"
    },
    {
      "x": 2,
      "y": 16,
      "z": -8,
      "name": "TFJ_Titanwood_Log",
      "rotation": 4
    },
    {
      "x": 2,
      "y": 18,
      "z": -8,
      "name": "TFJ_Canopy_Leaves"
    },
    {
      "x": 2,
      "y": 7,
      "z": -7,
      "name": "TFJ_Canopy_Leaves"
    },
    {
      "x": 2,
      "y": 9,
      "z": -7,
      "name": "TFJ_Titanwood_Log",
      "rotation": 1
    },
    {
      "x": 2,
      "y": 10,
      "z": -7,
      "name": "TFJ_Titanwood_Log",
      "rotation": 10
    },
    {
      "x": 2,
      "y": 15,
      "z": -7,
      "name": "TFJ_Titanwood_Log",
      "rotation": 3
    },
    {
      "x": 2,
      "y": 16,
      "z": -7,
      "name": "TFJ_Titanwood_Log",
      "rotation": 10
    },
    {
      "x": 2,
      "y": 17,
      "z": -7,
      "name": "TFJ_Canopy_Leaves"
    },
    {
      "x": 2,
      "y": 18,
      "z": -7,
      "name": "TFJ_Titanwood_Log",
      "rotation": 4
    },
    {
      "x": 2,
      "y": 19,
      "z": -7,
      "name": "TFJ_Canopy_Leaves"
    },
    {
      "x": 2,
      "y": 17,
      "z": -6,
      "name": "TFJ_Titanwood_Log",
      "rotation": 2
    },
    {
      "x": 2,
      "y": 18,
      "z": -6,
      "name": "TFJ_Titanwood_Log",
      "rotation": 10
    },
    {
      "x": 2,
      "y": 20,
      "z": -6,
      "name": "TFJ_Canopy_Leaves"
    },
    {
      "x": 2,
      "y": 14,
      "z": -5,
      "name": "TFJ_Titanwood_Log",
      "rotation": 3
    },
    {
      "x": 2,
      "y": 15,
      "z": -5,
      "name": "TFJ_Titanwood_Log"
    },
    {
      "x": 2,
      "y": 16,
      "z": -5,
      "name": "TFJ_Titanwood_Log"
    },
    {
      "x": 2,
      "y": 17,
      "z": -5,
      "name": "TFJ_Titanwood_Log",
      "rotation": 10
    },
    {
      "x": 2,
      "y": 23,
      "z": -3,
      "name": "TFJ_Canopy_Leaves"
    },
    {
      "x": 2,
      "y": 12,
      "z": -2,
      "name": "TFJ_Titanwood_Log"
    },
    {
      "x": 2,
      "y": 13,
      "z": -2,
      "name": "TFJ_Titanwood_Log"
    },
    {
      "x": 2,
      "y": 23,
      "z": -2,
      "name": "TFJ_Canopy_Leaves"
    },
    {
      "x": 2,
      "y": 8,
      "z": -1,
      "name": "TFJ_Titanwood_Log"
    },
    {
      "x": 2,
      "y": 12,
      "z": -1,
      "name": "TFJ_Titanwood_Log"
    },
    {
      "x": 2,
      "y": 22,
      "z": -1,
      "name": "TFJ_Canopy_Leaves"
    },
    {
      "x": 2,
      "y": 23,
      "z": -1,
      "name": "TFJ_Canopy_Leaves"
    },
    {
      "x": 2,
      "y": 24,
      "z": -1,
      "name": "TFJ_Canopy_Leaves"
    },
    {
      "x": 2,
      "y": -2,
      "z": 0,
      "name": "TFJ_Titanwood_Log"
    },
    {
      "x": 2,
      "y": -1,
      "z": 0,
      "name": "TFJ_Titanwood_Log"
    },
    {
      "x": 2,
      "y": 0,
      "z": 0,
      "name": "TFJ_Titanwood_Log"
    },
    {
      "x": 2,
      "y": 1,
      "z": 0,
      "name": "TFJ_Titanwood_Log"
    },
    {
      "x": 2,
      "y": 16,
      "z": 0,
      "name": "TFJ_Titanwood_Log"
    },
    {
      "x": 2,
      "y": 17,
      "z": 0,
      "name": "TFJ_Titanwood_Log"
    },
    {
      "x": 2,
      "y": 23,
      "z": 0,
      "name": "TFJ_Canopy_Leaves"
    },
    {
      "x": 2,
      "y": 22,
      "z": 1,
      "name": "TFJ_Canopy_Leaves"
    },
    {
      "x": 2,
      "y": 22,
      "z": 2,
      "name": "TFJ_Canopy_Leaves"
    },
    {
      "x": 2,
      "y": 23,
      "z": 2,
      "name": "TFJ_Canopy_Leaves"
    },
    {
      "x": 2,
      "y": -5,
      "z": 3,
      "name": "TFJ_Titanwood_Log",
      "rotation": 3
    },
    {
      "x": 2,
      "y": -4,
      "z": 3,
      "name": "TFJ_Titanwood_Log"
    },
    {
      "x": 2,
      "y": -3,
      "z": 3,
      "name": "TFJ_Titanwood_Log"
    },
    {
      "x": 2,
      "y": 21,
      "z": 3,
      "name": "TFJ_Canopy_Leaves"
    },
    {
      "x": 2,
      "y": 24,
      "z": 3,
      "name": "TFJ_Canopy_Leaves"
    },
    {
      "x": 2,
      "y": 9,
      "z": 4,
      "name": "TFJ_Titanwood_Log"
    },
    {
      "x": 2,
      "y": 10,
      "z": 4,
      "name": "TFJ_Titanwood_Log"
    },
    {
      "x": 2,
      "y": 21,
      "z": 4,
      "name": "TFJ_Canopy_Leaves"
    },
    {
      "x": 2,
      "y": 22,
      "z": 4,
      "name": "TFJ_Canopy_Leaves"
    },
    {
      "x": 2,
      "y": 10,
      "z": 5,
      "name": "TFJ_Titanwood_Log"
    },
    {
      "x": 2,
      "y": 11,
      "z": 5,
      "name": "TFJ_Titanwood_Log"
    },
    {
      "x": 2,
      "y": 16,
      "z": 5,
      "name": "TFJ_Titanwood_Log"
    },
    {
      "x": 2,
      "y": 17,
      "z": 5,
      "name": "TFJ_Titanwood_Log"
    },
    {
      "x": 2,
      "y": 18,
      "z": 5,
      "name": "TFJ_Titanwood_Log"
    },
    {
      "x": 2,
      "y": 19,
      "z": 5,
      "name": "TFJ_Titanwood_Log"
    },
    {
      "x": 2,
      "y": 20,
      "z": 5,
      "name": "TFJ_Canopy_Leaves"
    },
    {
      "x": 2,
      "y": 21,
      "z": 5,
      "name": "TFJ_Canopy_Leaves"
    },
    {
      "x": 2,
      "y": 22,
      "z": 5,
      "name": "TFJ_Canopy_Leaves"
    },
    {
      "x": 2,
      "y": 8,
      "z": 6,
      "name": "TFJ_Titanwood_Log",
      "rotation": 5
    },
    {
      "x": 2,
      "y": 18,
      "z": 6,
      "name": "TFJ_Canopy_Leaves"
    },
    {
      "x": 2,
      "y": 20,
      "z": 6,
      "name": "TFJ_Canopy_Leaves"
    },
    {
      "x": 2,
      "y": 21,
      "z": 6,
      "name": "TFJ_Canopy_Leaves"
    },
    {
      "x": 2,
      "y": 17,
      "z": 7,
      "name": "TFJ_Canopy_Leaves"
    },
    {
      "x": 2,
      "y": 18,
      "z": 7,
      "name": "TFJ_Canopy_Leaves"
    },
    {
      "x": 2,
      "y": 20,
      "z": 7,
      "name": "TFJ_Canopy_Leaves"
    },
    {
      "x": 2,
      "y": 7,
      "z": 8,
      "name": "TFJ_Canopy_Leaves"
    },
    {
      "x": 2,
      "y": 8,
      "z": 8,
      "name": "TFJ_Canopy_Leaves"
    },
    {
      "x": 2,
      "y": 9,
      "z": 8,
      "name": "TFJ_Canopy_Leaves"
    },
    {
      "x": 2,
      "y": 17,
      "z": 8,
      "name": "TFJ_Canopy_Leaves"
    },
    {
      "x": 2,
      "y": 18,
      "z": 8,
      "name": "TFJ_Canopy_Leaves"
    },
    {
      "x": 2,
      "y": 20,
      "z": 8,
      "name": "TFJ_Canopy_Leaves"
    },
    {
      "x": 2,
      "y": 7,
      "z": 9,
      "name": "TFJ_Canopy_Leaves"
    },
    {
      "x": 2,
      "y": 8,
      "z": 9,
      "name": "TFJ_Canopy_Leaves"
    },
    {
      "x": 2,
      "y": 9,
      "z": 9,
      "name": "TFJ_Canopy_Leaves"
    },
    {
      "x": 2,
      "y": 10,
      "z": 9,
      "name": "TFJ_Canopy_Leaves"
    },
    {
      "x": 2,
      "y": 17,
      "z": 9,
      "name": "TFJ_Canopy_Leaves"
    },
    {
      "x": 2,
      "y": 13,
      "z": 10,
      "name": "TFJ_Canopy_Leaves"
    },
    {
      "x": 2,
      "y": 14,
      "z": 10,
      "name": "TFJ_Canopy_Leaves"
    },
    {
      "x": 2,
      "y": 15,
      "z": 10,
      "name": "TFJ_Canopy_Leaves"
    },
    {
      "x": 2,
      "y": 17,
      "z": 10,
      "name": "TFJ_Canopy_Leaves"
    },
    {
      "x": 3,
      "y": 9,
      "z": -10,
      "name": "TFJ_Canopy_Leaves"
    },
    {
      "x": 3,
      "y": 15,
      "z": -10,
      "name": "TFJ_Canopy_Leaves"
    },
    {
      "x": 3,
      "y": 8,
      "z": -9,
      "name": "TFJ_Canopy_Leaves"
    },
    {
      "x": 3,
      "y": 9,
      "z": -9,
      "name": "TFJ_Canopy_Leaves"
    },
    {
      "x": 3,
      "y": 10,
      "z": -9,
      "name": "TFJ_Canopy_Leaves"
    },
    {
      "x": 3,
      "y": 11,
      "z": -9,
      "name": "TFJ_Canopy_Leaves"
    },
    {
      "x": 3,
      "y": 14,
